Workbook

Sheet Method
A1: Limerick Residential Pipeline – Method and Assumptions
A3: Assumptions (edit the yellow cells)
A4: Report date | B4: 46294 | C4: Date the register was queried. Used for staleness and expiry tests.
A5: Stale threshold (months) | B5: 24 | C5: A counted Permission Granted / Commencement Expected application with no CIS update for longer than this is reported as Constrained / uncertain until checked.
A6: Overlap search radius (m) | B6: 150 | C6: Used at build time to flag upstream records near another record. Changing it does not re-run the search.
A7: Location mismatch threshold (m) | B7: 500 | C7: Register point more than this far from the CIS point is flagged as a possible reference mismatch.
A10: Sources
A11: CIS granted/delivery export | B11: Granted/delivery records and their site grouping from the Existing Site Pipeline tab of Limerick_Residential_Pipeline_Full_Build.xlsx (226 records in 153 sites).
A12: CIS upstream export | B12: Export 20260923095518.xls as de-duplicated in the source workbook (55 records; 3 non-residential frameworks excluded).
A13: Planning register | B13: National Planning Applications dataset (Department of Housing, Local Government and Heritage), ArcGIS feature service IrishPlanningApplications, Limerick County Council records (12,835, received 2017 onwards). Queried 29/09/2026.
A14: An Coimisiún Pleanála | B14: SHD case pages at pleanala.ie/en-ie/case/<number>, read 29/09/2026 for the 6 records with ABP references.
A16: Counting (primacy)
A17: Counting unit | B17: The application. Each application gets a Relationship; only Primary, Additional phase, Additional application on site, Replaces earlier and Extension of duration (parent not in CIS) count. Sites group applications for review; site totals are sums of counted applications.
A18: Extension of duration | B18: Register EoD applications, or descriptions starting "extension of permission/duration", link to the parent file number in the description (or to the most similar earlier application on the site). Units stay on the parent; the parent expiry is extended.
A19: Replaces earlier | B19: A later application that (a) modifies a quoted earlier permission and restates at least half its units, (b) is consequent on a quoted outline permission, or (c) repeats an earlier live application nearby (description text match >= 85% with units within 25%, or units within 10% with text match >= 50%). The earlier application becomes Superseded.
A20: Amendment within parent | B20: Modifies a quoted earlier permission but covers less than half its units. Its units are treated as already counted in the parent.
A21: Additional phase | B21: Quotes an earlier permission without modification wording (e.g. phase 2, connecting to services of), or modifies a completed scheme or one with no unit count. Counted.
A22: Additional application on site | B22: Other live applications exist on the same site or within 100m, but no link could be found in the descriptions. Counted by default and marked Low confidence – these are the main remaining double-count risk and are in the Review Queue.
A23: Not live | B23: Refused, refused on appeal, withdrawn or invalid in the register. Not counted.
A24: Analyst override | B24: Set Analyst Relationship on the Applications tab to override the automatic relationship. Final Relationship and all totals update.
A26: Reporting tier and units
A27: Reporting Tier | B27: Per counted application. Analyst Status overrides. Otherwise Complete = Delivered; Permission Granted or Commencement Expected that is past expiry or stale = Constrained / uncertain; else the CIS tier.
A28: Units | B28: CIS units. Remaining = units less stated completions (completions recorded on the site are assigned to its largest Part Complete application). Delivered = units on Complete applications plus stated completions.
A29: Student accommodation | B29: Student units and bedspaces reported separately and never added to general dwellings.
A30: Expiry | B30: Register expiry date, replaced by a granted Extension of Duration expiry where one quotes the parent file number; ABP expiry = date signed + 5 (or 10) years; CIS decision date + 5 years as fallback.
A32: Bedroom mix
A33: Priority | B33: CIS / KPMG bedroom mix where present. Otherwise the register development description is parsed for "N no. X-bed ..." patterns.
A34: Acceptance rule | B34: A parsed mix is used only when the bedrooms found add up exactly to the stated unit total (description header, CIS units or register units). Partial parses are shown in Mix Note but not used.
A35: Coverage | B35: Mix Coverage on the Summary is the share of counted units with a known bedroom split. Descriptions that only say "N houses" carry no bedroom data; those need the planning drawings or schedule of accommodation.
A37: Limitations
A38: Part 8 and pre-2017 | B38: Part 8 references and applications before 2017 are not in the national dataset and stay unverified.
A39: Register unit counts | B39: NumResidentialUnits is blank or zero on many register records.
A40: Automatic relationships | B40: Rules read the text of descriptions. They cannot see drawings, so phase boundaries and repeat applications on different parts of a large landholding can be misread. Check Low and Medium confidence rows.
A41: Legal position | B41: Screening only. It does not confirm the legal status of any permission.
A42: Social housing report | B42: Social Housing Construction Projects Status Report Q1 2026 (Department of Housing, Limerick pages). The report has no planning references or coordinates; only schemes matched with confidence on name, address and units (and consistent dates) are shown in the Social Housing columns. Unmatched and uncertain rows are omitted.
A43: Contacts | B43: CIS project team names and emails are not carried into this file.

Sheet Summary
A1: Limerick Residential Pipeline – Summary
A2: ="Report date "&TEXT(Method!$B$4,"dd/mm/yyyy")&". Counted applications only (see Relationship). Delivered and Excluded kept out of pipeline totals." -> Report date 29/09/2026. Counted applications only (see Relationship). Delivered and Excluded kept out of pipeline totals.
A4: Headline pipeline
A5: Pipeline general dwellings (units remaining) | B5: =SUM(Applications!$AL$2:$AL$293) -> 8902
A6: Pipeline student units | B6: =SUM(Applications!$AM$2:$AM$293) -> 743
A7: Pipeline student bedspaces | B7: =SUM(Applications!$AN$2:$AN$293) -> 2142
A8: Of which firm (Committed, Committed Pre-Construction, Advanced Pre-Construction) | B8: =SUMIFS(Applications!$AL$2:$AL$293,Applications!$AG$2:$AG$293,"Committed")+SUMIFS(Applications!$AL$2:$AL$293,Applications!$AG$2:$AG$293,"Committed Pre-Construction")+SUMIFS(Applications!$AL$2:$AL$293,Applications!$AG$2:$AG$293,"Advanced Pre-Construction") -> 3655
A9: Delivered units (Complete applications + stated completions) | B9: =SUM(Applications!$AK$2:$AK$293) -> 1325
A10: Counted applications | B10: =COUNTIF(Applications!$Z$2:$Z$293,"Yes") -> 257
A11: Applications not counted (superseded, amendments, extensions, not live, excluded) | B11: =COUNTIF(Applications!$Z$2:$Z$293,"No") -> 35
A13: Reconciliation to the previous workbook
A14: Previous headline units (Pipeline Summary tab, application-level, all stages) | B14: 11402 | C14: Source: Pipeline Summary tab of Limerick_Residential_Pipeline_Full_Build.xlsx (sum of Units).
A15: Units on applications not counted (primacy / not live) | B15: =SUMIFS(Applications!$Q$2:$Q$293,Applications!$Z$2:$Z$293,"No",Applications!$N$2:$N$293,"Yes") -> 809
A16: Units on counted applications reported as Excluded by analyst | B16: =SUMIFS(Applications!$AI$2:$AI$293,Applications!$AG$2:$AG$293,"Excluded") -> 0
A17: New total: pipeline general + student units + delivered | B17: =B5+B6+B9 -> 10970
A18: Difference to previous headline | B18: =B17-B14 -> -432
A20: Pipeline by reporting tier
A21: Reporting Tier | B21: Applications | C21: General Dwellings | D21: Student Units | E21: Student Bedspaces | F21: Known Bedroom Mix | G21: Mix Coverage
A22: Committed | B22: =COUNTIFS(Applications!$AG$2:$AG$293,A22) -> 73 | C22: =SUMIFS(Applications!$AL$2:$AL$293,Applications!$AG$2:$AG$293,A22) -> 2879 | D22: =SUMIFS(Applications!$AM$2:$AM$293,Applications!$AG$2:$AG$293,A22) -> 26 | E22: =SUMIFS(Applications!$AN$2:$AN$293,Applications!$AG$2:$AG$293,A22) -> 202 | F22: =SUMIFS(Applications!$AV$2:$AV$293,Applications!$AG$2:$AG$293,A22,Applications!$P$2:$P$293,"General") -> 2428 | G22: =IF(SUMIFS(Applications!$AI$2:$AI$293,Applications!$AG$2:$AG$293,A22,Applications!$P$2:$P$293,"General")=0,"",MIN(1,F22/SUMIFS(Applications!$AI$2:$AI$293,Applications!$AG$2:$AG$293,A22,Applications!$P$2:$P$293,"General"))) -> 0.81531229
A23: Committed Pre-Construction | B23: =COUNTIFS(Applications!$AG$2:$AG$293,A23) -> 10 | C23: =SUMIFS(Applications!$AL$2:$AL$293,Applications!$AG$2:$AG$293,A23) -> 309 | D23: =SUMIFS(Applications!$AM$2:$AM$293,Applications!$AG$2:$AG$293,A23) -> 0 | E23: =SUMIFS(Applications!$AN$2:$AN$293,Applications!$AG$2:$AG$293,A23) -> 0 | F23: =SUMIFS(Applications!$AV$2:$AV$293,Applications!$AG$2:$AG$293,A23,Applications!$P$2:$P$293,"General") -> 225 | G23: =IF(SUMIFS(Applications!$AI$2:$AI$293,Applications!$AG$2:$AG$293,A23,Applications!$P$2:$P$293,"General")=0,"",MIN(1,F23/SUMIFS(Applications!$AI$2:$AI$293,Applications!$AG$2:$AG$293,A23,Applications!$P$2:$P$293,"General"))) -> 0.72815534
A24: Advanced Pre-Construction | B24: =COUNTIFS(Applications!$AG$2:$AG$293,A24) -> 13 | C24: =SUMIFS(Applications!$AL$2:$AL$293,Applications!$AG$2:$AG$293,A24) -> 467 | D24: =SUMIFS(Applications!$AM$2:$AM$293,Applications!$AG$2:$AG$293,A24) -> 0 | E24: =SUMIFS(Applications!$AN$2:$AN$293,Applications!$AG$2:$AG$293,A24) -> 0 | F24: =SUMIFS(Applications!$AV$2:$AV$293,Applications!$AG$2:$AG$293,A24,Applications!$P$2:$P$293,"General") -> 415 | G24: =IF(SUMIFS(Applications!$AI$2:$AI$293,Applications!$AG$2:$AG$293,A24,Applications!$P$2:$P$293,"General")=0,"",MIN(1,F24/SUMIFS(Applications!$AI$2:$AI$293,Applications!$AG$2:$AG$293,A24,Applications!$P$2:$P$293,"General"))) -> 0.88865096
A25: Likely | B25: =COUNTIFS(Applications!$AG$2:$AG$293,A25) -> 5 | C25: =SUMIFS(Applications!$AL$2:$AL$293,Applications!$AG$2:$AG$293,A25) -> 592 | D25: =SUMIFS(Applications!$AM$2:$AM$293,Applications!$AG$2:$AG$293,A25) -> 196 | E25: =SUMIFS(Applications!$AN$2:$AN$293,Applications!$AG$2:$AG$293,A25) -> 1400 | F25: =SUMIFS(Applications!$AV$2:$AV$293,Applications!$AG$2:$AG$293,A25,Applications!$P$2:$P$293,"General") -> 574 | G25: =IF(SUMIFS(Applications!$AI$2:$AI$293,Applications!$AG$2:$AG$293,A25,Applications!$P$2:$P$293,"General")=0,"",MIN(1,F25/SUMIFS(Applications!$AI$2:$AI$293,Applications!$AG$2:$AG$293,A25,Applications!$P$2:$P$293,"General"))) -> 0.96959459
A26: Potential | B26: =COUNTIFS(Applications!$AG$2:$AG$293,A26) -> 36 | C26: =SUMIFS(Applications!$AL$2:$AL$293,Applications!$AG$2:$AG$293,A26) -> 2803 | D26: =SUMIFS(Applications!$AM$2:$AM$293,Applications!$AG$2:$AG$293,A26) -> 465 | E26: =SUMIFS(Applications!$AN$2:$AN$293,Applications!$AG$2:$AG$293,A26) -> 424 | F26: =SUMIFS(Applications!$AV$2:$AV$293,Applications!$AG$2:$AG$293,A26,Applications!$P$2:$P$293,"General") -> 2669 | G26: =IF(SUMIFS(Applications!$AI$2:$AI$293,Applications!$AG$2:$AG$293,A26,Applications!$P$2:$P$293,"General")=0,"",MIN(1,F26/SUMIFS(Applications!$AI$2:$AI$293,Applications!$AG$2:$AG$293,A26,Applications!$P$2:$P$293,"General"))) -> 0.95219408
A27: Application Pipeline | B27: =COUNTIFS(Applications!$AG$2:$AG$293,A27) -> 15 | C27: =SUMIFS(Applications!$AL$2:$AL$293,Applications!$AG$2:$AG$293,A27) -> 263 | D27: =SUMIFS(Applications!$AM$2:$AM$293,Applications!$AG$2:$AG$293,A27) -> 0 | E27: =SUMIFS(Applications!$AN$2:$AN$293,Applications!$AG$2:$AG$293,A27) -> 0 | F27: =SUMIFS(Applications!$AV$2:$AV$293,Applications!$AG$2:$AG$293,A27,Applications!$P$2:$P$293,"General") -> 173 | G27: =IF(SUMIFS(Applications!$AI$2:$AI$293,Applications!$AG$2:$AG$293,A27,Applications!$P$2:$P$293,"General")=0,"",MIN(1,F27/SUMIFS(Applications!$AI$2:$AI$293,Applications!$AG$2:$AG$293,A27,Applications!$P$2:$P$293,"General"))) -> 0.65779468
A28: Constrained / uncertain | B28: =COUNTIFS(Applications!$AG$2:$AG$293,A28) -> 61 | C28: =SUMIFS(Applications!$AL$2:$AL$293,Applications!$AG$2:$AG$293,A28) -> 1589 | D28: =SUMIFS(Applications!$AM$2:$AM$293,Applications!$AG$2:$AG$293,A28) -> 56 | E28: =SUMIFS(Applications!$AN$2:$AN$293,Applications!$AG$2:$AG$293,A28) -> 116 | F28: =SUMIFS(Applications!$AV$2:$AV$293,Applications!$AG$2:$AG$293,A28,Applications!$P$2:$P$293,"General") -> 1043 | G28: =IF(SUMIFS(Applications!$AI$2:$AI$293,Applications!$AG$2:$AG$293,A28,Applications!$P$2:$P$293,"General")=0,"",MIN(1,F28/SUMIFS(Applications!$AI$2:$AI$293,Applications!$AG$2:$AG$293,A28,Applications!$P$2:$P$293,"General"))) -> 0.65638767
A29: Pipeline total | B29: =SUM(B22:B28) -> 213 | C29: =SUM(C22:C28) -> 8902 | D29: =SUM(D22:D28) -> 743 | E29: =SUM(E22:E28) -> 2142 | F29: =SUM(F22:F28) -> 7527 | G29: =IF(SUMIFS(Applications!$AI$2:$AI$293,Applications!$AG$2:$AG$293,A22,Applications!$P$2:$P$293,"General")+SUMIFS(Applications!$AI$2:$AI$293,Applications!$AG$2:$AG$293,A23,Applications!$P$2:$P$293,"General")+SUMIFS(Applications!$AI$2:$AI$293,Applications!$AG$2:$AG$293,A24,Applications!$P$2:$P$293,"General")+SUMIFS(Applications!$AI$2:$AI$293,Applications!$AG$2:$AG$293,A25,Applications!$P$2:$P$293,"General")+SUMIFS(Applications!$AI$2:$AI$293,Applications!$AG$2:$AG$293,A26,Applications!$P$2:$P$293,"General")+SUMIFS(Applications!$AI$2:$AI$293,Applications!$AG$2:$AG$293,A27,Applications!$P$2:$P$293,"General")+SUMIFS(Applications!$AI$2:$AI$293,Applications!$AG$2:$AG$293,A28,Applications!$P$2:$P$293,"General")=0,"",MIN(1,F29/(SUMIFS(Applications!$AI$2:$AI$293,Applications!$AG$2:$AG$293,A22,Applications!$P$2:$P$293,"General")+SUMIFS(Applications!$AI$2:$AI$293,Applications!$AG$2:$AG$293,A23,Applications!$P$2:$P$293,"General")+SUMIFS(Applications!$AI$2:$AI$293,Applications!$AG$2:$AG$293,A24,Applications!$P$2:$P$293,"General")+SUMIFS(Applications!$AI$2:$AI$293,Applications!$AG$2:$AG$293,A25,Applications!$P$2:$P$293,"General")+SUMIFS(Applications!$AI$2:$AI$293,Applications!$AG$2:$AG$293,A26,Applications!$P$2:$P$293,"General")+SUMIFS(Applications!$AI$2:$AI$293,Applications!$AG$2:$AG$293,A27,Applications!$P$2:$P$293,"General")+SUMIFS(Applications!$AI$2:$AI$293,Applications!$AG$2:$AG$293,A28,Applications!$P$2:$P$293,"General")))) -> 0.83624042
A30: Delivered | B30: =COUNTIFS(Applications!$AG$2:$AG$293,A30) -> 44 | C30: =SUMIFS(Applications!$AK$2:$AK$293,Applications!$AG$2:$AG$293,A30,Applications!$P$2:$P$293,"General") -> 1226
A31: Excluded | B31: =COUNTIFS(Applications!$AG$2:$AG$293,A31) -> 0 | C31: =SUMIFS(Applications!$AI$2:$AI$293,Applications!$AG$2:$AG$293,A31,Applications!$P$2:$P$293,"General") -> 0
A32: Mix coverage = counted general units with a known bedroom split, as a share of counted general units in the tier.
A34: Pipeline bedroom mix (general dwellings, counted applications with known mix)
A35: Bedrooms | B35: Units | C35: Share | D35: Of which from CIS / KPMG | E35: Of which from register description | F35: Of which from planning file documents
A36: Studio | B36: =SUMIFS(Applications!$AP$2:$AP$293,Applications!$AG$2:$AG$293,"<>Not counted",Applications!$AG$2:$AG$293,"<>Delivered",Applications!$AG$2:$AG$293,"<>Excluded",Applications!$P$2:$P$293,"General") -> 1 | C36: =IF($B$42=0,"",B36/$B$42) -> 0.00013285506 | D36: =SUMIFS(Applications!$AP$2:$AP$293,Applications!$AG$2:$AG$293,"<>Not counted",Applications!$AG$2:$AG$293,"<>Delivered",Applications!$AG$2:$AG$293,"<>Excluded",Applications!$P$2:$P$293,"General",Applications!$AO$2:$AO$293,"CIS / KPMG") -> 0 | E36: =SUMIFS(Applications!$AP$2:$AP$293,Applications!$AG$2:$AG$293,"<>Not counted",Applications!$AG$2:$AG$293,"<>Delivered",Applications!$AG$2:$AG$293,"<>Excluded",Applications!$P$2:$P$293,"General",Applications!$AO$2:$AO$293,"Register description") -> 1 | F36: =SUMIFS(Applications!$AP$2:$AP$293,Applications!$AG$2:$AG$293,"<>Not counted",Applications!$AG$2:$AG$293,"<>Delivered",Applications!$AG$2:$AG$293,"<>Excluded",Applications!$P$2:$P$293,"General",Applications!$AO$2:$AO$293,"Planning file documents") -> 0
A37: 1 Bed | B37: =SUMIFS(Applications!$AQ$2:$AQ$293,Applications!$AG$2:$AG$293,"<>Not counted",Applications!$AG$2:$AG$293,"<>Delivered",Applications!$AG$2:$AG$293,"<>Excluded",Applications!$P$2:$P$293,"General") -> 1726 | C37: =IF($B$42=0,"",B37/$B$42) -> 0.22930783 | D37: =SUMIFS(Applications!$AQ$2:$AQ$293,Applications!$AG$2:$AG$293,"<>Not counted",Applications!$AG$2:$AG$293,"<>Delivered",Applications!$AG$2:$AG$293,"<>Excluded",Applications!$P$2:$P$293,"General",Applications!$AO$2:$AO$293,"CIS / KPMG") -> 1084 | E37: =SUMIFS(Applications!$AQ$2:$AQ$293,Applications!$AG$2:$AG$293,"<>Not counted",Applications!$AG$2:$AG$293,"<>Delivered",Applications!$AG$2:$AG$293,"<>Excluded",Applications!$P$2:$P$293,"General",Applications!$AO$2:$AO$293,"Register description") -> 616 | F37: =SUMIFS(Applications!$AQ$2:$AQ$293,Applications!$AG$2:$AG$293,"<>Not counted",Applications!$AG$2:$AG$293,"<>Delivered",Applications!$AG$2:$AG$293,"<>Excluded",Applications!$P$2:$P$293,"General",Applications!$AO$2:$AO$293,"Planning file documents") -> 26
A38: 2 Bed | B38: =SUMIFS(Applications!$AR$2:$AR$293,Applications!$AG$2:$AG$293,"<>Not counted",Applications!$AG$2:$AG$293,"<>Delivered",Applications!$AG$2:$AG$293,"<>Excluded",Applications!$P$2:$P$293,"General") -> 2595 | C38: =IF($B$42=0,"",B38/$B$42) -> 0.34475887 | D38: =SUMIFS(Applications!$AR$2:$AR$293,Applications!$AG$2:$AG$293,"<>Not counted",Applications!$AG$2:$AG$293,"<>Delivered",Applications!$AG$2:$AG$293,"<>Excluded",Applications!$P$2:$P$293,"General",Applications!$AO$2:$AO$293,"CIS / KPMG") -> 1667 | E38: =SUMIFS(Applications!$AR$2:$AR$293,Applications!$AG$2:$AG$293,"<>Not counted",Applications!$AG$2:$AG$293,"<>Delivered",Applications!$AG$2:$AG$293,"<>Excluded",Applications!$P$2:$P$293,"General",Applications!$AO$2:$AO$293,"Register description") -> 823 | F38: =SUMIFS(Applications!$AR$2:$AR$293,Applications!$AG$2:$AG$293,"<>Not counted",Applications!$AG$2:$AG$293,"<>Delivered",Applications!$AG$2:$AG$293,"<>Excluded",Applications!$P$2:$P$293,"General",Applications!$AO$2:$AO$293,"Planning file documents") -> 105
A39: 3 Bed | B39: =SUMIFS(Applications!$AS$2:$AS$293,Applications!$AG$2:$AG$293,"<>Not counted",Applications!$AG$2:$AG$293,"<>Delivered",Applications!$AG$2:$AG$293,"<>Excluded",Applications!$P$2:$P$293,"General") -> 2502 | C39: =IF($B$42=0,"",B39/$B$42) -> 0.33240335 | D39: =SUMIFS(Applications!$AS$2:$AS$293,Applications!$AG$2:$AG$293,"<>Not counted",Applications!$AG$2:$AG$293,"<>Delivered",Applications!$AG$2:$AG$293,"<>Excluded",Applications!$P$2:$P$293,"General",Applications!$AO$2:$AO$293,"CIS / KPMG") -> 1298 | E39: =SUMIFS(Applications!$AS$2:$AS$293,Applications!$AG$2:$AG$293,"<>Not counted",Applications!$AG$2:$AG$293,"<>Delivered",Applications!$AG$2:$AG$293,"<>Excluded",Applications!$P$2:$P$293,"General",Applications!$AO$2:$AO$293,"Register description") -> 893 | F39: =SUMIFS(Applications!$AS$2:$AS$293,Applications!$AG$2:$AG$293,"<>Not counted",Applications!$AG$2:$AG$293,"<>Delivered",Applications!$AG$2:$AG$293,"<>Excluded",Applications!$P$2:$P$293,"General",Applications!$AO$2:$AO$293,"Planning file documents") -> 311
A40: 4 Bed | B40: =SUMIFS(Applications!$AT$2:$AT$293,Applications!$AG$2:$AG$293,"<>Not counted",Applications!$AG$2:$AG$293,"<>Delivered",Applications!$AG$2:$AG$293,"<>Excluded",Applications!$P$2:$P$293,"General") -> 664 | C40: =IF($B$42=0,"",B40/$B$42) -> 0.088215757 | D40: =SUMIFS(Applications!$AT$2:$AT$293,Applications!$AG$2:$AG$293,"<>Not counted",Applications!$AG$2:$AG$293,"<>Delivered",Applications!$AG$2:$AG$293,"<>Excluded",Applications!$P$2:$P$293,"General",Applications!$AO$2:$AO$293,"CIS / KPMG") -> 371 | E40: =SUMIFS(Applications!$AT$2:$AT$293,Applications!$AG$2:$AG$293,"<>Not counted",Applications!$AG$2:$AG$293,"<>Delivered",Applications!$AG$2:$AG$293,"<>Excluded",Applications!$P$2:$P$293,"General",Applications!$AO$2:$AO$293,"Register description") -> 261 | F40: =SUMIFS(Applications!$AT$2:$AT$293,Applications!$AG$2:$AG$293,"<>Not counted",Applications!$AG$2:$AG$293,"<>Delivered",Applications!$AG$2:$AG$293,"<>Excluded",Applications!$P$2:$P$293,"General",Applications!$AO$2:$AO$293,"Planning file documents") -> 32
A41: 5+ Bed | B41: =SUMIFS(Applications!$AU$2:$AU$293,Applications!$AG$2:$AG$293,"<>Not counted",Applications!$AG$2:$AG$293,"<>Delivered",Applications!$AG$2:$AG$293,"<>Excluded",Applications!$P$2:$P$293,"General") -> 39 | C41: =IF($B$42=0,"",B41/$B$42) -> 0.0051813472 | D41: =SUMIFS(Applications!$AU$2:$AU$293,Applications!$AG$2:$AG$293,"<>Not counted",Applications!$AG$2:$AG$293,"<>Delivered",Applications!$AG$2:$AG$293,"<>Excluded",Applications!$P$2:$P$293,"General",Applications!$AO$2:$AO$293,"CIS / KPMG") -> 33 | E41: =SUMIFS(Applications!$AU$2:$AU$293,Applications!$AG$2:$AG$293,"<>Not counted",Applications!$AG$2:$AG$293,"<>Delivered",Applications!$AG$2:$AG$293,"<>Excluded",Applications!$P$2:$P$293,"General",Applications!$AO$2:$AO$293,"Register description") -> 6 | F41: =SUMIFS(Applications!$AU$2:$AU$293,Applications!$AG$2:$AG$293,"<>Not counted",Applications!$AG$2:$AG$293,"<>Delivered",Applications!$AG$2:$AG$293,"<>Excluded",Applications!$P$2:$P$293,"General",Applications!$AO$2:$AO$293,"Planning file documents") -> 0
A42: Total with known mix | B42: =SUM(B36:B41) -> 7527 | D42: =SUM(D36:D41) -> 4453 | E42: =SUM(E36:E41) -> 2600 | F42: =SUM(F36:F41) -> 474
A43: Counted general units in pipeline (all, incl. unknown mix) | B43: =SUMIFS(Applications!$AI$2:$AI$293,Applications!$AG$2:$AG$293,"<>Not counted",Applications!$AG$2:$AG$293,"<>Delivered",Applications!$AG$2:$AG$293,"<>Excluded",Applications!$P$2:$P$293,"General") -> 9001
A44: Mix coverage | B44: =IF(B43=0,"",B42/B43) -> 0.83624042
...

Sheet Sites
A1: Site ID | B1: Origin | C1: Site / Project Heading | D1: Address | E1: Settlement | F1: Latitude | G1: Longitude | H1: Most Advanced CIS Stage | I1: Applications | J1: Counted Applications | K1: Counted Units | L1: Pipeline General Dwellings | M1: Pipeline Student Units | N1: Delivered Units | O1: Not-Counted Applications | P1: Low-Confidence Links (unreviewed) | Q1: Stale / Expired (counted) | R1: Possible Overlap | S1: Low-Confidence Grouping | T1: Review Required | U1: Site Reviewed | V1: Site Note
A2: P-1432711 | B2: Granted/delivery export (grouped) | C2: €39m - Large Residential Development, Mungret | D2: Mungret Park Road, Caheranardrish, Mungret | E2: Mungret | F2: 52.631157 | G2: -8.6902988 | H2: Permission Granted | I2: =COUNTIF(Applications!$B$2:$B$293,A2) -> 1 | J2: =COUNTIFS(Applications!$B$2:$B$293,A2,Applications!$Z$2:$Z$293,"Yes") -> 1 | K2: =SUMIFS(Applications!$AI$2:$AI$293,Applications!$B$2:$B$293,A2) -> 182 | L2: =SUMIFS(Applications!$AL$2:$AL$293,Applications!$B$2:$B$293,A2) -> 182 | M2: =SUMIFS(Applications!$AM$2:$AM$293,Applications!$B$2:$B$293,A2) -> 0 | N2: =SUMIFS(Applications!$AK$2:$AK$293,Applications!$B$2:$B$293,A2) -> 0 | O2: =I2-J2 -> 0 | P2: =COUNTIFS(Applications!$B$2:$B$293,A2,Applications!$W$2:$W$293,"Low",Applications!$X$2:$X$293,"") -> 0 | Q2: =COUNTIFS(Applications!$B$2:$B$293,A2,Applications!$AH$2:$AH$293,"Past*")+COUNTIFS(Applications!$B$2:$B$293,A2,Applications!$AH$2:$AH$293,"No CIS*") -> 0 | S2: No | T2: =IF(OR(R2<>"",S2="Yes",P2>0,Q2>0),IF(U2="Yes","Resolved","Yes"),"No") -> No
A3: P-1446288 | B3: Granted/delivery export (grouped) | C3: €125.6m - Large Residential Development, Castletroy | D3: Lands at Monaleen Road, Castletroy | E3: Limerick City and Suburbs | F3: 52.664122 | G3: -8.5618067 | H3: Permission Granted | I3: =COUNTIF(Applications!$B$2:$B$293,A3) -> 1 | J3: =COUNTIFS(Applications!$B$2:$B$293,A3,Applications!$Z$2:$Z$293,"Yes") -> 1 | K3: =SUMIFS(Applications!$AI$2:$AI$293,Applications!$B$2:$B$293,A3) -> 523 | L3: =SUMIFS(Applications!$AL$2:$AL$293,Applications!$B$2:$B$293,A3) -> 523 | M3: =SUMIFS(Applications!$AM$2:$AM$293,Applications!$B$2:$B$293,A3) -> 0 | N3: =SUMIFS(Applications!$AK$2:$AK$293,Applications!$B$2:$B$293,A3) -> 0 | O3: =I3-J3 -> 0 | P3: =COUNTIFS(Applications!$B$2:$B$293,A3,Applications!$W$2:$W$293,"Low",Applications!$X$2:$X$293,"") -> 0 | Q3: =COUNTIFS(Applications!$B$2:$B$293,A3,Applications!$AH$2:$AH$293,"Past*")+COUNTIFS(Applications!$B$2:$B$293,A3,Applications!$AH$2:$AH$293,"No CIS*") -> 0 | S3: No | T3: =IF(OR(R3<>"",S3="Yes",P3>0,Q3>0),IF(U3="Yes","Resolved","Yes"),"No") -> No
A4: P-1350850 | B4: Granted/delivery export (grouped) | C4: €3.9m - Residential Development, Castlemahon | D4: Main Street, Castlemahon | E4: Other County Limerick | F4: 52.431087 | G4: -9.0108993 | H4: Commencement Expected | I4: =COUNTIF(Applications!$B$2:$B$293,A4) -> 1 | J4: =COUNTIFS(Applications!$B$2:$B$293,A4,Applications!$Z$2:$Z$293,"Yes") -> 1 | K4: =SUMIFS(Applications!$AI$2:$AI$293,Applications!$B$2:$B$293,A4) -> 18 | L4: =SUMIFS(Applications!$AL$2:$AL$293,Applications!$B$2:$B$293,A4) -> 18 | M4: =SUMIFS(Applications!$AM$2:$AM$293,Applications!$B$2:$B$293,A4) -> 0 | N4: =SUMIFS(Applications!$AK$2:$AK$293,Applications!$B$2:$B$293,A4) -> 0 | O4: =I4-J4 -> 0 | P4: =COUNTIFS(Applications!$B$2:$B$293,A4,Applications!$W$2:$W$293,"Low",Applications!$X$2:$X$293,"") -> 0 | Q4: =COUNTIFS(Applications!$B$2:$B$293,A4,Applications!$AH$2:$AH$293,"Past*")+COUNTIFS(Applications!$B$2:$B$293,A4,Applications!$AH$2:$AH$293,"No CIS*") -> 0 | S4: No | T4: =IF(OR(R4<>"",S4="Yes",P4>0,Q4>0),IF(U4="Yes","Resolved","Yes"),"No") -> No
A5: SG-004 | B5: Granted/delivery export (grouped) | C5: €6.3m - Residential Development, Patrickswell | D5: Barnakyle, Patrickswell | E5: Patrickswell | F5: 52.601353 | G5: -8.7051357 | H5: On Site | I5: =COUNTIF(Applications!$B$2:$B$293,A5) -> 10 | J5: =COUNTIFS(Applications!$B$2:$B$293,A5,Applications!$Z$2:$Z$293,"Yes") -> 10 | K5: =SUMIFS(Applications!$AI$2:$AI$293,Applications!$B$2:$B$293,A5) -> 314 | L5: =SUMIFS(Applications!$AL$2:$AL$293,Applications!$B$2:$B$293,A5) -> 305 | M5: =SUMIFS(Applications!$AM$2:$AM$293,Applications!$B$2:$B$293,A5) -> 0 | N5: =SUMIFS(Applications!$AK$2:$AK$293,Applications!$B$2:$B$293,A5) -> 9 | O5: =I5-J5 -> 0 | P5: =COUNTIFS(Applications!$B$2:$B$293,A5,Applications!$W$2:$W$293,"Low",Applications!$X$2:$X$293,"") -> 9 | Q5: =COUNTIFS(Applications!$B$2:$B$293,A5,Applications!$AH$2:$AH$293,"Past*")+COUNTIFS(Applications!$B$2:$B$293,A5,Applications!$AH$2:$AH$293,"No CIS*") -> 3 | S5: Yes | T5: =IF(OR(R5<>"",S5="Yes",P5>0,Q5>0),IF(U5="Yes","Resolved","Yes"),"No") -> Yes
A6: P-1444384 | B6: Granted/delivery export (grouped) | C6: €8.6m - Staff Accommodation/8Apartments, Adare | D6: Fitzgerald's Woodlands House Hotel, Knockanes, Adare | E6: Adare | F6: 52.561726 | G6: -8.7657741 | H6: Permission Granted | I6: =COUNTIF(Applications!$B$2:$B$293,A6) -> 1 | J6: =COUNTIFS(Applications!$B$2:$B$293,A6,Applications!$Z$2:$Z$293,"Yes") -> 1 | K6: =SUMIFS(Applications!$AI$2:$AI$293,Applications!$B$2:$B$293,A6) -> 28 | L6: =SUMIFS(Applications!$AL$2:$AL$293,Applications!$B$2:$B$293,A6) -> 28 | M6: =SUMIFS(Applications!$AM$2:$AM$293,Applications!$B$2:$B$293,A6) -> 0 | N6: =SUMIFS(Applications!$AK$2:$AK$293,Applications!$B$2:$B$293,A6) -> 0 | O6: =I6-J6 -> 0 | P6: =COUNTIFS(Applications!$B$2:$B$293,A6,Applications!$W$2:$W$293,"Low",Applications!$X$2:$X$293,"") -> 0 | Q6: =COUNTIFS(Applications!$B$2:$B$293,A6,Applications!$AH$2:$AH$293,"Past*")+COUNTIFS(Applications!$B$2:$B$293,A6,Applications!$AH$2:$AH$293,"No CIS*") -> 0 | S6: No | T6: =IF(OR(R6<>"",S6="Yes",P6>0,Q6>0),IF(U6="Yes","Resolved","Yes"),"No") -> No
A7: P-1414007 | B7: Granted/delivery export (grouped) | C7: €1m - 8 Houses, Bruff | D7: Ardykeohane, Bruff | E7: Bruff | F7: 52.476941 | G7: -8.5370467 | H7: Permission Granted | I7: =COUNTIF(Applications!$B$2:$B$293,A7) -> 1 | J7: =COUNTIFS(Applications!$B$2:$B$293,A7,Applications!$Z$2:$Z$293,"Yes") -> 1 | K7: =SUMIFS(Applications!$AI$2:$AI$293,Applications!$B$2:$B$293,A7) -> 8 | L7: =SUMIFS(Applications!$AL$2:$AL$293,Applications!$B$2:$B$293,A7) -> 8 | M7: =SUMIFS(Applications!$AM$2:$AM$293,Applications!$B$2:$B$293,A7) -> 0 | N7: =SUMIFS(Applications!$AK$2:$AK$293,Applications!$B$2:$B$293,A7) -> 0 | O7: =I7-J7 -> 0 | P7: =COUNTIFS(Applications!$B$2:$B$293,A7,Applications!$W$2:$W$293,"Low",Applications!$X$2:$X$293,"") -> 0 | Q7: =COUNTIFS(Applications!$B$2:$B$293,A7,Applications!$AH$2:$AH$293,"Past*")+COUNTIFS(Applications!$B$2:$B$293,A7,Applications!$AH$2:$AH$293,"No CIS*") -> 0 | S7: No | T7: =IF(OR(R7<>"",S7="Yes",P7>0,Q7>0),IF(U7="Yes","Resolved","Yes"),"No") -> No
A8: SG-023 | B8: Granted/delivery export (grouped) | C8: €4m - Residential Development | D8: Broadford | E8: Other County Limerick | F8: 52.344978 | G8: -8.9745614 | H8: Part Complete | I8: =COUNTIF(Applications!$B$2:$B$293,A8) -> 2 | J8: =COUNTIFS(Applications!$B$2:$B$293,A8,Applications!$Z$2:$Z$293,"Yes") -> 1 | K8: =SUMIFS(Applications!$AI$2:$AI$293,Applications!$B$2:$B$293,A8) -> 18 | L8: =SUMIFS(Applications!$AL$2:$AL$293,Applications!$B$2:$B$293,A8) -> 7 | M8: =SUMIFS(Applications!$AM$2:$AM$293,Applications!$B$2:$B$293,A8) -> 0 | N8: =SUMIFS(Applications!$AK$2:$AK$293,Applications!$B$2:$B$293,A8) -> 11 | O8: =I8-J8 -> 1 | P8: =COUNTIFS(Applications!$B$2:$B$293,A8,Applications!$W$2:$W$293,"Low",Applications!$X$2:$X$293,"") -> 1 | Q8: =COUNTIFS(Applications!$B$2:$B$293,A8,Applications!$AH$2:$AH$293,"Past*")+COUNTIFS(Applications!$B$2:$B$293,A8,Applications!$AH$2:$AH$293,"No CIS*") -> 0 | S8: Yes | T8: =IF(OR(R8<>"",S8="Yes",P8>0,Q8>0),IF(U8="Yes","Resolved","Yes"),"No") -> Yes
A9: SG-003 | B9: Granted/delivery export (grouped) | C9: €5.9m - Residential Development, Patrickswell | D9: Ballyanrahan East, Patrickswell | E9: Patrickswell | F9: 52.599095 | G9: -8.7091281 | H9: Part Complete | I9: =COUNTIF(Applications!$B$2:$B$293,A9) -> 7 | J9: =COUNTIFS(Applications!$B$2:$B$293,A9,Applications!$Z$2:$Z$293,"Yes") -> 3 | K9: =SUMIFS(Applications!$AI$2:$AI$293,Applications!$B$2:$B$293,A9) -> 112 | L9: =SUMIFS(Applications!$AL$2:$AL$293,Applications!$B$2:$B$293,A9) -> 86 | M9: =SUMIFS(Applications!$AM$2:$AM$293,Applications!$B$2:$B$293,A9) -> 0 | N9: =SUMIFS(Applications!$AK$2:$AK$293,Applications!$B$2:$B$293,A9) -> 26 | O9: =I9-J9 -> 4 | P9: =COUNTIFS(Applications!$B$2:$B$293,A9,Applications!$W$2:$W$293,"Low",Applications!$X$2:$X$293,"") -> 2 | Q9: =COUNTIFS(Applications!$B$2:$B$293,A9,Applications!$AH$2:$AH$293,"Past*")+COUNTIFS(Applications!$B$2:$B$293,A9,Applications!$AH$2:$AH$293,"No CIS*") -> 0 | S9: Yes | T9: =IF(OR(R9<>"",S9="Yes",P9>0,Q9>0),IF(U9="Yes","Resolved","Yes"),"No") -> Yes
A10: SG-019 | B10: Granted/delivery export (grouped) | C10: €44m - Residential Development, Castletroy | D10: Newcastle, Castletroy | E10: Limerick City and Suburbs | F10: 52.666952 | G10: -8.5497456 | H10: On Site | I10: =COUNTIF(Applications!$B$2:$B$293,A10) -> 3 | J10: =COUNTIFS(Applications!$B$2:$B$293,A10,Applications!$Z$2:$Z$293,"Yes") -> 3 | K10: =SUMIFS(Applications!$AI$2:$AI$293,Applications!$B$2:$B$293,A10) -> 227 | L10: =SUMIFS(Applications!$AL$2:$AL$293,Applications!$B$2:$B$293,A10) -> 27 | M10: =SUMIFS(Applications!$AM$2:$AM$293,Applications!$B$2:$B$293,A10) -> 0 | N10: =SUMIFS(Applications!$AK$2:$AK$293,Applications!$B$2:$B$293,A10) -> 200 | O10: =I10-J10 -> 0 | P10: =COUNTIFS(Applications!$B$2:$B$293,A10,Applications!$W$2:$W$293,"Low",Applications!$X$2:$X$293,"") -> 2 | Q10: =COUNTIFS(Applications!$B$2:$B$293,A10,Applications!$AH$2:$AH$293,"Past*")+COUNTIFS(Applications!$B$2:$B$293,A10,Applications!$AH$2:$AH$293,"No CIS*") -> 0 | S10: Yes | T10: =IF(OR(R10<>"",S10="Yes",P10>0,Q10>0),IF(U10="Yes","Resolved","Yes"),"No") -> Yes
A11: P-1437215 | B11: Granted/delivery export (grouped) | C11: €84m - Parkway Valley LRD, Singland | D11: Site known as "Parkway Valley", Dublin Road (R445), Singland | E11: Other County Limerick | F11: 52.660173 | G11: -8.5885499 | H11: Permission Granted | I11: =COUNTIF(Applications!$B$2:$B$293,A11) -> 1 | J11: =COUNTIFS(Applications!$B$2:$B$293,A11,Applications!$Z$2:$Z$293,"Yes") -> 1 | K11: =SUMIFS(Applications!$AI$2:$AI$293,Applications!$B$2:$B$293,A11) -> 403 | L11: =SUMIFS(Applications!$AL$2:$AL$293,Applications!$B$2:$B$293,A11) -> 403 | M11: =SUMIFS(Applications!$AM$2:$AM$293,Applications!$B$2:$B$293,A11) -> 0 | N11: =SUMIFS(Applications!$AK$2:$AK$293,Applications!$B$2:$B$293,A11) -> 0 | O11: =I11-J11 -> 0 | P11: =COUNTIFS(Applications!$B$2:$B$293,A11,Applications!$W$2:$W$293,"Low",Applications!$X$2:$X$293,"") -> 0 | Q11: =COUNTIFS(Applications!$B$2:$B$293,A11,Applications!$AH$2:$AH$293,"Past*")+COUNTIFS(Applications!$B$2:$B$293,A11,Applications!$AH$2:$AH$293,"No CIS*") -> 0 | S11: No | T11: =IF(OR(R11<>"",S11="Yes",P11>0,Q11>0),IF(U11="Yes","Resolved","Yes"),"No") -> No
A12: P-1428325 | B12: Granted/delivery export (grouped) | C12: €42m - Large Residential Development,Limerick | D12: Towlerton , Ballysimon, Limerick | E12: Limerick City and Suburbs | F12: 52.655611 | G12: -8.5815955 | H12: Permission Granted | I12: =COUNTIF(Applications!$B$2:$B$293,A12) -> 1 | J12: =COUNTIFS(Applications!$B$2:$B$293,A12,Applications!$Z$2:$Z$293,"Yes") -> 1 | K12: =SUMIFS(Applications!$AI$2:$AI$293,Applications!$B$2:$B$293,A12) -> 212 | L12: =SUMIFS(Applications!$AL$2:$AL$293,Applications!$B$2:$B$293,A12) -> 212 | M12: =SUMIFS(Applications!$AM$2:$AM$293,Applications!$B$2:$B$293,A12) -> 0 | N12: =SUMIFS(Applications!$AK$2:$AK$293,Applications!$B$2:$B$293,A12) -> 0 | O12: =I12-J12 -> 0 | P12: =COUNTIFS(Applications!$B$2:$B$293,A12,Applications!$W$2:$W$293,"Low",Applications!$X$2:$X$293,"") -> 0 | Q12: =COUNTIFS(Applications!$B$2:$B$293,A12,Applications!$AH$2:$AH$293,"Past*")+COUNTIFS(Applications!$B$2:$B$293,A12,Applications!$AH$2:$AH$293,"No CIS*") -> 0 | S12: No | T12: =IF(OR(R12<>"",S12="Yes",P12>0,Q12>0),IF(U12="Yes","Resolved","Yes"),"No") -> No
A13: SG-020 | B13: Granted/delivery export (grouped) | C13: €47m - The Mungret Project | D13: Dromdarrig, Mungret | E13: Mungret | F13: 52.629688 | G13: -8.6773868 | H13: On Site | I13: =COUNTIF(Applications!$B$2:$B$293,A13) -> 2 | J13: =COUNTIFS(Applications!$B$2:$B$293,A13,Applications!$Z$2:$Z$293,"Yes") -> 2 | K13: =SUMIFS(Applications!$AI$2:$AI$293,Applications!$B$2:$B$293,A13) -> 419 | L13: =SUMIFS(Applications!$AL$2:$AL$293,Applications!$B$2:$B$293,A13) -> 419 | M13: =SUMIFS(Applications!$AM$2:$AM$293,Applications!$B$2:$B$293,A13) -> 0 | N13: =SUMIFS(Applications!$AK$2:$AK$293,Applications!$B$2:$B$293,A13) -> 0 | O13: =I13-J13 -> 0 | P13: =COUNTIFS(Applications!$B$2:$B$293,A13,Applications!$W$2:$W$293,"Low",Applications!$X$2:$X$293,"") -> 1 | Q13: =COUNTIFS(Applications!$B$2:$B$293,A13,Applications!$AH$2:$AH$293,"Past*")+COUNTIFS(Applications!$B$2:$B$293,A13,Applications!$AH$2:$AH$293,"No CIS*") -> 0 | S13: Yes | T13: =IF(OR(R13<>"",S13="Yes",P13>0,Q13>0),IF(U13="Yes","Resolved","Yes"),"No") -> Yes
... A154: P-978022 | B154: Granted/delivery export (grouped) | C154: €3m - Mixed Use Development | D154: Ellen Street/Carr Street/Punch's Row | E154: Other County Limerick | F154: 52.664066 | G154: -8.6220618 | H154: Permission Granted | I154: =COUNTIF(Applications!$B$2:$B$293,A154) -> 1 | J154: =COUNTIFS(Applications!$B$2:$B$293,A154,Applications!$Z$2:$Z$293,"Yes") -> 1 | K154: =SUMIFS(Applications!$AI$2:$AI$293,Applications!$B$2:$B$293,A154) -> 8 | L154: =SUMIFS(Applications!$AL$2:$AL$293,Applications!$B$2:$B$293,A154) -> 8 | M154: =SUMIFS(Applications!$AM$2:$AM$293,Applications!$B$2:$B$293,A154) -> 0 | N154: =SUMIFS(Applications!$AK$2:$AK$293,Applications!$B$2:$B$293,A154) -> 0 | O154: =I154-J154 -> 0 | P154: =COUNTIFS(Applications!$B$2:$B$293,A154,Applications!$W$2:$W$293,"Low",Applications!$X$2:$X$293,"") -> 0 | Q154: =COUNTIFS(Applications!$B$2:$B$293,A154,Applications!$AH$2:$AH$293,"Past*")+COUNTIFS(Applications!$B$2:$B$293,A154,Applications!$AH$2:$AH$293,"No CIS*") -> 1 | S154: No | T154: =IF(OR(R154<>"",S154="Yes",P154>0,Q154>0),IF(U154="Yes","Resolved","Yes"),"No") -> Yes
A155: U-837963 | B155: Latest upstream export | C155: €588k - 3 Houses | D155: adjacent to the Soccer Club and accessed of The Grove, Garrane Beg, Pallasgreen | E155: Other County Limerick | F155: 52.564175 | G155: -8.3381718 | H155: Tender | I155: =COUNTIF(Applications!$B$2:$B$293,A155) -> 1 | J155: =COUNTIFS(Applications!$B$2:$B$293,A155,Applications!$Z$2:$Z$293,"Yes") -> 1 | K155: =SUMIFS(Applications!$AI$2:$AI$293,Applications!$B$2:$B$293,A155) -> 3 | L155: =SUMIFS(Applications!$AL$2:$AL$293,Applications!$B$2:$B$293,A155) -> 3 | M155: =SUMIFS(Applications!$AM$2:$AM$293,Applications!$B$2:$B$293,A155) -> 0 | N155: =SUMIFS(Applications!$AK$2:$AK$293,Applications!$B$2:$B$293,A155) -> 0 | O155: =I155-J155 -> 0 | P155: =COUNTIFS(Applications!$B$2:$B$293,A155,Applications!$W$2:$W$293,"Low",Applications!$X$2:$X$293,"") -> 0 | Q155: =COUNTIFS(Applications!$B$2:$B$293,A155,Applications!$AH$2:$AH$293,"Past*")+COUNTIFS(Applications!$B$2:$B$293,A155,Applications!$AH$2:$AH$293,"No CIS*") -> 0 | R155: P-1278179 (20m): €1.5m - 3 Community Houses, Complete, 3 units | S155: No | T155: =IF(OR(R155<>"",S155="Yes",P155>0,Q155>0),IF(U155="Yes","Resolved","Yes"),"No") -> Yes
A156: U-1034286 | B156: Latest upstream export | C156: €567k - Change of Use to Care Residential Units | D156: Sisters of Mercy Convent, Main Street, Doon | E156: Other County Limerick | F156: 52.603895 | G156: -8.244808 | H156: Tender | I156: =COUNTIF(Applications!$B$2:$B$293,A156) -> 1 | J156: =COUNTIFS(Applications!$B$2:$B$293,A156,Applications!$Z$2:$Z$293,"Yes") -> 1 | K156: =SUMIFS(Applications!$AI$2:$AI$293,Applications!$B$2:$B$293,A156) -> 21 | L156: =SUMIFS(Applications!$AL$2:$AL$293,Applications!$B$2:$B$293,A156) -> 21 | M156: =SUMIFS(Applications!$AM$2:$AM$293,Applications!$B$2:$B$293,A156) -> 0 | N156: =SUMIFS(Applications!$AK$2:$AK$293,Applications!$B$2:$B$293,A156) -> 0 | O156: =I156-J156 -> 0 | P156: =COUNTIFS(Applications!$B$2:$B$293,A156,Applications!$W$2:$W$293,"Low",Applications!$X$2:$X$293,"") -> 0 | Q156: =COUNTIFS(Applications!$B$2:$B$293,A156,Applications!$AH$2:$AH$293,"Past*")+COUNTIFS(Applications!$B$2:$B$293,A156,Applications!$AH$2:$AH$293,"No CIS*") -> 0 | S156: No | T156: =IF(OR(R156<>"",S156="Yes",P156>0,Q156>0),IF(U156="Yes","Resolved","Yes"),"No") -> No
A157: U-1033981 | B157: Latest upstream export | C157: €960k - Residential Development | D157: St. Patrick Villas, Castleconnel | E157: Castleconnell | F157: 52.704525 | G157: -8.5059194 | H157: Tender | I157: =COUNTIF(Applications!$B$2:$B$293,A157) -> 1 | J157: =COUNTIFS(Applications!$B$2:$B$293,A157,Applications!$Z$2:$Z$293,"Yes") -> 1 | K157: =SUMIFS(Applications!$AI$2:$AI$293,Applications!$B$2:$B$293,A157) -> 4 | L157: =SUMIFS(Applications!$AL$2:$AL$293,Applications!$B$2:$B$293,A157) -> 4 | M157: =SUMIFS(Applications!$AM$2:$AM$293,Applications!$B$2:$B$293,A157) -> 0 | N157: =SUMIFS(Applications!$AK$2:$AK$293,Applications!$B$2:$B$293,A157) -> 0 | O157: =I157-J157 -> 0 | P157: =COUNTIFS(Applications!$B$2:$B$293,A157,Applications!$W$2:$W$293,"Low",Applications!$X$2:$X$293,"") -> 0 | Q157: =COUNTIFS(Applications!$B$2:$B$293,A157,Applications!$AH$2:$AH$293,"Past*")+COUNTIFS(Applications!$B$2:$B$293,A157,Applications!$AH$2:$AH$293,"No CIS*") -> 0 | S157: No | T157: =IF(OR(R157<>"",S157="Yes",P157>0,Q157>0),IF(U157="Yes","Resolved","Yes"),"No") -> No
A158: U-1040199 | B158: Latest upstream export | C158: €2.6m - Apartments | D158: Ballygrennan Close, Moyross | E158: Limerick City and Suburbs | F158: 52.683828 | G158: -8.6494762 | H158: Tender | I158: =COUNTIF(Applications!$B$2:$B$293,A158) -> 1 | J158: =COUNTIFS(Applications!$B$2:$B$293,A158,Applications!$Z$2:$Z$293,"Yes") -> 1 | K158: =SUMIFS(Applications!$AI$2:$AI$293,Applications!$B$2:$B$293,A158) -> 12 | L158: =SUMIFS(Applications!$AL$2:$AL$293,Applications!$B$2:$B$293,A158) -> 12 | M158: =SUMIFS(Applications!$AM$2:$AM$293,Applications!$B$2:$B$293,A158) -> 0 | N158: =SUMIFS(Applications!$AK$2:$AK$293,Applications!$B$2:$B$293,A158) -> 0 | O158: =I158-J158 -> 0 | P158: =COUNTIFS(Applications!$B$2:$B$293,A158,Applications!$W$2:$W$293,"Low",Applications!$X$2:$X$293,"") -> 0 | Q158: =COUNTIFS(Applications!$B$2:$B$293,A158,Applications!$AH$2:$AH$293,"Past*")+COUNTIFS(Applications!$B$2:$B$293,A158,Applications!$AH$2:$AH$293,"No CIS*") -> 0 | S158: No | T158: =IF(OR(R158<>"",S158="Yes",P158>0,Q158>0),IF(U158="Yes","Resolved","Yes"),"No") -> No
A159: U-1157017 | B159: Latest upstream export | C159: €2.5m - Residential Development, Mungret | D159: Castlemungret, Mungret, Co. Limerick, Republic of Ireland, V94 339H | E159: Mungret | F159: 52.635932 | G159: -8.6902517 | H159: On Site | I159: =COUNTIF(Applications!$B$2:$B$293,A159) -> 1 | J159: =COUNTIFS(Applications!$B$2:$B$293,A159,Applications!$Z$2:$Z$293,"Yes") -> 1 | K159: =SUMIFS(Applications!$AI$2:$AI$293,Applications!$B$2:$B$293,A159) -> 12 | L159: =SUMIFS(Applications!$AL$2:$AL$293,Applications!$B$2:$B$293,A159) -> 12 | M159: =SUMIFS(Applications!$AM$2:$AM$293,Applications!$B$2:$B$293,A159) -> 0 | N159: =SUMIFS(Applications!$AK$2:$AK$293,Applications!$B$2:$B$293,A159) -> 0 | O159: =I159-J159 -> 0 | P159: =COUNTIFS(Applications!$B$2:$B$293,A159,Applications!$W$2:$W$293,"Low",Applications!$X$2:$X$293,"") -> 0 | Q159: =COUNTIFS(Applications!$B$2:$B$293,A159,Applications!$AH$2:$AH$293,"Past*")+COUNTIFS(Applications!$B$2:$B$293,A159,Applications!$AH$2:$AH$293,"No CIS*") -> 0 | S159: No | T159: =IF(OR(R159<>"",S159="Yes",P159>0,Q159>0),IF(U159="Yes","Resolved","Yes"),"No") -> No
A160: U-1164424 | B160: Latest upstream export | C160: €9.6m - Residential Development | D160: Hillcroft Close, St. Patricks Road, Singland, Limerick | E160: Limerick City and Suburbs | F160: 52.661374 | G160: -8.5993881 | H160: Contract Awarded | I160: =COUNTIF(Applications!$B$2:$B$293,A160) -> 1 | J160: =COUNTIFS(Applications!$B$2:$B$293,A160,Applications!$Z$2:$Z$293,"Yes") -> 1 | K160: =SUMIFS(Applications!$AI$2:$AI$293,Applications!$B$2:$B$293,A160) -> 55 | L160: =SUMIFS(Applications!$AL$2:$AL$293,Applications!$B$2:$B$293,A160) -> 55 | M160: =SUMIFS(Applications!$AM$2:$AM$293,Applications!$B$2:$B$293,A160) -> 0 | N160: =SUMIFS(Applications!$AK$2:$AK$293,Applications!$B$2:$B$293,A160) -> 0 | O160: =I160-J160 -> 0 | P160: =COUNTIFS(Applications!$B$2:$B$293,A160,Applications!$W$2:$W$293,"Low",Applications!$X$2:$X$293,"") -> 0 | Q160: =COUNTIFS(Applications!$B$2:$B$293,A160,Applications!$AH$2:$AH$293,"Past*")+COUNTIFS(Applications!$B$2:$B$293,A160,Applications!$AH$2:$AH$293,"No CIS*") -> 0 | S160: No | T160: =IF(OR(R160<>"",S160="Yes",P160>0,Q160>0),IF(U160="Yes","Resolved","Yes"),"No") -> No
A161: U-1165485 | B161: Latest upstream export | C161: €11.3m - Residential Development | D161: Saint Ita's Road, Abbeyfeale West, Abbeyfeale | E161: Abbeyfeale | F161: 52.382036 | G161: -9.2982956 | H161: Contract Awarded | I161: =COUNTIF(Applications!$B$2:$B$293,A161) -> 1 | J161: =COUNTIFS(Applications!$B$2:$B$293,A161,Applications!$Z$2:$Z$293,"Yes") -> 1 | K161: =SUMIFS(Applications!$AI$2:$AI$293,Applications!$B$2:$B$293,A161) -> 68 | L161: =SUMIFS(Applications!$AL$2:$AL$293,Applications!$B$2:$B$293,A161) -> 68 | M161: =SUMIFS(Applications!$AM$2:$AM$293,Applications!$B$2:$B$293,A161) -> 0 | N161: =SUMIFS(Applications!$AK$2:$AK$293,Applications!$B$2:$B$293,A161) -> 0 | O161: =I161-J161 -> 0 | P161: =COUNTIFS(Applications!$B$2:$B$293,A161,Applications!$W$2:$W$293,"Low",Applications!$X$2:$X$293,"") -> 0 | Q161: =COUNTIFS(Applications!$B$2:$B$293,A161,Applications!$AH$2:$AH$293,"Past*")+COUNTIFS(Applications!$B$2:$B$293,A161,Applications!$AH$2:$AH$293,"No CIS*") -> 0 | S161: No | T161: =IF(OR(R161<>"",S161="Yes",P161>0,Q161>0),IF(U161="Yes","Resolved","Yes"),"No") -> No
A162: U-1166991 | B162: Latest upstream export | C162: €10.8m - Residential Development, Croom | D162: Skagh, Croom, Croom | E162: Other County Limerick | F162: 52.525037 | G162: -8.7170903 | H162: Contract Awarded | I162: =COUNTIF(Applications!$B$2:$B$293,A162) -> 1 | J162: =COUNTIFS(Applications!$B$2:$B$293,A162,Applications!$Z$2:$Z$293,"Yes") -> 1 | K162: =SUMIFS(Applications!$AI$2:$AI$293,Applications!$B$2:$B$293,A162) -> 51 | L162: =SUMIFS(Applications!$AL$2:$AL$293,Applications!$B$2:$B$293,A162) -> 51 | M162: =SUMIFS(Applications!$AM$2:$AM$293,Applications!$B$2:$B$293,A162) -> 0 | N162: =SUMIFS(Applications!$AK$2:$AK$293,Applications!$B$2:$B$293,A162) -> 0 | O162: =I162-J162 -> 0 | P162: =COUNTIFS(Applications!$B$2:$B$293,A162,Applications!$W$2:$W$293,"Low",Applications!$X$2:$X$293,"") -> 0 | Q162: =COUNTIFS(Applications!$B$2:$B$293,A162,Applications!$AH$2:$AH$293,"Past*")+COUNTIFS(Applications!$B$2:$B$293,A162,Applications!$AH$2:$AH$293,"No CIS*") -> 0 | S162: No | T162: =IF(OR(R162<>"",S162="Yes",P162>0,Q162>0),IF(U162="Yes","Resolved","Yes"),"No") -> No
A163: U-1212017 | B163: Latest upstream export | C163: €1m - Residential Development, Ballylanders | D163: Church Glen, Glennahaglish, Ballylanders | E163: Other County Limerick | F163: 52.36881 | G163: -8.34341 | H163: Contract Awarded | I163: =COUNTIF(Applications!$B$2:$B$293,A163) -> 1 | J163: =COUNTIFS(Applications!$B$2:$B$293,A163,Applications!$Z$2:$Z$293,"Yes") -> 0 | K163: =SUMIFS(Applications!$AI$2:$AI$293,Applications!$B$2:$B$293,A163) -> 0 | L163: =SUMIFS(Applications!$AL$2:$AL$293,Applications!$B$2:$B$293,A163) -> 0 | M163: =SUMIFS(Applications!$AM$2:$AM$293,Applications!$B$2:$B$293,A163) -> 0 | N163: =SUMIFS(Applications!$AK$2:$AK$293,Applications!$B$2:$B$293,A163) -> 0 | O163: =I163-J163 -> 1 | P163: =COUNTIFS(Applications!$B$2:$B$293,A163,Applications!$W$2:$W$293,"Low",Applications!$X$2:$X$293,"") -> 0 | Q163: =COUNTIFS(Applications!$B$2:$B$293,A163,Applications!$AH$2:$AH$293,"Past*")+COUNTIFS(Applications!$B$2:$B$293,A163,Applications!$AH$2:$AH$293,"No CIS*") -> 0 | R163: P-1213266 (79m): €2.5m - 9 Houses, On Site, 9 units | S163: No | T163: =IF(OR(R163<>"",S163="Yes",P163>0,Q163>0),IF(U163="Yes","Resolved","Yes"),"No") -> Yes
A164: U-1227182 | B164: Latest upstream export | C164: €4.5m - Housing Development, Mungret | D164: Rathmale, Mungret, Co. Limerick, Republic of Ireland | E164: Mungret | F164: 52.632858 | G164: -8.6983485 | H164: Permission Granted | I164: =COUNTIF(Applications!$B$2:$B$293,A164) -> 1 | J164: =COUNTIFS(Applications!$B$2:$B$293,A164,Applications!$Z$2:$Z$293,"Yes") -> 1 | K164: =SUMIFS(Applications!$AI$2:$AI$293,Applications!$B$2:$B$293,A164) -> 21 | L164: =SUMIFS(Applications!$AL$2:$AL$293,Applications!$B$2:$B$293,A164) -> 21 | M164: =SUMIFS(Applications!$AM$2:$AM$293,Applications!$B$2:$B$293,A164) -> 0 | N164: =SUMIFS(Applications!$AK$2:$AK$293,Applications!$B$2:$B$293,A164) -> 0 | O164: =I164-J164 -> 0 | P164: =COUNTIFS(Applications!$B$2:$B$293,A164,Applications!$W$2:$W$293,"Low",Applications!$X$2:$X$293,"") -> 0 | Q164: =COUNTIFS(Applications!$B$2:$B$293,A164,Applications!$AH$2:$AH$293,"Past*")+COUNTIFS(Applications!$B$2:$B$293,A164,Applications!$AH$2:$AH$293,"No CIS*") -> 1 | S164: No | T164: =IF(OR(R164<>"",S164="Yes",P164>0,Q164>0),IF(U164="Yes","Resolved","Yes"),"No") -> Yes
A165: U-1241529 | B165: Latest upstream export | C165: €4.5m - Housing Development, Limerick City | D165: St. Anne's, Dublin Road, Limerick City | E165: Limerick City and Suburbs | F165: 52.66476 | G165: -8.6087547 | H165: Contract Awarded | I165: =COUNTIF(Applications!$B$2:$B$293,A165) -> 1 | J165: =COUNTIFS(Applications!$B$2:$B$293,A165,Applications!$Z$2:$Z$293,"Yes") -> 1 | K165: =SUMIFS(Applications!$AI$2:$AI$293,Applications!$B$2:$B$293,A165) -> 20 | L165: =SUMIFS(Applications!$AL$2:$AL$293,Applications!$B$2:$B$293,A165) -> 20 | M165: =SUMIFS(Applications!$AM$2:$AM$293,Applications!$B$2:$B$293,A165) -> 0 | N165: =SUMIFS(Applications!$AK$2:$AK$293,Applications!$B$2:$B$293,A165) -> 0 | O165: =I165-J165 -> 0 | P165: =COUNTIFS(Applications!$B$2:$B$293,A165,Applications!$W$2:$W$293,"Low",Applications!$X$2:$X$293,"") -> 0 | Q165: =COUNTIFS(Applications!$B$2:$B$293,A165,Applications!$AH$2:$AH$293,"Past*")+COUNTIFS(Applications!$B$2:$B$293,A165,Applications!$AH$2:$AH$293,"No CIS*") -> 0 | S165: No | T165: =IF(OR(R165<>"",S165="Yes",P165>0,Q165>0),IF(U165="Yes","Resolved","Yes"),"No") -> No
A166: U-1250272 | B166: Latest upstream export | C166: €6.5m - Apartment Development, Limerick | D166: Windmill Street and Cogan Street, Limerick, Co. Limerick, Republic of Ireland, V94 DNH7 | E166: Limerick City and Suburbs | F166: 52.659338 | G166: -8.6354307 | H166: Permission Granted | I166: =COUNTIF(Applications!$B$2:$B$293,A166) -> 1 | J166: =COUNTIFS(Applications!$B$2:$B$293,A166,Applications!$Z$2:$Z$293,"Yes") -> 1 | K166: =SUMIFS(Applications!$AI$2:$AI$293,Applications!$B$2:$B$293,A166) -> 29 | L166: =SUMIFS(Applications!$AL$2:$AL$293,Applications!$B$2:$B$293,A166) -> 29 | M166: =SUMIFS(Applications!$AM$2:$AM$293,Applications!$B$2:$B$293,A166) -> 0 | N166: =SUMIFS(Applications!$AK$2:$AK$293,Applications!$B$2:$B$293,A166) -> 0 | O166: =I166-J166 -> 0 | P166: =COUNTIFS(Applications!$B$2:$B$293,A166,Applications!$W$2:$W$293,"Low",Applications!$X$2:$X$293,"") -> 1 | Q166: =COUNTIFS(Applications!$B$2:$B$293,A166,Applications!$AH$2:$AH$293,"Past*")+COUNTIFS(Applications!$B$2:$B$293,A166,Applications!$AH$2:$AH$293,"No CIS*") -> 1 | R166: P-1195465 (44m): €2.1m - Apartment Development , Permission Granted, 14 units; P-980328 (106m): €2m - Apartment Development , Complete, 14 units | S166: No | T166: =IF(OR(R166<>"",S166="Yes",P166>0,Q166>0),IF(U166="Yes","Resolved","Yes"),"No") -> Yes
A167: U-1254537 | B167: Latest upstream export | C167: €5m - Apartment/Retail Development, Dooradoyle | D167: Shannonside Kitchens Site, St Nessans Road, Dooradoyle, Co. Limerick, Republic of Ireland, V94 XH99 | E167: Limerick City and Suburbs | F167: 52.639955 | G167: -8.6504621 | H167: Permission Granted | I167: =COUNTIF(Applications!$B$2:$B$293,A167) -> 1 | J167: =COUNTIFS(Applications!$B$2:$B$293,A167,Applications!$Z$2:$Z$293,"Yes") -> 1 | K167: =SUMIFS(Applications!$AI$2:$AI$293,Applications!$B$2:$B$293,A167) -> 30 | L167: =SUMIFS(Applications!$AL$2:$AL$293,Applications!$B$2:$B$293,A167) -> 30 | M167: =SUMIFS(Applications!$AM$2:$AM$293,Applications!$B$2:$B$293,A167) -> 0 | N167: =SUMIFS(Applications!$AK$2:$AK$293,Applications!$B$2:$B$293,A167) -> 0 | O167: =I167-J167 -> 0 | P167: =COUNTIFS(Applications!$B$2:$B$293,A167,Applications!$W$2:$W$293,"Low",Applications!$X$2:$X$293,"") -> 0 | Q167: =COUNTIFS(Applications!$B$2:$B$293,A167,Applications!$AH$2:$AH$293,"Past*")+COUNTIFS(Applications!$B$2:$B$293,A167,Applications!$AH$2:$AH$293,"No CIS*") -> 1 | S167: No | T167: =IF(OR(R167<>"",S167="Yes",P167>0,Q167>0),IF(U167="Yes","Resolved","Yes"),"No") -> Yes
A168: U-1277663 | B168: Latest upstream export | C168: €9m - Housing Development, Patrickswell | D168: Ballyanrahan East, Patrickswell | E168: Patrickswell | F168: 52.600921 | G168: -8.7117481 | H168: Contract Awarded | I168: =COUNTIF(Applications!$B$2:$B$293,A168) -> 1 | J168: =COUNTIFS(Applications!$B$2:$B$293,A168,Applications!$Z$2:$Z$293,"Yes") -> 1 | K168: =SUMIFS(Applications!$AI$2:$AI$293,Applications!$B$2:$B$293,A168) -> 41 | L168: =SUMIFS(Applications!$AL$2:$AL$293,Applications!$B$2:$B$293,A168) -> 41 | M168: =SUMIFS(Applications!$AM$2:$AM$293,Applications!$B$2:$B$293,A168) -> 0 | N168: =SUMIFS(Applications!$AK$2:$AK$293,Applications!$B$2:$B$293,A168) -> 0 | O168: =I168-J168 -> 0 | P168: =COUNTIFS(Applications!$B$2:$B$293,A168,Applications!$W$2:$W$293,"Low",Applications!$X$2:$X$293,"") -> 1 | Q168: =COUNTIFS(Applications!$B$2:$B$293,A168,Applications!$AH$2:$AH$293,"Past*")+COUNTIFS(Applications!$B$2:$B$293,A168,Applications!$AH$2:$AH$293,"No CIS*") -> 0 | R168: SG-003 (73m): €2.2m - Housing Development , On Site, 5 units; SG-003 (76m): €3.9m - EOD - Residential Development, Patric, On Site, 16 units | S168: No | T168: =IF(OR(R168<>"",S168="Yes",P168>0,Q168>0),IF(U168="Yes","Resolved","Yes"),"No") -> Yes
A169: U-1278374 | B169: Latest upstream export | C169: €3m - Apartment Development, Limerick | D169: 21 & 21A Barringon Street, Limerick, Co. Limerick, Republic of Ireland, V94 RX33 | E169: Limerick City and Suburbs | F169: 52.658031 | G169: -8.6314016 | H169: On Site | I169: =COUNTIF(Applications!$B$2:$B$293,A169) -> 1 | J169: =COUNTIFS(Applications!$B$2:$B$293,A169,Applications!$Z$2:$Z$293,"Yes") -> 1 | K169: =SUMIFS(Applications!$AI$2:$AI$293,Applications!$B$2:$B$293,A169) -> 24 | L169: =SUMIFS(Applications!$AL$2:$AL$293,Applications!$B$2:$B$293,A169) -> 24 | M169: =SUMIFS(Applications!$AM$2:$AM$293,Applications!$B$2:$B$293,A169) -> 0 | N169: =SUMIFS(Applications!$AK$2:$AK$293,Applications!$B$2:$B$293,A169) -> 0 | O169: =I169-J169 -> 0 | P169: =COUNTIFS(Applications!$B$2:$B$293,A169,Applications!$W$2:$W$293,"Low",Applications!$X$2:$X$293,"") -> 0 | Q169: =COUNTIFS(Applications!$B$2:$B$293,A169,Applications!$AH$2:$AH$293,"Past*")+COUNTIFS(Applications!$B$2:$B$293,A169,Applications!$AH$2:$AH$293,"No CIS*") -> 0 | S169: No | T169: =IF(OR(R169<>"",S169="Yes",P169>0,Q169>0),IF(U169="Yes","Resolved","Yes"),"No") -> No
A170: U-1302008 | B170: Latest upstream export | C170: €3.6m - Hosuing Development, Crossagalla | D170: Ros Mor Estate, Kilmallock Road, Crossagalla | E170: Kilmallock | F170: 52.644131 | G170: -8.5877005 | H170: Plans Submitted | I170: =COUNTIF(Applications!$B$2:$B$293,A170) -> 1 | J170: =COUNTIFS(Applications!$B$2:$B$293,A170,Applications!$Z$2:$Z$293,"Yes") -> 0 | K170: =SUMIFS(Applications!$AI$2:$AI$293,Applications!$B$2:$B$293,A170) -> 0 | L170: =SUMIFS(Applications!$AL$2:$AL$293,Applications!$B$2:$B$293,A170) -> 0 | M170: =SUMIFS(Applications!$AM$2:$AM$293,Applications!$B$2:$B$293,A170) -> 0 | N170: =SUMIFS(Applications!$AK$2:$AK$293,Applications!$B$2:$B$293,A170) -> 0 | O170: =I170-J170 -> 1 | P170: =COUNTIFS(Applications!$B$2:$B$293,A170,Applications!$W$2:$W$293,"Low",Applications!$X$2:$X$293,"") -> 0 | Q170: =COUNTIFS(Applications!$B$2:$B$293,A170,Applications!$AH$2:$AH$293,"Past*")+COUNTIFS(Applications!$B$2:$B$293,A170,Applications!$AH$2:$AH$293,"No CIS*") -> 0 | R170: SG-007 (14m): €3.6m - Housing/Creche Development, Crossagal, On Site, 12 units; SG-007 (48m): €529k - 4 Houses , Permission Granted, 4 units | S170: No | T170: =IF(OR(R170<>"",S170="Yes",P170>0,Q170>0),IF(U170="Yes","Resolved","Yes"),"No") -> Yes
A171: U-1310780 | B171: Latest upstream export | C171: €27m - Mixed Use Development, Dooradoyle | D171: Southcourt, Raheen, Dooradoyle | E171: Limerick City and Suburbs | F171: 52.628242 | G171: -8.6636361 | H171: Tender | I171: =COUNTIF(Applications!$B$2:$B$293,A171) -> 1 | J171: =COUNTIFS(Applications!$B$2:$B$293,A171,Applications!$Z$2:$Z$293,"Yes") -> 1 | K171: =SUMIFS(Applications!$AI$2:$AI$293,Applications!$B$2:$B$293,A171) -> 104 | L171: =SUMIFS(Applications!$AL$2:$AL$293,Applications!$B$2:$B$293,A171) -> 104 | M171: =SUMIFS(Applications!$AM$2:$AM$293,Applications!$B$2:$B$293,A171) -> 0 | N171: =SUMIFS(Applications!$AK$2:$AK$293,Applications!$B$2:$B$293,A171) -> 0 | O171: =I171-J171 -> 0 | P171: =COUNTIFS(Applications!$B$2:$B$293,A171,Applications!$W$2:$W$293,"Low",Applications!$X$2:$X$293,"") -> 0 | Q171: =COUNTIFS(Applications!$B$2:$B$293,A171,Applications!$AH$2:$AH$293,"Past*")+COUNTIFS(Applications!$B$2:$B$293,A171,Applications!$AH$2:$AH$293,"No CIS*") -> 0 | S171: No | T171: =IF(OR(R171<>"",S171="Yes",P171>0,Q171>0),IF(U171="Yes","Resolved","Yes"),"No") -> No
A172: U-1315592 | B172: Latest upstream export | C172: €12.6m - Residential Development, Patrickswell | D172: Barnakyle, Patrickswell | E172: Patrickswell | F172: 52.601042 | G172: -8.7045513 | H172: Plans Submitted | I172: =COUNTIF(Applications!$B$2:$B$293,A172) -> 1 | J172: =COUNTIFS(Applications!$B$2:$B$293,A172,Applications!$Z$2:$Z$293,"Yes") -> 0 | K172: =SUMIFS(Applications!$AI$2:$AI$293,Applications!$B$2:$B$293,A172) -> 0 | L172: =SUMIFS(Applications!$AL$2:$AL$293,Applications!$B$2:$B$293,A172) -> 0 | M172: =SUMIFS(Applications!$AM$2:$AM$293,Applications!$B$2:$B$293,A172) -> 0 | N172: =SUMIFS(Applications!$AK$2:$AK$293,Applications!$B$2:$B$293,A172) -> 0 | O172: =I172-J172 -> 1 | P172: =COUNTIFS(Applications!$B$2:$B$293,A172,Applications!$W$2:$W$293,"Low",Applications!$X$2:$X$293,"") -> 0 | Q172: =COUNTIFS(Applications!$B$2:$B$293,A172,Applications!$AH$2:$AH$293,"Past*")+COUNTIFS(Applications!$B$2:$B$293,A172,Applications!$AH$2:$AH$293,"No CIS*") -> 0 | R172: SG-004 (69m): €15.9m - Residential Development, Patrickswel, Permission Granted, 63 units; SG-004 (108m): €6.3m - Residential Development, Patrickswell, Permission Granted, 49 units | S172: No | T172: =IF(OR(R172<>"",S172="Yes",P172>0,Q172>0),IF(U172="Yes","Resolved","Yes"),"No") -> Yes
A173: U-1316160 | B173: Latest upstream export | C173: €705k - Radharc an Ghleanna Residential Development, Mountcollins | D173: Radharc an Ghleanna, Mountcollins | E173: Other County Limerick | F173: 52.318745 | G173: -9.2332914 | H173: Tender | I173: =COUNTIF(Applications!$B$2:$B$293,A173) -> 1 | J173: =COUNTIFS(Applications!$B$2:$B$293,A173,Applications!$Z$2:$Z$293,"Yes") -> 1 | K173: =SUMIFS(Applications!$AI$2:$AI$293,Applications!$B$2:$B$293,A173) -> 4 | L173: =SUMIFS(Applications!$AL$2:$AL$293,Applications!$B$2:$B$293,A173) -> 4 | M173: =SUMIFS(Applications!$AM$2:$AM$293,Applications!$B$2:$B$293,A173) -> 0 | N173: =SUMIFS(Applications!$AK$2:$AK$293,Applications!$B$2:$B$293,A173) -> 0 | O173: =I173-J173 -> 0 | P173: =COUNTIFS(Applications!$B$2:$B$293,A173,Applications!$W$2:$W$293,"Low",Applications!$X$2:$X$293,"") -> 0 | Q173: =COUNTIFS(Applications!$B$2:$B$293,A173,Applications!$AH$2:$AH$293,"Past*")+COUNTIFS(Applications!$B$2:$B$293,A173,Applications!$AH$2:$AH$293,"No CIS*") -> 0 | S173: No | T173: =IF(OR(R173<>"",S173="Yes",P173>0,Q173>0),IF(U173="Yes","Resolved","Yes"),"No") -> No
A174: U-1319159 | B174: Latest upstream export | C174: €22m - Golf Links Road LRD, Monaleen | D174: Golf Links Road, Newtown, Monaleen, Co. Limerick, Republic of Ireland, V94 P821 | E174: Limerick City and Suburbs | F174: 52.652714 | G174: -8.5604119 | H174: On Site | I174: =COUNTIF(Applications!$B$2:$B$293,A174) -> 1 | J174: =COUNTIFS(Applications!$B$2:$B$293,A174,Applications!$Z$2:$Z$293,"Yes") -> 1 | K174: =SUMIFS(Applications!$AI$2:$AI$293,Applications!$B$2:$B$293,A174) -> 122 | L174: =SUMIFS(Applications!$AL$2:$AL$293,Applications!$B$2:$B$293,A174) -> 122 | M174: =SUMIFS(Applications!$AM$2:$AM$293,Applications!$B$2:$B$293,A174) -> 0 | N174: =SUMIFS(Applications!$AK$2:$AK$293,Applications!$B$2:$B$293,A174) -> 0 | O174: =I174-J174 -> 0 | P174: =COUNTIFS(Applications!$B$2:$B$293,A174,Applications!$W$2:$W$293,"Low",Applications!$X$2:$X$293,"") -> 0 | Q174: =COUNTIFS(Applications!$B$2:$B$293,A174,Applications!$AH$2:$AH$293,"Past*")+COUNTIFS(Applications!$B$2:$B$293,A174,Applications!$AH$2:$AH$293,"No CIS*") -> 0 | S174: No | T174: =IF(OR(R174<>"",S174="Yes",P174>0,Q174>0),IF(U174="Yes","Resolved","Yes"),"No") -> No
A175: U-1327665 | B175: Latest upstream export | C175: €2.5m - Assisted Living Dwelling Units, Glin | D175: Cloverfield Killacolla (Baker), Glin | E175: Other County Limerick | F175: 52.5698 | G175: -9.2806095 | H175: Tender | I175: =COUNTIF(Applications!$B$2:$B$293,A175) -> 1 | J175: =COUNTIFS(Applications!$B$2:$B$293,A175,Applications!$Z$2:$Z$293,"Yes") -> 1 | K175: =SUMIFS(Applications!$AI$2:$AI$293,Applications!$B$2:$B$293,A175) -> 10 | L175: =SUMIFS(Applications!$AL$2:$AL$293,Applications!$B$2:$B$293,A175) -> 10 | M175: =SUMIFS(Applications!$AM$2:$AM$293,Applications!$B$2:$B$293,A175) -> 0 | N175: =SUMIFS(Applications!$AK$2:$AK$293,Applications!$B$2:$B$293,A175) -> 0 | O175: =I175-J175 -> 0 | P175: =COUNTIFS(Applications!$B$2:$B$293,A175,Applications!$W$2:$W$293,"Low",Applications!$X$2:$X$293,"") -> 0 | Q175: =COUNTIFS(Applications!$B$2:$B$293,A175,Applications!$AH$2:$AH$293,"Past*")+COUNTIFS(Applications!$B$2:$B$293,A175,Applications!$AH$2:$AH$293,"No CIS*") -> 0 | S175: No | T175: =IF(OR(R175<>"",S175="Yes",P175>0,Q175>0),IF(U175="Yes","Resolved","Yes"),"No") -> No
