Workbook

Sheet Story
A1: Limerick: is there enough zoned land to build 39,865 homes by 2040?
A2: Reads top to bottom: demand, what the Housing Land Register holds, where supply sits, how fast it is delivered, and how much more land to zone. Numbers are live; change levers on Inputs.
B5: Housing target 2026–40 | D5: Register: homes still to build | F5: Deliverable by 2040 (selected) | H5: Shortfall against fair share | J5: Land to zone (ha) | L5: City share of new land
B6: =target_total -> 39865 | D6: =reg_fut -> 22519 | F6: =o_sup -> 17245 | H6: =o_gap -> 22620 | J6: =o_ha -> 1035.4702 | L6: =o_citypct -> 0.52144013
B7: ="Scenario shown: "&dens_scn&" · tenure position: "&tenure_scn&" · split city / settlements / remainder: "&TEXT(fs_city,"0%")&" / "&TEXT(fs_set,"0%")&" / "&TEXT(fs_rem,"0%")&" (set on Inputs)" -> Scenario shown: Current density · tenure position: Working · split city / settlements / remainder: 70% / 24% / 6% (set on Inputs)
B9: 1 Demand: what has to be built
B10: ="Limerick needs "&TEXT(target_total,"#,##0")&" homes between 2026 and 2040, about "&TEXT(target_total/15,"#,##0")&" a year. On the "&LOWER(tenure_scn)&" tenure position that is "&TEXT(d_soc,"#,##0")&" social ("&TEXT(d_soc/target_total,"0%")&"), "&TEXT(d_aff,"#,##0")&" affordable ("&TEXT(d_aff/target_total,"0%")&"), "&TEXT(d_prs,"#,##0")&" private rented ("&TEXT(d_prs/target_total,"0%")&") and "&TEXT(d_buy,"#,##0")&" for buyers ("&TEXT(d_buy/target_total,"0%")&")." -> Limerick needs 39,865 homes between 2026 and 2040, about 2,658 a year. On the working tenure position that is 8,362 social (21%), 5,019 affordable (13%), 5,292 private rented (13%) and 21,191 for buyers (53%).
B11: ="The Council profile front-loads delivery: "&TEXT('1 Demand'!D22,"#,##0")&" homes in 2026–28 against "&TEXT('1 Demand'!C22,"#,##0")&" of modelled need, then paid back after 2035. The totals are not the risk. The risk is the wrong tenures and sizes." -> The Council profile front-loads delivery: 12,789 homes in 2026–28 against 7,957 of modelled need, then paid back after 2035. The totals are not the risk. The risk is the wrong tenures and sizes.
B12: ="Specialist need inside social: about "&TEXT('1 Demand'!D46,"#,##0")&" disability, "&TEXT('1 Demand'!E46,"#,##0")&" older persons, "&TEXT('1 Demand'!F46,"#,##0")&" Traveller-specific and "&TEXT('1 Demand'!G46,"#,##0")&" community dwellings over 2026–40. On size, the Council plan is "&TEXT('1 Demand'!G58,"0%")&" one-bed overall; need-based mix gives "&TEXT('1 Demand'!G57,"0%")&", and "&TEXT(mix_Social1,"0%")&" for social alone." -> Specialist need inside social: about 1,554 disability, 891 older persons, 92 Traveller-specific and 155 community dwellings over 2026–40. On size, the Council plan is 24% one-bed overall; need-based mix gives 31%, and 55% for social alone.
B14: 2 The register: what it holds
B15: ="The register has "&TEXT(reg_parcels,"#,##0")&" parcels and "&TEXT('2 Register'!C27,"#,##0")&" counted permissions. Consented homes total "&TEXT(reg_cons,"#,##0")&", of which "&TEXT(reg_comp,"#,##0")&" are complete. Council audit land and zoning estimates with no consent add "&TEXT(reg_unc,"#,##0")&" of capacity. Total supply is "&TEXT(reg_tot,"#,##0")&"; "&TEXT(reg_fut,"#,##0")&" are still to be built." -> The register has 446 parcels and 236 counted permissions. Consented homes total 10,500, of which 1,631 are complete. Council audit land and zoning estimates with no consent add 13,650 of capacity. Total supply is 24,150; 22,519 are still to be built.
B16: Parcels hold the land and permissions hold the consents, one permission to one parcel. Only Complete, Under construction, Permitted – not started and Stalled count; Expired and In planning are kept but not counted. The register also carries a quarterly GeoDirectory check of new addresses (see 2 Register).
B18: 3 Where the supply sits
B19: ="City Centre holds "&TEXT('3 Supply'!L7,"#,##0")&" homes of future supply ("&TEXT('3 Supply'!M7,"0%")&"), the rest of the city "&TEXT('3 Supply'!L8,"#,##0")&" ("&TEXT('3 Supply'!M8,"0%")&"), the 15 settlements "&TEXT('3 Supply'!L10,"#,##0")&" ("&TEXT('3 Supply'!M10,"0%")&") and the remainder of the county "&TEXT('3 Supply'!L11,"#,##0")&" ("&TEXT('3 Supply'!M11,"0%")&"). Only "&TEXT('3 Supply'!I7,"#,##0")&" City Centre homes have a consent; "&TEXT('3 Supply'!J7,"#,##0")&" sit on audit land with none." -> City Centre holds 4,127 homes of future supply (18%), the rest of the city 13,258 (59%), the 15 settlements 4,550 (20%) and the remainder of the county 584 (3%). Only 925 City Centre homes have a consent; 3,301 sit on audit land with none.
B20: ="In the settlements "&TEXT('3 Supply'!I10,"#,##0")&" homes are consented ("&TEXT('3 Supply'!I10/'3 Supply'!K10,"0%")&" of their total supply) and "&TEXT('3 Supply'!J10,"#,##0")&" are zoned-land estimates with no consent. Area-by-area detail for all 24 study areas is on 3b Study Areas." -> In the settlements 1,738 homes are consented (36% of their total supply) and 3,063 are zoned-land estimates with no consent. Area-by-area detail for all 24 study areas is on 3b Study Areas.
B21: ="The City Centre figure rests on a few large audit parcels. Across City Centre audit land with no consent, capacity works out at "&TEXT('3 Supply'!B47,"0")&" homes a hectare, against a register density band of 100+ on most of it. The largest parcel, "&TEXT('3 Supply'!A69,"@")&" ("&TEXT('3 Supply'!F69,"0")&" ha), works out at "&TEXT('3 Supply'!J69,"0")&". The density lever tests that gap." -> The City Centre figure rests on a few large audit parcels. Across City Centre audit land with no consent, capacity works out at 44 homes a hectare, against a register density band of 100+ on most of it. The largest parcel, CITY-107 (68 ha), works out at 37. The density lever tests that gap.
B23: 4 Delivery: how fast sites activate
B24: ="Of the units granted permission in 2018–23, "&TEXT(act_old,"0%")&" have started. Projected delivery from the register (scenario: "&dens_scn&") averages "&TEXT(v_pipe_26_30,"#,##0")&" a year in 2026–30, "&TEXT(v_avg2,"#,##0")&" in 2031–35 and "&TEXT(v_avg3,"#,##0")&" in 2036–40, against a Council profile of 4,263 a year to 2030." -> Of the units granted permission in 2018–23, 79% have started. Projected delivery from the register (scenario: Current density) averages 1,746 a year in 2026–30, 3,257 in 2031–35 and 2,970 in 2036–40, against a Council profile of 4,263 a year to 2030.
B25: ="Projected delivery to 2040 is "&TEXT(v_total,"#,##0")&" against a target of "&TEXT(target_total,"#,##0")&". Without any new zoning the gap in 2040 would be "&TEXT(-v_nonew_gap,"#,##0")&" homes. New land is sized to close that total, but it delivers from "&TEXT(new_s,"0")&", so the cumulative shortfall against the Council profile peaks at "&TEXT(-v_peak,"#,##0")&" homes in "&TEXT(v_peak_yr,"0")&"." -> Projected delivery to 2040 is 39,865 against a target of 39,865. Without any new zoning the gap in 2040 would be 22,619 homes. New land is sized to close that total, but it delivers from 2031, so the cumulative shortfall against the Council profile peaks at 12,586 homes in 2030.
B27: 5 Land: how much more to zone
B28: ="The fair-share test splits future demand "&TEXT(fs_city,"0%")&" city, "&TEXT(fs_set,"0%")&" settlements and "&TEXT(fs_rem,"0%")&" remainder of the county. Against that, the register delivers "&TEXT('5 Land Need'!B8,"#,##0")&" homes at current densities and "&TEXT('5 Land Need'!C8,"#,##0")&" at increased density, against "&TEXT('5 Land Need'!B7,"#,##0")&" required. The shortfall is "&TEXT('5 Land Need'!B9,"#,##0")&" and "&TEXT('5 Land Need'!C9,"#,##0")&" homes." -> The fair-share test splits future demand 70% city, 24% settlements and 6% remainder of the county. Against that, the register delivers 17,245 homes at current densities and 20,242 at increased density, against 39,865 required. The shortfall is 22,620 and 19,623 homes.
B29: ="Land to zone: "&TEXT('5 Land Need'!B16,"#,##0")&" ha at current densities (City Centre "&TEXT('5 Land Need'!B12,"#,##0")&", rest of city "&TEXT('5 Land Need'!B13,"#,##0")&", settlements "&TEXT('5 Land Need'!B14,"#,##0")&", remainder "&TEXT('5 Land Need'!B15,"#,##0")&") or "&TEXT('5 Land Need'!C16,"#,##0")&" ha with the City Centre at "&TEXT(cc_dph_inc,"0")&" homes a hectare (City Centre "&TEXT('5 Land Need'!C12,"#,##0")&", rest of city "&TEXT('5 Land Need'!C13,"#,##0")&", settlements "&TEXT('5 Land Need'!C14,"#,##0")&", remainder "&TEXT('5 Land Need'!C15,"#,##0")&")." -> Land to zone: 1,035 ha at current densities (City Centre 125, rest of city 415, settlements 375, remainder 120) or 924 ha with the City Centre at 100 homes a hectare (City Centre 13, rest of city 415, settlements 375, remainder 120).
B31: 6 Recommendation
B32: ="Zone about "&TEXT(o_ha,"#,##0")&" more hectares ("&dens_scn&"): "&TEXT(o_ha_city,"#,##0")&" ha ("&TEXT(o_citypct,"0%")&") in the city, "&TEXT(o_ha_set,"#,##0")&" ha in the settlements and "&TEXT(o_ha_rem,"#,##0")&" ha in the remainder of the county. At the planned tenure, the homes still to find are "&TEXT(t_shsoc,"0%")&" social, "&TEXT(t_shaff,"0%")&" affordable and "&TEXT(t_shpriv,"0%")&" private market." -> Zone about 1,035 more hectares (Current density): 540 ha (52%) in the city, 375 ha in the settlements and 120 ha in the remainder of the county. At the planned tenure, the homes still to find are 24% social, 15% affordable and 61% private market.
B33: The city share follows the fair-share principle (city about 70% of the county). The split of the other 30% between settlements and the remainder is a placeholder, as are realisation rates and timing. Check them against the county land audit and the 25 open register checks.
B35: Charts
B73: Sources: Limerick Housing Land Register (GeoPackage, register file date October 2026); Limerick Interim HNDA synopsis, Spatialis, October 2026 working draft. Realisation rates, timing and the city / county fair share are working assumptions or placeholders, marked on Inputs. Source not verified for the fair share.

Sheet Inputs
A1: Inputs and levers
A2: Change the yellow cells. Everything else in the workbook recalculates. Blue text = input; black = formula; green = link to another sheet.
B5: 1 Scenario switches
B6: Tenure position used as the plan | C6: Working | E6: Working = the middle position from the HNDA note (sums to the Council target). Lower / Upper normalise the published range ends to the same total.
B7: (index) | C7: =IF(tenure_scn="Lower",1,IF(tenure_scn="Upper",3,2)) -> 2
B8: Density scenario that drives the annual projection | C8: Current density | E8: Both scenarios are always shown side by side on 5 Land Need. This switch picks the one used on 4 Delivery and the Story page.
B9: (1 = increased) | C9: =IF(dens_scn="Increased density",1,0) -> 0
B10: Add housing-list need to social (taken from buyers) | C10: No | E10: HNDA note: 1,308 households on the list are not in the model. Yes moves them from buyers to social over 2026–35 so the total stays at target.
B11: Housing-list households to add | C11: 1308 | D11: homes | E11: Source: HNDA synopsis, social demand table (housing list note). Spread evenly 2026–35.
B12: 2 Target and fair share
B13: Housing target 2026–2040 | C13: 39865 | D13: homes | E13: Source: HNDA synopsis (Council target for 2026–40 equals the new HNDA need). The annual figures on 1 Demand are rounded and sum to 39,864.
B14: Completions 1 Jan – 30 Sep 2026 not yet in the register | C14: 0 | D14: homes | E14: Source not verified. The register holds no completion dates, so this is left at 0. Enter the figure when known.
B15: Supply from outside the register 2026–40 (small sites, vacancy, conversions) | C15: 0 | D15: homes | E15: Not in the register. Left at 0 so the model reflects the register as it stands.
B16: City share of future demand (Limerick City ≈ 70% of the county) | C16: 0.7 | E16: Fair-share principle from the project brief: the city is about 70% of the county, so future demand is accommodated in that proportion. Change to test other splits.
B17: Settlements share (the 15 key towns and large villages) | C17: 0.24 | E17: PLACEHOLDER. Source not verified. Assumes 80% of the non-city 30% goes to the 15 settlements. Council to set from the settlement strategy.
B18: Remainder of county share (everywhere outside the 24 study areas) | C18: 0.06 | E18: PLACEHOLDER. Source not verified. The other 20% of the non-city 30%.
B19: Total of the three shares (should be 100%) | C19: =city_share+set_share+rem_share -> 1 | E19: The model rescales the three shares to 100% if they do not add up.
B20: City share used | C20: =city_share/fs_tot -> 0.7
B21: Settlements share used | C21: =set_share/fs_tot -> 0.24
B22: Remainder share used | C22: =rem_share/fs_tot -> 0.06
B23: City Centre share of the City target | C23: 0.25 | E23: PLACEHOLDER. Source not verified. Set from the city centre strategy / Development Plan.
B24: 3 How much of each register layer is actually built by 2040 (realisation)
B25: Under construction | C25: 1 | E25: Working assumption.
B26: Permitted – not started | C26: 0.85 | E26: Working assumption. Evidence on 4 Delivery: share of units granted 2018–23 that have started.
B27: Stalled | C27: 0.5 | E27: Working assumption.
B28: Council audit land with no consent (unconsented capacity) | C28: 0.7 | E28: Working assumption. These parcels have no permission yet.
B29: Zoned land, no consent (county estimate) | C29: 0.6 | E29: Working assumption. Interim estimate in the register until the county audit arrives.
B30: Newly zoned land | C30: 0.8 | E30: Working assumption. Applied when sizing how much land to zone.
B31: Student (PBSA) units counted towards the target | C31: 1 | E31: The register counts PBSA units in its totals. Set to 0% if student schemes do not meet HNDA need.
B32: 4 Density
B33: City Centre density in the increased scenario | C33: 100 | D33: homes/ha | E33: Register density band for city centre parcels is "100+". Applied to unconsented audit land and to newly zoned City Centre land. 0 = no change.
B34: Rest of City density in the increased scenario | C34: 0 | D34: homes/ha | E34: 0 = no change from the register capacity.
B35: Density on newly zoned Rest of City land | C35: 34 | D35: homes/ha | E35: Register: median of 39 permitted city-suburb schemes of 10+ homes (zoned-land parcels, density_basis).
B36: Density on newly zoned county town land (fallback) | C36: 25 | D36: homes/ha | E36: Register: median of 102 permitted county town and village schemes of 10+ homes.
B37: Density on newly zoned county serviced sites (fallback) | C37: 19 | D37: homes/ha | E37: Register: lower quartile of permitted county schemes, serviced-site zoning.
B38: Density on newly zoned settlement land: override | C38: 0 | D38: homes/ha | E38: 0 = use the average zoning density the register already carries for each settlement (3b Study Areas), else the county blend above.
B39: Density on newly zoned remainder-of-county land: override | C39: 0 | D39: homes/ha | E39: 0 = register average for the remainder, else the county blend.
B40: Developable share of zoned land | C40: 0.91 | E40: Register: council city audit developable area / mapped area. Gross zoned hectares = net capacity / (density × this).
B41: 5 Timing of delivery (even spread between the start and end years)
B42: Register pipeline beyond 2030: spread to | C42: 2033 | D42: year | E42: Register holds one "2031+" figure. Working assumption.
...

Sheet 1 Demand
A1: 1 Demand: what Limerick has to build, 2026–2040
A2: Target, tenure, unit mix and specialist need from the Limerick Interim HNDA synopsis (Spatialis, October 2026 working draft). The rest of the workbook uses these totals.
A5: A Housing target by year and tenure (hard-coded from the HNDA synopsis, summary table 1)
A6: Year | B6: Core Strat. HST | C6: New HNDA need | D6: Council target | E6: Social Lower | F6: Social Working | G6: Social Upper | H6: Afford. Lower | I6: Afford. Working | J6: Afford. Upper | K6: PRS Lower | L6: PRS Working | M6: PRS Upper | N6: Buyers Lower | O6: Buyers Working | P6: Buyers Upper | R6: Social (plan) | S6: Affordable (plan) | T6: Private rented (plan) | U6: Buyers (plan) | V6: Housing list uplift | W6: Social (final) | X6: Buyers (final) | Y6: Total (check)
A7: 2026 | B7: 2598 | C7: 2617 | D7: 4263 | E7: 756 | F7: 964 | G7: 1208 | H7: 305 | I7: 543 | J7: 802 | K7: 300 | L7: 532 | M7: 785 | N7: 1832 | O7: 2224 | P7: 2701 | R7: =$D7*INDEX(E7:G7,sc_idx)/(INDEX(E7:G7,sc_idx)+INDEX(H7:J7,sc_idx)+INDEX(K7:M7,sc_idx)+INDEX(N7:P7,sc_idx)) -> 964 | S7: =$D7*INDEX(H7:J7,sc_idx)/(INDEX(E7:G7,sc_idx)+INDEX(H7:J7,sc_idx)+INDEX(K7:M7,sc_idx)+INDEX(N7:P7,sc_idx)) -> 543 | T7: =$D7*INDEX(K7:M7,sc_idx)/(INDEX(E7:G7,sc_idx)+INDEX(H7:J7,sc_idx)+INDEX(K7:M7,sc_idx)+INDEX(N7:P7,sc_idx)) -> 532 | U7: =$D7*INDEX(N7:P7,sc_idx)/(INDEX(E7:G7,sc_idx)+INDEX(H7:J7,sc_idx)+INDEX(K7:M7,sc_idx)+INDEX(N7:P7,sc_idx)) -> 2224 | V7: =IF(AND(hl_incl="Yes",A7<=2035),hl_total/10,0) -> 0 | W7: =R7+V7 -> 964 | X7: =U7-V7 -> 2224 | Y7: =W7+S7+T7+X7 -> 4263
A8: 2027 | B8: 2598 | C8: 2662 | D8: 4263 | E8: 756 | F8: 964 | G8: 1208 | H8: 305 | I8: 543 | J8: 802 | K8: 300 | L8: 532 | M8: 785 | N8: 1832 | O8: 2224 | P8: 2701 | R8: =$D8*INDEX(E8:G8,sc_idx)/(INDEX(E8:G8,sc_idx)+INDEX(H8:J8,sc_idx)+INDEX(K8:M8,sc_idx)+INDEX(N8:P8,sc_idx)) -> 964 | S8: =$D8*INDEX(H8:J8,sc_idx)/(INDEX(E8:G8,sc_idx)+INDEX(H8:J8,sc_idx)+INDEX(K8:M8,sc_idx)+INDEX(N8:P8,sc_idx)) -> 543 | T8: =$D8*INDEX(K8:M8,sc_idx)/(INDEX(E8:G8,sc_idx)+INDEX(H8:J8,sc_idx)+INDEX(K8:M8,sc_idx)+INDEX(N8:P8,sc_idx)) -> 532 | U8: =$D8*INDEX(N8:P8,sc_idx)/(INDEX(E8:G8,sc_idx)+INDEX(H8:J8,sc_idx)+INDEX(K8:M8,sc_idx)+INDEX(N8:P8,sc_idx)) -> 2224 | V8: =IF(AND(hl_incl="Yes",A8<=2035),hl_total/10,0) -> 0 | W8: =R8+V8 -> 964 | X8: =U8-V8 -> 2224 | Y8: =W8+S8+T8+X8 -> 4263
A9: 2028 | B9: 2598 | C9: 2678 | D9: 4263 | E9: 756 | F9: 964 | G9: 1208 | H9: 305 | I9: 543 | J9: 802 | K9: 300 | L9: 532 | M9: 785 | N9: 1832 | O9: 2224 | P9: 2701 | R9: =$D9*INDEX(E9:G9,sc_idx)/(INDEX(E9:G9,sc_idx)+INDEX(H9:J9,sc_idx)+INDEX(K9:M9,sc_idx)+INDEX(N9:P9,sc_idx)) -> 964 | S9: =$D9*INDEX(H9:J9,sc_idx)/(INDEX(E9:G9,sc_idx)+INDEX(H9:J9,sc_idx)+INDEX(K9:M9,sc_idx)+INDEX(N9:P9,sc_idx)) -> 543 | T9: =$D9*INDEX(K9:M9,sc_idx)/(INDEX(E9:G9,sc_idx)+INDEX(H9:J9,sc_idx)+INDEX(K9:M9,sc_idx)+INDEX(N9:P9,sc_idx)) -> 532 | U9: =$D9*INDEX(N9:P9,sc_idx)/(INDEX(E9:G9,sc_idx)+INDEX(H9:J9,sc_idx)+INDEX(K9:M9,sc_idx)+INDEX(N9:P9,sc_idx)) -> 2224 | V9: =IF(AND(hl_incl="Yes",A9<=2035),hl_total/10,0) -> 0 | W9: =R9+V9 -> 964 | X9: =U9-V9 -> 2224 | Y9: =W9+S9+T9+X9 -> 4263
A10: 2029 | C10: 2700 | D10: 4263 | E10: 756 | F10: 964 | G10: 1208 | H10: 305 | I10: 543 | J10: 802 | K10: 300 | L10: 532 | M10: 785 | N10: 1832 | O10: 2224 | P10: 2701 | R10: =$D10*INDEX(E10:G10,sc_idx)/(INDEX(E10:G10,sc_idx)+INDEX(H10:J10,sc_idx)+INDEX(K10:M10,sc_idx)+INDEX(N10:P10,sc_idx)) -> 964 | S10: =$D10*INDEX(H10:J10,sc_idx)/(INDEX(E10:G10,sc_idx)+INDEX(H10:J10,sc_idx)+INDEX(K10:M10,sc_idx)+INDEX(N10:P10,sc_idx)) -> 543 | T10: =$D10*INDEX(K10:M10,sc_idx)/(INDEX(E10:G10,sc_idx)+INDEX(H10:J10,sc_idx)+INDEX(K10:M10,sc_idx)+INDEX(N10:P10,sc_idx)) -> 532 | U10: =$D10*INDEX(N10:P10,sc_idx)/(INDEX(E10:G10,sc_idx)+INDEX(H10:J10,sc_idx)+INDEX(K10:M10,sc_idx)+INDEX(N10:P10,sc_idx)) -> 2224 | V10: =IF(AND(hl_incl="Yes",A10<=2035),hl_total/10,0) -> 0 | W10: =R10+V10 -> 964 | X10: =U10-V10 -> 2224 | Y10: =W10+S10+T10+X10 -> 4263
A11: 2030 | C11: 2749 | D11: 4263 | E11: 756 | F11: 964 | G11: 1208 | H11: 305 | I11: 543 | J11: 802 | K11: 300 | L11: 532 | M11: 785 | N11: 1832 | O11: 2224 | P11: 2701 | R11: =$D11*INDEX(E11:G11,sc_idx)/(INDEX(E11:G11,sc_idx)+INDEX(H11:J11,sc_idx)+INDEX(K11:M11,sc_idx)+INDEX(N11:P11,sc_idx)) -> 964 | S11: =$D11*INDEX(H11:J11,sc_idx)/(INDEX(E11:G11,sc_idx)+INDEX(H11:J11,sc_idx)+INDEX(K11:M11,sc_idx)+INDEX(N11:P11,sc_idx)) -> 543 | T11: =$D11*INDEX(K11:M11,sc_idx)/(INDEX(E11:G11,sc_idx)+INDEX(H11:J11,sc_idx)+INDEX(K11:M11,sc_idx)+INDEX(N11:P11,sc_idx)) -> 532 | U11: =$D11*INDEX(N11:P11,sc_idx)/(INDEX(E11:G11,sc_idx)+INDEX(H11:J11,sc_idx)+INDEX(K11:M11,sc_idx)+INDEX(N11:P11,sc_idx)) -> 2224 | V11: =IF(AND(hl_incl="Yes",A11<=2035),hl_total/10,0) -> 0 | W11: =R11+V11 -> 964 | X11: =U11-V11 -> 2224 | Y11: =W11+S11+T11+X11 -> 4263
A12: 2031 | C12: 2532 | D12: 2168 | E12: 385 | F12: 490 | G12: 614 | H12: 155 | I12: 276 | J12: 408 | K12: 153 | L12: 271 | M12: 399 | N12: 932 | O12: 1131 | P12: 1374 | R12: =$D12*INDEX(E12:G12,sc_idx)/(INDEX(E12:G12,sc_idx)+INDEX(H12:J12,sc_idx)+INDEX(K12:M12,sc_idx)+INDEX(N12:P12,sc_idx)) -> 490 | S12: =$D12*INDEX(H12:J12,sc_idx)/(INDEX(E12:G12,sc_idx)+INDEX(H12:J12,sc_idx)+INDEX(K12:M12,sc_idx)+INDEX(N12:P12,sc_idx)) -> 276 | T12: =$D12*INDEX(K12:M12,sc_idx)/(INDEX(E12:G12,sc_idx)+INDEX(H12:J12,sc_idx)+INDEX(K12:M12,sc_idx)+INDEX(N12:P12,sc_idx)) -> 271 | U12: =$D12*INDEX(N12:P12,sc_idx)/(INDEX(E12:G12,sc_idx)+INDEX(H12:J12,sc_idx)+INDEX(K12:M12,sc_idx)+INDEX(N12:P12,sc_idx)) -> 1131 | V12: =IF(AND(hl_incl="Yes",A12<=2035),hl_total/10,0) -> 0 | W12: =R12+V12 -> 490 | X12: =U12-V12 -> 1131 | Y12: =W12+S12+T12+X12 -> 2168
A13: 2032 | C13: 2541 | D13: 2168 | E13: 385 | F13: 490 | G13: 614 | H13: 155 | I13: 276 | J13: 408 | K13: 153 | L13: 271 | M13: 399 | N13: 932 | O13: 1131 | P13: 1374 | R13: =$D13*INDEX(E13:G13,sc_idx)/(INDEX(E13:G13,sc_idx)+INDEX(H13:J13,sc_idx)+INDEX(K13:M13,sc_idx)+INDEX(N13:P13,sc_idx)) -> 490 | S13: =$D13*INDEX(H13:J13,sc_idx)/(INDEX(E13:G13,sc_idx)+INDEX(H13:J13,sc_idx)+INDEX(K13:M13,sc_idx)+INDEX(N13:P13,sc_idx)) -> 276 | T13: =$D13*INDEX(K13:M13,sc_idx)/(INDEX(E13:G13,sc_idx)+INDEX(H13:J13,sc_idx)+INDEX(K13:M13,sc_idx)+INDEX(N13:P13,sc_idx)) -> 271 | U13: =$D13*INDEX(N13:P13,sc_idx)/(INDEX(E13:G13,sc_idx)+INDEX(H13:J13,sc_idx)+INDEX(K13:M13,sc_idx)+INDEX(N13:P13,sc_idx)) -> 1131 | V13: =IF(AND(hl_incl="Yes",A13<=2035),hl_total/10,0) -> 0 | W13: =R13+V13 -> 490 | X13: =U13-V13 -> 1131 | Y13: =W13+S13+T13+X13 -> 2168
A14: 2033 | C14: 2530 | D14: 2168 | E14: 385 | F14: 490 | G14: 614 | H14: 155 | I14: 276 | J14: 408 | K14: 153 | L14: 271 | M14: 399 | N14: 932 | O14: 1131 | P14: 1374 | R14: =$D14*INDEX(E14:G14,sc_idx)/(INDEX(E14:G14,sc_idx)+INDEX(H14:J14,sc_idx)+INDEX(K14:M14,sc_idx)+INDEX(N14:P14,sc_idx)) -> 490 | S14: =$D14*INDEX(H14:J14,sc_idx)/(INDEX(E14:G14,sc_idx)+INDEX(H14:J14,sc_idx)+INDEX(K14:M14,sc_idx)+INDEX(N14:P14,sc_idx)) -> 276 | T14: =$D14*INDEX(K14:M14,sc_idx)/(INDEX(E14:G14,sc_idx)+INDEX(H14:J14,sc_idx)+INDEX(K14:M14,sc_idx)+INDEX(N14:P14,sc_idx)) -> 271 | U14: =$D14*INDEX(N14:P14,sc_idx)/(INDEX(E14:G14,sc_idx)+INDEX(H14:J14,sc_idx)+INDEX(K14:M14,sc_idx)+INDEX(N14:P14,sc_idx)) -> 1131 | V14: =IF(AND(hl_incl="Yes",A14<=2035),hl_total/10,0) -> 0 | W14: =R14+V14 -> 490 | X14: =U14-V14 -> 1131 | Y14: =W14+S14+T14+X14 -> 2168
A15: 2034 | C15: 2518 | D15: 2168 | E15: 385 | F15: 490 | G15: 614 | H15: 155 | I15: 276 | J15: 408 | K15: 153 | L15: 271 | M15: 399 | N15: 932 | O15: 1131 | P15: 1374 | R15: =$D15*INDEX(E15:G15,sc_idx)/(INDEX(E15:G15,sc_idx)+INDEX(H15:J15,sc_idx)+INDEX(K15:M15,sc_idx)+INDEX(N15:P15,sc_idx)) -> 490 | S15: =$D15*INDEX(H15:J15,sc_idx)/(INDEX(E15:G15,sc_idx)+INDEX(H15:J15,sc_idx)+INDEX(K15:M15,sc_idx)+INDEX(N15:P15,sc_idx)) -> 276 | T15: =$D15*INDEX(K15:M15,sc_idx)/(INDEX(E15:G15,sc_idx)+INDEX(H15:J15,sc_idx)+INDEX(K15:M15,sc_idx)+INDEX(N15:P15,sc_idx)) -> 271 | U15: =$D15*INDEX(N15:P15,sc_idx)/(INDEX(E15:G15,sc_idx)+INDEX(H15:J15,sc_idx)+INDEX(K15:M15,sc_idx)+INDEX(N15:P15,sc_idx)) -> 1131 | V15: =IF(AND(hl_incl="Yes",A15<=2035),hl_total/10,0) -> 0 | W15: =R15+V15 -> 490 | X15: =U15-V15 -> 1131 | Y15: =W15+S15+T15+X15 -> 2168
A16: 2035 | C16: 3584 | D16: 2095 | E16: 372 | F16: 474 | G16: 594 | H16: 150 | I16: 267 | J16: 394 | K16: 148 | L16: 262 | M16: 386 | N16: 900 | O16: 1093 | P16: 1327 | R16: =$D16*INDEX(E16:G16,sc_idx)/(INDEX(E16:G16,sc_idx)+INDEX(H16:J16,sc_idx)+INDEX(K16:M16,sc_idx)+INDEX(N16:P16,sc_idx)) -> 473.77385 | S16: =$D16*INDEX(H16:J16,sc_idx)/(INDEX(E16:G16,sc_idx)+INDEX(H16:J16,sc_idx)+INDEX(K16:M16,sc_idx)+INDEX(N16:P16,sc_idx)) -> 266.87261 | T16: =$D16*INDEX(K16:M16,sc_idx)/(INDEX(E16:G16,sc_idx)+INDEX(H16:J16,sc_idx)+INDEX(K16:M16,sc_idx)+INDEX(N16:P16,sc_idx)) -> 261.875 | U16: =$D16*INDEX(N16:P16,sc_idx)/(INDEX(E16:G16,sc_idx)+INDEX(H16:J16,sc_idx)+INDEX(K16:M16,sc_idx)+INDEX(N16:P16,sc_idx)) -> 1092.4785 | V16: =IF(AND(hl_incl="Yes",A16<=2035),hl_total/10,0) -> 0 | W16: =R16+V16 -> 473.77385 | X16: =U16-V16 -> 1092.4785 | Y16: =W16+S16+T16+X16 -> 2095
A17: 2036 | C17: 2600 | D17: 1587 | E17: 241 | F17: 241 | G17: 241 | H17: 159 | I17: 159 | J17: 159 | K17: 273 | L17: 273 | M17: 273 | N17: 914 | O17: 914 | P17: 914 | R17: =$D17*INDEX(E17:G17,sc_idx)/(INDEX(E17:G17,sc_idx)+INDEX(H17:J17,sc_idx)+INDEX(K17:M17,sc_idx)+INDEX(N17:P17,sc_idx)) -> 241 | S17: =$D17*INDEX(H17:J17,sc_idx)/(INDEX(E17:G17,sc_idx)+INDEX(H17:J17,sc_idx)+INDEX(K17:M17,sc_idx)+INDEX(N17:P17,sc_idx)) -> 159 | T17: =$D17*INDEX(K17:M17,sc_idx)/(INDEX(E17:G17,sc_idx)+INDEX(H17:J17,sc_idx)+INDEX(K17:M17,sc_idx)+INDEX(N17:P17,sc_idx)) -> 273 | U17: =$D17*INDEX(N17:P17,sc_idx)/(INDEX(E17:G17,sc_idx)+INDEX(H17:J17,sc_idx)+INDEX(K17:M17,sc_idx)+INDEX(N17:P17,sc_idx)) -> 914 | V17: =IF(AND(hl_incl="Yes",A17<=2035),hl_total/10,0) -> 0 | W17: =R17+V17 -> 241 | X17: =U17-V17 -> 914 | Y17: =W17+S17+T17+X17 -> 1587
A18: 2037 | C18: 2580 | D18: 1574 | E18: 227 | F18: 227 | G18: 227 | H18: 189 | I18: 189 | J18: 189 | K18: 252 | L18: 252 | M18: 252 | N18: 907 | O18: 907 | P18: 907 | R18: =$D18*INDEX(E18:G18,sc_idx)/(INDEX(E18:G18,sc_idx)+INDEX(H18:J18,sc_idx)+INDEX(K18:M18,sc_idx)+INDEX(N18:P18,sc_idx)) -> 226.85587 | S18: =$D18*INDEX(H18:J18,sc_idx)/(INDEX(E18:G18,sc_idx)+INDEX(H18:J18,sc_idx)+INDEX(K18:M18,sc_idx)+INDEX(N18:P18,sc_idx)) -> 188.88 | T18: =$D18*INDEX(K18:M18,sc_idx)/(INDEX(E18:G18,sc_idx)+INDEX(H18:J18,sc_idx)+INDEX(K18:M18,sc_idx)+INDEX(N18:P18,sc_idx)) -> 251.84 | U18: =$D18*INDEX(N18:P18,sc_idx)/(INDEX(E18:G18,sc_idx)+INDEX(H18:J18,sc_idx)+INDEX(K18:M18,sc_idx)+INDEX(N18:P18,sc_idx)) -> 906.42413 | V18: =IF(AND(hl_incl="Yes",A18<=2035),hl_total/10,0) -> 0 | W18: =R18+V18 -> 226.85587 | X18: =U18-V18 -> 906.42413 | Y18: =W18+S18+T18+X18 -> 1574
A19: 2038 | C19: 2549 | D19: 1555 | E19: 224 | F19: 224 | G19: 224 | H19: 187 | I19: 187 | J19: 187 | K19: 249 | L19: 249 | M19: 249 | N19: 896 | O19: 896 | P19: 896 | R19: =$D19*INDEX(E19:G19,sc_idx)/(INDEX(E19:G19,sc_idx)+INDEX(H19:J19,sc_idx)+INDEX(K19:M19,sc_idx)+INDEX(N19:P19,sc_idx)) -> 223.85604 | S19: =$D19*INDEX(H19:J19,sc_idx)/(INDEX(E19:G19,sc_idx)+INDEX(H19:J19,sc_idx)+INDEX(K19:M19,sc_idx)+INDEX(N19:P19,sc_idx)) -> 186.87982 | T19: =$D19*INDEX(K19:M19,sc_idx)/(INDEX(E19:G19,sc_idx)+INDEX(H19:J19,sc_idx)+INDEX(K19:M19,sc_idx)+INDEX(N19:P19,sc_idx)) -> 248.83997 | U19: =$D19*INDEX(N19:P19,sc_idx)/(INDEX(E19:G19,sc_idx)+INDEX(H19:J19,sc_idx)+INDEX(K19:M19,sc_idx)+INDEX(N19:P19,sc_idx)) -> 895.42416 | V19: =IF(AND(hl_incl="Yes",A19<=2035),hl_total/10,0) -> 0 | W19: =R19+V19 -> 223.85604 | X19: =U19-V19 -> 895.42416 | Y19: =W19+S19+T19+X19 -> 1555
A20: 2039 | C20: 2525 | D20: 1541 | E20: 210 | F20: 210 | G20: 210 | H20: 200 | I20: 200 | J20: 200 | K20: 257 | L20: 257 | M20: 257 | N20: 874 | O20: 874 | P20: 874 | R20: =$D20*INDEX(E20:G20,sc_idx)/(INDEX(E20:G20,sc_idx)+INDEX(H20:J20,sc_idx)+INDEX(K20:M20,sc_idx)+INDEX(N20:P20,sc_idx)) -> 210 | S20: =$D20*INDEX(H20:J20,sc_idx)/(INDEX(E20:G20,sc_idx)+INDEX(H20:J20,sc_idx)+INDEX(K20:M20,sc_idx)+INDEX(N20:P20,sc_idx)) -> 200 | T20: =$D20*INDEX(K20:M20,sc_idx)/(INDEX(E20:G20,sc_idx)+INDEX(H20:J20,sc_idx)+INDEX(K20:M20,sc_idx)+INDEX(N20:P20,sc_idx)) -> 257 | U20: =$D20*INDEX(N20:P20,sc_idx)/(INDEX(E20:G20,sc_idx)+INDEX(H20:J20,sc_idx)+INDEX(K20:M20,sc_idx)+INDEX(N20:P20,sc_idx)) -> 874 | V20: =IF(AND(hl_incl="Yes",A20<=2035),hl_total/10,0) -> 0 | W20: =R20+V20 -> 210 | X20: =U20-V20 -> 874 | Y20: =W20+S20+T20+X20 -> 1541
A21: 2040 | C21: 2499 | D21: 1525 | E21: 207 | F21: 207 | G21: 207 | H21: 198 | I21: 198 | J21: 198 | K21: 255 | L21: 255 | M21: 255 | N21: 865 | O21: 865 | P21: 865 | R21: =$D21*INDEX(E21:G21,sc_idx)/(INDEX(E21:G21,sc_idx)+INDEX(H21:J21,sc_idx)+INDEX(K21:M21,sc_idx)+INDEX(N21:P21,sc_idx)) -> 207 | S21: =$D21*INDEX(H21:J21,sc_idx)/(INDEX(E21:G21,sc_idx)+INDEX(H21:J21,sc_idx)+INDEX(K21:M21,sc_idx)+INDEX(N21:P21,sc_idx)) -> 198 | T21: =$D21*INDEX(K21:M21,sc_idx)/(INDEX(E21:G21,sc_idx)+INDEX(H21:J21,sc_idx)+INDEX(K21:M21,sc_idx)+INDEX(N21:P21,sc_idx)) -> 255 | U21: =$D21*INDEX(N21:P21,sc_idx)/(INDEX(E21:G21,sc_idx)+INDEX(H21:J21,sc_idx)+INDEX(K21:M21,sc_idx)+INDEX(N21:P21,sc_idx)) -> 865 | V21: =IF(AND(hl_incl="Yes",A21<=2035),hl_total/10,0) -> 0 | W21: =R21+V21 -> 207 | X21: =U21-V21 -> 865 | Y21: =W21+S21+T21+X21 -> 1525
A22: 2026–28 | B22: =SUM(B7:B9) -> 7794 | C22: =SUM(C7:C9) -> 7957 | D22: =SUM(D7:D9) -> 12789 | E22: =SUM(E7:E9) -> 2268 | F22: =SUM(F7:F9) -> 2892 | G22: =SUM(G7:G9) -> 3624 | H22: =SUM(H7:H9) -> 915 | I22: =SUM(I7:I9) -> 1629 | ... P22: =SUM(P7:P9) -> 8103 | R22: =SUM(R7:R9) -> 2892 | S22: =SUM(S7:S9) -> 1629 | T22: =SUM(T7:T9) -> 1596 | U22: =SUM(U7:U9) -> 6672 | V22: =SUM(V7:V9) -> 0 | W22: =SUM(W7:W9) -> 2892 | X22: =SUM(X7:X9) -> 6672 | Y22: =SUM(Y7:Y9) -> 12789
A23: 2029–35 | B23: =SUM(B10:B16) -> 0 | C23: =SUM(C10:C16) -> 19154 | D23: =SUM(D10:D16) -> 19293 | E23: =SUM(E10:E16) -> 3424 | F23: =SUM(F10:F16) -> 4362 | G23: =SUM(G10:G16) -> 5466 | H23: =SUM(H10:H16) -> 1380 | I23: =SUM(I10:I16) -> 2457 | ... P23: =SUM(P10:P16) -> 12225 | R23: =SUM(R10:R16) -> 4361.7739 | S23: =SUM(S10:S16) -> 2456.8726 | T23: =SUM(T10:T16) -> 2409.875 | U23: =SUM(U10:U16) -> 10064.479 | V23: =SUM(V10:V16) -> 0 | W23: =SUM(W10:W16) -> 4361.7739 | X23: =SUM(X10:X16) -> 10064.479 | Y23: =SUM(Y10:Y16) -> 19293
A24: 2036–40 | B24: =SUM(B17:B21) -> 0 | C24: =SUM(C17:C21) -> 12753 | D24: =SUM(D17:D21) -> 7782 | E24: =SUM(E17:E21) -> 1109 | F24: =SUM(F17:F21) -> 1109 | G24: =SUM(G17:G21) -> 1109 | H24: =SUM(H17:H21) -> 933 | I24: =SUM(I17:I21) -> 933 | ... P24: =SUM(P17:P21) -> 4456 | R24: =SUM(R17:R21) -> 1108.7119 | S24: =SUM(S17:S21) -> 932.75982 | T24: =SUM(T17:T21) -> 1285.68 | U24: =SUM(U17:U21) -> 4454.8483 | V24: =SUM(V17:V21) -> 0 | W24: =SUM(W17:W21) -> 1108.7119 | X24: =SUM(X17:X21) -> 4454.8483 | Y24: =SUM(Y17:Y21) -> 7782
A25: 2026–40 | B25: =SUM(B7:B21) -> 7794 | C25: =SUM(C7:C21) -> 39864 | D25: =SUM(D7:D21) -> 39864 | E25: =SUM(E7:E21) -> 6801 | F25: =SUM(F7:F21) -> 8363 | G25: =SUM(G7:G21) -> 10199 | H25: =SUM(H7:H21) -> 3228 | I25: =SUM(I7:I21) -> 5019 | ... P25: =SUM(P7:P21) -> 24784 | R25: =SUM(R7:R21) -> 8362.4858 | S25: =SUM(S7:S21) -> 5018.6324 | T25: =SUM(T7:T21) -> 5291.555 | U25: =SUM(U7:U21) -> 21191.327 | V25: =SUM(V7:V21) -> 0 | W25: =SUM(W7:W21) -> 8362.4858 | X25: =SUM(X7:X21) -> 21191.327 | Y25: =SUM(Y7:Y21) -> 39864
A26: Share of total | R26: =R25/$D$25 -> 0.20977538 | S26: =S25/$D$25 -> 0.12589385 | T26: =T25/$D$25 -> 0.13274019 | U26: =U25/$D$25 -> 0.53159058 | W26: =W25/$D$25 -> 0.20977538 | X26: =X25/$D$25 -> 0.53159058
A27: Source: HNDA synopsis, "Housing target by year and tenure". Council target 2026–35 is the front-loaded profile (32,082); 2036–40 is reduced so 2026–40 equals the new HNDA need of 39,865. Lower and upper are the ends of the Council's published range per tenure. Working is a Spatialis working assumption, not a Council figure. Plan columns normalise the chosen position to the Council target each year, so Lower and Upper still sum to the target. The published 2026–40 total is 39,865; the rounded annual figures sum to 39,864 (shown in row 25). Core Strategy HST: Development Plan 2022–2028, 2,598 a year; no later adopted all-tenure target in the source documents.
A29: B Social demand and specialist need (shares from the HDAP assessment on Inputs)
A30: Year | B30: Social (final) | C30: General needs | D30: Disability | E30: Older persons | F30: Traveller-specific | G30: Community dwellings (H15) | H30: HDAP social planned
A31: =A7 -> 2026 | B31: =W7 -> 964 | C31: =B31-SUM(D31:G31) -> 653.63367 | D31: =B31*h_dis/h_all -> 179.1278 | E31: =B31*h_old/h_all -> 102.72431 | F31: =B31*h_trav/h_all -> 10.601441 | G31: =B31*h_com/h_all -> 17.91278
A32: =A8 -> 2027 | B32: =W8 -> 964 | C32: =B32-SUM(D32:G32) -> 653.63367 | D32: =B32*h_dis/h_all -> 179.1278 | E32: =B32*h_old/h_all -> 102.72431 | F32: =B32*h_trav/h_all -> 10.601441 | G32: =B32*h_com/h_all -> 17.91278 | H32: 569
A33: =A9 -> 2028 | B33: =W9 -> 964 | C33: =B33-SUM(D33:G33) -> 653.63367 | D33: =B33*h_dis/h_all -> 179.1278 | E33: =B33*h_old/h_all -> 102.72431 | F33: =B33*h_trav/h_all -> 10.601441 | G33: =B33*h_com/h_all -> 17.91278 | H33: 751
A34: =A10 -> 2029 | B34: =W10 -> 964 | C34: =B34-SUM(D34:G34) -> 653.63367 | D34: =B34*h_dis/h_all -> 179.1278 | E34: =B34*h_old/h_all -> 102.72431 | F34: =B34*h_trav/h_all -> 10.601441 | G34: =B34*h_com/h_all -> 17.91278 | H34: 885
A35: =A11 -> 2030 | B35: =W11 -> 964 | C35: =B35-SUM(D35:G35) -> 653.63367 | D35: =B35*h_dis/h_all -> 179.1278 | E35: =B35*h_old/h_all -> 102.72431 | F35: =B35*h_trav/h_all -> 10.601441 | G35: =B35*h_com/h_all -> 17.91278 | H35: 602
A36: =A12 -> 2031 | B36: =W12 -> 490 | C36: =B36-SUM(D36:G36) -> 332.24118 | D36: =B36*h_dis/h_all -> 91.050436 | E36: =B36*h_old/h_all -> 52.214638 | F36: =B36*h_trav/h_all -> 5.3886993 | G36: =B36*h_com/h_all -> 9.1050436
A37: =A13 -> 2032 | B37: =W13 -> 490 | C37: =B37-SUM(D37:G37) -> 332.24118 | D37: =B37*h_dis/h_all -> 91.050436 | E37: =B37*h_old/h_all -> 52.214638 | F37: =B37*h_trav/h_all -> 5.3886993 | G37: =B37*h_com/h_all -> 9.1050436
A38: =A14 -> 2033 | B38: =W14 -> 490 | C38: =B38-SUM(D38:G38) -> 332.24118 | D38: =B38*h_dis/h_all -> 91.050436 | E38: =B38*h_old/h_all -> 52.214638 | F38: =B38*h_trav/h_all -> 5.3886993 | G38: =B38*h_com/h_all -> 9.1050436
A39: =A15 -> 2034 | B39: =W15 -> 490 | C39: =B39-SUM(D39:G39) -> 332.24118 | D39: =B39*h_dis/h_all -> 91.050436 | E39: =B39*h_old/h_all -> 52.214638 | F39: =B39*h_trav/h_all -> 5.3886993 | G39: =B39*h_com/h_all -> 9.1050436
A40: =A16 -> 2035 | B40: =W16 -> 473.77385 | C40: =B40-SUM(D40:G40) -> 321.23916 | D40: =B40*h_dis/h_all -> 88.035339 | E40: =B40*h_old/h_all -> 50.485572 | F40: =B40*h_trav/h_all -> 5.2102548 | G40: =B40*h_com/h_all -> 8.8035339
A41: =A17 -> 2036 | B41: =W17 -> 241 | C41: =B41-SUM(D41:G41) -> 163.40842 | D41: =B41*h_dis/h_all -> 44.781949 | E41: =B41*h_old/h_all -> 25.681077 | F41: =B41*h_trav/h_all -> 2.6503603 | G41: =B41*h_com/h_all -> 4.4781949
A42: =A18 -> 2037 | B42: =W18 -> 226.85587 | C42: =B42-SUM(D42:G42) -> 153.81809 | D42: =B42*h_dis/h_all -> 42.153727 | E42: =B42*h_old/h_all -> 24.173872 | F42: =B42*h_trav/h_all -> 2.4948124 | G42: =B42*h_com/h_all -> 4.2153727
A43: =A19 -> 2038 | B43: =W19 -> 223.85604 | C43: =B43-SUM(D43:G43) -> 151.78407 | D43: =B43*h_dis/h_all -> 41.596306 | E43: =B43*h_old/h_all -> 23.854208 | F43: =B43*h_trav/h_all -> 2.4618222 | G43: =B43*h_com/h_all -> 4.1596306
...

Sheet 2 Register
A1: 2 The Housing Land Register: what it holds and how it is divided
A2: Limerick Housing Land Register (GeoPackage): 446 parcels, 265 permissions, quarterly GeoDirectory check. All numbers below are live formulas on the Data sheets.
A5: A Structure: parcels carry the land, permissions carry the consents
A6: Parcels | B6: One row per piece of land. Four kinds: Council audit parcels (the city land audit, ref CITY-n); reinstated audit parcels; consent parcels outside the audit (PC-ref, drawn from the planning boundary); and zoned-land estimates for new residential zoning with no consent (interim until the county audit replaces them).
A7: Permissions | B7: One row per permission, each on exactly one parcel. Only Complete, Under construction, Permitted – not started and Stalled count as consented. Expired and In planning are held but not counted.
A8: Totals | B8: Consented units + unconsented capacity (council capacity less consented units, floored at zero) = total supply. Future supply = total supply less homes already complete. Totals are calculated, never typed, with no double counting.
A9: Progress | B9: Status comes from CIS and building control. GeoDirectory moves a scheme to Complete when new built addresses reach 95% of its units. Each quarter the build is rerun and mismatches go to the register_checks list.
A11: B Parcels by source and scope
A12: Parcel source | B12: Scope | C12: Parcels | D12: Developable ha | E12: Council / zoning capacity | F12: Complete | G12: Under constr. | H12: Permitted not started | I12: Stalled | J12: Consented | K12: Unconsented capacity | L12: Total supply | M12: Future supply
A13: Council audit | B13: City | C13: =COUNTIFS(dp_src,$A13,dp_scope,$B13) -> 131 | D13: =SUMIFS(dp_area,dp_src,$A13,dp_scope,$B13) -> 312.219 | E13: =SUMIFS(dp_cap,dp_src,$A13,dp_scope,$B13) -> 13927 | F13: =SUMIFS(dp_comp,dp_src,$A13,dp_scope,$B13) -> 76 | G13: =SUMIFS(dp_uc,dp_src,$A13,dp_scope,$B13) -> 1635 | H13: =SUMIFS(dp_pns,dp_src,$A13,dp_scope,$B13) -> 3483 | I13: =SUMIFS(dp_stl,dp_src,$A13,dp_scope,$B13) -> 31 | J13: =SUMIFS(dp_cons,dp_src,$A13,dp_scope,$B13) -> 5225 | K13: =SUMIFS(dp_unc,dp_src,$A13,dp_scope,$B13) -> 10005 | L13: =SUMIFS(dp_tot,dp_src,$A13,dp_scope,$B13) -> 15230 | M13: =SUMIFS(dp_fut,dp_src,$A13,dp_scope,$B13) -> 15154
A14: Council audit – reinstated | B14: City | C14: =COUNTIFS(dp_src,$A14,dp_scope,$B14) -> 3 | D14: =SUMIFS(dp_area,dp_src,$A14,dp_scope,$B14) -> 3.993 | E14: =SUMIFS(dp_cap,dp_src,$A14,dp_scope,$B14) -> 165 | F14: =SUMIFS(dp_comp,dp_src,$A14,dp_scope,$B14) -> 0 | G14: =SUMIFS(dp_uc,dp_src,$A14,dp_scope,$B14) -> 0 | H14: =SUMIFS(dp_pns,dp_src,$A14,dp_scope,$B14) -> 27 | I14: =SUMIFS(dp_stl,dp_src,$A14,dp_scope,$B14) -> 0 | J14: =SUMIFS(dp_cons,dp_src,$A14,dp_scope,$B14) -> 27 | K14: =SUMIFS(dp_unc,dp_src,$A14,dp_scope,$B14) -> 138 | L14: =SUMIFS(dp_tot,dp_src,$A14,dp_scope,$B14) -> 165 | M14: =SUMIFS(dp_fut,dp_src,$A14,dp_scope,$B14) -> 165
A15: Planning consent – not in council audit | B15: City | C15: =COUNTIFS(dp_src,$A15,dp_scope,$B15) -> 103 | D15: =SUMIFS(dp_area,dp_src,$A15,dp_scope,$B15) -> 102.379 | E15: =SUMIFS(dp_cap,dp_src,$A15,dp_scope,$B15) -> 0 | F15: =SUMIFS(dp_comp,dp_src,$A15,dp_scope,$B15) -> 1260 | G15: =SUMIFS(dp_uc,dp_src,$A15,dp_scope,$B15) -> 1319 | H15: =SUMIFS(dp_pns,dp_src,$A15,dp_scope,$B15) -> 700 | I15: =SUMIFS(dp_stl,dp_src,$A15,dp_scope,$B15) -> 0 | J15: =SUMIFS(dp_cons,dp_src,$A15,dp_scope,$B15) -> 3279 | K15: =SUMIFS(dp_unc,dp_src,$A15,dp_scope,$B15) -> 0 | L15: =SUMIFS(dp_tot,dp_src,$A15,dp_scope,$B15) -> 3279 | M15: =SUMIFS(dp_fut,dp_src,$A15,dp_scope,$B15) -> 2019
A16: Zoned land – no consent (estimate) | B16: City | C16: =COUNTIFS(dp_src,$A16,dp_scope,$B16) -> 5 | D16: =SUMIFS(dp_area,dp_src,$A16,dp_scope,$B16) -> 1.384 | E16: =SUMIFS(dp_cap,dp_src,$A16,dp_scope,$B16) -> 47 | F16: =SUMIFS(dp_comp,dp_src,$A16,dp_scope,$B16) -> 0 | G16: =SUMIFS(dp_uc,dp_src,$A16,dp_scope,$B16) -> 0 | H16: =SUMIFS(dp_pns,dp_src,$A16,dp_scope,$B16) -> 0 | I16: =SUMIFS(dp_stl,dp_src,$A16,dp_scope,$B16) -> 0 | J16: =SUMIFS(dp_cons,dp_src,$A16,dp_scope,$B16) -> 0 | K16: =SUMIFS(dp_unc,dp_src,$A16,dp_scope,$B16) -> 47 | L16: =SUMIFS(dp_tot,dp_src,$A16,dp_scope,$B16) -> 47 | M16: =SUMIFS(dp_fut,dp_src,$A16,dp_scope,$B16) -> 47
A17: Planning consent – not in council audit | B17: County | C17: =COUNTIFS(dp_src,$A17,dp_scope,$B17) -> 85 | D17: =SUMIFS(dp_area,dp_src,$A17,dp_scope,$B17) -> 116.115 | E17: =SUMIFS(dp_cap,dp_src,$A17,dp_scope,$B17) -> 0 | F17: =SUMIFS(dp_comp,dp_src,$A17,dp_scope,$B17) -> 295 | G17: =SUMIFS(dp_uc,dp_src,$A17,dp_scope,$B17) -> 757 | H17: =SUMIFS(dp_pns,dp_src,$A17,dp_scope,$B17) -> 792 | I17: =SUMIFS(dp_stl,dp_src,$A17,dp_scope,$B17) -> 125 | J17: =SUMIFS(dp_cons,dp_src,$A17,dp_scope,$B17) -> 1969 | K17: =SUMIFS(dp_unc,dp_src,$A17,dp_scope,$B17) -> 0 | L17: =SUMIFS(dp_tot,dp_src,$A17,dp_scope,$B17) -> 1969 | M17: =SUMIFS(dp_fut,dp_src,$A17,dp_scope,$B17) -> 1674
A18: Zoned land – no consent (estimate) | B18: County | C18: =COUNTIFS(dp_src,$A18,dp_scope,$B18) -> 119 | D18: =SUMIFS(dp_area,dp_src,$A18,dp_scope,$B18) -> 148.073 | E18: =SUMIFS(dp_cap,dp_src,$A18,dp_scope,$B18) -> 3460 | F18: =SUMIFS(dp_comp,dp_src,$A18,dp_scope,$B18) -> 0 | G18: =SUMIFS(dp_uc,dp_src,$A18,dp_scope,$B18) -> 0 | H18: =SUMIFS(dp_pns,dp_src,$A18,dp_scope,$B18) -> 0 | I18: =SUMIFS(dp_stl,dp_src,$A18,dp_scope,$B18) -> 0 | J18: =SUMIFS(dp_cons,dp_src,$A18,dp_scope,$B18) -> 0 | K18: =SUMIFS(dp_unc,dp_src,$A18,dp_scope,$B18) -> 3460 | L18: =SUMIFS(dp_tot,dp_src,$A18,dp_scope,$B18) -> 3460 | M18: =SUMIFS(dp_fut,dp_src,$A18,dp_scope,$B18) -> 3460
A19: Register total | C19: =SUM(C13:C18) -> 446 | D19: =SUM(D13:D18) -> 684.163 | E19: =SUM(E13:E18) -> 17599 | F19: =SUM(F13:F18) -> 1631 | G19: =SUM(G13:G18) -> 3711 | H19: =SUM(H13:H18) -> 5002 | I19: =SUM(I13:I18) -> 156 | J19: =SUM(J13:J18) -> 10500 | ... M19: =SUM(M13:M18) -> 22519
A21: C Consent tracking: permissions by status
A22: Status | B22: Counts toward totals? | C22: Permissions | D22: Units | E22: % of counted units | F22: Student bedspaces (memo)
A23: Complete | B23: Yes | C23: =COUNTIFS(dm_status,A23) -> 66 | D23: =SUMIFS(dm_units,dm_status,A23) -> 1631 | E23: =D23/$D$27 -> 0.15533333 | F23: =SUMIFS(dm_beds,dm_status,A23) -> 0
A24: Under construction | B24: Yes | C24: =COUNTIFS(dm_status,A24) -> 78 | D24: =SUMIFS(dm_units,dm_status,A24) -> 3711 | E24: =D24/$D$27 -> 0.35342857 | F24: =SUMIFS(dm_beds,dm_status,A24) -> 202
A25: Permitted – not started | B25: Yes | C25: =COUNTIFS(dm_status,A25) -> 88 | D25: =SUMIFS(dm_units,dm_status,A25) -> 5002 | E25: =D25/$D$27 -> 0.47638095 | F25: =SUMIFS(dm_beds,dm_status,A25) -> 1940
A26: Stalled | B26: Yes | C26: =COUNTIFS(dm_status,A26) -> 4 | D26: =SUMIFS(dm_units,dm_status,A26) -> 156 | E26: =D26/$D$27 -> 0.014857143 | F26: =SUMIFS(dm_beds,dm_status,A26) -> 0
A27: Consented (counted) | C27: =SUM(C23:C26) -> 236 | D27: =SUM(D23:D26) -> 10500 | E27: =D27/$D$27 -> 1 | F27: =SUM(F23:F26) -> 2142
A28: Expired – not started | B28: No | C28: =COUNTIFS(dm_status,A28) -> 14 | D28: =SUMIFS(dm_units,dm_status,A28) -> 311
A29: In planning | B29: No | C29: =COUNTIFS(dm_status,A29) -> 15 | D29: =SUMIFS(dm_units,dm_status,A29) -> 263
A30: Check: counted units equal the parcel-level consented total | D30: =D27-reg_cons -> 0
A32: D Parcel progress and evidence on the ground
A33: Parcel status (register) | B33: Parcels | C33: Of which City | D33: Of which County
A34: Built out | B34: =COUNTIFS(dp_pstat,A34) -> 50 | C34: =COUNTIFS(dp_pstat,A34,dp_scope,"City") -> 30 | D34: =COUNTIFS(dp_pstat,A34,dp_scope,"County") -> 20
A35: Partly built | B35: =COUNTIFS(dp_pstat,A35) -> 7 | C35: =COUNTIFS(dp_pstat,A35,dp_scope,"City") -> 5 | D35: =COUNTIFS(dp_pstat,A35,dp_scope,"County") -> 2
A36: Consented – not built | B36: =COUNTIFS(dp_pstat,A36) -> 145 | C36: =COUNTIFS(dp_pstat,A36,dp_scope,"City") -> 89 | D36: =COUNTIFS(dp_pstat,A36,dp_scope,"County") -> 56
A37: No consent | B37: =COUNTIFS(dp_pstat,A37) -> 244 | C37: =COUNTIFS(dp_pstat,A37,dp_scope,"City") -> 118 | D37: =COUNTIFS(dp_pstat,A37,dp_scope,"County") -> 126
A38: GeoDirectory new residential addresses on register parcels since 2019 | B38: =SUM(dp_geodnew) -> 2889
A39: Consented parcels flagged "Consented above capacity" (council capacity below consent) | B39: =COUNTIFS(dp_flag,"Consented above capacity") -> 14
A41: E Open data checks in the register (register_checks sheet)
A42: Check | B42: Count
A43: GeoDirectory: Fewer addresses than units – check | B43: 14
A44: GeoDirectory: No new addresses found – check location | B44: 7
A45: GeoDirectory: Under construction – check | B45: 4
A46: Counts typed from the register_checks table at the file date. Each one needs a person to confirm status or location; they do not change totals until confirmed.

Sheet 3 Supply
A1: 3 Land supply: capacity, pipeline and progress by location
A2: City Centre, rest of the city, the 15 settlements and the remainder of the county. Live formulas on Data_Parcels and Data_Perms. Area-by-area detail is on 3b Study Areas.
A5: A Register position by location
A6: Location | B6: Parcels | C6: Developable ha | D6: Capacity (audit + zoning est.) | E6: Complete | F6: Under constr. | G6: Permitted not started | H6: Stalled | I6: Consented | J6: Unconsented capacity | K6: Total supply | L6: Future supply (not yet built) | M6: % of future supply | N6: Memo: expired + in planning (not counted)
A7: City Centre | B7: =COUNTIFS(dp_geo,"City Centre") -> 56 | C7: =SUMIFS(dp_area,dp_geo,"City Centre") -> 80.92 | D7: =SUMIFS(dp_cap,dp_geo,"City Centre") -> 3633 | E7: =SUMIFS(dp_comp,dp_geo,"City Centre") -> 99 | F7: =SUMIFS(dp_uc,dp_geo,"City Centre") -> 111 | G7: =SUMIFS(dp_pns,dp_geo,"City Centre") -> 715 | H7: =SUMIFS(dp_stl,dp_geo,"City Centre") -> 0 | I7: =SUMIFS(dp_cons,dp_geo,"City Centre") -> 925 | J7: =SUMIFS(dp_unc,dp_geo,"City Centre") -> 3301 | K7: =SUMIFS(dp_tot,dp_geo,"City Centre") -> 4226 | L7: =SUMIFS(dp_fut,dp_geo,"City Centre") -> 4127 | M7: =L7/$L$13 -> 0.18326746 | N7: =SUMIFS(dp_exp,dp_geo,"City Centre")+SUMIFS(dp_inpl,dp_geo,"City Centre") -> 85
A8: Rest of City | B8: =COUNTIFS(dp_geo,"Rest of City") -> 186 | C8: =SUMIFS(dp_area,dp_geo,"Rest of City") -> 339.055 | D8: =SUMIFS(dp_cap,dp_geo,"Rest of City") -> 10506 | E8: =SUMIFS(dp_comp,dp_geo,"Rest of City") -> 1237 | F8: =SUMIFS(dp_uc,dp_geo,"Rest of City") -> 2843 | G8: =SUMIFS(dp_pns,dp_geo,"Rest of City") -> 3495 | H8: =SUMIFS(dp_stl,dp_geo,"Rest of City") -> 31 | I8: =SUMIFS(dp_cons,dp_geo,"Rest of City") -> 7606 | J8: =SUMIFS(dp_unc,dp_geo,"Rest of City") -> 6889 | K8: =SUMIFS(dp_tot,dp_geo,"Rest of City") -> 14495 | L8: =SUMIFS(dp_fut,dp_geo,"Rest of City") -> 13258 | M8: =L8/$L$13 -> 0.58874728 | N8: =SUMIFS(dp_exp,dp_geo,"Rest of City")+SUMIFS(dp_inpl,dp_geo,"Rest of City") -> 308
A9: City total | B9: =B7+B8 -> 242 | C9: =C7+C8 -> 419.975 | D9: =D7+D8 -> 14139 | E9: =E7+E8 -> 1336 | F9: =F7+F8 -> 2954 | G9: =G7+G8 -> 4210 | H9: =H7+H8 -> 31 | I9: =I7+I8 -> 8531 | ... L9: =L7+L8 -> 17385 | M9: =L9/$L$13 -> 0.77201474 | N9: =N7+N8 -> 393
A10: Settlements (15) | B10: =COUNTIFS(dp_geo,"Settlements") -> 157 | C10: =SUMIFS(dp_area,dp_geo,"Settlements") -> 225.481 | D10: =SUMIFS(dp_cap,dp_geo,"Settlements") -> 3063 | E10: =SUMIFS(dp_comp,dp_geo,"Settlements") -> 251 | F10: =SUMIFS(dp_uc,dp_geo,"Settlements") -> 651 | G10: =SUMIFS(dp_pns,dp_geo,"Settlements") -> 711 | H10: =SUMIFS(dp_stl,dp_geo,"Settlements") -> 125 | I10: =SUMIFS(dp_cons,dp_geo,"Settlements") -> 1738 | J10: =SUMIFS(dp_unc,dp_geo,"Settlements") -> 3063 | K10: =SUMIFS(dp_tot,dp_geo,"Settlements") -> 4801 | L10: =SUMIFS(dp_fut,dp_geo,"Settlements") -> 4550 | M10: =L10/$L$13 -> 0.2020516 | N10: =SUMIFS(dp_exp,dp_geo,"Settlements")+SUMIFS(dp_inpl,dp_geo,"Settlements") -> 127
A11: Remainder of county | B11: =COUNTIFS(dp_geo,"Remainder of County") -> 47 | C11: =SUMIFS(dp_area,dp_geo,"Remainder of County") -> 38.707 | D11: =SUMIFS(dp_cap,dp_geo,"Remainder of County") -> 397 | E11: =SUMIFS(dp_comp,dp_geo,"Remainder of County") -> 44 | F11: =SUMIFS(dp_uc,dp_geo,"Remainder of County") -> 106 | G11: =SUMIFS(dp_pns,dp_geo,"Remainder of County") -> 81 | H11: =SUMIFS(dp_stl,dp_geo,"Remainder of County") -> 0 | I11: =SUMIFS(dp_cons,dp_geo,"Remainder of County") -> 231 | J11: =SUMIFS(dp_unc,dp_geo,"Remainder of County") -> 397 | K11: =SUMIFS(dp_tot,dp_geo,"Remainder of County") -> 628 | L11: =SUMIFS(dp_fut,dp_geo,"Remainder of County") -> 584 | M11: =L11/$L$13 -> 0.025933656 | N11: =SUMIFS(dp_exp,dp_geo,"Remainder of County")+SUMIFS(dp_inpl,dp_geo,"Remainder of County") -> 54
A12: County total | B12: =B10+B11 -> 204 | C12: =C10+C11 -> 264.188 | D12: =D10+D11 -> 3460 | E12: =E10+E11 -> 295 | F12: =F10+F11 -> 757 | G12: =G10+G11 -> 792 | H12: =H10+H11 -> 125 | I12: =I10+I11 -> 1969 | ... L12: =L10+L11 -> 5134 | M12: =L12/$L$13 -> 0.22798526 | N12: =N10+N11 -> 181
A13: Register total | B13: =B9+B12 -> 446 | C13: =C9+C12 -> 684.163 | D13: =D9+D12 -> 17599 | E13: =E9+E12 -> 1631 | F13: =F9+F12 -> 3711 | G13: =G9+G12 -> 5002 | H13: =H9+H12 -> 156 | I13: =I9+I12 -> 10500 | ... L13: =L9+L12 -> 22519 | M13: =L13/$L$13 -> 1 | N13: =N9+N12 -> 574
A14: Check against register tab | L14: =L13-reg_fut -> 0
A15: City Centre = parcels in the City Centre neighbourhood. Rest of City = the other eight city neighbourhoods. Settlements = parcels assigned to one of the 15 study settlements (6 key towns, 9 large villages). Remainder = county parcels outside every study catchment. Capacity is blank on consent parcels (their capacity is the consented units).
A17: B Future supply by layer (homes still to be built)
A18: Layer | B18: City Centre | C18: Rest of City | D18: Settlements | E18: Remainder of County | F18: Total | G18: % of total
A19: Consented pipeline: under construction | B19: =SUMIFS(dp_uc,dp_geo,"City Centre") -> 111 | C19: =SUMIFS(dp_uc,dp_geo,"Rest of City") -> 2843 | D19: =SUMIFS(dp_uc,dp_geo,"Settlements") -> 651 | E19: =SUMIFS(dp_uc,dp_geo,"Remainder of County") -> 106 | F19: =SUM(B19:E19) -> 3711 | G19: =F19/$F$25 -> 0.16479417
A20: Consented pipeline: permitted, not started | B20: =SUMIFS(dp_pns,dp_geo,"City Centre") -> 715 | C20: =SUMIFS(dp_pns,dp_geo,"Rest of City") -> 3495 | D20: =SUMIFS(dp_pns,dp_geo,"Settlements") -> 711 | E20: =SUMIFS(dp_pns,dp_geo,"Remainder of County") -> 81 | F20: =SUM(B20:E20) -> 5002 | G20: =F20/$F$25 -> 0.22212354
A21: Consented pipeline: stalled | B21: =SUMIFS(dp_stl,dp_geo,"City Centre") -> 0 | C21: =SUMIFS(dp_stl,dp_geo,"Rest of City") -> 31 | D21: =SUMIFS(dp_stl,dp_geo,"Settlements") -> 125 | E21: =SUMIFS(dp_stl,dp_geo,"Remainder of County") -> 0 | F21: =SUM(B21:E21) -> 156 | G21: =F21/$F$25 -> 0.0069274835
A22: Council audit land, no consent | B22: =SUMIFS(dp_unc,dp_geo,"City Centre",dp_grp,"Audit") -> 3301 | C22: =SUMIFS(dp_unc,dp_geo,"Rest of City",dp_grp,"Audit") -> 6842 | D22: =SUMIFS(dp_unc,dp_geo,"Settlements",dp_grp,"Audit") -> 0 | E22: =SUMIFS(dp_unc,dp_geo,"Remainder of County",dp_grp,"Audit") -> 0 | F22: =SUM(B22:E22) -> 10143 | G22: =F22/$F$25 -> 0.45041965
A23: Zoned land, no consent (estimate) | B23: =SUMIFS(dp_unc,dp_geo,"City Centre",dp_grp,"Zoned") -> 0 | C23: =SUMIFS(dp_unc,dp_geo,"Rest of City",dp_grp,"Zoned") -> 47 | D23: =SUMIFS(dp_unc,dp_geo,"Settlements",dp_grp,"Zoned") -> 3063 | E23: =SUMIFS(dp_unc,dp_geo,"Remainder of County",dp_grp,"Zoned") -> 397 | F23: =SUM(B23:E23) -> 3507 | G23: =F23/$F$25 -> 0.15573516
A24: Consent parcels outside the audit: unconsented capacity | B24: =SUMIFS(dp_unc,dp_geo,"City Centre",dp_grp,"Consent") -> 0 | C24: =SUMIFS(dp_unc,dp_geo,"Rest of City",dp_grp,"Consent") -> 0 | D24: =SUMIFS(dp_unc,dp_geo,"Settlements",dp_grp,"Consent") -> 0 | E24: =SUMIFS(dp_unc,dp_geo,"Remainder of County",dp_grp,"Consent") -> 0 | F24: =SUM(B24:E24) -> 0 | G24: =F24/$F$25 -> 0
A25: Future supply | B25: =SUM(B19:B24) -> 4127 | C25: =SUM(C19:C24) -> 13258 | D25: =SUM(D19:D24) -> 4550 | E25: =SUM(E19:E24) -> 584 | F25: =SUM(F19:F24) -> 22519 | G25: =F25/$F$25 -> 1
A26: Check: layers less future supply in table A | F26: =F25-L13 -> 0
A28: C City neighbourhoods and county
A29: Neighbourhood / area | B29: Parcels | C29: Developable ha (audit) | D29: Audit capacity | E29: Consented | F29: Unconsented capacity | G29: Future supply | H29: Effective density, audit land (homes/ha)
A30: City Centre | B30: =COUNTIFS(dp_nbhd,A30) -> 56 | C30: =SUMIFS(dp_area,dp_nbhd,A30,dp_grp,"Audit") -> 77.639 | D30: =SUMIFS(dp_cap,dp_nbhd,A30,dp_grp,"Audit") -> 3633 | E30: =SUMIFS(dp_cons,dp_nbhd,A30) -> 925 | F30: =SUMIFS(dp_unc,dp_nbhd,A30) -> 3301 | G30: =SUMIFS(dp_fut,dp_nbhd,A30) -> 4127 | H30: =IF(C30>0,D30/C30,0) -> 46.793493
A31: Caherdavin | B31: =COUNTIFS(dp_nbhd,A31) -> 33 | C31: =SUMIFS(dp_area,dp_nbhd,A31,dp_grp,"Audit") -> 47.86 | D31: =SUMIFS(dp_cap,dp_nbhd,A31,dp_grp,"Audit") -> 1933 | E31: =SUMIFS(dp_cons,dp_nbhd,A31) -> 1298 | F31: =SUMIFS(dp_unc,dp_nbhd,A31) -> 938 | G31: =SUMIFS(dp_fut,dp_nbhd,A31) -> 2084 | H31: =IF(C31>0,D31/C31,0) -> 40.388634
A32: Castletroy/Annacotty | B32: =COUNTIFS(dp_nbhd,A32) -> 32 | C32: =SUMIFS(dp_area,dp_nbhd,A32,dp_grp,"Audit") -> 56.808 | D32: =SUMIFS(dp_cap,dp_nbhd,A32,dp_grp,"Audit") -> 2355 | E32: =SUMIFS(dp_cons,dp_nbhd,A32) -> 2810 | F32: =SUMIFS(dp_unc,dp_nbhd,A32) -> 1193 | G32: =SUMIFS(dp_fut,dp_nbhd,A32) -> 3387 | H32: =IF(C32>0,D32/C32,0) -> 41.455429
A33: Dooradoyle | B33: =COUNTIFS(dp_nbhd,A33) -> 36 | C33: =SUMIFS(dp_area,dp_nbhd,A33,dp_grp,"Audit") -> 80.257 | D33: =SUMIFS(dp_cap,dp_nbhd,A33,dp_grp,"Audit") -> 3699 | E33: =SUMIFS(dp_cons,dp_nbhd,A33) -> 1920 | F33: =SUMIFS(dp_unc,dp_nbhd,A33) -> 2806 | G33: =SUMIFS(dp_fut,dp_nbhd,A33) -> 4616 | H33: =IF(C33>0,D33/C33,0) -> 46.089438
A34: Southhill | B34: =COUNTIFS(dp_nbhd,A34) -> 31 | C34: =SUMIFS(dp_area,dp_nbhd,A34,dp_grp,"Audit") -> 18.641 | D34: =SUMIFS(dp_cap,dp_nbhd,A34,dp_grp,"Audit") -> 956 | E34: =SUMIFS(dp_cons,dp_nbhd,A34) -> 754 | F34: =SUMIFS(dp_unc,dp_nbhd,A34) -> 683 | G34: =SUMIFS(dp_fut,dp_nbhd,A34) -> 1148 | H34: =IF(C34>0,D34/C34,0) -> 51.284802
A35: Singland/Garryowen | B35: =COUNTIFS(dp_nbhd,A35) -> 28 | C35: =SUMIFS(dp_area,dp_nbhd,A35,dp_grp,"Audit") -> 13.036 | D35: =SUMIFS(dp_cap,dp_nbhd,A35,dp_grp,"Audit") -> 615 | E35: =SUMIFS(dp_cons,dp_nbhd,A35) -> 269 | F35: =SUMIFS(dp_unc,dp_nbhd,A35) -> 492 | G35: =SUMIFS(dp_fut,dp_nbhd,A35) -> 732 | H35: =IF(C35>0,D35/C35,0) -> 47.177048
A36: Corbally/Grove Island | B36: =COUNTIFS(dp_nbhd,A36) -> 12 | C36: =SUMIFS(dp_area,dp_nbhd,A36,dp_grp,"Audit") -> 16.707 | D36: =SUMIFS(dp_cap,dp_nbhd,A36,dp_grp,"Audit") -> 646 | E36: =SUMIFS(dp_cons,dp_nbhd,A36) -> 90 | F36: =SUMIFS(dp_unc,dp_nbhd,A36) -> 599 | G36: =SUMIFS(dp_fut,dp_nbhd,A36) -> 665 | H36: =IF(C36>0,D36/C36,0) -> 38.666427
A37: Ballinacurra | B37: =COUNTIFS(dp_nbhd,A37) -> 9 | C37: =SUMIFS(dp_area,dp_nbhd,A37,dp_grp,"Audit") -> 4.53 | D37: =SUMIFS(dp_cap,dp_nbhd,A37,dp_grp,"Audit") -> 203 | E37: =SUMIFS(dp_cons,dp_nbhd,A37) -> 415 | F37: =SUMIFS(dp_unc,dp_nbhd,A37) -> 153 | G37: =SUMIFS(dp_fut,dp_nbhd,A37) -> 551 | H37: =IF(C37>0,D37/C37,0) -> 44.812362
A38: Kings Island | B38: =COUNTIFS(dp_nbhd,A38) -> 5 | C38: =SUMIFS(dp_area,dp_nbhd,A38,dp_grp,"Audit") -> 0.734 | D38: =SUMIFS(dp_cap,dp_nbhd,A38,dp_grp,"Audit") -> 52 | E38: =SUMIFS(dp_cons,dp_nbhd,A38) -> 50 | F38: =SUMIFS(dp_unc,dp_nbhd,A38) -> 25 | G38: =SUMIFS(dp_fut,dp_nbhd,A38) -> 75 | H38: =IF(C38>0,D38/C38,0) -> 70.844687
A39: Settlements (15) | B39: =COUNTIFS(dp_geo,"Settlements") -> 157 | C39: =SUMIFS(dp_area,dp_geo,"Settlements",dp_grp,"Audit") -> 0 | D39: =SUMIFS(dp_cap,dp_geo,"Settlements",dp_grp,"Audit") -> 0 | E39: =SUMIFS(dp_cons,dp_geo,"Settlements") -> 1738 | F39: =SUMIFS(dp_unc,dp_geo,"Settlements") -> 3063 | G39: =SUMIFS(dp_fut,dp_geo,"Settlements") -> 4550 | H39: n/a (zoning estimates)
A40: Remainder of county | B40: =COUNTIFS(dp_geo,"Remainder of County") -> 47 | C40: =SUMIFS(dp_area,dp_geo,"Remainder of County",dp_grp,"Audit") -> 0 | D40: =SUMIFS(dp_cap,dp_geo,"Remainder of County",dp_grp,"Audit") -> 0 | E40: =SUMIFS(dp_cons,dp_geo,"Remainder of County") -> 231 | F40: =SUMIFS(dp_unc,dp_geo,"Remainder of County") -> 397 | G40: =SUMIFS(dp_fut,dp_geo,"Remainder of County") -> 584 | H40: n/a (zoning estimates)
A41: Total | B41: =SUM(B30:B40) -> 446 | C41: =SUM(C30:C40) -> 316.212 | D41: =SUM(D30:D40) -> 14092 | E41: =SUM(E30:E40) -> 10500 | F41: =SUM(F30:F40) -> 13650 | G41: =SUM(G30:G40) -> 22519 | H41: =IF(C41>0,D41/C41,0) -> 44.565039
A43: D Density the register assumes on unconsented land
A44: Measure | B44: City Centre | C44: Rest of City | D44: Settlements | E44: Remainder of County
A45: Unconsented audit capacity (homes) | B45: =SUMIFS(dp_unc,dp_geo,"City Centre",dp_grp,"Audit") -> 3301 | C45: =SUMIFS(dp_unc,dp_geo,"Rest of City",dp_grp,"Audit") -> 6842 | D45: =SUMIFS(dp_unc,dp_geo,"Settlements",dp_grp,"Audit") -> 0 | E45: =SUMIFS(dp_unc,dp_geo,"Remainder of County",dp_grp,"Audit") -> 0
...

Sheet 3b Study Areas
A1: 3b Study areas: land capacity and consents for the 24 areas and the county remainder
A2: 9 city neighbourhoods, 6 key towns, 9 large villages (15 settlements) and everything outside them. Each parcel sits in the one catchment it overlaps most (as in the register catchment_summary).
A5: A Capacity and consents by study area
A6: Study area | B6: Type | C6: Parcels | D6: Developable ha | E6: Complete | F6: Under constr. | G6: Permitted not started | H6: Stalled | I6: Consented (counted) | J6: Unconsented capacity | K6: of which zoned-land estimate | L6: Total supply | M6: Future supply (not yet built) | N6: Consented share of total supply | O6: Consented, not yet built, share of future supply | P6: Memo: expired + in planning | Q6: New GeoDirectory addresses since 2019 | R6: Effective weight (helper)
A7: City Centre | B7: City neighbourhood | C7: =COUNTIFS(dp_catch,$A7) -> 56 | D7: =SUMIFS(dp_area,dp_catch,$A7) -> 80.92 | E7: =SUMIFS(dp_comp,dp_catch,$A7) -> 99 | F7: =SUMIFS(dp_uc,dp_catch,$A7) -> 111 | G7: =SUMIFS(dp_pns,dp_catch,$A7) -> 715 | H7: =SUMIFS(dp_stl,dp_catch,$A7) -> 0 | I7: =SUMIFS(dp_cons,dp_catch,$A7) -> 925 | J7: =SUMIFS(dp_unc,dp_catch,$A7) -> 3301 | K7: =SUMIFS(dp_unc,dp_catch,$A7,dp_grp,"Zoned") -> 0 | L7: =SUMIFS(dp_tot,dp_catch,$A7) -> 4226 | M7: =SUMIFS(dp_fut,dp_catch,$A7) -> 4127 | N7: =IF(L7>0,I7/L7,0) -> 0.2188831 | O7: =IF(M7>0,(F7+G7+H7)/M7,0) -> 0.20014538 | P7: =SUMIFS(dp_exp,dp_catch,$A7)+SUMIFS(dp_inpl,dp_catch,$A7) -> 85 | Q7: =SUMIFS(dp_geodnew,dp_catch,$A7) -> 47
A8: Caherdavin | B8: City neighbourhood | C8: =COUNTIFS(dp_catch,$A8) -> 33 | D8: =SUMIFS(dp_area,dp_catch,$A8) -> 64.726 | E8: =SUMIFS(dp_comp,dp_catch,$A8) -> 152 | F8: =SUMIFS(dp_uc,dp_catch,$A8) -> 539 | G8: =SUMIFS(dp_pns,dp_catch,$A8) -> 576 | H8: =SUMIFS(dp_stl,dp_catch,$A8) -> 31 | I8: =SUMIFS(dp_cons,dp_catch,$A8) -> 1298 | J8: =SUMIFS(dp_unc,dp_catch,$A8) -> 938 | K8: =SUMIFS(dp_unc,dp_catch,$A8,dp_grp,"Zoned") -> 0 | L8: =SUMIFS(dp_tot,dp_catch,$A8) -> 2236 | M8: =SUMIFS(dp_fut,dp_catch,$A8) -> 2084 | N8: =IF(L8>0,I8/L8,0) -> 0.58050089 | O8: =IF(M8>0,(F8+G8+H8)/M8,0) -> 0.54990403 | P8: =SUMIFS(dp_exp,dp_catch,$A8)+SUMIFS(dp_inpl,dp_catch,$A8) -> 46 | Q8: =SUMIFS(dp_geodnew,dp_catch,$A8) -> 294
A9: Castletroy/Annacotty | B9: City neighbourhood | C9: =COUNTIFS(dp_catch,$A9) -> 32 | D9: =SUMIFS(dp_area,dp_catch,$A9) -> 99.594 | E9: =SUMIFS(dp_comp,dp_catch,$A9) -> 616 | F9: =SUMIFS(dp_uc,dp_catch,$A9) -> 604 | G9: =SUMIFS(dp_pns,dp_catch,$A9) -> 1590 | H9: =SUMIFS(dp_stl,dp_catch,$A9) -> 0 | I9: =SUMIFS(dp_cons,dp_catch,$A9) -> 2810 | J9: =SUMIFS(dp_unc,dp_catch,$A9) -> 1193 | K9: =SUMIFS(dp_unc,dp_catch,$A9,dp_grp,"Zoned") -> 5 | L9: =SUMIFS(dp_tot,dp_catch,$A9) -> 4003 | M9: =SUMIFS(dp_fut,dp_catch,$A9) -> 3387 | N9: =IF(L9>0,I9/L9,0) -> 0.70197352 | O9: =IF(M9>0,(F9+G9+H9)/M9,0) -> 0.64777089 | P9: =SUMIFS(dp_exp,dp_catch,$A9)+SUMIFS(dp_inpl,dp_catch,$A9) -> 149 | Q9: =SUMIFS(dp_geodnew,dp_catch,$A9) -> 923
A10: Dooradoyle | B10: City neighbourhood | C10: =COUNTIFS(dp_catch,$A10) -> 36 | D10: =SUMIFS(dp_area,dp_catch,$A10) -> 103.808 | E10: =SUMIFS(dp_comp,dp_catch,$A10) -> 110 | F10: =SUMIFS(dp_uc,dp_catch,$A10) -> 1121 | G10: =SUMIFS(dp_pns,dp_catch,$A10) -> 689 | H10: =SUMIFS(dp_stl,dp_catch,$A10) -> 0 | I10: =SUMIFS(dp_cons,dp_catch,$A10) -> 1920 | J10: =SUMIFS(dp_unc,dp_catch,$A10) -> 2806 | K10: =SUMIFS(dp_unc,dp_catch,$A10,dp_grp,"Zoned") -> 14 | L10: =SUMIFS(dp_tot,dp_catch,$A10) -> 4726 | M10: =SUMIFS(dp_fut,dp_catch,$A10) -> 4616 | N10: =IF(L10>0,I10/L10,0) -> 0.40626322 | O10: =IF(M10>0,(F10+G10+H10)/M10,0) -> 0.39211438 | P10: =SUMIFS(dp_exp,dp_catch,$A10)+SUMIFS(dp_inpl,dp_catch,$A10) -> 0 | Q10: =SUMIFS(dp_geodnew,dp_catch,$A10) -> 436
