Workbook

Sheet Summary
A1: Limerick housing land register
A2: Council audit parcels plus parcels for residential consents outside the audit. Every permission is linked to one parcel; totals are calculated from the Permissions sheet.
A4: By parcel source
B5: Parcels | C5: Developable ha | D5: Consented | E5: Built to date | F5: Unconsented capacity | G5: Total supply | H5: Future supply
A6: Council audit | B6: =COUNTIFS(Parcels!$B$2:$B$3000,$A6) -> 131 | C6: =SUMIFS(Parcels!$P$2:$P$3000,Parcels!$B$2:$B$3000,$A6) -> 313.164 | D6: =SUMIFS(Parcels!$AM$2:$AM$3000,Parcels!$B$2:$B$3000,$A6) -> 5225 | E6: =SUMIFS(Parcels!$AR$2:$AR$3000,Parcels!$B$2:$B$3000,$A6) -> 227 | F6: =SUMIFS(Parcels!$AP$2:$AP$3000,Parcels!$B$2:$B$3000,$A6) -> 10104 | G6: =SUMIFS(Parcels!$AQ$2:$AQ$3000,Parcels!$B$2:$B$3000,$A6) -> 15329 | H6: =SUMIFS(Parcels!$AS$2:$AS$3000,Parcels!$B$2:$B$3000,$A6) -> 15102
A7: Council audit – reinstated | B7: =COUNTIFS(Parcels!$B$2:$B$3000,$A7) -> 3 | C7: =SUMIFS(Parcels!$P$2:$P$3000,Parcels!$B$2:$B$3000,$A7) -> 3.993 | D7: =SUMIFS(Parcels!$AM$2:$AM$3000,Parcels!$B$2:$B$3000,$A7) -> 27 | E7: =SUMIFS(Parcels!$AR$2:$AR$3000,Parcels!$B$2:$B$3000,$A7) -> 0 | F7: =SUMIFS(Parcels!$AP$2:$AP$3000,Parcels!$B$2:$B$3000,$A7) -> 138 | G7: =SUMIFS(Parcels!$AQ$2:$AQ$3000,Parcels!$B$2:$B$3000,$A7) -> 165 | H7: =SUMIFS(Parcels!$AS$2:$AS$3000,Parcels!$B$2:$B$3000,$A7) -> 165
A8: Planning consent – not in council audit | B8: =COUNTIFS(Parcels!$B$2:$B$3000,$A8) -> 184 | C8: =SUMIFS(Parcels!$P$2:$P$3000,Parcels!$B$2:$B$3000,$A8) -> 216.101 | D8: =SUMIFS(Parcels!$AM$2:$AM$3000,Parcels!$B$2:$B$3000,$A8) -> 5204 | E8: =SUMIFS(Parcels!$AR$2:$AR$3000,Parcels!$B$2:$B$3000,$A8) -> 1999 | F8: =SUMIFS(Parcels!$AP$2:$AP$3000,Parcels!$B$2:$B$3000,$A8) -> 195 | G8: =SUMIFS(Parcels!$AQ$2:$AQ$3000,Parcels!$B$2:$B$3000,$A8) -> 5399 | H8: =SUMIFS(Parcels!$AS$2:$AS$3000,Parcels!$B$2:$B$3000,$A8) -> 3400
A9: Zoned land – no consent (estimate) | B9: =COUNTIFS(Parcels!$B$2:$B$3000,$A9) -> 88 | C9: =SUMIFS(Parcels!$P$2:$P$3000,Parcels!$B$2:$B$3000,$A9) -> 118.343 | D9: =SUMIFS(Parcels!$AM$2:$AM$3000,Parcels!$B$2:$B$3000,$A9) -> 0 | E9: =SUMIFS(Parcels!$AR$2:$AR$3000,Parcels!$B$2:$B$3000,$A9) -> 0 | F9: =SUMIFS(Parcels!$AP$2:$AP$3000,Parcels!$B$2:$B$3000,$A9) -> 2805 | G9: =SUMIFS(Parcels!$AQ$2:$AQ$3000,Parcels!$B$2:$B$3000,$A9) -> 2805 | H9: =SUMIFS(Parcels!$AS$2:$AS$3000,Parcels!$B$2:$B$3000,$A9) -> 2805
A10: Total | B10: =SUM(B6:B9) -> 406 | C10: =SUM(C6:C9) -> 651.601 | D10: =SUM(D6:D9) -> 10456 | E10: =SUM(E6:E9) -> 2226 | F10: =SUM(F6:F9) -> 13242 | G10: =SUM(G6:G9) -> 23698 | H10: =SUM(H6:H9) -> 21472
A12: By scope
B13: Parcels | C13: Developable ha | D13: Consented | E13: Built to date | F13: Unconsented capacity | G13: Total supply | H13: Future supply
A14: City | B14: =COUNTIFS(Parcels!$C$2:$C$3000,$A14) -> 241 | C14: =SUMIFS(Parcels!$P$2:$P$3000,Parcels!$C$2:$C$3000,$A14) -> 420.728 | D14: =SUMIFS(Parcels!$AM$2:$AM$3000,Parcels!$C$2:$C$3000,$A14) -> 8543 | E14: =SUMIFS(Parcels!$AR$2:$AR$3000,Parcels!$C$2:$C$3000,$A14) -> 1878 | F14: =SUMIFS(Parcels!$AP$2:$AP$3000,Parcels!$C$2:$C$3000,$A14) -> 10400 | G14: =SUMIFS(Parcels!$AQ$2:$AQ$3000,Parcels!$C$2:$C$3000,$A14) -> 18943 | H14: =SUMIFS(Parcels!$AS$2:$AS$3000,Parcels!$C$2:$C$3000,$A14) -> 17065
A15: County | B15: =COUNTIFS(Parcels!$C$2:$C$3000,$A15) -> 206 | C15: =SUMIFS(Parcels!$P$2:$P$3000,Parcels!$C$2:$C$3000,$A15) -> 272.358 | D15: =SUMIFS(Parcels!$AM$2:$AM$3000,Parcels!$C$2:$C$3000,$A15) -> 1951 | E15: =SUMIFS(Parcels!$AR$2:$AR$3000,Parcels!$C$2:$C$3000,$A15) -> 354 | F15: =SUMIFS(Parcels!$AP$2:$AP$3000,Parcels!$C$2:$C$3000,$A15) -> 3532 | G15: =SUMIFS(Parcels!$AQ$2:$AQ$3000,Parcels!$C$2:$C$3000,$A15) -> 5483 | H15: =SUMIFS(Parcels!$AS$2:$AS$3000,Parcels!$C$2:$C$3000,$A15) -> 5129
A16: Total | B16: =SUM(B14:B15) -> 447 | C16: =SUM(C14:C15) -> 693.086 | D16: =SUM(D14:D15) -> 10494 | E16: =SUM(E14:E15) -> 2232 | F16: =SUM(F14:F15) -> 13932 | G16: =SUM(G14:G15) -> 24426 | H16: =SUM(H14:H15) -> 22194
A18: By catchment type
B19: Parcels | C19: Developable ha | D19: Consented | E19: Built to date | F19: Unconsented capacity | G19: Total supply | H19: Future supply
A20: City neighbourhood | B20: =COUNTIFS(Parcels!$E$2:$E$3000,$A20) -> 241 | C20: =SUMIFS(Parcels!$P$2:$P$3000,Parcels!$E$2:$E$3000,$A20) -> 420.728 | D20: =SUMIFS(Parcels!$AM$2:$AM$3000,Parcels!$E$2:$E$3000,$A20) -> 8543 | E20: =SUMIFS(Parcels!$AR$2:$AR$3000,Parcels!$E$2:$E$3000,$A20) -> 1878 | F20: =SUMIFS(Parcels!$AP$2:$AP$3000,Parcels!$E$2:$E$3000,$A20) -> 10400 | G20: =SUMIFS(Parcels!$AQ$2:$AQ$3000,Parcels!$E$2:$E$3000,$A20) -> 18943 | H20: =SUMIFS(Parcels!$AS$2:$AS$3000,Parcels!$E$2:$E$3000,$A20) -> 17065
A21: Key town | B21: =COUNTIFS(Parcels!$E$2:$E$3000,$A21) -> 80 | C21: =SUMIFS(Parcels!$P$2:$P$3000,Parcels!$E$2:$E$3000,$A21) -> 125.614 | D21: =SUMIFS(Parcels!$AM$2:$AM$3000,Parcels!$E$2:$E$3000,$A21) -> 618 | E21: =SUMIFS(Parcels!$AR$2:$AR$3000,Parcels!$E$2:$E$3000,$A21) -> 118 | F21: =SUMIFS(Parcels!$AP$2:$AP$3000,Parcels!$E$2:$E$3000,$A21) -> 2327 | G21: =SUMIFS(Parcels!$AQ$2:$AQ$3000,Parcels!$E$2:$E$3000,$A21) -> 2945 | H21: =SUMIFS(Parcels!$AS$2:$AS$3000,Parcels!$E$2:$E$3000,$A21) -> 2827
A22: Large village | B22: =COUNTIFS(Parcels!$E$2:$E$3000,$A22) -> 80 | C22: =SUMIFS(Parcels!$P$2:$P$3000,Parcels!$E$2:$E$3000,$A22) -> 104.484 | D22: =SUMIFS(Parcels!$AM$2:$AM$3000,Parcels!$E$2:$E$3000,$A22) -> 1120 | E22: =SUMIFS(Parcels!$AR$2:$AR$3000,Parcels!$E$2:$E$3000,$A22) -> 189 | F22: =SUMIFS(Parcels!$AP$2:$AP$3000,Parcels!$E$2:$E$3000,$A22) -> 789 | G22: =SUMIFS(Parcels!$AQ$2:$AQ$3000,Parcels!$E$2:$E$3000,$A22) -> 1909 | H22: =SUMIFS(Parcels!$AS$2:$AS$3000,Parcels!$E$2:$E$3000,$A22) -> 1720
A23: Rest of county | B23: =COUNTIFS(Parcels!$E$2:$E$3000,$A23) -> 46 | C23: =SUMIFS(Parcels!$P$2:$P$3000,Parcels!$E$2:$E$3000,$A23) -> 42.26 | D23: =SUMIFS(Parcels!$AM$2:$AM$3000,Parcels!$E$2:$E$3000,$A23) -> 213 | E23: =SUMIFS(Parcels!$AR$2:$AR$3000,Parcels!$E$2:$E$3000,$A23) -> 47 | F23: =SUMIFS(Parcels!$AP$2:$AP$3000,Parcels!$E$2:$E$3000,$A23) -> 416 | G23: =SUMIFS(Parcels!$AQ$2:$AQ$3000,Parcels!$E$2:$E$3000,$A23) -> 629 | H23: =SUMIFS(Parcels!$AS$2:$AS$3000,Parcels!$E$2:$E$3000,$A23) -> 582
A24: Total | B24: =SUM(B20:B23) -> 447 | C24: =SUM(C20:C23) -> 693.086 | D24: =SUM(D20:D23) -> 10494 | E24: =SUM(E20:E23) -> 2232 | F24: =SUM(F20:F23) -> 13932 | G24: =SUM(G20:G23) -> 24426 | H24: =SUM(H20:H23) -> 22194
A26: By parcel status
B27: Parcels | C27: Developable ha | D27: Consented | E27: Built to date | F27: Unconsented capacity | G27: Total supply | H27: Future supply
A28: Finished | B28: =COUNTIFS(Parcels!$BC$2:$BC$3000,$A28) -> 50 | C28: =SUMIFS(Parcels!$P$2:$P$3000,Parcels!$BC$2:$BC$3000,$A28) -> 59.406 | D28: =SUMIFS(Parcels!$AM$2:$AM$3000,Parcels!$BC$2:$BC$3000,$A28) -> 1196 | E28: =SUMIFS(Parcels!$AR$2:$AR$3000,Parcels!$BC$2:$BC$3000,$A28) -> 1196 | F28: =SUMIFS(Parcels!$AP$2:$AP$3000,Parcels!$BC$2:$BC$3000,$A28) -> 0 | G28: =SUMIFS(Parcels!$AQ$2:$AQ$3000,Parcels!$BC$2:$BC$3000,$A28) -> 1196 | H28: =SUMIFS(Parcels!$AS$2:$AS$3000,Parcels!$BC$2:$BC$3000,$A28) -> 0
A29: Partly built | B29: =COUNTIFS(Parcels!$BC$2:$BC$3000,$A29) -> 23 | C29: =SUMIFS(Parcels!$P$2:$P$3000,Parcels!$BC$2:$BC$3000,$A29) -> 128.138 | D29: =SUMIFS(Parcels!$AM$2:$AM$3000,Parcels!$BC$2:$BC$3000,$A29) -> 2209 | E29: =SUMIFS(Parcels!$AR$2:$AR$3000,Parcels!$BC$2:$BC$3000,$A29) -> 1036 | F29: =SUMIFS(Parcels!$AP$2:$AP$3000,Parcels!$BC$2:$BC$3000,$A29) -> 2625 | G29: =SUMIFS(Parcels!$AQ$2:$AQ$3000,Parcels!$BC$2:$BC$3000,$A29) -> 4834 | H29: =SUMIFS(Parcels!$AS$2:$AS$3000,Parcels!$BC$2:$BC$3000,$A29) -> 3798
A30: Consented – not built | B30: =COUNTIFS(Parcels!$BC$2:$BC$3000,$A30) -> 130 | C30: =SUMIFS(Parcels!$P$2:$P$3000,Parcels!$BC$2:$BC$3000,$A30) -> 210.641 | D30: =SUMIFS(Parcels!$AM$2:$AM$3000,Parcels!$BC$2:$BC$3000,$A30) -> 7089 | E30: =SUMIFS(Parcels!$AR$2:$AR$3000,Parcels!$BC$2:$BC$3000,$A30) -> 0 | F30: =SUMIFS(Parcels!$AP$2:$AP$3000,Parcels!$BC$2:$BC$3000,$A30) -> 1660 | G30: =SUMIFS(Parcels!$AQ$2:$AQ$3000,Parcels!$BC$2:$BC$3000,$A30) -> 8749 | H30: =SUMIFS(Parcels!$AS$2:$AS$3000,Parcels!$BC$2:$BC$3000,$A30) -> 8749
A31: No consent | B31: =COUNTIFS(Parcels!$BC$2:$BC$3000,$A31) -> 244 | C31: =SUMIFS(Parcels!$P$2:$P$3000,Parcels!$BC$2:$BC$3000,$A31) -> 294.901 | D31: =SUMIFS(Parcels!$AM$2:$AM$3000,Parcels!$BC$2:$BC$3000,$A31) -> 0 | E31: =SUMIFS(Parcels!$AR$2:$AR$3000,Parcels!$BC$2:$BC$3000,$A31) -> 0 | F31: =SUMIFS(Parcels!$AP$2:$AP$3000,Parcels!$BC$2:$BC$3000,$A31) -> 9647 | G31: =SUMIFS(Parcels!$AQ$2:$AQ$3000,Parcels!$BC$2:$BC$3000,$A31) -> 9647 | H31: =SUMIFS(Parcels!$AS$2:$AS$3000,Parcels!$BC$2:$BC$3000,$A31) -> 9647
A32: Total | B32: =SUM(B28:B31) -> 447 | C32: =SUM(C28:C31) -> 693.086 | D32: =SUM(D28:D31) -> 10494 | E32: =SUM(E28:E31) -> 2232 | F32: =SUM(F28:F31) -> 13932 | G32: =SUM(G28:G31) -> 24426 | H32: =SUM(H28:H31) -> 22194
A34: Expected completions (consented schemes; estimates)
B35: Q4 2026 | C35: 2027 | D35: 2028 | E35: 2029 | F35: 2030 | G35: 2031+
A36: All parcels | B36: =SUM(Parcels!$AT$2:$AT$3000) -> 506.2 | C36: =SUM(Parcels!$AU$2:$AU$3000) -> 2084.7 | D36: =SUM(Parcels!$AV$2:$AV$3000) -> 1725.2 | E36: =SUM(Parcels!$AW$2:$AW$3000) -> 1954.7 | F36: =SUM(Parcels!$AX$2:$AX$3000) -> 851 | G36: =SUM(Parcels!$AY$2:$AY$3000) -> 1573.2
A38: Checks (all should be zero)
A39: Permissions with a problem (see check column) | B39: =COUNTIF(Permissions!$AT$2:$AT$3000,"?*") -> 0
A40: Parcels with a flag | B40: =COUNTIF(Parcels!$BD$2:$BD$3000,"?*")-COUNTIF(Parcels!$BD$2:$BD$3000,"Consented above capacity") -> 0
A41: Units on Permissions not reaching a parcel | B41: =SUMIFS(Permissions!$G$2:$G$3000,Permissions!$R$2:$R$3000,"Yes")-SUM(Parcels!$AM$2:$AM$3000)-SUM(Parcels!$AN$2:$AN$3000)-SUM(Parcels!$AO$2:$AO$3000) -> 0
A42: Permissions with no parcel_id | B42: =COUNTIFS(Permissions!$A$2:$A$3000,"?*",Permissions!$B$2:$B$3000,"") -> 0
A43: Parcels consented above council capacity (review capacity) | B43: =COUNTIF(Parcels!$BD$2:$BD$3000,"Consented above capacity") -> 14
A45: Blue-grey columns are calculated. Edit only the white columns. capacity_units (council estimate on audit parcels, zoning estimate on zoned-land parcels) is the only unit figure typed on the Parcels sheet.

Sheet Catchments
A1: Supply by study catchment
A2: Each parcel is assigned to the catchment it overlaps most. Parcels just outside a key town or village are added to it when zoned in its LAP, within 500 m, or named in the scheme and within 2 km (catchment_basis on Parcels). Live formulas on the Parcels sheet.
A4: Catchment type | B4: Catchment | C4: Parcels | D4: Developable ha | E4: Consented | F4: Complete | G4: Under construction | H4: Permitted, not started | I4: Unconsented capacity | J4: Total supply | K4: Future supply | L4: Q4 2026 | M4: 2027 | N4: 2028 | O4: 2029 | P4: 2030 | Q4: 2031+
A5: City neighbourhood | B5: Ballinacurra | C5: =COUNTIFS(Parcels!$D$2:$D$3000,$B5) -> 9 | D5: =SUMIFS(Parcels!$P$2:$P$3000,Parcels!$D$2:$D$3000,$B5) -> 5.562 | E5: =SUMIFS(Parcels!$AM$2:$AM$3000,Parcels!$D$2:$D$3000,$B5) -> 415 | F5: =SUMIFS(Parcels!$AI$2:$AI$3000,Parcels!$D$2:$D$3000,$B5) -> 17 | G5: =SUMIFS(Parcels!$AJ$2:$AJ$3000,Parcels!$D$2:$D$3000,$B5) -> 398 | H5: =SUMIFS(Parcels!$AK$2:$AK$3000,Parcels!$D$2:$D$3000,$B5) -> 0 | I5: =SUMIFS(Parcels!$AP$2:$AP$3000,Parcels!$D$2:$D$3000,$B5) -> 153 | J5: =SUMIFS(Parcels!$AQ$2:$AQ$3000,Parcels!$D$2:$D$3000,$B5) -> 568 | K5: =SUMIFS(Parcels!$AS$2:$AS$3000,Parcels!$D$2:$D$3000,$B5) -> 430 | L5: =SUMIFS(Parcels!$AT$2:$AT$3000,Parcels!$D$2:$D$3000,$B5) -> 24.7 | M5: =SUMIFS(Parcels!$AU$2:$AU$3000,Parcels!$D$2:$D$3000,$B5) -> 107 | N5: =SUMIFS(Parcels!$AV$2:$AV$3000,Parcels!$D$2:$D$3000,$B5) -> 93 | O5: =SUMIFS(Parcels!$AW$2:$AW$3000,Parcels!$D$2:$D$3000,$B5) -> 88.5 | P5: =SUMIFS(Parcels!$AX$2:$AX$3000,Parcels!$D$2:$D$3000,$B5) -> 84.9 | Q5: =SUMIFS(Parcels!$AY$2:$AY$3000,Parcels!$D$2:$D$3000,$B5) -> -0.1
A6: City neighbourhood | B6: Caherdavin | C6: =COUNTIFS(Parcels!$D$2:$D$3000,$B6) -> 33 | D6: =SUMIFS(Parcels!$P$2:$P$3000,Parcels!$D$2:$D$3000,$B6) -> 64.726 | E6: =SUMIFS(Parcels!$AM$2:$AM$3000,Parcels!$D$2:$D$3000,$B6) -> 1298 | F6: =SUMIFS(Parcels!$AI$2:$AI$3000,Parcels!$D$2:$D$3000,$B6) -> 152 | G6: =SUMIFS(Parcels!$AJ$2:$AJ$3000,Parcels!$D$2:$D$3000,$B6) -> 539 | H6: =SUMIFS(Parcels!$AK$2:$AK$3000,Parcels!$D$2:$D$3000,$B6) -> 576 | I6: =SUMIFS(Parcels!$AP$2:$AP$3000,Parcels!$D$2:$D$3000,$B6) -> 985 | J6: =SUMIFS(Parcels!$AQ$2:$AQ$3000,Parcels!$D$2:$D$3000,$B6) -> 2283 | K6: =SUMIFS(Parcels!$AS$2:$AS$3000,Parcels!$D$2:$D$3000,$B6) -> 2083 | L6: =SUMIFS(Parcels!$AT$2:$AT$3000,Parcels!$D$2:$D$3000,$B6) -> 64.5 | M6: =SUMIFS(Parcels!$AU$2:$AU$3000,Parcels!$D$2:$D$3000,$B6) -> 306.2 | N6: =SUMIFS(Parcels!$AV$2:$AV$3000,Parcels!$D$2:$D$3000,$B6) -> 337.3 | O6: =SUMIFS(Parcels!$AW$2:$AW$3000,Parcels!$D$2:$D$3000,$B6) -> 304.1 | P6: =SUMIFS(Parcels!$AX$2:$AX$3000,Parcels!$D$2:$D$3000,$B6) -> 102.8 | Q6: =SUMIFS(Parcels!$AY$2:$AY$3000,Parcels!$D$2:$D$3000,$B6) -> 0.1
A7: City neighbourhood | B7: Castletroy/Annacotty | C7: =COUNTIFS(Parcels!$D$2:$D$3000,$B7) -> 32 | D7: =SUMIFS(Parcels!$P$2:$P$3000,Parcels!$D$2:$D$3000,$B7) -> 99.594 | E7: =SUMIFS(Parcels!$AM$2:$AM$3000,Parcels!$D$2:$D$3000,$B7) -> 2822 | F7: =SUMIFS(Parcels!$AI$2:$AI$3000,Parcels!$D$2:$D$3000,$B7) -> 628 | G7: =SUMIFS(Parcels!$AJ$2:$AJ$3000,Parcels!$D$2:$D$3000,$B7) -> 604 | H7: =SUMIFS(Parcels!$AK$2:$AK$3000,Parcels!$D$2:$D$3000,$B7) -> 1590 | I7: =SUMIFS(Parcels!$AP$2:$AP$3000,Parcels!$D$2:$D$3000,$B7) -> 1193 | J7: =SUMIFS(Parcels!$AQ$2:$AQ$3000,Parcels!$D$2:$D$3000,$B7) -> 4015 | K7: =SUMIFS(Parcels!$AS$2:$AS$3000,Parcels!$D$2:$D$3000,$B7) -> 3219 | L7: =SUMIFS(Parcels!$AT$2:$AT$3000,Parcels!$D$2:$D$3000,$B7) -> 139.5 | M7: =SUMIFS(Parcels!$AU$2:$AU$3000,Parcels!$D$2:$D$3000,$B7) -> 463.2 | N7: =SUMIFS(Parcels!$AV$2:$AV$3000,Parcels!$D$2:$D$3000,$B7) -> 23.4 | O7: =SUMIFS(Parcels!$AW$2:$AW$3000,Parcels!$D$2:$D$3000,$B7) -> 473.6 | P7: =SUMIFS(Parcels!$AX$2:$AX$3000,Parcels!$D$2:$D$3000,$B7) -> 202.6 | Q7: =SUMIFS(Parcels!$AY$2:$AY$3000,Parcels!$D$2:$D$3000,$B7) -> 891.7
A8: City neighbourhood | B8: City Centre | C8: =COUNTIFS(Parcels!$D$2:$D$3000,$B8) -> 55 | D8: =SUMIFS(Parcels!$P$2:$P$3000,Parcels!$D$2:$D$3000,$B8) -> 81.522 | E8: =SUMIFS(Parcels!$AM$2:$AM$3000,Parcels!$D$2:$D$3000,$B8) -> 925 | F8: =SUMIFS(Parcels!$AI$2:$AI$3000,Parcels!$D$2:$D$3000,$B8) -> 99 | G8: =SUMIFS(Parcels!$AJ$2:$AJ$3000,Parcels!$D$2:$D$3000,$B8) -> 111 | H8: =SUMIFS(Parcels!$AK$2:$AK$3000,Parcels!$D$2:$D$3000,$B8) -> 715 | I8: =SUMIFS(Parcels!$AP$2:$AP$3000,Parcels!$D$2:$D$3000,$B8) -> 3412 | J8: =SUMIFS(Parcels!$AQ$2:$AQ$3000,Parcels!$D$2:$D$3000,$B8) -> 4337 | K8: =SUMIFS(Parcels!$AS$2:$AS$3000,Parcels!$D$2:$D$3000,$B8) -> 4238 | L8: =SUMIFS(Parcels!$AT$2:$AT$3000,Parcels!$D$2:$D$3000,$B8) -> 13.8 | M8: =SUMIFS(Parcels!$AU$2:$AU$3000,Parcels!$D$2:$D$3000,$B8) -> 85.5 | N8: =SUMIFS(Parcels!$AV$2:$AV$3000,Parcels!$D$2:$D$3000,$B8) -> 242.4 | O8: =SUMIFS(Parcels!$AW$2:$AW$3000,Parcels!$D$2:$D$3000,$B8) -> 258.9 | P8: =SUMIFS(Parcels!$AX$2:$AX$3000,Parcels!$D$2:$D$3000,$B8) -> 72.7 | Q8: =SUMIFS(Parcels!$AY$2:$AY$3000,Parcels!$D$2:$D$3000,$B8) -> 152.7
A9: City neighbourhood | B9: Corbally/Grove Island | C9: =COUNTIFS(Parcels!$D$2:$D$3000,$B9) -> 12 | D9: =SUMIFS(Parcels!$P$2:$P$3000,Parcels!$D$2:$D$3000,$B9) -> 19.019 | E9: =SUMIFS(Parcels!$AM$2:$AM$3000,Parcels!$D$2:$D$3000,$B9) -> 90 | F9: =SUMIFS(Parcels!$AI$2:$AI$3000,Parcels!$D$2:$D$3000,$B9) -> 24 | G9: =SUMIFS(Parcels!$AJ$2:$AJ$3000,Parcels!$D$2:$D$3000,$B9) -> 26 | H9: =SUMIFS(Parcels!$AK$2:$AK$3000,Parcels!$D$2:$D$3000,$B9) -> 40 | I9: =SUMIFS(Parcels!$AP$2:$AP$3000,Parcels!$D$2:$D$3000,$B9) -> 605 | J9: =SUMIFS(Parcels!$AQ$2:$AQ$3000,Parcels!$D$2:$D$3000,$B9) -> 695 | K9: =SUMIFS(Parcels!$AS$2:$AS$3000,Parcels!$D$2:$D$3000,$B9) -> 671 | L9: =SUMIFS(Parcels!$AT$2:$AT$3000,Parcels!$D$2:$D$3000,$B9) -> 6.1 | M9: =SUMIFS(Parcels!$AU$2:$AU$3000,Parcels!$D$2:$D$3000,$B9) -> 19.9 | N9: =SUMIFS(Parcels!$AV$2:$AV$3000,Parcels!$D$2:$D$3000,$B9) -> 23.5 | O9: =SUMIFS(Parcels!$AW$2:$AW$3000,Parcels!$D$2:$D$3000,$B9) -> 16.5 | P9: =SUMIFS(Parcels!$AX$2:$AX$3000,Parcels!$D$2:$D$3000,$B9) -> 0 | Q9: =SUMIFS(Parcels!$AY$2:$AY$3000,Parcels!$D$2:$D$3000,$B9) -> 0
A10: City neighbourhood | B10: Dooradoyle | C10: =COUNTIFS(Parcels!$D$2:$D$3000,$B10) -> 36 | D10: =SUMIFS(Parcels!$P$2:$P$3000,Parcels!$D$2:$D$3000,$B10) -> 103.808 | E10: =SUMIFS(Parcels!$AM$2:$AM$3000,Parcels!$D$2:$D$3000,$B10) -> 1920 | F10: =SUMIFS(Parcels!$AI$2:$AI$3000,Parcels!$D$2:$D$3000,$B10) -> 110 | G10: =SUMIFS(Parcels!$AJ$2:$AJ$3000,Parcels!$D$2:$D$3000,$B10) -> 1121 | H10: =SUMIFS(Parcels!$AK$2:$AK$3000,Parcels!$D$2:$D$3000,$B10) -> 689 | I10: =SUMIFS(Parcels!$AP$2:$AP$3000,Parcels!$D$2:$D$3000,$B10) -> 2811 | J10: =SUMIFS(Parcels!$AQ$2:$AQ$3000,Parcels!$D$2:$D$3000,$B10) -> 4731 | K10: =SUMIFS(Parcels!$AS$2:$AS$3000,Parcels!$D$2:$D$3000,$B10) -> 4454 | L10: =SUMIFS(Parcels!$AT$2:$AT$3000,Parcels!$D$2:$D$3000,$B10) -> 108.4 | M10: =SUMIFS(Parcels!$AU$2:$AU$3000,Parcels!$D$2:$D$3000,$B10) -> 439.7 | N10: =SUMIFS(Parcels!$AV$2:$AV$3000,Parcels!$D$2:$D$3000,$B10) -> 343.6 | O10: =SUMIFS(Parcels!$AW$2:$AW$3000,Parcels!$D$2:$D$3000,$B10) -> 391.1 | P10: =SUMIFS(Parcels!$AX$2:$AX$3000,Parcels!$D$2:$D$3000,$B10) -> 302.4 | Q10: =SUMIFS(Parcels!$AY$2:$AY$3000,Parcels!$D$2:$D$3000,$B10) -> 224.8
A11: City neighbourhood | B11: Kings Island | C11: =COUNTIFS(Parcels!$D$2:$D$3000,$B11) -> 5 | D11: =SUMIFS(Parcels!$P$2:$P$3000,Parcels!$D$2:$D$3000,$B11) -> 0.906 | E11: =SUMIFS(Parcels!$AM$2:$AM$3000,Parcels!$D$2:$D$3000,$B11) -> 50 | F11: =SUMIFS(Parcels!$AI$2:$AI$3000,Parcels!$D$2:$D$3000,$B11) -> 0 | G11: =SUMIFS(Parcels!$AJ$2:$AJ$3000,Parcels!$D$2:$D$3000,$B11) -> 0 | H11: =SUMIFS(Parcels!$AK$2:$AK$3000,Parcels!$D$2:$D$3000,$B11) -> 50 | I11: =SUMIFS(Parcels!$AP$2:$AP$3000,Parcels!$D$2:$D$3000,$B11) -> 25 | J11: =SUMIFS(Parcels!$AQ$2:$AQ$3000,Parcels!$D$2:$D$3000,$B11) -> 75 | K11: =SUMIFS(Parcels!$AS$2:$AS$3000,Parcels!$D$2:$D$3000,$B11) -> 75 | L11: =SUMIFS(Parcels!$AT$2:$AT$3000,Parcels!$D$2:$D$3000,$B11) -> 0 | M11: =SUMIFS(Parcels!$AU$2:$AU$3000,Parcels!$D$2:$D$3000,$B11) -> 0 | N11: =SUMIFS(Parcels!$AV$2:$AV$3000,Parcels!$D$2:$D$3000,$B11) -> 30.1 | O11: =SUMIFS(Parcels!$AW$2:$AW$3000,Parcels!$D$2:$D$3000,$B11) -> 19.6 | P11: =SUMIFS(Parcels!$AX$2:$AX$3000,Parcels!$D$2:$D$3000,$B11) -> 0.3 | Q11: =SUMIFS(Parcels!$AY$2:$AY$3000,Parcels!$D$2:$D$3000,$B11) -> 0
A12: City neighbourhood | B12: Singland/Garryowen | C12: =COUNTIFS(Parcels!$D$2:$D$3000,$B12) -> 28 | D12: =SUMIFS(Parcels!$P$2:$P$3000,Parcels!$D$2:$D$3000,$B12) -> 15.732 | E12: =SUMIFS(Parcels!$AM$2:$AM$3000,Parcels!$D$2:$D$3000,$B12) -> 269 | F12: =SUMIFS(Parcels!$AI$2:$AI$3000,Parcels!$D$2:$D$3000,$B12) -> 29 | G12: =SUMIFS(Parcels!$AJ$2:$AJ$3000,Parcels!$D$2:$D$3000,$B12) -> 108 | H12: =SUMIFS(Parcels!$AK$2:$AK$3000,Parcels!$D$2:$D$3000,$B12) -> 132 | I12: =SUMIFS(Parcels!$AP$2:$AP$3000,Parcels!$D$2:$D$3000,$B12) -> 517 | J12: =SUMIFS(Parcels!$AQ$2:$AQ$3000,Parcels!$D$2:$D$3000,$B12) -> 786 | K12: =SUMIFS(Parcels!$AS$2:$AS$3000,Parcels!$D$2:$D$3000,$B12) -> 734 | L12: =SUMIFS(Parcels!$AT$2:$AT$3000,Parcels!$D$2:$D$3000,$B12) -> 18 | M12: =SUMIFS(Parcels!$AU$2:$AU$3000,Parcels!$D$2:$D$3000,$B12) -> 91.4 | N12: =SUMIFS(Parcels!$AV$2:$AV$3000,Parcels!$D$2:$D$3000,$B12) -> 104.5 | O12: =SUMIFS(Parcels!$AW$2:$AW$3000,Parcels!$D$2:$D$3000,$B12) -> 26.1 | P12: =SUMIFS(Parcels!$AX$2:$AX$3000,Parcels!$D$2:$D$3000,$B12) -> 0 | Q12: =SUMIFS(Parcels!$AY$2:$AY$3000,Parcels!$D$2:$D$3000,$B12) -> 0
A13: City neighbourhood | B13: Southhill | C13: =COUNTIFS(Parcels!$D$2:$D$3000,$B13) -> 31 | D13: =SUMIFS(Parcels!$P$2:$P$3000,Parcels!$D$2:$D$3000,$B13) -> 29.859 | E13: =SUMIFS(Parcels!$AM$2:$AM$3000,Parcels!$D$2:$D$3000,$B13) -> 754 | F13: =SUMIFS(Parcels!$AI$2:$AI$3000,Parcels!$D$2:$D$3000,$B13) -> 289 | G13: =SUMIFS(Parcels!$AJ$2:$AJ$3000,Parcels!$D$2:$D$3000,$B13) -> 47 | H13: =SUMIFS(Parcels!$AK$2:$AK$3000,Parcels!$D$2:$D$3000,$B13) -> 418 | I13: =SUMIFS(Parcels!$AP$2:$AP$3000,Parcels!$D$2:$D$3000,$B13) -> 699 | J13: =SUMIFS(Parcels!$AQ$2:$AQ$3000,Parcels!$D$2:$D$3000,$B13) -> 1453 | K13: =SUMIFS(Parcels!$AS$2:$AS$3000,Parcels!$D$2:$D$3000,$B13) -> 1161 | L13: =SUMIFS(Parcels!$AT$2:$AT$3000,Parcels!$D$2:$D$3000,$B13) -> 3.7 | M13: =SUMIFS(Parcels!$AU$2:$AU$3000,Parcels!$D$2:$D$3000,$B13) -> 40.8 | N13: =SUMIFS(Parcels!$AV$2:$AV$3000,Parcels!$D$2:$D$3000,$B13) -> 15.3 | O13: =SUMIFS(Parcels!$AW$2:$AW$3000,Parcels!$D$2:$D$3000,$B13) -> 43.8 | P13: =SUMIFS(Parcels!$AX$2:$AX$3000,Parcels!$D$2:$D$3000,$B13) -> 57.4 | Q13: =SUMIFS(Parcels!$AY$2:$AY$3000,Parcels!$D$2:$D$3000,$B13) -> 304
A14: City neighbourhood total | C14: =SUM(C5:C13) -> 241 | D14: =SUM(D5:D13) -> 420.728 | E14: =SUM(E5:E13) -> 8543 | F14: =SUM(F5:F13) -> 1348 | G14: =SUM(G5:G13) -> 2954 | H14: =SUM(H5:H13) -> 4210 | I14: =SUM(I5:I13) -> 10400 | J14: =SUM(J5:J13) -> 18943 | ... Q14: =SUM(Q5:Q13) -> 1573.2
A16: Key town | B16: Abbeyfeale | C16: =COUNTIFS(Parcels!$D$2:$D$3000,$B16) -> 10 | D16: =SUMIFS(Parcels!$P$2:$P$3000,Parcels!$D$2:$D$3000,$B16) -> 11.181 | E16: =SUMIFS(Parcels!$AM$2:$AM$3000,Parcels!$D$2:$D$3000,$B16) -> 87 | F16: =SUMIFS(Parcels!$AI$2:$AI$3000,Parcels!$D$2:$D$3000,$B16) -> 0 | G16: =SUMIFS(Parcels!$AJ$2:$AJ$3000,Parcels!$D$2:$D$3000,$B16) -> 0 | H16: =SUMIFS(Parcels!$AK$2:$AK$3000,Parcels!$D$2:$D$3000,$B16) -> 87 | I16: =SUMIFS(Parcels!$AP$2:$AP$3000,Parcels!$D$2:$D$3000,$B16) -> 176 | J16: =SUMIFS(Parcels!$AQ$2:$AQ$3000,Parcels!$D$2:$D$3000,$B16) -> 263 | K16: =SUMIFS(Parcels!$AS$2:$AS$3000,Parcels!$D$2:$D$3000,$B16) -> 263 | L16: =SUMIFS(Parcels!$AT$2:$AT$3000,Parcels!$D$2:$D$3000,$B16) -> 0 | M16: =SUMIFS(Parcels!$AU$2:$AU$3000,Parcels!$D$2:$D$3000,$B16) -> 0 | N16: =SUMIFS(Parcels!$AV$2:$AV$3000,Parcels!$D$2:$D$3000,$B16) -> 57.4 | O16: =SUMIFS(Parcels!$AW$2:$AW$3000,Parcels!$D$2:$D$3000,$B16) -> 28.9 | P16: =SUMIFS(Parcels!$AX$2:$AX$3000,Parcels!$D$2:$D$3000,$B16) -> 0.7 | Q16: =SUMIFS(Parcels!$AY$2:$AY$3000,Parcels!$D$2:$D$3000,$B16) -> 0
A17: Key town | B17: Caherconlish | C17: =COUNTIFS(Parcels!$D$2:$D$3000,$B17) -> 7 | D17: =SUMIFS(Parcels!$P$2:$P$3000,Parcels!$D$2:$D$3000,$B17) -> 8.214 | E17: =SUMIFS(Parcels!$AM$2:$AM$3000,Parcels!$D$2:$D$3000,$B17) -> 9 | F17: =SUMIFS(Parcels!$AI$2:$AI$3000,Parcels!$D$2:$D$3000,$B17) -> 9 | G17: =SUMIFS(Parcels!$AJ$2:$AJ$3000,Parcels!$D$2:$D$3000,$B17) -> 0 | H17: =SUMIFS(Parcels!$AK$2:$AK$3000,Parcels!$D$2:$D$3000,$B17) -> 0 | I17: =SUMIFS(Parcels!$AP$2:$AP$3000,Parcels!$D$2:$D$3000,$B17) -> 190 | J17: =SUMIFS(Parcels!$AQ$2:$AQ$3000,Parcels!$D$2:$D$3000,$B17) -> 199 | K17: =SUMIFS(Parcels!$AS$2:$AS$3000,Parcels!$D$2:$D$3000,$B17) -> 190 | L17: =SUMIFS(Parcels!$AT$2:$AT$3000,Parcels!$D$2:$D$3000,$B17) -> 0 | M17: =SUMIFS(Parcels!$AU$2:$AU$3000,Parcels!$D$2:$D$3000,$B17) -> 0 | N17: =SUMIFS(Parcels!$AV$2:$AV$3000,Parcels!$D$2:$D$3000,$B17) -> 0 | O17: =SUMIFS(Parcels!$AW$2:$AW$3000,Parcels!$D$2:$D$3000,$B17) -> 0 | P17: =SUMIFS(Parcels!$AX$2:$AX$3000,Parcels!$D$2:$D$3000,$B17) -> 0 | Q17: =SUMIFS(Parcels!$AY$2:$AY$3000,Parcels!$D$2:$D$3000,$B17) -> 0
A18: Key town | B18: Castleconnell | C18: =COUNTIFS(Parcels!$D$2:$D$3000,$B18) -> 13 | D18: =SUMIFS(Parcels!$P$2:$P$3000,Parcels!$D$2:$D$3000,$B18) -> 20.846 | E18: =SUMIFS(Parcels!$AM$2:$AM$3000,Parcels!$D$2:$D$3000,$B18) -> 156 | F18: =SUMIFS(Parcels!$AI$2:$AI$3000,Parcels!$D$2:$D$3000,$B18) -> 68 | G18: =SUMIFS(Parcels!$AJ$2:$AJ$3000,Parcels!$D$2:$D$3000,$B18) -> 74 | H18: =SUMIFS(Parcels!$AK$2:$AK$3000,Parcels!$D$2:$D$3000,$B18) -> 14 | I18: =SUMIFS(Parcels!$AP$2:$AP$3000,Parcels!$D$2:$D$3000,$B18) -> 208 | J18: =SUMIFS(Parcels!$AQ$2:$AQ$3000,Parcels!$D$2:$D$3000,$B18) -> 364 | K18: =SUMIFS(Parcels!$AS$2:$AS$3000,Parcels!$D$2:$D$3000,$B18) -> 296 | L18: =SUMIFS(Parcels!$AT$2:$AT$3000,Parcels!$D$2:$D$3000,$B18) -> 17.2 | M18: =SUMIFS(Parcels!$AU$2:$AU$3000,Parcels!$D$2:$D$3000,$B18) -> 56.8 | N18: =SUMIFS(Parcels!$AV$2:$AV$3000,Parcels!$D$2:$D$3000,$B18) -> 8.2 | O18: =SUMIFS(Parcels!$AW$2:$AW$3000,Parcels!$D$2:$D$3000,$B18) -> 5.8 | P18: =SUMIFS(Parcels!$AX$2:$AX$3000,Parcels!$D$2:$D$3000,$B18) -> 0 | Q18: =SUMIFS(Parcels!$AY$2:$AY$3000,Parcels!$D$2:$D$3000,$B18) -> 0
A19: Key town | B19: Kilmallock | C19: =COUNTIFS(Parcels!$D$2:$D$3000,$B19) -> 12 | D19: =SUMIFS(Parcels!$P$2:$P$3000,Parcels!$D$2:$D$3000,$B19) -> 18.914 | E19: =SUMIFS(Parcels!$AM$2:$AM$3000,Parcels!$D$2:$D$3000,$B19) -> 75 | F19: =SUMIFS(Parcels!$AI$2:$AI$3000,Parcels!$D$2:$D$3000,$B19) -> 5 | G19: =SUMIFS(Parcels!$AJ$2:$AJ$3000,Parcels!$D$2:$D$3000,$B19) -> 70 | H19: =SUMIFS(Parcels!$AK$2:$AK$3000,Parcels!$D$2:$D$3000,$B19) -> 0 | I19: =SUMIFS(Parcels!$AP$2:$AP$3000,Parcels!$D$2:$D$3000,$B19) -> 355 | J19: =SUMIFS(Parcels!$AQ$2:$AQ$3000,Parcels!$D$2:$D$3000,$B19) -> 430 | K19: =SUMIFS(Parcels!$AS$2:$AS$3000,Parcels!$D$2:$D$3000,$B19) -> 425 | L19: =SUMIFS(Parcels!$AT$2:$AT$3000,Parcels!$D$2:$D$3000,$B19) -> 1.2 | M19: =SUMIFS(Parcels!$AU$2:$AU$3000,Parcels!$D$2:$D$3000,$B19) -> 58.8 | N19: =SUMIFS(Parcels!$AV$2:$AV$3000,Parcels!$D$2:$D$3000,$B19) -> 10 | O19: =SUMIFS(Parcels!$AW$2:$AW$3000,Parcels!$D$2:$D$3000,$B19) -> 0 | P19: =SUMIFS(Parcels!$AX$2:$AX$3000,Parcels!$D$2:$D$3000,$B19) -> 0 | Q19: =SUMIFS(Parcels!$AY$2:$AY$3000,Parcels!$D$2:$D$3000,$B19) -> 0
A20: Key town | B20: Newcastle West | C20: =COUNTIFS(Parcels!$D$2:$D$3000,$B20) -> 27 | D20: =SUMIFS(Parcels!$P$2:$P$3000,Parcels!$D$2:$D$3000,$B20) -> 58.216 | E20: =SUMIFS(Parcels!$AM$2:$AM$3000,Parcels!$D$2:$D$3000,$B20) -> 280 | F20: =SUMIFS(Parcels!$AI$2:$AI$3000,Parcels!$D$2:$D$3000,$B20) -> 6 | G20: =SUMIFS(Parcels!$AJ$2:$AJ$3000,Parcels!$D$2:$D$3000,$B20) -> 166 | H20: =SUMIFS(Parcels!$AK$2:$AK$3000,Parcels!$D$2:$D$3000,$B20) -> 55 | I20: =SUMIFS(Parcels!$AP$2:$AP$3000,Parcels!$D$2:$D$3000,$B20) -> 1209 | J20: =SUMIFS(Parcels!$AQ$2:$AQ$3000,Parcels!$D$2:$D$3000,$B20) -> 1489 | K20: =SUMIFS(Parcels!$AS$2:$AS$3000,Parcels!$D$2:$D$3000,$B20) -> 1453 | L20: =SUMIFS(Parcels!$AT$2:$AT$3000,Parcels!$D$2:$D$3000,$B20) -> 38.7 | M20: =SUMIFS(Parcels!$AU$2:$AU$3000,Parcels!$D$2:$D$3000,$B20) -> 127.3 | N20: =SUMIFS(Parcels!$AV$2:$AV$3000,Parcels!$D$2:$D$3000,$B20) -> 40.2 | O20: =SUMIFS(Parcels!$AW$2:$AW$3000,Parcels!$D$2:$D$3000,$B20) -> 14.8 | P20: =SUMIFS(Parcels!$AX$2:$AX$3000,Parcels!$D$2:$D$3000,$B20) -> 0 | Q20: =SUMIFS(Parcels!$AY$2:$AY$3000,Parcels!$D$2:$D$3000,$B20) -> 0
A21: Key town | B21: Rathkeale | C21: =COUNTIFS(Parcels!$D$2:$D$3000,$B21) -> 11 | D21: =SUMIFS(Parcels!$P$2:$P$3000,Parcels!$D$2:$D$3000,$B21) -> 8.243 | E21: =SUMIFS(Parcels!$AM$2:$AM$3000,Parcels!$D$2:$D$3000,$B21) -> 11 | F21: =SUMIFS(Parcels!$AI$2:$AI$3000,Parcels!$D$2:$D$3000,$B21) -> 0 | G21: =SUMIFS(Parcels!$AJ$2:$AJ$3000,Parcels!$D$2:$D$3000,$B21) -> 11 | H21: =SUMIFS(Parcels!$AK$2:$AK$3000,Parcels!$D$2:$D$3000,$B21) -> 0 | I21: =SUMIFS(Parcels!$AP$2:$AP$3000,Parcels!$D$2:$D$3000,$B21) -> 189 | J21: =SUMIFS(Parcels!$AQ$2:$AQ$3000,Parcels!$D$2:$D$3000,$B21) -> 200 | K21: =SUMIFS(Parcels!$AS$2:$AS$3000,Parcels!$D$2:$D$3000,$B21) -> 200 | L21: =SUMIFS(Parcels!$AT$2:$AT$3000,Parcels!$D$2:$D$3000,$B21) -> 2.6 | M21: =SUMIFS(Parcels!$AU$2:$AU$3000,Parcels!$D$2:$D$3000,$B21) -> 8.4 | N21: =SUMIFS(Parcels!$AV$2:$AV$3000,Parcels!$D$2:$D$3000,$B21) -> 0 | O21: =SUMIFS(Parcels!$AW$2:$AW$3000,Parcels!$D$2:$D$3000,$B21) -> 0 | P21: =SUMIFS(Parcels!$AX$2:$AX$3000,Parcels!$D$2:$D$3000,$B21) -> 0 | Q21: =SUMIFS(Parcels!$AY$2:$AY$3000,Parcels!$D$2:$D$3000,$B21) -> 0
A22: Key town total | C22: =SUM(C16:C21) -> 80 | D22: =SUM(D16:D21) -> 125.614 | E22: =SUM(E16:E21) -> 618 | F22: =SUM(F16:F21) -> 88 | G22: =SUM(G16:G21) -> 321 | H22: =SUM(H16:H21) -> 156 | I22: =SUM(I16:I21) -> 2327 | J22: =SUM(J16:J21) -> 2945 | ... Q22: =SUM(Q16:Q21) -> 0
A24: Large village | B24: Adare | C24: =COUNTIFS(Parcels!$D$2:$D$3000,$B24) -> 13 | D24: =SUMIFS(Parcels!$P$2:$P$3000,Parcels!$D$2:$D$3000,$B24) -> 34.555 | E24: =SUMIFS(Parcels!$AM$2:$AM$3000,Parcels!$D$2:$D$3000,$B24) -> 226 | F24: =SUMIFS(Parcels!$AI$2:$AI$3000,Parcels!$D$2:$D$3000,$B24) -> 0 | G24: =SUMIFS(Parcels!$AJ$2:$AJ$3000,Parcels!$D$2:$D$3000,$B24) -> 15 | H24: =SUMIFS(Parcels!$AK$2:$AK$3000,Parcels!$D$2:$D$3000,$B24) -> 211 | I24: =SUMIFS(Parcels!$AP$2:$AP$3000,Parcels!$D$2:$D$3000,$B24) -> 191 | J24: =SUMIFS(Parcels!$AQ$2:$AQ$3000,Parcels!$D$2:$D$3000,$B24) -> 417 | K24: =SUMIFS(Parcels!$AS$2:$AS$3000,Parcels!$D$2:$D$3000,$B24) -> 415 | L24: =SUMIFS(Parcels!$AT$2:$AT$3000,Parcels!$D$2:$D$3000,$B24) -> 1.2 | M24: =SUMIFS(Parcels!$AU$2:$AU$3000,Parcels!$D$2:$D$3000,$B24) -> 10.7 | N24: =SUMIFS(Parcels!$AV$2:$AV$3000,Parcels!$D$2:$D$3000,$B24) -> 92.1 | O24: =SUMIFS(Parcels!$AW$2:$AW$3000,Parcels!$D$2:$D$3000,$B24) -> 99.8 | P24: =SUMIFS(Parcels!$AX$2:$AX$3000,Parcels!$D$2:$D$3000,$B24) -> 22.2 | Q24: =SUMIFS(Parcels!$AY$2:$AY$3000,Parcels!$D$2:$D$3000,$B24) -> 0
A25: Large village | B25: Bruff | C25: =COUNTIFS(Parcels!$D$2:$D$3000,$B25) -> 8 | D25: =SUMIFS(Parcels!$P$2:$P$3000,Parcels!$D$2:$D$3000,$B25) -> 6.843 | E25: =SUMIFS(Parcels!$AM$2:$AM$3000,Parcels!$D$2:$D$3000,$B25) -> 102 | F25: =SUMIFS(Parcels!$AI$2:$AI$3000,Parcels!$D$2:$D$3000,$B25) -> 2 | G25: =SUMIFS(Parcels!$AJ$2:$AJ$3000,Parcels!$D$2:$D$3000,$B25) -> 18 | H25: =SUMIFS(Parcels!$AK$2:$AK$3000,Parcels!$D$2:$D$3000,$B25) -> 82 | I25: =SUMIFS(Parcels!$AP$2:$AP$3000,Parcels!$D$2:$D$3000,$B25) -> 41 | J25: =SUMIFS(Parcels!$AQ$2:$AQ$3000,Parcels!$D$2:$D$3000,$B25) -> 143 | K25: =SUMIFS(Parcels!$AS$2:$AS$3000,Parcels!$D$2:$D$3000,$B25) -> 141 | L25: =SUMIFS(Parcels!$AT$2:$AT$3000,Parcels!$D$2:$D$3000,$B25) -> 0 | M25: =SUMIFS(Parcels!$AU$2:$AU$3000,Parcels!$D$2:$D$3000,$B25) -> 10.2 | N25: =SUMIFS(Parcels!$AV$2:$AV$3000,Parcels!$D$2:$D$3000,$B25) -> 36.7 | O25: =SUMIFS(Parcels!$AW$2:$AW$3000,Parcels!$D$2:$D$3000,$B25) -> 53.1 | P25: =SUMIFS(Parcels!$AX$2:$AX$3000,Parcels!$D$2:$D$3000,$B25) -> 0 | Q25: =SUMIFS(Parcels!$AY$2:$AY$3000,Parcels!$D$2:$D$3000,$B25) -> 0
A26: Large village | B26: Cappamore | C26: =COUNTIFS(Parcels!$D$2:$D$3000,$B26) -> 7 | D26: =SUMIFS(Parcels!$P$2:$P$3000,Parcels!$D$2:$D$3000,$B26) -> 3.724 | E26: =SUMIFS(Parcels!$AM$2:$AM$3000,Parcels!$D$2:$D$3000,$B26) -> 56 | F26: =SUMIFS(Parcels!$AI$2:$AI$3000,Parcels!$D$2:$D$3000,$B26) -> 27 | G26: =SUMIFS(Parcels!$AJ$2:$AJ$3000,Parcels!$D$2:$D$3000,$B26) -> 22 | H26: =SUMIFS(Parcels!$AK$2:$AK$3000,Parcels!$D$2:$D$3000,$B26) -> 7 | I26: =SUMIFS(Parcels!$AP$2:$AP$3000,Parcels!$D$2:$D$3000,$B26) -> 20 | J26: =SUMIFS(Parcels!$AQ$2:$AQ$3000,Parcels!$D$2:$D$3000,$B26) -> 76 | K26: =SUMIFS(Parcels!$AS$2:$AS$3000,Parcels!$D$2:$D$3000,$B26) -> 49 | L26: =SUMIFS(Parcels!$AT$2:$AT$3000,Parcels!$D$2:$D$3000,$B26) -> 3.1 | M26: =SUMIFS(Parcels!$AU$2:$AU$3000,Parcels!$D$2:$D$3000,$B26) -> 13.5 | N26: =SUMIFS(Parcels!$AV$2:$AV$3000,Parcels!$D$2:$D$3000,$B26) -> 9.8 | O26: =SUMIFS(Parcels!$AW$2:$AW$3000,Parcels!$D$2:$D$3000,$B26) -> 2.6 | P26: =SUMIFS(Parcels!$AX$2:$AX$3000,Parcels!$D$2:$D$3000,$B26) -> 0 | Q26: =SUMIFS(Parcels!$AY$2:$AY$3000,Parcels!$D$2:$D$3000,$B26) -> 0
A27: Large village | B27: Croom | C27: =COUNTIFS(Parcels!$D$2:$D$3000,$B27) -> 13 | D27: =SUMIFS(Parcels!$P$2:$P$3000,Parcels!$D$2:$D$3000,$B27) -> 13.627 | E27: =SUMIFS(Parcels!$AM$2:$AM$3000,Parcels!$D$2:$D$3000,$B27) -> 137 | F27: =SUMIFS(Parcels!$AI$2:$AI$3000,Parcels!$D$2:$D$3000,$B27) -> 16 | G27: =SUMIFS(Parcels!$AJ$2:$AJ$3000,Parcels!$D$2:$D$3000,$B27) -> 0 | H27: =SUMIFS(Parcels!$AK$2:$AK$3000,Parcels!$D$2:$D$3000,$B27) -> 121 | I27: =SUMIFS(Parcels!$AP$2:$AP$3000,Parcels!$D$2:$D$3000,$B27) -> 192 | J27: =SUMIFS(Parcels!$AQ$2:$AQ$3000,Parcels!$D$2:$D$3000,$B27) -> 329 | K27: =SUMIFS(Parcels!$AS$2:$AS$3000,Parcels!$D$2:$D$3000,$B27) -> 313 | L27: =SUMIFS(Parcels!$AT$2:$AT$3000,Parcels!$D$2:$D$3000,$B27) -> 0 | M27: =SUMIFS(Parcels!$AU$2:$AU$3000,Parcels!$D$2:$D$3000,$B27) -> 0 | N27: =SUMIFS(Parcels!$AV$2:$AV$3000,Parcels!$D$2:$D$3000,$B27) -> 85.7 | O27: =SUMIFS(Parcels!$AW$2:$AW$3000,Parcels!$D$2:$D$3000,$B27) -> 35.3 | P27: =SUMIFS(Parcels!$AX$2:$AX$3000,Parcels!$D$2:$D$3000,$B27) -> 0 | Q27: =SUMIFS(Parcels!$AY$2:$AY$3000,Parcels!$D$2:$D$3000,$B27) -> 0
A28: Large village | B28: Hospital | C28: =COUNTIFS(Parcels!$D$2:$D$3000,$B28) -> 6 | D28: =SUMIFS(Parcels!$P$2:$P$3000,Parcels!$D$2:$D$3000,$B28) -> 7.019 | E28: =SUMIFS(Parcels!$AM$2:$AM$3000,Parcels!$D$2:$D$3000,$B28) -> 20 | F28: =SUMIFS(Parcels!$AI$2:$AI$3000,Parcels!$D$2:$D$3000,$B28) -> 20 | G28: =SUMIFS(Parcels!$AJ$2:$AJ$3000,Parcels!$D$2:$D$3000,$B28) -> 0 | H28: =SUMIFS(Parcels!$AK$2:$AK$3000,Parcels!$D$2:$D$3000,$B28) -> 0 | I28: =SUMIFS(Parcels!$AP$2:$AP$3000,Parcels!$D$2:$D$3000,$B28) -> 128 | J28: =SUMIFS(Parcels!$AQ$2:$AQ$3000,Parcels!$D$2:$D$3000,$B28) -> 148 | K28: =SUMIFS(Parcels!$AS$2:$AS$3000,Parcels!$D$2:$D$3000,$B28) -> 128 | L28: =SUMIFS(Parcels!$AT$2:$AT$3000,Parcels!$D$2:$D$3000,$B28) -> 0 | M28: =SUMIFS(Parcels!$AU$2:$AU$3000,Parcels!$D$2:$D$3000,$B28) -> 0 | N28: =SUMIFS(Parcels!$AV$2:$AV$3000,Parcels!$D$2:$D$3000,$B28) -> 0 | O28: =SUMIFS(Parcels!$AW$2:$AW$3000,Parcels!$D$2:$D$3000,$B28) -> 0 | P28: =SUMIFS(Parcels!$AX$2:$AX$3000,Parcels!$D$2:$D$3000,$B28) -> 0 | Q28: =SUMIFS(Parcels!$AY$2:$AY$3000,Parcels!$D$2:$D$3000,$B28) -> 0
A29: Large village | B29: Kilfinnane | C29: =COUNTIFS(Parcels!$D$2:$D$3000,$B29) -> 8 | D29: =SUMIFS(Parcels!$P$2:$P$3000,Parcels!$D$2:$D$3000,$B29) -> 4.521 | E29: =SUMIFS(Parcels!$AM$2:$AM$3000,Parcels!$D$2:$D$3000,$B29) -> 33 | F29: =SUMIFS(Parcels!$AI$2:$AI$3000,Parcels!$D$2:$D$3000,$B29) -> 19 | G29: =SUMIFS(Parcels!$AJ$2:$AJ$3000,Parcels!$D$2:$D$3000,$B29) -> 14 | H29: =SUMIFS(Parcels!$AK$2:$AK$3000,Parcels!$D$2:$D$3000,$B29) -> 0 | I29: =SUMIFS(Parcels!$AP$2:$AP$3000,Parcels!$D$2:$D$3000,$B29) -> 58 | J29: =SUMIFS(Parcels!$AQ$2:$AQ$3000,Parcels!$D$2:$D$3000,$B29) -> 91 | K29: =SUMIFS(Parcels!$AS$2:$AS$3000,Parcels!$D$2:$D$3000,$B29) -> 72 | L29: =SUMIFS(Parcels!$AT$2:$AT$3000,Parcels!$D$2:$D$3000,$B29) -> 3.3 | M29: =SUMIFS(Parcels!$AU$2:$AU$3000,Parcels!$D$2:$D$3000,$B29) -> 10.7 | N29: =SUMIFS(Parcels!$AV$2:$AV$3000,Parcels!$D$2:$D$3000,$B29) -> 0 | O29: =SUMIFS(Parcels!$AW$2:$AW$3000,Parcels!$D$2:$D$3000,$B29) -> 0 | P29: =SUMIFS(Parcels!$AX$2:$AX$3000,Parcels!$D$2:$D$3000,$B29) -> 0 | Q29: =SUMIFS(Parcels!$AY$2:$AY$3000,Parcels!$D$2:$D$3000,$B29) -> 0
A30: Large village | B30: Moroe | C30: =COUNTIFS(Parcels!$D$2:$D$3000,$B30) -> 5 | D30: =SUMIFS(Parcels!$P$2:$P$3000,Parcels!$D$2:$D$3000,$B30) -> 6.409 | E30: =SUMIFS(Parcels!$AM$2:$AM$3000,Parcels!$D$2:$D$3000,$B30) -> 36 | F30: =SUMIFS(Parcels!$AI$2:$AI$3000,Parcels!$D$2:$D$3000,$B30) -> 0 | G30: =SUMIFS(Parcels!$AJ$2:$AJ$3000,Parcels!$D$2:$D$3000,$B30) -> 4 | H30: =SUMIFS(Parcels!$AK$2:$AK$3000,Parcels!$D$2:$D$3000,$B30) -> 0 | I30: =SUMIFS(Parcels!$AP$2:$AP$3000,Parcels!$D$2:$D$3000,$B30) -> 81 | J30: =SUMIFS(Parcels!$AQ$2:$AQ$3000,Parcels!$D$2:$D$3000,$B30) -> 117 | K30: =SUMIFS(Parcels!$AS$2:$AS$3000,Parcels!$D$2:$D$3000,$B30) -> 117 | L30: =SUMIFS(Parcels!$AT$2:$AT$3000,Parcels!$D$2:$D$3000,$B30) -> 0 | M30: =SUMIFS(Parcels!$AU$2:$AU$3000,Parcels!$D$2:$D$3000,$B30) -> 3.7 | N30: =SUMIFS(Parcels!$AV$2:$AV$3000,Parcels!$D$2:$D$3000,$B30) -> 0.3 | O30: =SUMIFS(Parcels!$AW$2:$AW$3000,Parcels!$D$2:$D$3000,$B30) -> 0 | P30: =SUMIFS(Parcels!$AX$2:$AX$3000,Parcels!$D$2:$D$3000,$B30) -> 0 | Q30: =SUMIFS(Parcels!$AY$2:$AY$3000,Parcels!$D$2:$D$3000,$B30) -> 0
A31: Large village | B31: Patrickswell | C31: =COUNTIFS(Parcels!$D$2:$D$3000,$B31) -> 20 | D31: =SUMIFS(Parcels!$P$2:$P$3000,Parcels!$D$2:$D$3000,$B31) -> 27.786 | E31: =SUMIFS(Parcels!$AM$2:$AM$3000,Parcels!$D$2:$D$3000,$B31) -> 510 | F31: =SUMIFS(Parcels!$AI$2:$AI$3000,Parcels!$D$2:$D$3000,$B31) -> 79 | G31: =SUMIFS(Parcels!$AJ$2:$AJ$3000,Parcels!$D$2:$D$3000,$B31) -> 257 | H31: =SUMIFS(Parcels!$AK$2:$AK$3000,Parcels!$D$2:$D$3000,$B31) -> 134 | I31: =SUMIFS(Parcels!$AP$2:$AP$3000,Parcels!$D$2:$D$3000,$B31) -> 78 | J31: =SUMIFS(Parcels!$AQ$2:$AQ$3000,Parcels!$D$2:$D$3000,$B31) -> 588 | K31: =SUMIFS(Parcels!$AS$2:$AS$3000,Parcels!$D$2:$D$3000,$B31) -> 485 | L31: =SUMIFS(Parcels!$AT$2:$AT$3000,Parcels!$D$2:$D$3000,$B31) -> 36.1 | M31: =SUMIFS(Parcels!$AU$2:$AU$3000,Parcels!$D$2:$D$3000,$B31) -> 149 | N31: =SUMIFS(Parcels!$AV$2:$AV$3000,Parcels!$D$2:$D$3000,$B31) -> 133.4 | O31: =SUMIFS(Parcels!$AW$2:$AW$3000,Parcels!$D$2:$D$3000,$B31) -> 67.5 | P31: =SUMIFS(Parcels!$AX$2:$AX$3000,Parcels!$D$2:$D$3000,$B31) -> 5 | Q31: =SUMIFS(Parcels!$AY$2:$AY$3000,Parcels!$D$2:$D$3000,$B31) -> 0
A32: Large village total | C32: =SUM(C24:C31) -> 80 | D32: =SUM(D24:D31) -> 104.484 | E32: =SUM(E24:E31) -> 1120 | F32: =SUM(F24:F31) -> 163 | G32: =SUM(G24:G31) -> 330 | H32: =SUM(H24:H31) -> 555 | I32: =SUM(I24:I31) -> 789 | J32: =SUM(J24:J31) -> 1909 | ... Q32: =SUM(Q24:Q31) -> 0
A34: Rest of county | B34: Rest of county | C34: =COUNTIFS(Parcels!$D$2:$D$3000,$B34) -> 46 | D34: =SUMIFS(Parcels!$P$2:$P$3000,Parcels!$D$2:$D$3000,$B34) -> 42.26 | E34: =SUMIFS(Parcels!$AM$2:$AM$3000,Parcels!$D$2:$D$3000,$B34) -> 213 | F34: =SUMIFS(Parcels!$AI$2:$AI$3000,Parcels!$D$2:$D$3000,$B34) -> 44 | G34: =SUMIFS(Parcels!$AJ$2:$AJ$3000,Parcels!$D$2:$D$3000,$B34) -> 106 | H34: =SUMIFS(Parcels!$AK$2:$AK$3000,Parcels!$D$2:$D$3000,$B34) -> 63 | I34: =SUMIFS(Parcels!$AP$2:$AP$3000,Parcels!$D$2:$D$3000,$B34) -> 416 | J34: =SUMIFS(Parcels!$AQ$2:$AQ$3000,Parcels!$D$2:$D$3000,$B34) -> 629 | K34: =SUMIFS(Parcels!$AS$2:$AS$3000,Parcels!$D$2:$D$3000,$B34) -> 582 | L34: =SUMIFS(Parcels!$AT$2:$AT$3000,Parcels!$D$2:$D$3000,$B34) -> 24.1 | M34: =SUMIFS(Parcels!$AU$2:$AU$3000,Parcels!$D$2:$D$3000,$B34) -> 81.9 | N34: =SUMIFS(Parcels!$AV$2:$AV$3000,Parcels!$D$2:$D$3000,$B34) -> 38.3 | O34: =SUMIFS(Parcels!$AW$2:$AW$3000,Parcels!$D$2:$D$3000,$B34) -> 24.7 | P34: =SUMIFS(Parcels!$AX$2:$AX$3000,Parcels!$D$2:$D$3000,$B34) -> 0 | Q34: =SUMIFS(Parcels!$AY$2:$AY$3000,Parcels!$D$2:$D$3000,$B34) -> 0
A35: Rest of county total | C35: =SUM(C34:C34) -> 46 | D35: =SUM(D34:D34) -> 42.26 | E35: =SUM(E34:E34) -> 213 | F35: =SUM(F34:F34) -> 44 | G35: =SUM(G34:G34) -> 106 | H35: =SUM(H34:H34) -> 63 | I35: =SUM(I34:I34) -> 416 | J35: =SUM(J34:J34) -> 629 | ... Q35: =SUM(Q34:Q34) -> 0

Sheet How to update
A1: The rule | B1: One permission, one parcel. Units live only on the Permissions sheet. Parcel totals add them up, so a home cannot be counted twice. Parcels do not overlap.
A2: New permission on an existing parcel | B2: Add a row to Permissions with a new perm_id, pick the parcel_id from the list, enter units and status, counts_toward_totals = Yes. The parcel totals update.
A3: New permission on new land | B3: Draw a parcel in the GeoPackage from the planning boundary (clip out any existing parcel), id PC-<planning ref without slashes>, parcel_source = Planning consent – not in council audit. Add the same parcel row here, then the permission row.
A4: Amendment, repeat or extension of duration | B4: Add the row with counts_toward_totals = No unless it replaces the counted permission. If it replaces it (e.g. a new scheme on the same land), set the old row to No and the new row to Yes.
A5: Status changes | B5: Change status on the Permissions row (Permitted – not started → Under construction → Complete). Use building control commencement and completion notices as the source; note it in notes and update last_updated.
A6: Expired permissions | B6: Set status to Expired – not started. The units drop out of consented supply; on an audit parcel the council capacity becomes unconsented capacity again.
A7: Capacity | B7: Audit parcels: council estimate. Zoned-land parcels: zoned area x developable share x density (see density_basis). If a permission shows the capacity was wrong, update capacity_units and say why in notes. Consent parcels have no capacity figure: their supply is the consented units.
A8: Zoned land (interim) | B8: Zoned-land parcels are estimates from new residential zoning not in any other parcel and not built on. When a permission is granted on one, draw the consent parcel and cut it out of the zoned parcel. When the county audit arrives, replace them.
A9: County audit | B9: Add county audit parcels with parcel_source = Council audit – county and scope = County. Move county permissions onto them by changing parcel_id, then retire any consent parcel left empty (flag: Consent parcel with no permission).
A10: GeoDirectory | B10: Each quarter, rerun the build with the new GeoDirectory extract. A scheme whose new built addresses reach 95% of its units moves to Complete (status_source says so); other differences are listed on the GeoDirectory checks sheet for a person to confirm.
A11: Retiring a parcel | B11: Do not delete. parcel_status turns to Finished when every counted home is complete and no council capacity is left; filter Finished parcels off the map. Their homes stay in the delivery record.
A12: Checks | B12: Summary sheet checks must all be zero before figures are reported. Red cells on Permissions (check column) and Parcels (flag) show what to fix.

Sheet Parcels
A1: parcel_id | B1: parcel_source | C1: scope | D1: catchment | E1: catchment_type | F1: catchment_share | G1: catchment_basis | H1: rsca | I1: neighbourhood | J1: lea | K1: local_name | L1: landowner | M1: zoning | N1: site_type | O1: density_band | P1: developable_area_ha | Q1: mapped_area_ha | R1: capacity_units | S1: capacity_basis | T1: density_estimate_units | U1: plan_name | V1: zone_gzt | W1: phase | X1: density_tier | Y1: density_dph | Z1: density_basis | AA1: rzlt_2027_share | AB1: geod_addresses_now | AC1: geod_new_since_2019 | AD1: register_status | AE1: notes | AF1: last_reviewed | AG1: reviewed_by | AH1: capacity_used | AI1: complete_units | AJ1: under_construction_units | AK1: permitted_not_started_units | AL1: stalled_units | AM1: consented_units | AN1: expired_units | AO1: in_planning_units | AP1: unconsented_capacity | AQ1: total_supply_units | AR1: built_units | AS1: future_supply_units | AT1: est_q4_2026 | AU1: est_2027 | AV1: est_2028 | AW1: est_2029 | AX1: est_2030 | AY1: est_2031_plus | AZ1: permissions | BA1: geod_new_built | BB1: geod_new_vacant | BC1: parcel_status | BD1: flag
A2: CITY-129 | B2: Council audit | C2: City | D2: Ballinacurra | E2: City neighbourhood | F2: 1 | G2: Inside catchment | H2: 129 | I2: Ballinacurra | J2: LIMERICK CITY WEST LEA-7 | K2: City Centre | L2: Council | M2: New Resi | N2: Brownfield | O2: 45+ | P2: 2.208 | Q2: 2.208 | R2: 99 | S2: Council estimate (area × density band) | T2: 75 | X2: City suburbs | Y2: 34 | Z2: 34 homes/ha = median of 39 permitted Limerick schemes of 10+ homes in city suburbs; applied to developable for density_estimate_units only | AB2: 0 | AC2: 0 | AD2: Undeveloped/Permission Sought | AE2: Unchanged | AF2: 2026-10-11 | AH2: =IF(R2="",AM2,R2) -> 99 | AI2: =SUMIFS(Permissions!$G$2:$G$3000,Permissions!$B$2:$B$3000,$A2,Permissions!$I$2:$I$3000,"Complete",Permissions!$R$2:$R$3000,"Yes") -> 0 | AJ2: =SUMIFS(Permissions!$G$2:$G$3000,Permissions!$B$2:$B$3000,$A2,Permissions!$I$2:$I$3000,"Under construction",Permissions!$R$2:$R$3000,"Yes") -> 0 | AK2: =SUMIFS(Permissions!$G$2:$G$3000,Permissions!$B$2:$B$3000,$A2,Permissions!$I$2:$I$3000,"Permitted – not started",Permissions!$R$2:$R$3000,"Yes") -> 0 | AL2: =SUMIFS(Permissions!$G$2:$G$3000,Permissions!$B$2:$B$3000,$A2,Permissions!$I$2:$I$3000,"Stalled",Permissions!$R$2:$R$3000,"Yes") -> 0 | AM2: =AI2+AJ2+AK2+AL2 -> 0 | AN2: =SUMIFS(Permissions!$G$2:$G$3000,Permissions!$B$2:$B$3000,$A2,Permissions!$I$2:$I$3000,"Expired – not started",Permissions!$R$2:$R$3000,"Yes") -> 0 | AO2: =SUMIFS(Permissions!$G$2:$G$3000,Permissions!$B$2:$B$3000,$A2,Permissions!$I$2:$I$3000,"In planning",Permissions!$R$2:$R$3000,"Yes") -> 0 | AP2: =IF(R2="",0,MAX(R2-AM2,0)) -> 99 | AQ2: =AM2+AP2 -> 99 | AR2: =SUMIFS(Permissions!$L$2:$L$3000,Permissions!$B$2:$B$3000,$A2,Permissions!$R$2:$R$3000,"Yes",Permissions!$I$2:$I$3000,"<>Expired – not started",Permissions!$I$2:$I$3000,"<>In planning") -> 0 | AS2: =AQ2-AR2 -> 99 | AT2: =SUMIFS(Permissions!$AJ$2:$AJ$3000,Permissions!$B$2:$B$3000,$A2,Permissions!$R$2:$R$3000,"Yes") -> 0 | AU2: =SUMIFS(Permissions!$AK$2:$AK$3000,Permissions!$B$2:$B$3000,$A2,Permissions!$R$2:$R$3000,"Yes") -> 0 | AV2: =SUMIFS(Permissions!$AL$2:$AL$3000,Permissions!$B$2:$B$3000,$A2,Permissions!$R$2:$R$3000,"Yes") -> 0 | AW2: =SUMIFS(Permissions!$AM$2:$AM$3000,Permissions!$B$2:$B$3000,$A2,Permissions!$R$2:$R$3000,"Yes") -> 0 | AX2: =SUMIFS(Permissions!$AN$2:$AN$3000,Permissions!$B$2:$B$3000,$A2,Permissions!$R$2:$R$3000,"Yes") -> 0 | AY2: =SUMIFS(Permissions!$AO$2:$AO$3000,Permissions!$B$2:$B$3000,$A2,Permissions!$R$2:$R$3000,"Yes") -> 0 | AZ2: =COUNTIFS(Permissions!$B$2:$B$3000,$A2,Permissions!$R$2:$R$3000,"Yes") -> 0 | BA2: =SUMIFS(Permissions!$M$2:$M$3000,Permissions!$B$2:$B$3000,$A2,Permissions!$R$2:$R$3000,"Yes") -> 0 | BB2: =SUMIFS(Permissions!$O$2:$O$3000,Permissions!$B$2:$B$3000,$A2,Permissions!$R$2:$R$3000,"Yes") -> 0 | BC2: =IF(AND(AM2>0,AR2>=AM2,AP2=0),"Finished",IF(AR2>0,"Partly built",IF(AM2>0,"Consented – not built","No consent"))) -> No consent | BD2: =IF(AND(R2<>"",AM2>1.1*R2),"Consented above capacity",IF(AND(LEFT(B2,8)="Planning",AZ2=0),"Consent parcel with no permission",IF(COUNTIF($A$2:$A$3000,$A2)>1,"Duplicate parcel_id","")))
A3: CITY-130 | B3: Council audit | C3: City | D3: Ballinacurra | E3: City neighbourhood | F3: 1 | G3: Inside catchment | H3: 130 | I3: Ballinacurra | J3: LIMERICK CITY WEST LEA-7 | K3: City Centre | L3: Council | M3: Exist Resi | N3: Infill | O3: 45+ | P3: 0.144 | Q3: 0.144 | R3: 6 | S3: Council estimate (area × density band) | T3: 5 | X3: City suburbs | Y3: 34 | Z3: 34 homes/ha = median of 39 permitted Limerick schemes of 10+ homes in city suburbs; applied to developable for density_estimate_units only | AB3: 0 | AC3: 0 | AD3: Undeveloped/Permission Sought | AE3: Unchanged | AF3: 2026-10-11 | AH3: =IF(R3="",AM3,R3) -> 6 | AI3: =SUMIFS(Permissions!$G$2:$G$3000,Permissions!$B$2:$B$3000,$A3,Permissions!$I$2:$I$3000,"Complete",Permissions!$R$2:$R$3000,"Yes") -> 0 | AJ3: =SUMIFS(Permissions!$G$2:$G$3000,Permissions!$B$2:$B$3000,$A3,Permissions!$I$2:$I$3000,"Under construction",Permissions!$R$2:$R$3000,"Yes") -> 0 | AK3: =SUMIFS(Permissions!$G$2:$G$3000,Permissions!$B$2:$B$3000,$A3,Permissions!$I$2:$I$3000,"Permitted – not started",Permissions!$R$2:$R$3000,"Yes") -> 0 | AL3: =SUMIFS(Permissions!$G$2:$G$3000,Permissions!$B$2:$B$3000,$A3,Permissions!$I$2:$I$3000,"Stalled",Permissions!$R$2:$R$3000,"Yes") -> 0 | AM3: =AI3+AJ3+AK3+AL3 -> 0 | AN3: =SUMIFS(Permissions!$G$2:$G$3000,Permissions!$B$2:$B$3000,$A3,Permissions!$I$2:$I$3000,"Expired – not started",Permissions!$R$2:$R$3000,"Yes") -> 0 | AO3: =SUMIFS(Permissions!$G$2:$G$3000,Permissions!$B$2:$B$3000,$A3,Permissions!$I$2:$I$3000,"In planning",Permissions!$R$2:$R$3000,"Yes") -> 0 | AP3: =IF(R3="",0,MAX(R3-AM3,0)) -> 6 | AQ3: =AM3+AP3 -> 6 | AR3: =SUMIFS(Permissions!$L$2:$L$3000,Permissions!$B$2:$B$3000,$A3,Permissions!$R$2:$R$3000,"Yes",Permissions!$I$2:$I$3000,"<>Expired – not started",Permissions!$I$2:$I$3000,"<>In planning") -> 0 | AS3: =AQ3-AR3 -> 6 | AT3: =SUMIFS(Permissions!$AJ$2:$AJ$3000,Permissions!$B$2:$B$3000,$A3,Permissions!$R$2:$R$3000,"Yes") -> 0 | AU3: =SUMIFS(Permissions!$AK$2:$AK$3000,Permissions!$B$2:$B$3000,$A3,Permissions!$R$2:$R$3000,"Yes") -> 0 | AV3: =SUMIFS(Permissions!$AL$2:$AL$3000,Permissions!$B$2:$B$3000,$A3,Permissions!$R$2:$R$3000,"Yes") -> 0 | AW3: =SUMIFS(Permissions!$AM$2:$AM$3000,Permissions!$B$2:$B$3000,$A3,Permissions!$R$2:$R$3000,"Yes") -> 0 | AX3: =SUMIFS(Permissions!$AN$2:$AN$3000,Permissions!$B$2:$B$3000,$A3,Permissions!$R$2:$R$3000,"Yes") -> 0 | AY3: =SUMIFS(Permissions!$AO$2:$AO$3000,Permissions!$B$2:$B$3000,$A3,Permissions!$R$2:$R$3000,"Yes") -> 0 | AZ3: =COUNTIFS(Permissions!$B$2:$B$3000,$A3,Permissions!$R$2:$R$3000,"Yes") -> 0 | BA3: =SUMIFS(Permissions!$M$2:$M$3000,Permissions!$B$2:$B$3000,$A3,Permissions!$R$2:$R$3000,"Yes") -> 0 | BB3: =SUMIFS(Permissions!$O$2:$O$3000,Permissions!$B$2:$B$3000,$A3,Permissions!$R$2:$R$3000,"Yes") -> 0 | BC3: =IF(AND(AM3>0,AR3>=AM3,AP3=0),"Finished",IF(AR3>0,"Partly built",IF(AM3>0,"Consented – not built","No consent"))) -> No consent | BD3: =IF(AND(R3<>"",AM3>1.1*R3),"Consented above capacity",IF(AND(LEFT(B3,8)="Planning",AZ3=0),"Consent parcel with no permission",IF(COUNTIF($A$2:$A$3000,$A3)>1,"Duplicate parcel_id","")))
A4: CITY-131 | B4: Council audit | C4: City | D4: Ballinacurra | E4: City neighbourhood | F4: 1 | G4: Inside catchment | H4: 131 | I4: Ballinacurra | J4: LIMERICK CITY WEST LEA-7 | K4: City Centre | L4: Council | M4: New Resi | N4: Infill | O4: 45+ | P4: 0.252 | Q4: 0.252 | R4: 11 | S4: Council estimate (area × density band) | T4: 9 | X4: City suburbs | Y4: 34 | Z4: 34 homes/ha = median of 39 permitted Limerick schemes of 10+ homes in city suburbs; applied to developable for density_estimate_units only | AB4: 0 | AC4: 0 | AD4: Undeveloped/Permission Sought | AE4: Unchanged | AF4: 2026-10-11 | AH4: =IF(R4="",AM4,R4) -> 11 | AI4: =SUMIFS(Permissions!$G$2:$G$3000,Permissions!$B$2:$B$3000,$A4,Permissions!$I$2:$I$3000,"Complete",Permissions!$R$2:$R$3000,"Yes") -> 0 | AJ4: =SUMIFS(Permissions!$G$2:$G$3000,Permissions!$B$2:$B$3000,$A4,Permissions!$I$2:$I$3000,"Under construction",Permissions!$R$2:$R$3000,"Yes") -> 0 | AK4: =SUMIFS(Permissions!$G$2:$G$3000,Permissions!$B$2:$B$3000,$A4,Permissions!$I$2:$I$3000,"Permitted – not started",Permissions!$R$2:$R$3000,"Yes") -> 0 | AL4: =SUMIFS(Permissions!$G$2:$G$3000,Permissions!$B$2:$B$3000,$A4,Permissions!$I$2:$I$3000,"Stalled",Permissions!$R$2:$R$3000,"Yes") -> 0 | AM4: =AI4+AJ4+AK4+AL4 -> 0 | AN4: =SUMIFS(Permissions!$G$2:$G$3000,Permissions!$B$2:$B$3000,$A4,Permissions!$I$2:$I$3000,"Expired – not started",Permissions!$R$2:$R$3000,"Yes") -> 0 | AO4: =SUMIFS(Permissions!$G$2:$G$3000,Permissions!$B$2:$B$3000,$A4,Permissions!$I$2:$I$3000,"In planning",Permissions!$R$2:$R$3000,"Yes") -> 0 | AP4: =IF(R4="",0,MAX(R4-AM4,0)) -> 11 | AQ4: =AM4+AP4 -> 11 | AR4: =SUMIFS(Permissions!$L$2:$L$3000,Permissions!$B$2:$B$3000,$A4,Permissions!$R$2:$R$3000,"Yes",Permissions!$I$2:$I$3000,"<>Expired – not started",Permissions!$I$2:$I$3000,"<>In planning") -> 0 | AS4: =AQ4-AR4 -> 11 | AT4: =SUMIFS(Permissions!$AJ$2:$AJ$3000,Permissions!$B$2:$B$3000,$A4,Permissions!$R$2:$R$3000,"Yes") -> 0 | AU4: =SUMIFS(Permissions!$AK$2:$AK$3000,Permissions!$B$2:$B$3000,$A4,Permissions!$R$2:$R$3000,"Yes") -> 0 | AV4: =SUMIFS(Permissions!$AL$2:$AL$3000,Permissions!$B$2:$B$3000,$A4,Permissions!$R$2:$R$3000,"Yes") -> 0 | AW4: =SUMIFS(Permissions!$AM$2:$AM$3000,Permissions!$B$2:$B$3000,$A4,Permissions!$R$2:$R$3000,"Yes") -> 0 | AX4: =SUMIFS(Permissions!$AN$2:$AN$3000,Permissions!$B$2:$B$3000,$A4,Permissions!$R$2:$R$3000,"Yes") -> 0 | AY4: =SUMIFS(Permissions!$AO$2:$AO$3000,Permissions!$B$2:$B$3000,$A4,Permissions!$R$2:$R$3000,"Yes") -> 0 | AZ4: =COUNTIFS(Permissions!$B$2:$B$3000,$A4,Permissions!$R$2:$R$3000,"Yes") -> 0 | BA4: =SUMIFS(Permissions!$M$2:$M$3000,Permissions!$B$2:$B$3000,$A4,Permissions!$R$2:$R$3000,"Yes") -> 0 | BB4: =SUMIFS(Permissions!$O$2:$O$3000,Permissions!$B$2:$B$3000,$A4,Permissions!$R$2:$R$3000,"Yes") -> 0 | BC4: =IF(AND(AM4>0,AR4>=AM4,AP4=0),"Finished",IF(AR4>0,"Partly built",IF(AM4>0,"Consented – not built","No consent"))) -> No consent | BD4: =IF(AND(R4<>"",AM4>1.1*R4),"Consented above capacity",IF(AND(LEFT(B4,8)="Planning",AZ4=0),"Consent parcel with no permission",IF(COUNTIF($A$2:$A$3000,$A4)>1,"Duplicate parcel_id","")))
A5: CITY-132 | B5: Council audit | C5: City | D5: Ballinacurra | E5: City neighbourhood | F5: 1 | G5: Inside catchment | H5: 132 | I5: Ballinacurra | J5: LIMERICK CITY WEST LEA-7 | K5: Dock Rd | L5: Private | M5: Exist Resi | N5: Brownfield | O5: 45+ | P5: 0.706 | Q5: 0.706 | R5: 32 | S5: Council estimate (area × density band) | T5: 24 | X5: City suburbs | Y5: 34 | Z5: 34 homes/ha = median of 39 permitted Limerick schemes of 10+ homes in city suburbs; applied to developable for density_estimate_units only | AB5: 0 | AC5: 0 | AD5: Undeveloped/Permission Sought | AE5: Unchanged | AF5: 2026-10-11 | AH5: =IF(R5="",AM5,R5) -> 32 | AI5: =SUMIFS(Permissions!$G$2:$G$3000,Permissions!$B$2:$B$3000,$A5,Permissions!$I$2:$I$3000,"Complete",Permissions!$R$2:$R$3000,"Yes") -> 0 | AJ5: =SUMIFS(Permissions!$G$2:$G$3000,Permissions!$B$2:$B$3000,$A5,Permissions!$I$2:$I$3000,"Under construction",Permissions!$R$2:$R$3000,"Yes") -> 0 | AK5: =SUMIFS(Permissions!$G$2:$G$3000,Permissions!$B$2:$B$3000,$A5,Permissions!$I$2:$I$3000,"Permitted – not started",Permissions!$R$2:$R$3000,"Yes") -> 0 | AL5: =SUMIFS(Permissions!$G$2:$G$3000,Permissions!$B$2:$B$3000,$A5,Permissions!$I$2:$I$3000,"Stalled",Permissions!$R$2:$R$3000,"Yes") -> 0 | AM5: =AI5+AJ5+AK5+AL5 -> 0 | AN5: =SUMIFS(Permissions!$G$2:$G$3000,Permissions!$B$2:$B$3000,$A5,Permissions!$I$2:$I$3000,"Expired – not started",Permissions!$R$2:$R$3000,"Yes") -> 0 | AO5: =SUMIFS(Permissions!$G$2:$G$3000,Permissions!$B$2:$B$3000,$A5,Permissions!$I$2:$I$3000,"In planning",Permissions!$R$2:$R$3000,"Yes") -> 0 | AP5: =IF(R5="",0,MAX(R5-AM5,0)) -> 32 | AQ5: =AM5+AP5 -> 32 | AR5: =SUMIFS(Permissions!$L$2:$L$3000,Permissions!$B$2:$B$3000,$A5,Permissions!$R$2:$R$3000,"Yes",Permissions!$I$2:$I$3000,"<>Expired – not started",Permissions!$I$2:$I$3000,"<>In planning") -> 0 | AS5: =AQ5-AR5 -> 32 | AT5: =SUMIFS(Permissions!$AJ$2:$AJ$3000,Permissions!$B$2:$B$3000,$A5,Permissions!$R$2:$R$3000,"Yes") -> 0 | AU5: =SUMIFS(Permissions!$AK$2:$AK$3000,Permissions!$B$2:$B$3000,$A5,Permissions!$R$2:$R$3000,"Yes") -> 0 | AV5: =SUMIFS(Permissions!$AL$2:$AL$3000,Permissions!$B$2:$B$3000,$A5,Permissions!$R$2:$R$3000,"Yes") -> 0 | AW5: =SUMIFS(Permissions!$AM$2:$AM$3000,Permissions!$B$2:$B$3000,$A5,Permissions!$R$2:$R$3000,"Yes") -> 0 | AX5: =SUMIFS(Permissions!$AN$2:$AN$3000,Permissions!$B$2:$B$3000,$A5,Permissions!$R$2:$R$3000,"Yes") -> 0 | AY5: =SUMIFS(Permissions!$AO$2:$AO$3000,Permissions!$B$2:$B$3000,$A5,Permissions!$R$2:$R$3000,"Yes") -> 0 | AZ5: =COUNTIFS(Permissions!$B$2:$B$3000,$A5,Permissions!$R$2:$R$3000,"Yes") -> 0 | BA5: =SUMIFS(Permissions!$M$2:$M$3000,Permissions!$B$2:$B$3000,$A5,Permissions!$R$2:$R$3000,"Yes") -> 0 | BB5: =SUMIFS(Permissions!$O$2:$O$3000,Permissions!$B$2:$B$3000,$A5,Permissions!$R$2:$R$3000,"Yes") -> 0 | BC5: =IF(AND(AM5>0,AR5>=AM5,AP5=0),"Finished",IF(AR5>0,"Partly built",IF(AM5>0,"Consented – not built","No consent"))) -> No consent | BD5: =IF(AND(R5<>"",AM5>1.1*R5),"Consented above capacity",IF(AND(LEFT(B5,8)="Planning",AZ5=0),"Consent parcel with no permission",IF(COUNTIF($A$2:$A$3000,$A5)>1,"Duplicate parcel_id","")))
A6: CITY-133 | B6: Council audit | C6: City | D6: Ballinacurra | E6: City neighbourhood | F6: 1 | G6: Inside catchment | H6: 133 | I6: Ballinacurra | J6: LIMERICK CITY WEST LEA-7 | K6: Dock Rd | L6: Private | M6: New Resi | N6: Infill | O6: 6.659 in 45+ 2.284 in 35+ | P6: 1.22 | Q6: 9.479 | R6: 55 | S6: Council estimate (area × density band) | T6: 41 | X6: City suburbs | Y6: 34 | Z6: 34 homes/ha = median of 39 permitted Limerick schemes of 10+ homes in city suburbs; applied to developable for density_estimate_units only | AB6: 310 | AC6: 310 | AD6: Complete/Commenced | AE6: Reduced Area | AF6: 2026-10-11 | AH6: =IF(R6="",AM6,R6) -> 55 | AI6: =SUMIFS(Permissions!$G$2:$G$3000,Permissions!$B$2:$B$3000,$A6,Permissions!$I$2:$I$3000,"Complete",Permissions!$R$2:$R$3000,"Yes") -> 0 | AJ6: =SUMIFS(Permissions!$G$2:$G$3000,Permissions!$B$2:$B$3000,$A6,Permissions!$I$2:$I$3000,"Under construction",Permissions!$R$2:$R$3000,"Yes") -> 371 | AK6: =SUMIFS(Permissions!$G$2:$G$3000,Permissions!$B$2:$B$3000,$A6,Permissions!$I$2:$I$3000,"Permitted – not started",Permissions!$R$2:$R$3000,"Yes") -> 0 | AL6: =SUMIFS(Permissions!$G$2:$G$3000,Permissions!$B$2:$B$3000,$A6,Permissions!$I$2:$I$3000,"Stalled",Permissions!$R$2:$R$3000,"Yes") -> 0 | AM6: =AI6+AJ6+AK6+AL6 -> 371 | AN6: =SUMIFS(Permissions!$G$2:$G$3000,Permissions!$B$2:$B$3000,$A6,Permissions!$I$2:$I$3000,"Expired – not started",Permissions!$R$2:$R$3000,"Yes") -> 0 | AO6: =SUMIFS(Permissions!$G$2:$G$3000,Permissions!$B$2:$B$3000,$A6,Permissions!$I$2:$I$3000,"In planning",Permissions!$R$2:$R$3000,"Yes") -> 0 | AP6: =IF(R6="",0,MAX(R6-AM6,0)) -> 0 | AQ6: =AM6+AP6 -> 371 | AR6: =SUMIFS(Permissions!$L$2:$L$3000,Permissions!$B$2:$B$3000,$A6,Permissions!$R$2:$R$3000,"Yes",Permissions!$I$2:$I$3000,"<>Expired – not started",Permissions!$I$2:$I$3000,"<>In planning") -> 121 | AS6: =AQ6-AR6 -> 250 | AT6: =SUMIFS(Permissions!$AJ$2:$AJ$3000,Permissions!$B$2:$B$3000,$A6,Permissions!$R$2:$R$3000,"Yes") -> 20.6 | AU6: =SUMIFS(Permissions!$AK$2:$AK$3000,Permissions!$B$2:$B$3000,$A6,Permissions!$R$2:$R$3000,"Yes") -> 88.5 | AV6: =SUMIFS(Permissions!$AL$2:$AL$3000,Permissions!$B$2:$B$3000,$A6,Permissions!$R$2:$R$3000,"Yes") -> 88.5 | AW6: =SUMIFS(Permissions!$AM$2:$AM$3000,Permissions!$B$2:$B$3000,$A6,Permissions!$R$2:$R$3000,"Yes") -> 88.5 | AX6: =SUMIFS(Permissions!$AN$2:$AN$3000,Permissions!$B$2:$B$3000,$A6,Permissions!$R$2:$R$3000,"Yes") -> 84.9 | AY6: =SUMIFS(Permissions!$AO$2:$AO$3000,Permissions!$B$2:$B$3000,$A6,Permissions!$R$2:$R$3000,"Yes") -> 0 | AZ6: =COUNTIFS(Permissions!$B$2:$B$3000,$A6,Permissions!$R$2:$R$3000,"Yes") -> 1 | BA6: =SUMIFS(Permissions!$M$2:$M$3000,Permissions!$B$2:$B$3000,$A6,Permissions!$R$2:$R$3000,"Yes") -> 121 | BB6: =SUMIFS(Permissions!$O$2:$O$3000,Permissions!$B$2:$B$3000,$A6,Permissions!$R$2:$R$3000,"Yes") -> 4 | BC6: =IF(AND(AM6>0,AR6>=AM6,AP6=0),"Finished",IF(AR6>0,"Partly built",IF(AM6>0,"Consented – not built","No consent"))) -> Partly built | BD6: =IF(AND(R6<>"",AM6>1.1*R6),"Consented above capacity",IF(AND(LEFT(B6,8)="Planning",AZ6=0),"Consent parcel with no permission",IF(COUNTIF($A$2:$A$3000,$A6)>1,"Duplicate parcel_id",""))) -> Consented above capacity
