Workbook

Sheet Intro
A1: Limerick Housing Delivery Strategy 2040 · housing need by catchment
A2: Spatialis for Limerick City and County Council. The same model as the story dashboard: choose the scenario levers below and every tab updates.
A3: Yellow cells with blue text are the levers: pick from each drop-down. Everything else is calculated. The Total tab is the sum of the 25 catchment tabs; the Validation tab checks that everything adds up.
A5: Group | B5: Lever | C5: Selection | D5: What it does
A6: Timing | B6: Plan to the end of | C6: 2040 | D6: Years after this are zero in every tab. The Council target is front-loaded (4,263 a year to 2030) and meets the HNDA need total in 2040.
A7: 1 · Spatial allocation | B7: Share homes between places | C7: S1: Core Strategy (Variation No. 3) | D7: S1 applies the Core Strategy shares (Variation No. 3, Table 2.6) to the 2026–2040 total; the city figure is split between the 9 neighbourhoods by 2022 population. S2 and S3 use Census 2022 population or households.
A8: 2 · Unit mix | B8: Bedroom mix scenario | C8: S1: Moving PPH proxy | D8: S1: the Council's planned split by year (persons per household read as bedrooms). S2: the bedrooms each catchment's 2022 households need, applied to its new homes.
A9: 2 · Unit mix (S2 modifier) | B9: Sharing benchmark | C9: Catchment's own 2011 rate | D9: Unrelated adults sharing above this rate are counted as people who would live alone, each needing a 1-bed. Only affects S2.
A10: 2 · Unit mix (S2 modifier) | B10: Children's bedrooms | C10: One bedroom per child | D10: Only affects S2.
A11: 2 · Unit mix (S2 modifier) | B11: Singles and younger couples given a 2-bed | C11: 0 | D11: 0% is the minimum rule: one bedroom per single person or couple. Only affects S2.
A12: 2 · Unit mix (S2 modifier) | B12: Downsizers: older couples given a 2-bed | C12: 0 | D12: Empty-nest and retired couples (CSO family cycle). Only affects S2.
A13: 3 · Tenure mix | B13: Limerick tenure scenario | C13: S1: Working position | D13: Working position and market scenarios A, B and D from the Spatialis Limerick HNDA synopsis.
A14: 3 · Tenure mix (modifier) | B14: Add housing list need to social | C14: No | D14: Moves 1,308 list households not already in the HNDA model (cleared over 2026–2035) into social, taken from private homes so the total stays fixed.
A15: 3 · Tenure mix (modifier) | B15: Affordable homes for purchase | C15: 0.5 | D15: The rest are cost rental. No source document gives this split; 50% is a placeholder.
A16: 3 · Where social homes go | B16: Rule | C16: City first, with a floor and a ceiling | D16: City first: every area gets at least the floor; the rest of Limerick's social homes go to the city neighbourhoods in proportion to their new homes, without taking any above the ceiling.
A17: 3 · Where social homes go | B17: Ceiling: social share of a neighbourhood by the end year | C17: 0.2 | D17: Counts existing (Census 2022 stated tenure) and new homes. 20% is about twice Limerick's current 9.7%. City-first rule only.
A18: 3 · Where social homes go | B18: Floor: social share of new homes everywhere | C18: 0.1 | D18: 10% matches the social part of Part V. City-first rule only.
A19: 4 · Land (Council densities) | B19: Point in the Council density ranges | C19: Minimum | D19: Used by the Land at Council density tab only. Minimum is the lower bound of each range in Variation No. 3, Table 2.5/2.6 (the density that shall generally be applied).
A20: Defaults match the story dashboard's default settings.
A22: Headline results for the selected levers
B23: New homes, 2026 to end year | C23: =Total!B28 -> 39864
B24: Social homes | C24: =SUM(Total!K28:O28) -> 8362.3707
B25: Affordable homes (purchase and cost rental) | C25: =Total!I28+Total!J28 -> 5018.6223
B26: Private homes (purchase and rent) | C26: =Total!G28+Total!H28 -> 26483.007
B27: 1-bed share of new homes | C27: =Total!C29 -> 0.24123231
B28: 4+ bed share of new homes | C28: =Total!F29 -> 0.26149544
B29: Validation | C29: =Validation!E7&" ("&Validation!C6&" checks)" -> ALL PASS (91 checks)
A31: Tabs
B32: Total | D32: Sum of the 25 catchment tabs, per year, with bedrooms and tenure.
B33: Land | D33: New homes by year for every catchment and the land needed at its existing net density (editable).
B34: Land at Council density | D34: The same homes at the Council's target densities from Variation No. 3, with the difference from existing densities.
B35: Zoned land vs need | D35: Land already identified in the land register against the 2040 need at Council densities: shortfall, additional land to 2040, and with headroom (yellow lever).
B36: Opportunity sites & options | D36: What the opportunity sites could add to the shortfall, what is left for infill, and options to close it (city infill density lever).
B37: 25 catchment tabs | D37: 9 city neighbourhoods, 6 key towns, 9 villages and the rest of the county, in that order.
B38: Validation | D38: Checks that homes, bedrooms and tenure add up and match the Limerick totals.
B39: Model | D39: Every calculation, one row per catchment.
B40: Data | D40: The input data and the drop-down lists.
A42: Assumptions and sources
B43: Homes per year | D43: Council delivery target by year, from the Spatialis Limerick HNDA synopsis (October 2026). It totals 39,864 by 2040, matching the new HNDA need.
B44: Spatial allocation | D44: Core Strategy, Variation No. 3 of the Limerick Development Plan 2022–2028 (made 28 September 2026), Table 2.6, housing growth requirement June 2025 to December 2030. Its shares are applied to the 2026–2040 total. The study's town and village groupings differ from the Core Strategy levels.
...

Sheet Total
A1: Limerick City and County · total of all catchments
A2: ="Sum of the 25 catchment tabs · new homes per year, 2026–"&Model!$B$3&" · set by the levers on the Intro tab" -> Sum of the 25 catchment tabs · new homes per year, 2026–2040 · set by the levers on the Intro tab
A4: Catchments summed | C4: 25
A5: New homes, 2026 to end year | C5: =B28 -> 39864
A6: Social share of new homes | C6: =IF(B28>0,SUM(K28:O28)/B28,0) -> 0.20977249
A7: Social rent share of households, 2022 | C7: =SUMPRODUCT(Data!$E$23:$E$47,Data!$F$23:$F$47)/SUM(Data!$E$23:$E$47) -> 0.099139755
A8: Social share of all homes at end year (2022 plus new) | C8: =(SUMPRODUCT(Data!$E$23:$E$47,Data!$F$23:$F$47)+SUM(K28:O28))/(SUM(Data!$E$23:$E$47)+B28) -> 0.13710723
A9: Bedroom mix | C9: =IF(Model!$B$5=1,"S1: the Council's planned split for each year","S2: each catchment's own need, weighted by its homes") -> S1: the Council's planned split for each year
A12: Year | B12: Homes | C12: 1-bed | D12: 2-bed | E12: 3-bed | F12: 4+ bed | G12: Private purchase | H12: Private rent | I12: Affordable purchase | J12: Cost rental | K12: Social: general needs | L12: Social: disability | M12: Social: older people | N12: Social: Traveller | O12: Social: community
A13: 2026 | B13: =Ballinacurra!B13+Caherdavin!B13+'Castletroy-Annacotty'!B13+'City Centre'!B13+'Corbally-Grove Island'!B13+Dooradoyle!B13+'Kings Island'!B13+'Singland-Garryowen'!B13+Southhill!B13+Abbeyfeale!B13+Caherconlish!B13+Castleconnell!B13+Kilmallock!B13+'Newcastle West'!B13+Rathkeale!B13+Adare!B13+Askeaton!B13+Bruff!B13+Cappamore!B13+Croom!B13+Hospital!B13+Kilfinnane!B13+Moroe!B13+Patrickswell!B13+'Rest of county'!B13 -> 4263 | C13: =Ballinacurra!C13+Caherdavin!C13+'Castletroy-Annacotty'!C13+'City Centre'!C13+'Corbally-Grove Island'!C13+Dooradoyle!C13+'Kings Island'!C13+'Singland-Garryowen'!C13+Southhill!C13+Abbeyfeale!C13+Caherconlish!C13+Castleconnell!C13+Kilmallock!C13+'Newcastle West'!C13+Rathkeale!C13+Adare!C13+Askeaton!C13+Bruff!C13+Cappamore!C13+Croom!C13+Hospital!C13+Kilfinnane!C13+Moroe!C13+Patrickswell!C13+'Rest of county'!C13 -> 1102.7413 | D13: =Ballinacurra!D13+Caherdavin!D13+'Castletroy-Annacotty'!D13+'City Centre'!D13+'Corbally-Grove Island'!D13+Dooradoyle!D13+'Kings Island'!D13+'Singland-Garryowen'!D13+Southhill!D13+Abbeyfeale!D13+Caherconlish!D13+Castleconnell!D13+Kilmallock!D13+'Newcastle West'!D13+Rathkeale!D13+Adare!D13+Askeaton!D13+Bruff!D13+Cappamore!D13+Croom!D13+Hospital!D13+Kilfinnane!D13+Moroe!D13+Patrickswell!D13+'Rest of county'!D13 -> 1349.6834 | E13: =Ballinacurra!E13+Caherdavin!E13+'Castletroy-Annacotty'!E13+'City Centre'!E13+'Corbally-Grove Island'!E13+Dooradoyle!E13+'Kings Island'!E13+'Singland-Garryowen'!E13+Southhill!E13+Abbeyfeale!E13+Caherconlish!E13+Castleconnell!E13+Kilmallock!E13+'Newcastle West'!E13+Rathkeale!E13+Adare!E13+Askeaton!E13+Bruff!E13+Cappamore!E13+Croom!E13+Hospital!E13+Kilfinnane!E13+Moroe!E13+Patrickswell!E13+'Rest of county'!E13 -> 788.81496 | F13: =Ballinacurra!F13+Caherdavin!F13+'Castletroy-Annacotty'!F13+'City Centre'!F13+'Corbally-Grove Island'!F13+Dooradoyle!F13+'Kings Island'!F13+'Singland-Garryowen'!F13+Southhill!F13+Abbeyfeale!F13+Caherconlish!F13+Castleconnell!F13+Kilmallock!F13+'Newcastle West'!F13+Rathkeale!F13+Adare!F13+Askeaton!F13+Bruff!F13+Cappamore!F13+Croom!F13+Hospital!F13+Kilfinnane!F13+Moroe!F13+Patrickswell!F13+'Rest of county'!F13 -> 1021.7603 | G13: =Ballinacurra!G13+Caherdavin!G13+'Castletroy-Annacotty'!G13+'City Centre'!G13+'Corbally-Grove Island'!G13+Dooradoyle!G13+'Kings Island'!G13+'Singland-Garryowen'!G13+Southhill!G13+Abbeyfeale!G13+Caherconlish!G13+Castleconnell!G13+Kilmallock!G13+'Newcastle West'!G13+Rathkeale!G13+Adare!G13+Askeaton!G13+Bruff!G13+Cappamore!G13+Croom!G13+Hospital!G13+Kilfinnane!G13+Moroe!G13+Patrickswell!G13+'Rest of county'!G13 -> 2266.179 | H13: =Ballinacurra!H13+Caherdavin!H13+'Castletroy-Annacotty'!H13+'City Centre'!H13+'Corbally-Grove Island'!H13+Dooradoyle!H13+'Kings Island'!H13+'Singland-Garryowen'!H13+Southhill!H13+Abbeyfeale!H13+Caherconlish!H13+Castleconnell!H13+Kilmallock!H13+'Newcastle West'!H13+Rathkeale!H13+Adare!H13+Askeaton!H13+Bruff!H13+Cappamore!H13+Croom!H13+Hospital!H13+Kilfinnane!H13+Moroe!H13+Patrickswell!H13+'Rest of county'!H13 -> 565.87644 | I13: =Ballinacurra!I13+Caherdavin!I13+'Castletroy-Annacotty'!I13+'City Centre'!I13+'Corbally-Grove Island'!I13+Dooradoyle!I13+'Kings Island'!I13+'Singland-Garryowen'!I13+Southhill!I13+Abbeyfeale!I13+Caherconlish!I13+Castleconnell!I13+Kilmallock!I13+'Newcastle West'!I13+Rathkeale!I13+Adare!I13+Askeaton!I13+Bruff!I13+Cappamore!I13+Croom!I13+Hospital!I13+Kilfinnane!I13+Moroe!I13+Patrickswell!I13+'Rest of county'!I13 -> 268.3422 | ... O13: =Ballinacurra!O13+Caherdavin!O13+'Castletroy-Annacotty'!O13+'City Centre'!O13+'Corbally-Grove Island'!O13+Dooradoyle!O13+'Kings Island'!O13+'Singland-Garryowen'!O13+Southhill!O13+Abbeyfeale!O13+Caherconlish!O13+Castleconnell!O13+Kilmallock!O13+'Newcastle West'!O13+Rathkeale!O13+Adare!O13+Askeaton!O13+Bruff!O13+Cappamore!O13+Croom!O13+Hospital!O13+Kilfinnane!O13+Moroe!O13+Patrickswell!O13+'Rest of county'!O13 -> 16.616893
A14: 2027 | B14: =Ballinacurra!B14+Caherdavin!B14+'Castletroy-Annacotty'!B14+'City Centre'!B14+'Corbally-Grove Island'!B14+Dooradoyle!B14+'Kings Island'!B14+'Singland-Garryowen'!B14+Southhill!B14+Abbeyfeale!B14+Caherconlish!B14+Castleconnell!B14+Kilmallock!B14+'Newcastle West'!B14+Rathkeale!B14+Adare!B14+Askeaton!B14+Bruff!B14+Cappamore!B14+Croom!B14+Hospital!B14+Kilfinnane!B14+Moroe!B14+Patrickswell!B14+'Rest of county'!B14 -> 4263 | C14: =Ballinacurra!C14+Caherdavin!C14+'Castletroy-Annacotty'!C14+'City Centre'!C14+'Corbally-Grove Island'!C14+Dooradoyle!C14+'Kings Island'!C14+'Singland-Garryowen'!C14+Southhill!C14+Abbeyfeale!C14+Caherconlish!C14+Castleconnell!C14+Kilmallock!C14+'Newcastle West'!C14+Rathkeale!C14+Adare!C14+Askeaton!C14+Bruff!C14+Cappamore!C14+Croom!C14+Hospital!C14+Kilfinnane!C14+Moroe!C14+Patrickswell!C14+'Rest of county'!C14 -> 1071.7486 | D14: =Ballinacurra!D14+Caherdavin!D14+'Castletroy-Annacotty'!D14+'City Centre'!D14+'Corbally-Grove Island'!D14+Dooradoyle!D14+'Kings Island'!D14+'Singland-Garryowen'!D14+Southhill!D14+Abbeyfeale!D14+Caherconlish!D14+Castleconnell!D14+Kilmallock!D14+'Newcastle West'!D14+Rathkeale!D14+Adare!D14+Askeaton!D14+Bruff!D14+Cappamore!D14+Croom!D14+Hospital!D14+Kilfinnane!D14+Moroe!D14+Patrickswell!D14+'Rest of county'!D14 -> 1353.6825 | E14: =Ballinacurra!E14+Caherdavin!E14+'Castletroy-Annacotty'!E14+'City Centre'!E14+'Corbally-Grove Island'!E14+Dooradoyle!E14+'Kings Island'!E14+'Singland-Garryowen'!E14+Southhill!E14+Abbeyfeale!E14+Caherconlish!E14+Castleconnell!E14+Kilmallock!E14+'Newcastle West'!E14+Rathkeale!E14+Adare!E14+Askeaton!E14+Bruff!E14+Cappamore!E14+Croom!E14+Hospital!E14+Kilfinnane!E14+Moroe!E14+Patrickswell!E14+'Rest of county'!E14 -> 786.81543 | F14: =Ballinacurra!F14+Caherdavin!F14+'Castletroy-Annacotty'!F14+'City Centre'!F14+'Corbally-Grove Island'!F14+Dooradoyle!F14+'Kings Island'!F14+'Singland-Garryowen'!F14+Southhill!F14+Abbeyfeale!F14+Caherconlish!F14+Castleconnell!F14+Kilmallock!F14+'Newcastle West'!F14+Rathkeale!F14+Adare!F14+Askeaton!F14+Bruff!F14+Cappamore!F14+Croom!F14+Hospital!F14+Kilfinnane!F14+Moroe!F14+Patrickswell!F14+'Rest of county'!F14 -> 1050.7535 | G14: =Ballinacurra!G14+Caherdavin!G14+'Castletroy-Annacotty'!G14+'City Centre'!G14+'Corbally-Grove Island'!G14+Dooradoyle!G14+'Kings Island'!G14+'Singland-Garryowen'!G14+Southhill!G14+Abbeyfeale!G14+Caherconlish!G14+Castleconnell!G14+Kilmallock!G14+'Newcastle West'!G14+Rathkeale!G14+Adare!G14+Askeaton!G14+Bruff!G14+Cappamore!G14+Croom!G14+Hospital!G14+Kilfinnane!G14+Moroe!G14+Patrickswell!G14+'Rest of county'!G14 -> 2266.179 | H14: =Ballinacurra!H14+Caherdavin!H14+'Castletroy-Annacotty'!H14+'City Centre'!H14+'Corbally-Grove Island'!H14+Dooradoyle!H14+'Kings Island'!H14+'Singland-Garryowen'!H14+Southhill!H14+Abbeyfeale!H14+Caherconlish!H14+Castleconnell!H14+Kilmallock!H14+'Newcastle West'!H14+Rathkeale!H14+Adare!H14+Askeaton!H14+Bruff!H14+Cappamore!H14+Croom!H14+Hospital!H14+Kilfinnane!H14+Moroe!H14+Patrickswell!H14+'Rest of county'!H14 -> 565.87644 | I14: =Ballinacurra!I14+Caherdavin!I14+'Castletroy-Annacotty'!I14+'City Centre'!I14+'Corbally-Grove Island'!I14+Dooradoyle!I14+'Kings Island'!I14+'Singland-Garryowen'!I14+Southhill!I14+Abbeyfeale!I14+Caherconlish!I14+Castleconnell!I14+Kilmallock!I14+'Newcastle West'!I14+Rathkeale!I14+Adare!I14+Askeaton!I14+Bruff!I14+Cappamore!I14+Croom!I14+Hospital!I14+Kilfinnane!I14+Moroe!I14+Patrickswell!I14+'Rest of county'!I14 -> 268.3422 | ... O14: =Ballinacurra!O14+Caherdavin!O14+'Castletroy-Annacotty'!O14+'City Centre'!O14+'Corbally-Grove Island'!O14+Dooradoyle!O14+'Kings Island'!O14+'Singland-Garryowen'!O14+Southhill!O14+Abbeyfeale!O14+Caherconlish!O14+Castleconnell!O14+Kilmallock!O14+'Newcastle West'!O14+Rathkeale!O14+Adare!O14+Askeaton!O14+Bruff!O14+Cappamore!O14+Croom!O14+Hospital!O14+Kilfinnane!O14+Moroe!O14+Patrickswell!O14+'Rest of county'!O14 -> 16.616893
A15: 2028 | B15: =Ballinacurra!B15+Caherdavin!B15+'Castletroy-Annacotty'!B15+'City Centre'!B15+'Corbally-Grove Island'!B15+Dooradoyle!B15+'Kings Island'!B15+'Singland-Garryowen'!B15+Southhill!B15+Abbeyfeale!B15+Caherconlish!B15+Castleconnell!B15+Kilmallock!B15+'Newcastle West'!B15+Rathkeale!B15+Adare!B15+Askeaton!B15+Bruff!B15+Cappamore!B15+Croom!B15+Hospital!B15+Kilfinnane!B15+Moroe!B15+Patrickswell!B15+'Rest of county'!B15 -> 4263 | C15: =Ballinacurra!C15+Caherdavin!C15+'Castletroy-Annacotty'!C15+'City Centre'!C15+'Corbally-Grove Island'!C15+Dooradoyle!C15+'Kings Island'!C15+'Singland-Garryowen'!C15+Southhill!C15+Abbeyfeale!C15+Caherconlish!C15+Castleconnell!C15+Kilmallock!C15+'Newcastle West'!C15+Rathkeale!C15+Adare!C15+Askeaton!C15+Bruff!C15+Cappamore!C15+Croom!C15+Hospital!C15+Kilfinnane!C15+Moroe!C15+Patrickswell!C15+'Rest of county'!C15 -> 1068.2506 | D15: =Ballinacurra!D15+Caherdavin!D15+'Castletroy-Annacotty'!D15+'City Centre'!D15+'Corbally-Grove Island'!D15+Dooradoyle!D15+'Kings Island'!D15+'Singland-Garryowen'!D15+Southhill!D15+Abbeyfeale!D15+Caherconlish!D15+Castleconnell!D15+Kilmallock!D15+'Newcastle West'!D15+Rathkeale!D15+Adare!D15+Askeaton!D15+Bruff!D15+Cappamore!D15+Croom!D15+Hospital!D15+Kilfinnane!D15+Moroe!D15+Patrickswell!D15+'Rest of county'!D15 -> 1354.3177 | E15: =Ballinacurra!E15+Caherdavin!E15+'Castletroy-Annacotty'!E15+'City Centre'!E15+'Corbally-Grove Island'!E15+Dooradoyle!E15+'Kings Island'!E15+'Singland-Garryowen'!E15+Southhill!E15+Abbeyfeale!E15+Caherconlish!E15+Castleconnell!E15+Kilmallock!E15+'Newcastle West'!E15+Rathkeale!E15+Adare!E15+Askeaton!E15+Bruff!E15+Cappamore!E15+Croom!E15+Hospital!E15+Kilfinnane!E15+Moroe!E15+Patrickswell!E15+'Rest of county'!E15 -> 787.18466 | F15: =Ballinacurra!F15+Caherdavin!F15+'Castletroy-Annacotty'!F15+'City Centre'!F15+'Corbally-Grove Island'!F15+Dooradoyle!F15+'Kings Island'!F15+'Singland-Garryowen'!F15+Southhill!F15+Abbeyfeale!F15+Caherconlish!F15+Castleconnell!F15+Kilmallock!F15+'Newcastle West'!F15+Rathkeale!F15+Adare!F15+Askeaton!F15+Bruff!F15+Cappamore!F15+Croom!F15+Hospital!F15+Kilfinnane!F15+Moroe!F15+Patrickswell!F15+'Rest of county'!F15 -> 1053.2471 | G15: =Ballinacurra!G15+Caherdavin!G15+'Castletroy-Annacotty'!G15+'City Centre'!G15+'Corbally-Grove Island'!G15+Dooradoyle!G15+'Kings Island'!G15+'Singland-Garryowen'!G15+Southhill!G15+Abbeyfeale!G15+Caherconlish!G15+Castleconnell!G15+Kilmallock!G15+'Newcastle West'!G15+Rathkeale!G15+Adare!G15+Askeaton!G15+Bruff!G15+Cappamore!G15+Croom!G15+Hospital!G15+Kilfinnane!G15+Moroe!G15+Patrickswell!G15+'Rest of county'!G15 -> 2266.179 | H15: =Ballinacurra!H15+Caherdavin!H15+'Castletroy-Annacotty'!H15+'City Centre'!H15+'Corbally-Grove Island'!H15+Dooradoyle!H15+'Kings Island'!H15+'Singland-Garryowen'!H15+Southhill!H15+Abbeyfeale!H15+Caherconlish!H15+Castleconnell!H15+Kilmallock!H15+'Newcastle West'!H15+Rathkeale!H15+Adare!H15+Askeaton!H15+Bruff!H15+Cappamore!H15+Croom!H15+Hospital!H15+Kilfinnane!H15+Moroe!H15+Patrickswell!H15+'Rest of county'!H15 -> 565.87644 | I15: =Ballinacurra!I15+Caherdavin!I15+'Castletroy-Annacotty'!I15+'City Centre'!I15+'Corbally-Grove Island'!I15+Dooradoyle!I15+'Kings Island'!I15+'Singland-Garryowen'!I15+Southhill!I15+Abbeyfeale!I15+Caherconlish!I15+Castleconnell!I15+Kilmallock!I15+'Newcastle West'!I15+Rathkeale!I15+Adare!I15+Askeaton!I15+Bruff!I15+Cappamore!I15+Croom!I15+Hospital!I15+Kilfinnane!I15+Moroe!I15+Patrickswell!I15+'Rest of county'!I15 -> 268.3422 | ... O15: =Ballinacurra!O15+Caherdavin!O15+'Castletroy-Annacotty'!O15+'City Centre'!O15+'Corbally-Grove Island'!O15+Dooradoyle!O15+'Kings Island'!O15+'Singland-Garryowen'!O15+Southhill!O15+Abbeyfeale!O15+Caherconlish!O15+Castleconnell!O15+Kilmallock!O15+'Newcastle West'!O15+Rathkeale!O15+Adare!O15+Askeaton!O15+Bruff!O15+Cappamore!O15+Croom!O15+Hospital!O15+Kilfinnane!O15+Moroe!O15+Patrickswell!O15+'Rest of county'!O15 -> 16.616893
A16: 2029 | B16: =Ballinacurra!B16+Caherdavin!B16+'Castletroy-Annacotty'!B16+'City Centre'!B16+'Corbally-Grove Island'!B16+Dooradoyle!B16+'Kings Island'!B16+'Singland-Garryowen'!B16+Southhill!B16+Abbeyfeale!B16+Caherconlish!B16+Castleconnell!B16+Kilmallock!B16+'Newcastle West'!B16+Rathkeale!B16+Adare!B16+Askeaton!B16+Bruff!B16+Cappamore!B16+Croom!B16+Hospital!B16+Kilfinnane!B16+Moroe!B16+Patrickswell!B16+'Rest of county'!B16 -> 4263 | C16: =Ballinacurra!C16+Caherdavin!C16+'Castletroy-Annacotty'!C16+'City Centre'!C16+'Corbally-Grove Island'!C16+Dooradoyle!C16+'Kings Island'!C16+'Singland-Garryowen'!C16+Southhill!C16+Abbeyfeale!C16+Caherconlish!C16+Castleconnell!C16+Kilmallock!C16+'Newcastle West'!C16+Rathkeale!C16+Adare!C16+Askeaton!C16+Bruff!C16+Cappamore!C16+Croom!C16+Hospital!C16+Kilfinnane!C16+Moroe!C16+Patrickswell!C16+'Rest of county'!C16 -> 1057 | D16: =Ballinacurra!D16+Caherdavin!D16+'Castletroy-Annacotty'!D16+'City Centre'!D16+'Corbally-Grove Island'!D16+Dooradoyle!D16+'Kings Island'!D16+'Singland-Garryowen'!D16+Southhill!D16+Abbeyfeale!D16+Caherconlish!D16+Castleconnell!D16+Kilmallock!D16+'Newcastle West'!D16+Rathkeale!D16+Adare!D16+Askeaton!D16+Bruff!D16+Cappamore!D16+Croom!D16+Hospital!D16+Kilfinnane!D16+Moroe!D16+Patrickswell!D16+'Rest of county'!D16 -> 1347 | E16: =Ballinacurra!E16+Caherdavin!E16+'Castletroy-Annacotty'!E16+'City Centre'!E16+'Corbally-Grove Island'!E16+Dooradoyle!E16+'Kings Island'!E16+'Singland-Garryowen'!E16+Southhill!E16+Abbeyfeale!E16+Caherconlish!E16+Castleconnell!E16+Kilmallock!E16+'Newcastle West'!E16+Rathkeale!E16+Adare!E16+Askeaton!E16+Bruff!E16+Cappamore!E16+Croom!E16+Hospital!E16+Kilfinnane!E16+Moroe!E16+Patrickswell!E16+'Rest of county'!E16 -> 782 | F16: =Ballinacurra!F16+Caherdavin!F16+'Castletroy-Annacotty'!F16+'City Centre'!F16+'Corbally-Grove Island'!F16+Dooradoyle!F16+'Kings Island'!F16+'Singland-Garryowen'!F16+Southhill!F16+Abbeyfeale!F16+Caherconlish!F16+Castleconnell!F16+Kilmallock!F16+'Newcastle West'!F16+Rathkeale!F16+Adare!F16+Askeaton!F16+Bruff!F16+Cappamore!F16+Croom!F16+Hospital!F16+Kilfinnane!F16+Moroe!F16+Patrickswell!F16+'Rest of county'!F16 -> 1077 | G16: =Ballinacurra!G16+Caherdavin!G16+'Castletroy-Annacotty'!G16+'City Centre'!G16+'Corbally-Grove Island'!G16+Dooradoyle!G16+'Kings Island'!G16+'Singland-Garryowen'!G16+Southhill!G16+Abbeyfeale!G16+Caherconlish!G16+Castleconnell!G16+Kilmallock!G16+'Newcastle West'!G16+Rathkeale!G16+Adare!G16+Askeaton!G16+Bruff!G16+Cappamore!G16+Croom!G16+Hospital!G16+Kilfinnane!G16+Moroe!G16+Patrickswell!G16+'Rest of county'!G16 -> 2266.179 | H16: =Ballinacurra!H16+Caherdavin!H16+'Castletroy-Annacotty'!H16+'City Centre'!H16+'Corbally-Grove Island'!H16+Dooradoyle!H16+'Kings Island'!H16+'Singland-Garryowen'!H16+Southhill!H16+Abbeyfeale!H16+Caherconlish!H16+Castleconnell!H16+Kilmallock!H16+'Newcastle West'!H16+Rathkeale!H16+Adare!H16+Askeaton!H16+Bruff!H16+Cappamore!H16+Croom!H16+Hospital!H16+Kilfinnane!H16+Moroe!H16+Patrickswell!H16+'Rest of county'!H16 -> 565.87644 | I16: =Ballinacurra!I16+Caherdavin!I16+'Castletroy-Annacotty'!I16+'City Centre'!I16+'Corbally-Grove Island'!I16+Dooradoyle!I16+'Kings Island'!I16+'Singland-Garryowen'!I16+Southhill!I16+Abbeyfeale!I16+Caherconlish!I16+Castleconnell!I16+Kilmallock!I16+'Newcastle West'!I16+Rathkeale!I16+Adare!I16+Askeaton!I16+Bruff!I16+Cappamore!I16+Croom!I16+Hospital!I16+Kilfinnane!I16+Moroe!I16+Patrickswell!I16+'Rest of county'!I16 -> 268.3422 | ... O16: =Ballinacurra!O16+Caherdavin!O16+'Castletroy-Annacotty'!O16+'City Centre'!O16+'Corbally-Grove Island'!O16+Dooradoyle!O16+'Kings Island'!O16+'Singland-Garryowen'!O16+Southhill!O16+Abbeyfeale!O16+Caherconlish!O16+Castleconnell!O16+Kilmallock!O16+'Newcastle West'!O16+Rathkeale!O16+Adare!O16+Askeaton!O16+Bruff!O16+Cappamore!O16+Croom!O16+Hospital!O16+Kilfinnane!O16+Moroe!O16+Patrickswell!O16+'Rest of county'!O16 -> 16.616893
A17: 2030 | B17: =Ballinacurra!B17+Caherdavin!B17+'Castletroy-Annacotty'!B17+'City Centre'!B17+'Corbally-Grove Island'!B17+Dooradoyle!B17+'Kings Island'!B17+'Singland-Garryowen'!B17+Southhill!B17+Abbeyfeale!B17+Caherconlish!B17+Castleconnell!B17+Kilmallock!B17+'Newcastle West'!B17+Rathkeale!B17+Adare!B17+Askeaton!B17+Bruff!B17+Cappamore!B17+Croom!B17+Hospital!B17+Kilfinnane!B17+Moroe!B17+Patrickswell!B17+'Rest of county'!B17 -> 4263 | C17: =Ballinacurra!C17+Caherdavin!C17+'Castletroy-Annacotty'!C17+'City Centre'!C17+'Corbally-Grove Island'!C17+Dooradoyle!C17+'Kings Island'!C17+'Singland-Garryowen'!C17+Southhill!C17+Abbeyfeale!C17+Caherconlish!C17+Castleconnell!C17+Kilmallock!C17+'Newcastle West'!C17+Rathkeale!C17+Adare!C17+Askeaton!C17+Bruff!C17+Cappamore!C17+Croom!C17+Hospital!C17+Kilfinnane!C17+Moroe!C17+Patrickswell!C17+'Rest of county'!C17 -> 1055.2475 | D17: =Ballinacurra!D17+Caherdavin!D17+'Castletroy-Annacotty'!D17+'City Centre'!D17+'Corbally-Grove Island'!D17+Dooradoyle!D17+'Kings Island'!D17+'Singland-Garryowen'!D17+Southhill!D17+Abbeyfeale!D17+Caherconlish!D17+Castleconnell!D17+Kilmallock!D17+'Newcastle West'!D17+Rathkeale!D17+Adare!D17+Askeaton!D17+Bruff!D17+Cappamore!D17+Croom!D17+Hospital!D17+Kilfinnane!D17+Moroe!D17+Patrickswell!D17+'Rest of county'!D17 -> 1327.3114 | E17: =Ballinacurra!E17+Caherdavin!E17+'Castletroy-Annacotty'!E17+'City Centre'!E17+'Corbally-Grove Island'!E17+Dooradoyle!E17+'Kings Island'!E17+'Singland-Garryowen'!E17+Southhill!E17+Abbeyfeale!E17+Caherconlish!E17+Castleconnell!E17+Kilmallock!E17+'Newcastle West'!E17+Rathkeale!E17+Adare!E17+Askeaton!E17+Bruff!E17+Cappamore!E17+Croom!E17+Hospital!E17+Kilfinnane!E17+Moroe!E17+Patrickswell!E17+'Rest of county'!E17 -> 783.18372 | F17: =Ballinacurra!F17+Caherdavin!F17+'Castletroy-Annacotty'!F17+'City Centre'!F17+'Corbally-Grove Island'!F17+Dooradoyle!F17+'Kings Island'!F17+'Singland-Garryowen'!F17+Southhill!F17+Abbeyfeale!F17+Caherconlish!F17+Castleconnell!F17+Kilmallock!F17+'Newcastle West'!F17+Rathkeale!F17+Adare!F17+Askeaton!F17+Bruff!F17+Cappamore!F17+Croom!F17+Hospital!F17+Kilfinnane!F17+Moroe!F17+Patrickswell!F17+'Rest of county'!F17 -> 1097.2574 | G17: =Ballinacurra!G17+Caherdavin!G17+'Castletroy-Annacotty'!G17+'City Centre'!G17+'Corbally-Grove Island'!G17+Dooradoyle!G17+'Kings Island'!G17+'Singland-Garryowen'!G17+Southhill!G17+Abbeyfeale!G17+Caherconlish!G17+Castleconnell!G17+Kilmallock!G17+'Newcastle West'!G17+Rathkeale!G17+Adare!G17+Askeaton!G17+Bruff!G17+Cappamore!G17+Croom!G17+Hospital!G17+Kilfinnane!G17+Moroe!G17+Patrickswell!G17+'Rest of county'!G17 -> 2266.179 | H17: =Ballinacurra!H17+Caherdavin!H17+'Castletroy-Annacotty'!H17+'City Centre'!H17+'Corbally-Grove Island'!H17+Dooradoyle!H17+'Kings Island'!H17+'Singland-Garryowen'!H17+Southhill!H17+Abbeyfeale!H17+Caherconlish!H17+Castleconnell!H17+Kilmallock!H17+'Newcastle West'!H17+Rathkeale!H17+Adare!H17+Askeaton!H17+Bruff!H17+Cappamore!H17+Croom!H17+Hospital!H17+Kilfinnane!H17+Moroe!H17+Patrickswell!H17+'Rest of county'!H17 -> 565.87644 | I17: =Ballinacurra!I17+Caherdavin!I17+'Castletroy-Annacotty'!I17+'City Centre'!I17+'Corbally-Grove Island'!I17+Dooradoyle!I17+'Kings Island'!I17+'Singland-Garryowen'!I17+Southhill!I17+Abbeyfeale!I17+Caherconlish!I17+Castleconnell!I17+Kilmallock!I17+'Newcastle West'!I17+Rathkeale!I17+Adare!I17+Askeaton!I17+Bruff!I17+Cappamore!I17+Croom!I17+Hospital!I17+Kilfinnane!I17+Moroe!I17+Patrickswell!I17+'Rest of county'!I17 -> 268.3422 | ... O17: =Ballinacurra!O17+Caherdavin!O17+'Castletroy-Annacotty'!O17+'City Centre'!O17+'Corbally-Grove Island'!O17+Dooradoyle!O17+'Kings Island'!O17+'Singland-Garryowen'!O17+Southhill!O17+Abbeyfeale!O17+Caherconlish!O17+Castleconnell!O17+Kilmallock!O17+'Newcastle West'!O17+Rathkeale!O17+Adare!O17+Askeaton!O17+Bruff!O17+Cappamore!O17+Croom!O17+Hospital!O17+Kilfinnane!O17+Moroe!O17+Patrickswell!O17+'Rest of county'!O17 -> 16.616893
A18: 2031 | B18: =Ballinacurra!B18+Caherdavin!B18+'Castletroy-Annacotty'!B18+'City Centre'!B18+'Corbally-Grove Island'!B18+Dooradoyle!B18+'Kings Island'!B18+'Singland-Garryowen'!B18+Southhill!B18+Abbeyfeale!B18+Caherconlish!B18+Castleconnell!B18+Kilmallock!B18+'Newcastle West'!B18+Rathkeale!B18+Adare!B18+Askeaton!B18+Bruff!B18+Cappamore!B18+Croom!B18+Hospital!B18+Kilfinnane!B18+Moroe!B18+Patrickswell!B18+'Rest of county'!B18 -> 2168 | C18: =Ballinacurra!C18+Caherdavin!C18+'Castletroy-Annacotty'!C18+'City Centre'!C18+'Corbally-Grove Island'!C18+Dooradoyle!C18+'Kings Island'!C18+'Singland-Garryowen'!C18+Southhill!C18+Abbeyfeale!C18+Caherconlish!C18+Castleconnell!C18+Kilmallock!C18+'Newcastle West'!C18+Rathkeale!C18+Adare!C18+Askeaton!C18+Bruff!C18+Cappamore!C18+Croom!C18+Hospital!C18+Kilfinnane!C18+Moroe!C18+Patrickswell!C18+'Rest of county'!C18 -> 501 | D18: =Ballinacurra!D18+Caherdavin!D18+'Castletroy-Annacotty'!D18+'City Centre'!D18+'Corbally-Grove Island'!D18+Dooradoyle!D18+'Kings Island'!D18+'Singland-Garryowen'!D18+Southhill!D18+Abbeyfeale!D18+Caherconlish!D18+Castleconnell!D18+Kilmallock!D18+'Newcastle West'!D18+Rathkeale!D18+Adare!D18+Askeaton!D18+Bruff!D18+Cappamore!D18+Croom!D18+Hospital!D18+Kilfinnane!D18+Moroe!D18+Patrickswell!D18+'Rest of county'!D18 -> 659 | E18: =Ballinacurra!E18+Caherdavin!E18+'Castletroy-Annacotty'!E18+'City Centre'!E18+'Corbally-Grove Island'!E18+Dooradoyle!E18+'Kings Island'!E18+'Singland-Garryowen'!E18+Southhill!E18+Abbeyfeale!E18+Caherconlish!E18+Castleconnell!E18+Kilmallock!E18+'Newcastle West'!E18+Rathkeale!E18+Adare!E18+Askeaton!E18+Bruff!E18+Cappamore!E18+Croom!E18+Hospital!E18+Kilfinnane!E18+Moroe!E18+Patrickswell!E18+'Rest of county'!E18 -> 412 | F18: =Ballinacurra!F18+Caherdavin!F18+'Castletroy-Annacotty'!F18+'City Centre'!F18+'Corbally-Grove Island'!F18+Dooradoyle!F18+'Kings Island'!F18+'Singland-Garryowen'!F18+Southhill!F18+Abbeyfeale!F18+Caherconlish!F18+Castleconnell!F18+Kilmallock!F18+'Newcastle West'!F18+Rathkeale!F18+Adare!F18+Askeaton!F18+Bruff!F18+Cappamore!F18+Croom!F18+Hospital!F18+Kilfinnane!F18+Moroe!F18+Patrickswell!F18+'Rest of county'!F18 -> 596 | G18: =Ballinacurra!G18+Caherdavin!G18+'Castletroy-Annacotty'!G18+'City Centre'!G18+'Corbally-Grove Island'!G18+Dooradoyle!G18+'Kings Island'!G18+'Singland-Garryowen'!G18+Southhill!G18+Abbeyfeale!G18+Caherconlish!G18+Castleconnell!G18+Kilmallock!G18+'Newcastle West'!G18+Rathkeale!G18+Adare!G18+Askeaton!G18+Bruff!G18+Cappamore!G18+Croom!G18+Hospital!G18+Kilfinnane!G18+Moroe!G18+Patrickswell!G18+'Rest of county'!G18 -> 1152.4926 | H18: =Ballinacurra!H18+Caherdavin!H18+'Castletroy-Annacotty'!H18+'City Centre'!H18+'Corbally-Grove Island'!H18+Dooradoyle!H18+'Kings Island'!H18+'Singland-Garryowen'!H18+Southhill!H18+Abbeyfeale!H18+Caherconlish!H18+Castleconnell!H18+Kilmallock!H18+'Newcastle West'!H18+Rathkeale!H18+Adare!H18+Askeaton!H18+Bruff!H18+Cappamore!H18+Croom!H18+Hospital!H18+Kilfinnane!H18+Moroe!H18+Patrickswell!H18+'Rest of county'!H18 -> 287.78328 | I18: =Ballinacurra!I18+Caherdavin!I18+'Castletroy-Annacotty'!I18+'City Centre'!I18+'Corbally-Grove Island'!I18+Dooradoyle!I18+'Kings Island'!I18+'Singland-Garryowen'!I18+Southhill!I18+Abbeyfeale!I18+Caherconlish!I18+Castleconnell!I18+Kilmallock!I18+'Newcastle West'!I18+Rathkeale!I18+Adare!I18+Askeaton!I18+Bruff!I18+Cappamore!I18+Croom!I18+Hospital!I18+Kilfinnane!I18+Moroe!I18+Patrickswell!I18+'Rest of county'!I18 -> 136.46866 | ... O18: =Ballinacurra!O18+Caherdavin!O18+'Castletroy-Annacotty'!O18+'City Centre'!O18+'Corbally-Grove Island'!O18+Dooradoyle!O18+'Kings Island'!O18+'Singland-Garryowen'!O18+Southhill!O18+Abbeyfeale!O18+Caherconlish!O18+Castleconnell!O18+Kilmallock!O18+'Newcastle West'!O18+Rathkeale!O18+Adare!O18+Askeaton!O18+Bruff!O18+Cappamore!O18+Croom!O18+Hospital!O18+Kilfinnane!O18+Moroe!O18+Patrickswell!O18+'Rest of county'!O18 -> 8.4507211
A19: 2032 | B19: =Ballinacurra!B19+Caherdavin!B19+'Castletroy-Annacotty'!B19+'City Centre'!B19+'Corbally-Grove Island'!B19+Dooradoyle!B19+'Kings Island'!B19+'Singland-Garryowen'!B19+Southhill!B19+Abbeyfeale!B19+Caherconlish!B19+Castleconnell!B19+Kilmallock!B19+'Newcastle West'!B19+Rathkeale!B19+Adare!B19+Askeaton!B19+Bruff!B19+Cappamore!B19+Croom!B19+Hospital!B19+Kilfinnane!B19+Moroe!B19+Patrickswell!B19+'Rest of county'!B19 -> 2168 | C19: =Ballinacurra!C19+Caherdavin!C19+'Castletroy-Annacotty'!C19+'City Centre'!C19+'Corbally-Grove Island'!C19+Dooradoyle!C19+'Kings Island'!C19+'Singland-Garryowen'!C19+Southhill!C19+Abbeyfeale!C19+Caherconlish!C19+Castleconnell!C19+Kilmallock!C19+'Newcastle West'!C19+Rathkeale!C19+Adare!C19+Askeaton!C19+Bruff!C19+Cappamore!C19+Croom!C19+Hospital!C19+Kilfinnane!C19+Moroe!C19+Patrickswell!C19+'Rest of county'!C19 -> 482 | D19: =Ballinacurra!D19+Caherdavin!D19+'Castletroy-Annacotty'!D19+'City Centre'!D19+'Corbally-Grove Island'!D19+Dooradoyle!D19+'Kings Island'!D19+'Singland-Garryowen'!D19+Southhill!D19+Abbeyfeale!D19+Caherconlish!D19+Castleconnell!D19+Kilmallock!D19+'Newcastle West'!D19+Rathkeale!D19+Adare!D19+Askeaton!D19+Bruff!D19+Cappamore!D19+Croom!D19+Hospital!D19+Kilfinnane!D19+Moroe!D19+Patrickswell!D19+'Rest of county'!D19 -> 646 | E19: =Ballinacurra!E19+Caherdavin!E19+'Castletroy-Annacotty'!E19+'City Centre'!E19+'Corbally-Grove Island'!E19+Dooradoyle!E19+'Kings Island'!E19+'Singland-Garryowen'!E19+Southhill!E19+Abbeyfeale!E19+Caherconlish!E19+Castleconnell!E19+Kilmallock!E19+'Newcastle West'!E19+Rathkeale!E19+Adare!E19+Askeaton!E19+Bruff!E19+Cappamore!E19+Croom!E19+Hospital!E19+Kilfinnane!E19+Moroe!E19+Patrickswell!E19+'Rest of county'!E19 -> 419 | F19: =Ballinacurra!F19+Caherdavin!F19+'Castletroy-Annacotty'!F19+'City Centre'!F19+'Corbally-Grove Island'!F19+Dooradoyle!F19+'Kings Island'!F19+'Singland-Garryowen'!F19+Southhill!F19+Abbeyfeale!F19+Caherconlish!F19+Castleconnell!F19+Kilmallock!F19+'Newcastle West'!F19+Rathkeale!F19+Adare!F19+Askeaton!F19+Bruff!F19+Cappamore!F19+Croom!F19+Hospital!F19+Kilfinnane!F19+Moroe!F19+Patrickswell!F19+'Rest of county'!F19 -> 621 | G19: =Ballinacurra!G19+Caherdavin!G19+'Castletroy-Annacotty'!G19+'City Centre'!G19+'Corbally-Grove Island'!G19+Dooradoyle!G19+'Kings Island'!G19+'Singland-Garryowen'!G19+Southhill!G19+Abbeyfeale!G19+Caherconlish!G19+Castleconnell!G19+Kilmallock!G19+'Newcastle West'!G19+Rathkeale!G19+Adare!G19+Askeaton!G19+Bruff!G19+Cappamore!G19+Croom!G19+Hospital!G19+Kilfinnane!G19+Moroe!G19+Patrickswell!G19+'Rest of county'!G19 -> 1152.4926 | H19: =Ballinacurra!H19+Caherdavin!H19+'Castletroy-Annacotty'!H19+'City Centre'!H19+'Corbally-Grove Island'!H19+Dooradoyle!H19+'Kings Island'!H19+'Singland-Garryowen'!H19+Southhill!H19+Abbeyfeale!H19+Caherconlish!H19+Castleconnell!H19+Kilmallock!H19+'Newcastle West'!H19+Rathkeale!H19+Adare!H19+Askeaton!H19+Bruff!H19+Cappamore!H19+Croom!H19+Hospital!H19+Kilfinnane!H19+Moroe!H19+Patrickswell!H19+'Rest of county'!H19 -> 287.78328 | I19: =Ballinacurra!I19+Caherdavin!I19+'Castletroy-Annacotty'!I19+'City Centre'!I19+'Corbally-Grove Island'!I19+Dooradoyle!I19+'Kings Island'!I19+'Singland-Garryowen'!I19+Southhill!I19+Abbeyfeale!I19+Caherconlish!I19+Castleconnell!I19+Kilmallock!I19+'Newcastle West'!I19+Rathkeale!I19+Adare!I19+Askeaton!I19+Bruff!I19+Cappamore!I19+Croom!I19+Hospital!I19+Kilfinnane!I19+Moroe!I19+Patrickswell!I19+'Rest of county'!I19 -> 136.46866 | ... O19: =Ballinacurra!O19+Caherdavin!O19+'Castletroy-Annacotty'!O19+'City Centre'!O19+'Corbally-Grove Island'!O19+Dooradoyle!O19+'Kings Island'!O19+'Singland-Garryowen'!O19+Southhill!O19+Abbeyfeale!O19+Caherconlish!O19+Castleconnell!O19+Kilmallock!O19+'Newcastle West'!O19+Rathkeale!O19+Adare!O19+Askeaton!O19+Bruff!O19+Cappamore!O19+Croom!O19+Hospital!O19+Kilfinnane!O19+Moroe!O19+Patrickswell!O19+'Rest of county'!O19 -> 8.4507211
A20: 2033 | B20: =Ballinacurra!B20+Caherdavin!B20+'Castletroy-Annacotty'!B20+'City Centre'!B20+'Corbally-Grove Island'!B20+Dooradoyle!B20+'Kings Island'!B20+'Singland-Garryowen'!B20+Southhill!B20+Abbeyfeale!B20+Caherconlish!B20+Castleconnell!B20+Kilmallock!B20+'Newcastle West'!B20+Rathkeale!B20+Adare!B20+Askeaton!B20+Bruff!B20+Cappamore!B20+Croom!B20+Hospital!B20+Kilfinnane!B20+Moroe!B20+Patrickswell!B20+'Rest of county'!B20 -> 2168 | C20: =Ballinacurra!C20+Caherdavin!C20+'Castletroy-Annacotty'!C20+'City Centre'!C20+'Corbally-Grove Island'!C20+Dooradoyle!C20+'Kings Island'!C20+'Singland-Garryowen'!C20+Southhill!C20+Abbeyfeale!C20+Caherconlish!C20+Castleconnell!C20+Kilmallock!C20+'Newcastle West'!C20+Rathkeale!C20+Adare!C20+Askeaton!C20+Bruff!C20+Cappamore!C20+Croom!C20+Hospital!C20+Kilfinnane!C20+Moroe!C20+Patrickswell!C20+'Rest of county'!C20 -> 478.22058 | D20: =Ballinacurra!D20+Caherdavin!D20+'Castletroy-Annacotty'!D20+'City Centre'!D20+'Corbally-Grove Island'!D20+Dooradoyle!D20+'Kings Island'!D20+'Singland-Garryowen'!D20+Southhill!D20+Abbeyfeale!D20+Caherconlish!D20+Castleconnell!D20+Kilmallock!D20+'Newcastle West'!D20+Rathkeale!D20+Adare!D20+Askeaton!D20+Bruff!D20+Cappamore!D20+Croom!D20+Hospital!D20+Kilfinnane!D20+Moroe!D20+Patrickswell!D20+'Rest of county'!D20 -> 648.29903 | E20: =Ballinacurra!E20+Caherdavin!E20+'Castletroy-Annacotty'!E20+'City Centre'!E20+'Corbally-Grove Island'!E20+Dooradoyle!E20+'Kings Island'!E20+'Singland-Garryowen'!E20+Southhill!E20+Abbeyfeale!E20+Caherconlish!E20+Castleconnell!E20+Kilmallock!E20+'Newcastle West'!E20+Rathkeale!E20+Adare!E20+Askeaton!E20+Bruff!E20+Cappamore!E20+Croom!E20+Hospital!E20+Kilfinnane!E20+Moroe!E20+Patrickswell!E20+'Rest of county'!E20 -> 419.19335 | F20: =Ballinacurra!F20+Caherdavin!F20+'Castletroy-Annacotty'!F20+'City Centre'!F20+'Corbally-Grove Island'!F20+Dooradoyle!F20+'Kings Island'!F20+'Singland-Garryowen'!F20+Southhill!F20+Abbeyfeale!F20+Caherconlish!F20+Castleconnell!F20+Kilmallock!F20+'Newcastle West'!F20+Rathkeale!F20+Adare!F20+Askeaton!F20+Bruff!F20+Cappamore!F20+Croom!F20+Hospital!F20+Kilfinnane!F20+Moroe!F20+Patrickswell!F20+'Rest of county'!F20 -> 622.28703 | G20: =Ballinacurra!G20+Caherdavin!G20+'Castletroy-Annacotty'!G20+'City Centre'!G20+'Corbally-Grove Island'!G20+Dooradoyle!G20+'Kings Island'!G20+'Singland-Garryowen'!G20+Southhill!G20+Abbeyfeale!G20+Caherconlish!G20+Castleconnell!G20+Kilmallock!G20+'Newcastle West'!G20+Rathkeale!G20+Adare!G20+Askeaton!G20+Bruff!G20+Cappamore!G20+Croom!G20+Hospital!G20+Kilfinnane!G20+Moroe!G20+Patrickswell!G20+'Rest of county'!G20 -> 1152.4926 | H20: =Ballinacurra!H20+Caherdavin!H20+'Castletroy-Annacotty'!H20+'City Centre'!H20+'Corbally-Grove Island'!H20+Dooradoyle!H20+'Kings Island'!H20+'Singland-Garryowen'!H20+Southhill!H20+Abbeyfeale!H20+Caherconlish!H20+Castleconnell!H20+Kilmallock!H20+'Newcastle West'!H20+Rathkeale!H20+Adare!H20+Askeaton!H20+Bruff!H20+Cappamore!H20+Croom!H20+Hospital!H20+Kilfinnane!H20+Moroe!H20+Patrickswell!H20+'Rest of county'!H20 -> 287.78328 | I20: =Ballinacurra!I20+Caherdavin!I20+'Castletroy-Annacotty'!I20+'City Centre'!I20+'Corbally-Grove Island'!I20+Dooradoyle!I20+'Kings Island'!I20+'Singland-Garryowen'!I20+Southhill!I20+Abbeyfeale!I20+Caherconlish!I20+Castleconnell!I20+Kilmallock!I20+'Newcastle West'!I20+Rathkeale!I20+Adare!I20+Askeaton!I20+Bruff!I20+Cappamore!I20+Croom!I20+Hospital!I20+Kilfinnane!I20+Moroe!I20+Patrickswell!I20+'Rest of county'!I20 -> 136.46866 | ... O20: =Ballinacurra!O20+Caherdavin!O20+'Castletroy-Annacotty'!O20+'City Centre'!O20+'Corbally-Grove Island'!O20+Dooradoyle!O20+'Kings Island'!O20+'Singland-Garryowen'!O20+Southhill!O20+Abbeyfeale!O20+Caherconlish!O20+Castleconnell!O20+Kilmallock!O20+'Newcastle West'!O20+Rathkeale!O20+Adare!O20+Askeaton!O20+Bruff!O20+Cappamore!O20+Croom!O20+Hospital!O20+Kilfinnane!O20+Moroe!O20+Patrickswell!O20+'Rest of county'!O20 -> 8.4507211
A21: 2034 | B21: =Ballinacurra!B21+Caherdavin!B21+'Castletroy-Annacotty'!B21+'City Centre'!B21+'Corbally-Grove Island'!B21+Dooradoyle!B21+'Kings Island'!B21+'Singland-Garryowen'!B21+Southhill!B21+Abbeyfeale!B21+Caherconlish!B21+Castleconnell!B21+Kilmallock!B21+'Newcastle West'!B21+Rathkeale!B21+Adare!B21+Askeaton!B21+Bruff!B21+Cappamore!B21+Croom!B21+Hospital!B21+Kilfinnane!B21+Moroe!B21+Patrickswell!B21+'Rest of county'!B21 -> 2168 | C21: =Ballinacurra!C21+Caherdavin!C21+'Castletroy-Annacotty'!C21+'City Centre'!C21+'Corbally-Grove Island'!C21+Dooradoyle!C21+'Kings Island'!C21+'Singland-Garryowen'!C21+Southhill!C21+Abbeyfeale!C21+Caherconlish!C21+Castleconnell!C21+Kilmallock!C21+'Newcastle West'!C21+Rathkeale!C21+Adare!C21+Askeaton!C21+Bruff!C21+Cappamore!C21+Croom!C21+Hospital!C21+Kilfinnane!C21+Moroe!C21+Patrickswell!C21+'Rest of county'!C21 -> 474 | D21: =Ballinacurra!D21+Caherdavin!D21+'Castletroy-Annacotty'!D21+'City Centre'!D21+'Corbally-Grove Island'!D21+Dooradoyle!D21+'Kings Island'!D21+'Singland-Garryowen'!D21+Southhill!D21+Abbeyfeale!D21+Caherconlish!D21+Castleconnell!D21+Kilmallock!D21+'Newcastle West'!D21+Rathkeale!D21+Adare!D21+Askeaton!D21+Bruff!D21+Cappamore!D21+Croom!D21+Hospital!D21+Kilfinnane!D21+Moroe!D21+Patrickswell!D21+'Rest of county'!D21 -> 650 | E21: =Ballinacurra!E21+Caherdavin!E21+'Castletroy-Annacotty'!E21+'City Centre'!E21+'Corbally-Grove Island'!E21+Dooradoyle!E21+'Kings Island'!E21+'Singland-Garryowen'!E21+Southhill!E21+Abbeyfeale!E21+Caherconlish!E21+Castleconnell!E21+Kilmallock!E21+'Newcastle West'!E21+Rathkeale!E21+Adare!E21+Askeaton!E21+Bruff!E21+Cappamore!E21+Croom!E21+Hospital!E21+Kilfinnane!E21+Moroe!E21+Patrickswell!E21+'Rest of county'!E21 -> 419 | F21: =Ballinacurra!F21+Caherdavin!F21+'Castletroy-Annacotty'!F21+'City Centre'!F21+'Corbally-Grove Island'!F21+Dooradoyle!F21+'Kings Island'!F21+'Singland-Garryowen'!F21+Southhill!F21+Abbeyfeale!F21+Caherconlish!F21+Castleconnell!F21+Kilmallock!F21+'Newcastle West'!F21+Rathkeale!F21+Adare!F21+Askeaton!F21+Bruff!F21+Cappamore!F21+Croom!F21+Hospital!F21+Kilfinnane!F21+Moroe!F21+Patrickswell!F21+'Rest of county'!F21 -> 625 | G21: =Ballinacurra!G21+Caherdavin!G21+'Castletroy-Annacotty'!G21+'City Centre'!G21+'Corbally-Grove Island'!G21+Dooradoyle!G21+'Kings Island'!G21+'Singland-Garryowen'!G21+Southhill!G21+Abbeyfeale!G21+Caherconlish!G21+Castleconnell!G21+Kilmallock!G21+'Newcastle West'!G21+Rathkeale!G21+Adare!G21+Askeaton!G21+Bruff!G21+Cappamore!G21+Croom!G21+Hospital!G21+Kilfinnane!G21+Moroe!G21+Patrickswell!G21+'Rest of county'!G21 -> 1152.4926 | H21: =Ballinacurra!H21+Caherdavin!H21+'Castletroy-Annacotty'!H21+'City Centre'!H21+'Corbally-Grove Island'!H21+Dooradoyle!H21+'Kings Island'!H21+'Singland-Garryowen'!H21+Southhill!H21+Abbeyfeale!H21+Caherconlish!H21+Castleconnell!H21+Kilmallock!H21+'Newcastle West'!H21+Rathkeale!H21+Adare!H21+Askeaton!H21+Bruff!H21+Cappamore!H21+Croom!H21+Hospital!H21+Kilfinnane!H21+Moroe!H21+Patrickswell!H21+'Rest of county'!H21 -> 287.78328 | I21: =Ballinacurra!I21+Caherdavin!I21+'Castletroy-Annacotty'!I21+'City Centre'!I21+'Corbally-Grove Island'!I21+Dooradoyle!I21+'Kings Island'!I21+'Singland-Garryowen'!I21+Southhill!I21+Abbeyfeale!I21+Caherconlish!I21+Castleconnell!I21+Kilmallock!I21+'Newcastle West'!I21+Rathkeale!I21+Adare!I21+Askeaton!I21+Bruff!I21+Cappamore!I21+Croom!I21+Hospital!I21+Kilfinnane!I21+Moroe!I21+Patrickswell!I21+'Rest of county'!I21 -> 136.46866 | ... O21: =Ballinacurra!O21+Caherdavin!O21+'Castletroy-Annacotty'!O21+'City Centre'!O21+'Corbally-Grove Island'!O21+Dooradoyle!O21+'Kings Island'!O21+'Singland-Garryowen'!O21+Southhill!O21+Abbeyfeale!O21+Caherconlish!O21+Castleconnell!O21+Kilmallock!O21+'Newcastle West'!O21+Rathkeale!O21+Adare!O21+Askeaton!O21+Bruff!O21+Cappamore!O21+Croom!O21+Hospital!O21+Kilfinnane!O21+Moroe!O21+Patrickswell!O21+'Rest of county'!O21 -> 8.4507211
A22: 2035 | B22: =Ballinacurra!B22+Caherdavin!B22+'Castletroy-Annacotty'!B22+'City Centre'!B22+'Corbally-Grove Island'!B22+Dooradoyle!B22+'Kings Island'!B22+'Singland-Garryowen'!B22+Southhill!B22+Abbeyfeale!B22+Caherconlish!B22+Castleconnell!B22+Kilmallock!B22+'Newcastle West'!B22+Rathkeale!B22+Adare!B22+Askeaton!B22+Bruff!B22+Cappamore!B22+Croom!B22+Hospital!B22+Kilfinnane!B22+Moroe!B22+Patrickswell!B22+'Rest of county'!B22 -> 2095 | C22: =Ballinacurra!C22+Caherdavin!C22+'Castletroy-Annacotty'!C22+'City Centre'!C22+'Corbally-Grove Island'!C22+Dooradoyle!C22+'Kings Island'!C22+'Singland-Garryowen'!C22+Southhill!C22+Abbeyfeale!C22+Caherconlish!C22+Castleconnell!C22+Kilmallock!C22+'Newcastle West'!C22+Rathkeale!C22+Adare!C22+Askeaton!C22+Bruff!C22+Cappamore!C22+Croom!C22+Hospital!C22+Kilfinnane!C22+Moroe!C22+Patrickswell!C22+'Rest of county'!C22 -> 449 | D22: =Ballinacurra!D22+Caherdavin!D22+'Castletroy-Annacotty'!D22+'City Centre'!D22+'Corbally-Grove Island'!D22+Dooradoyle!D22+'Kings Island'!D22+'Singland-Garryowen'!D22+Southhill!D22+Abbeyfeale!D22+Caherconlish!D22+Castleconnell!D22+Kilmallock!D22+'Newcastle West'!D22+Rathkeale!D22+Adare!D22+Askeaton!D22+Bruff!D22+Cappamore!D22+Croom!D22+Hospital!D22+Kilfinnane!D22+Moroe!D22+Patrickswell!D22+'Rest of county'!D22 -> 619 | E22: =Ballinacurra!E22+Caherdavin!E22+'Castletroy-Annacotty'!E22+'City Centre'!E22+'Corbally-Grove Island'!E22+Dooradoyle!E22+'Kings Island'!E22+'Singland-Garryowen'!E22+Southhill!E22+Abbeyfeale!E22+Caherconlish!E22+Castleconnell!E22+Kilmallock!E22+'Newcastle West'!E22+Rathkeale!E22+Adare!E22+Askeaton!E22+Bruff!E22+Cappamore!E22+Croom!E22+Hospital!E22+Kilfinnane!E22+Moroe!E22+Patrickswell!E22+'Rest of county'!E22 -> 402 | F22: =Ballinacurra!F22+Caherdavin!F22+'Castletroy-Annacotty'!F22+'City Centre'!F22+'Corbally-Grove Island'!F22+Dooradoyle!F22+'Kings Island'!F22+'Singland-Garryowen'!F22+Southhill!F22+Abbeyfeale!F22+Caherconlish!F22+Castleconnell!F22+Kilmallock!F22+'Newcastle West'!F22+Rathkeale!F22+Adare!F22+Askeaton!F22+Bruff!F22+Cappamore!F22+Croom!F22+Hospital!F22+Kilfinnane!F22+Moroe!F22+Patrickswell!F22+'Rest of county'!F22 -> 625 | G22: =Ballinacurra!G22+Caherdavin!G22+'Castletroy-Annacotty'!G22+'City Centre'!G22+'Corbally-Grove Island'!G22+Dooradoyle!G22+'Kings Island'!G22+'Singland-Garryowen'!G22+Southhill!G22+Abbeyfeale!G22+Caherconlish!G22+Castleconnell!G22+Kilmallock!G22+'Newcastle West'!G22+Rathkeale!G22+Adare!G22+Askeaton!G22+Bruff!G22+Cappamore!G22+Croom!G22+Hospital!G22+Kilfinnane!G22+Moroe!G22+Patrickswell!G22+'Rest of county'!G22 -> 1113.6864 | H22: =Ballinacurra!H22+Caherdavin!H22+'Castletroy-Annacotty'!H22+'City Centre'!H22+'Corbally-Grove Island'!H22+Dooradoyle!H22+'Kings Island'!H22+'Singland-Garryowen'!H22+Southhill!H22+Abbeyfeale!H22+Caherconlish!H22+Castleconnell!H22+Kilmallock!H22+'Newcastle West'!H22+Rathkeale!H22+Adare!H22+Askeaton!H22+Bruff!H22+Cappamore!H22+Croom!H22+Hospital!H22+Kilfinnane!H22+Moroe!H22+Patrickswell!H22+'Rest of county'!H22 -> 278.09316 | I22: =Ballinacurra!I22+Caherdavin!I22+'Castletroy-Annacotty'!I22+'City Centre'!I22+'Corbally-Grove Island'!I22+Dooradoyle!I22+'Kings Island'!I22+'Singland-Garryowen'!I22+Southhill!I22+Abbeyfeale!I22+Caherconlish!I22+Castleconnell!I22+Kilmallock!I22+'Newcastle West'!I22+Rathkeale!I22+Adare!I22+Askeaton!I22+Bruff!I22+Cappamore!I22+Croom!I22+Hospital!I22+Kilfinnane!I22+Moroe!I22+Patrickswell!I22+'Rest of county'!I22 -> 131.87354 | ... O22: =Ballinacurra!O22+Caherdavin!O22+'Castletroy-Annacotty'!O22+'City Centre'!O22+'Corbally-Grove Island'!O22+Dooradoyle!O22+'Kings Island'!O22+'Singland-Garryowen'!O22+Southhill!O22+Abbeyfeale!O22+Caherconlish!O22+Castleconnell!O22+Kilmallock!O22+'Newcastle West'!O22+Rathkeale!O22+Adare!O22+Askeaton!O22+Bruff!O22+Cappamore!O22+Croom!O22+Hospital!O22+Kilfinnane!O22+Moroe!O22+Patrickswell!O22+'Rest of county'!O22 -> 8.1661719
A23: 2036 | B23: =Ballinacurra!B23+Caherdavin!B23+'Castletroy-Annacotty'!B23+'City Centre'!B23+'Corbally-Grove Island'!B23+Dooradoyle!B23+'Kings Island'!B23+'Singland-Garryowen'!B23+Southhill!B23+Abbeyfeale!B23+Caherconlish!B23+Castleconnell!B23+Kilmallock!B23+'Newcastle West'!B23+Rathkeale!B23+Adare!B23+Askeaton!B23+Bruff!B23+Cappamore!B23+Croom!B23+Hospital!B23+Kilfinnane!B23+Moroe!B23+Patrickswell!B23+'Rest of county'!B23 -> 1587 | C23: =Ballinacurra!C23+Caherdavin!C23+'Castletroy-Annacotty'!C23+'City Centre'!C23+'Corbally-Grove Island'!C23+Dooradoyle!C23+'Kings Island'!C23+'Singland-Garryowen'!C23+Southhill!C23+Abbeyfeale!C23+Caherconlish!C23+Castleconnell!C23+Kilmallock!C23+'Newcastle West'!C23+Rathkeale!C23+Adare!C23+Askeaton!C23+Bruff!C23+Cappamore!C23+Croom!C23+Hospital!C23+Kilfinnane!C23+Moroe!C23+Patrickswell!C23+'Rest of county'!C23 -> 382.83698 | D23: =Ballinacurra!D23+Caherdavin!D23+'Castletroy-Annacotty'!D23+'City Centre'!D23+'Corbally-Grove Island'!D23+Dooradoyle!D23+'Kings Island'!D23+'Singland-Garryowen'!D23+Southhill!D23+Abbeyfeale!D23+Caherconlish!D23+Castleconnell!D23+Kilmallock!D23+'Newcastle West'!D23+Rathkeale!D23+Adare!D23+Askeaton!D23+Bruff!D23+Cappamore!D23+Croom!D23+Hospital!D23+Kilfinnane!D23+Moroe!D23+Patrickswell!D23+'Rest of county'!D23 -> 492.40978 | E23: =Ballinacurra!E23+Caherdavin!E23+'Castletroy-Annacotty'!E23+'City Centre'!E23+'Corbally-Grove Island'!E23+Dooradoyle!E23+'Kings Island'!E23+'Singland-Garryowen'!E23+Southhill!E23+Abbeyfeale!E23+Caherconlish!E23+Castleconnell!E23+Kilmallock!E23+'Newcastle West'!E23+Rathkeale!E23+Adare!E23+Askeaton!E23+Bruff!E23+Cappamore!E23+Croom!E23+Hospital!E23+Kilfinnane!E23+Moroe!E23+Patrickswell!E23+'Rest of county'!E23 -> 296.76173 | F23: =Ballinacurra!F23+Caherdavin!F23+'Castletroy-Annacotty'!F23+'City Centre'!F23+'Corbally-Grove Island'!F23+Dooradoyle!F23+'Kings Island'!F23+'Singland-Garryowen'!F23+Southhill!F23+Abbeyfeale!F23+Caherconlish!F23+Castleconnell!F23+Kilmallock!F23+'Newcastle West'!F23+Rathkeale!F23+Adare!F23+Askeaton!F23+Bruff!F23+Cappamore!F23+Croom!F23+Hospital!F23+Kilfinnane!F23+Moroe!F23+Patrickswell!F23+'Rest of county'!F23 -> 414.99152 | G23: =Ballinacurra!G23+Caherdavin!G23+'Castletroy-Annacotty'!G23+'City Centre'!G23+'Corbally-Grove Island'!G23+Dooradoyle!G23+'Kings Island'!G23+'Singland-Garryowen'!G23+Southhill!G23+Abbeyfeale!G23+Caherconlish!G23+Castleconnell!G23+Kilmallock!G23+'Newcastle West'!G23+Rathkeale!G23+Adare!G23+Askeaton!G23+Bruff!G23+Cappamore!G23+Croom!G23+Hospital!G23+Kilfinnane!G23+Moroe!G23+Patrickswell!G23+'Rest of county'!G23 -> 843.63737 | H23: =Ballinacurra!H23+Caherdavin!H23+'Castletroy-Annacotty'!H23+'City Centre'!H23+'Corbally-Grove Island'!H23+Dooradoyle!H23+'Kings Island'!H23+'Singland-Garryowen'!H23+Southhill!H23+Abbeyfeale!H23+Caherconlish!H23+Castleconnell!H23+Kilmallock!H23+'Newcastle West'!H23+Rathkeale!H23+Adare!H23+Askeaton!H23+Bruff!H23+Cappamore!H23+Croom!H23+Hospital!H23+Kilfinnane!H23+Moroe!H23+Patrickswell!H23+'Rest of county'!H23 -> 210.66055 | I23: =Ballinacurra!I23+Caherdavin!I23+'Castletroy-Annacotty'!I23+'City Centre'!I23+'Corbally-Grove Island'!I23+Dooradoyle!I23+'Kings Island'!I23+'Singland-Garryowen'!I23+Southhill!I23+Abbeyfeale!I23+Caherconlish!I23+Castleconnell!I23+Kilmallock!I23+'Newcastle West'!I23+Rathkeale!I23+Adare!I23+Askeaton!I23+Bruff!I23+Cappamore!I23+Croom!I23+Hospital!I23+Kilfinnane!I23+Moroe!I23+Patrickswell!I23+'Rest of county'!I23 -> 99.896569 | ... O23: =Ballinacurra!O23+Caherdavin!O23+'Castletroy-Annacotty'!O23+'City Centre'!O23+'Corbally-Grove Island'!O23+Dooradoyle!O23+'Kings Island'!O23+'Singland-Garryowen'!O23+Southhill!O23+Abbeyfeale!O23+Caherconlish!O23+Castleconnell!O23+Kilmallock!O23+'Newcastle West'!O23+Rathkeale!O23+Adare!O23+Askeaton!O23+Bruff!O23+Cappamore!O23+Croom!O23+Hospital!O23+Kilfinnane!O23+Moroe!O23+Patrickswell!O23+'Rest of county'!O23 -> 6.1860214
A24: 2037 | B24: =Ballinacurra!B24+Caherdavin!B24+'Castletroy-Annacotty'!B24+'City Centre'!B24+'Corbally-Grove Island'!B24+Dooradoyle!B24+'Kings Island'!B24+'Singland-Garryowen'!B24+Southhill!B24+Abbeyfeale!B24+Caherconlish!B24+Castleconnell!B24+Kilmallock!B24+'Newcastle West'!B24+Rathkeale!B24+Adare!B24+Askeaton!B24+Bruff!B24+Cappamore!B24+Croom!B24+Hospital!B24+Kilfinnane!B24+Moroe!B24+Patrickswell!B24+'Rest of county'!B24 -> 1574 | C24: =Ballinacurra!C24+Caherdavin!C24+'Castletroy-Annacotty'!C24+'City Centre'!C24+'Corbally-Grove Island'!C24+Dooradoyle!C24+'Kings Island'!C24+'Singland-Garryowen'!C24+Southhill!C24+Abbeyfeale!C24+Caherconlish!C24+Castleconnell!C24+Kilmallock!C24+'Newcastle West'!C24+Rathkeale!C24+Adare!C24+Askeaton!C24+Bruff!C24+Cappamore!C24+Croom!C24+Hospital!C24+Kilfinnane!C24+Moroe!C24+Patrickswell!C24+'Rest of county'!C24 -> 379.70094 | D24: =Ballinacurra!D24+Caherdavin!D24+'Castletroy-Annacotty'!D24+'City Centre'!D24+'Corbally-Grove Island'!D24+Dooradoyle!D24+'Kings Island'!D24+'Singland-Garryowen'!D24+Southhill!D24+Abbeyfeale!D24+Caherconlish!D24+Castleconnell!D24+Kilmallock!D24+'Newcastle West'!D24+Rathkeale!D24+Adare!D24+Askeaton!D24+Bruff!D24+Cappamore!D24+Croom!D24+Hospital!D24+Kilfinnane!D24+Moroe!D24+Patrickswell!D24+'Rest of county'!D24 -> 488.37617 | E24: =Ballinacurra!E24+Caherdavin!E24+'Castletroy-Annacotty'!E24+'City Centre'!E24+'Corbally-Grove Island'!E24+Dooradoyle!E24+'Kings Island'!E24+'Singland-Garryowen'!E24+Southhill!E24+Abbeyfeale!E24+Caherconlish!E24+Castleconnell!E24+Kilmallock!E24+'Newcastle West'!E24+Rathkeale!E24+Adare!E24+Askeaton!E24+Bruff!E24+Cappamore!E24+Croom!E24+Hospital!E24+Kilfinnane!E24+Moroe!E24+Patrickswell!E24+'Rest of county'!E24 -> 294.33079 | F24: =Ballinacurra!F24+Caherdavin!F24+'Castletroy-Annacotty'!F24+'City Centre'!F24+'Corbally-Grove Island'!F24+Dooradoyle!F24+'Kings Island'!F24+'Singland-Garryowen'!F24+Southhill!F24+Abbeyfeale!F24+Caherconlish!F24+Castleconnell!F24+Kilmallock!F24+'Newcastle West'!F24+Rathkeale!F24+Adare!F24+Askeaton!F24+Bruff!F24+Cappamore!F24+Croom!F24+Hospital!F24+Kilfinnane!F24+Moroe!F24+Patrickswell!F24+'Rest of county'!F24 -> 411.5921 | G24: =Ballinacurra!G24+Caherdavin!G24+'Castletroy-Annacotty'!G24+'City Centre'!G24+'Corbally-Grove Island'!G24+Dooradoyle!G24+'Kings Island'!G24+'Singland-Garryowen'!G24+Southhill!G24+Abbeyfeale!G24+Caherconlish!G24+Castleconnell!G24+Kilmallock!G24+'Newcastle West'!G24+Rathkeale!G24+Adare!G24+Askeaton!G24+Bruff!G24+Cappamore!G24+Croom!G24+Hospital!G24+Kilfinnane!G24+Moroe!G24+Patrickswell!G24+'Rest of county'!G24 -> 836.72667 | H24: =Ballinacurra!H24+Caherdavin!H24+'Castletroy-Annacotty'!H24+'City Centre'!H24+'Corbally-Grove Island'!H24+Dooradoyle!H24+'Kings Island'!H24+'Singland-Garryowen'!H24+Southhill!H24+Abbeyfeale!H24+Caherconlish!H24+Castleconnell!H24+Kilmallock!H24+'Newcastle West'!H24+Rathkeale!H24+Adare!H24+Askeaton!H24+Bruff!H24+Cappamore!H24+Croom!H24+Hospital!H24+Kilfinnane!H24+Moroe!H24+Patrickswell!H24+'Rest of county'!H24 -> 208.93491 | I24: =Ballinacurra!I24+Caherdavin!I24+'Castletroy-Annacotty'!I24+'City Centre'!I24+'Corbally-Grove Island'!I24+Dooradoyle!I24+'Kings Island'!I24+'Singland-Garryowen'!I24+Southhill!I24+Abbeyfeale!I24+Caherconlish!I24+Castleconnell!I24+Kilmallock!I24+'Newcastle West'!I24+Rathkeale!I24+Adare!I24+Askeaton!I24+Bruff!I24+Cappamore!I24+Croom!I24+Hospital!I24+Kilfinnane!I24+Moroe!I24+Patrickswell!I24+'Rest of county'!I24 -> 99.07826 | ... O24: =Ballinacurra!O24+Caherdavin!O24+'Castletroy-Annacotty'!O24+'City Centre'!O24+'Corbally-Grove Island'!O24+Dooradoyle!O24+'Kings Island'!O24+'Singland-Garryowen'!O24+Southhill!O24+Abbeyfeale!O24+Caherconlish!O24+Castleconnell!O24+Kilmallock!O24+'Newcastle West'!O24+Rathkeale!O24+Adare!O24+Askeaton!O24+Bruff!O24+Cappamore!O24+Croom!O24+Hospital!O24+Kilfinnane!O24+Moroe!O24+Patrickswell!O24+'Rest of county'!O24 -> 6.1353483
... A27: 2040 | B27: =Ballinacurra!B27+Caherdavin!B27+'Castletroy-Annacotty'!B27+'City Centre'!B27+'Corbally-Grove Island'!B27+Dooradoyle!B27+'Kings Island'!B27+'Singland-Garryowen'!B27+Southhill!B27+Abbeyfeale!B27+Caherconlish!B27+Castleconnell!B27+Kilmallock!B27+'Newcastle West'!B27+Rathkeale!B27+Adare!B27+Askeaton!B27+Bruff!B27+Cappamore!B27+Croom!B27+Hospital!B27+Kilfinnane!B27+Moroe!B27+Patrickswell!B27+'Rest of county'!B27 -> 1525 | C27: =Ballinacurra!C27+Caherdavin!C27+'Castletroy-Annacotty'!C27+'City Centre'!C27+'Corbally-Grove Island'!C27+Dooradoyle!C27+'Kings Island'!C27+'Singland-Garryowen'!C27+Southhill!C27+Abbeyfeale!C27+Caherconlish!C27+Castleconnell!C27+Kilmallock!C27+'Newcastle West'!C27+Rathkeale!C27+Adare!C27+Askeaton!C27+Bruff!C27+Cappamore!C27+Croom!C27+Hospital!C27+Kilfinnane!C27+Moroe!C27+Patrickswell!C27+'Rest of county'!C27 -> 367.88052 | D27: =Ballinacurra!D27+Caherdavin!D27+'Castletroy-Annacotty'!D27+'City Centre'!D27+'Corbally-Grove Island'!D27+Dooradoyle!D27+'Kings Island'!D27+'Singland-Garryowen'!D27+Southhill!D27+Abbeyfeale!D27+Caherconlish!D27+Castleconnell!D27+Kilmallock!D27+'Newcastle West'!D27+Rathkeale!D27+Adare!D27+Askeaton!D27+Bruff!D27+Cappamore!D27+Croom!D27+Hospital!D27+Kilfinnane!D27+Moroe!D27+Patrickswell!D27+'Rest of county'!D27 -> 473.17259 | E27: =Ballinacurra!E27+Caherdavin!E27+'Castletroy-Annacotty'!E27+'City Centre'!E27+'Corbally-Grove Island'!E27+Dooradoyle!E27+'Kings Island'!E27+'Singland-Garryowen'!E27+Southhill!E27+Abbeyfeale!E27+Caherconlish!E27+Castleconnell!E27+Kilmallock!E27+'Newcastle West'!E27+Rathkeale!E27+Adare!E27+Askeaton!E27+Bruff!E27+Cappamore!E27+Croom!E27+Hospital!E27+Kilfinnane!E27+Moroe!E27+Patrickswell!E27+'Rest of county'!E27 -> 285.16801 | F27: =Ballinacurra!F27+Caherdavin!F27+'Castletroy-Annacotty'!F27+'City Centre'!F27+'Corbally-Grove Island'!F27+Dooradoyle!F27+'Kings Island'!F27+'Singland-Garryowen'!F27+Southhill!F27+Abbeyfeale!F27+Caherconlish!F27+Castleconnell!F27+Kilmallock!F27+'Newcastle West'!F27+Rathkeale!F27+Adare!F27+Askeaton!F27+Bruff!F27+Cappamore!F27+Croom!F27+Hospital!F27+Kilfinnane!F27+Moroe!F27+Patrickswell!F27+'Rest of county'!F27 -> 398.77887 | G27: =Ballinacurra!G27+Caherdavin!G27+'Castletroy-Annacotty'!G27+'City Centre'!G27+'Corbally-Grove Island'!G27+Dooradoyle!G27+'Kings Island'!G27+'Singland-Garryowen'!G27+Southhill!G27+Abbeyfeale!G27+Caherconlish!G27+Castleconnell!G27+Kilmallock!G27+'Newcastle West'!G27+Rathkeale!G27+Adare!G27+Askeaton!G27+Bruff!G27+Cappamore!G27+Croom!G27+Hospital!G27+Kilfinnane!G27+Moroe!G27+Patrickswell!G27+'Rest of county'!G27 -> 810.67863 | H27: =Ballinacurra!H27+Caherdavin!H27+'Castletroy-Annacotty'!H27+'City Centre'!H27+'Corbally-Grove Island'!H27+Dooradoyle!H27+'Kings Island'!H27+'Singland-Garryowen'!H27+Southhill!H27+Abbeyfeale!H27+Caherconlish!H27+Castleconnell!H27+Kilmallock!H27+'Newcastle West'!H27+Rathkeale!H27+Adare!H27+Askeaton!H27+Bruff!H27+Cappamore!H27+Croom!H27+Hospital!H27+Kilfinnane!H27+Moroe!H27+Patrickswell!H27+'Rest of county'!H27 -> 202.43058 | I27: =Ballinacurra!I27+Caherdavin!I27+'Castletroy-Annacotty'!I27+'City Centre'!I27+'Corbally-Grove Island'!I27+Dooradoyle!I27+'Kings Island'!I27+'Singland-Garryowen'!I27+Southhill!I27+Abbeyfeale!I27+Caherconlish!I27+Castleconnell!I27+Kilmallock!I27+'Newcastle West'!I27+Rathkeale!I27+Adare!I27+Askeaton!I27+Bruff!I27+Cappamore!I27+Croom!I27+Hospital!I27+Kilfinnane!I27+Moroe!I27+Patrickswell!I27+'Rest of county'!I27 -> 95.993867 | ... O27: =Ballinacurra!O27+Caherdavin!O27+'Castletroy-Annacotty'!O27+'City Centre'!O27+'Corbally-Grove Island'!O27+Dooradoyle!O27+'Kings Island'!O27+'Singland-Garryowen'!O27+Southhill!O27+Abbeyfeale!O27+Caherconlish!O27+Castleconnell!O27+Kilmallock!O27+'Newcastle West'!O27+Rathkeale!O27+Adare!O27+Askeaton!O27+Bruff!O27+Cappamore!O27+Croom!O27+Hospital!O27+Kilfinnane!O27+Moroe!O27+Patrickswell!O27+'Rest of county'!O27 -> 5.9443495
A28: Total 2026 to end year | B28: =SUM(B13:B27) -> 39864 | C28: =SUM(C13:C27) -> 9616.4848 | D28: =SUM(D13:D27) -> 12368.87 | E28: =SUM(E13:E27) -> 7454.3905 | F28: =SUM(F13:F27) -> 10424.254 | G28: =SUM(G13:G27) -> 21191.405 | H28: =SUM(H13:H27) -> 5291.6018 | I28: =SUM(I13:I27) -> 2509.3112 | ... O28: =SUM(O13:O27) -> 155.38724
A29: Share of new homes | B29: =IF($B$28>0,B28/$B$28,0) -> 1 | C29: =IF($B$28>0,C28/$B$28,0) -> 0.24123231 | D29: =IF($B$28>0,D28/$B$28,0) -> 0.3102767 | E29: =IF($B$28>0,E28/$B$28,0) -> 0.18699555 | F29: =IF($B$28>0,F28/$B$28,0) -> 0.26149544 | G29: =IF($B$28>0,G28/$B$28,0) -> 0.53159255 | H29: =IF($B$28>0,H28/$B$28,0) -> 0.13274137 | I29: =IF($B$28>0,I28/$B$28,0) -> 0.062946798 | ... O29: =IF($B$28>0,O28/$B$28,0) -> 0.0038979341
A32: Unit mix: existing homes, new homes and the two combined at the end year
A33: Bedrooms | B33: Existing homes, 2022 | C33: % | D33: New homes | E33: % | F33: Combined | G33: %
A34: 1-bed | B34: =Ballinacurra!B34+Caherdavin!B34+'Castletroy-Annacotty'!B34+'City Centre'!B34+'Corbally-Grove Island'!B34+Dooradoyle!B34+'Kings Island'!B34+'Singland-Garryowen'!B34+Southhill!B34+Abbeyfeale!B34+Caherconlish!B34+Castleconnell!B34+Kilmallock!B34+'Newcastle West'!B34+Rathkeale!B34+Adare!B34+Askeaton!B34+Bruff!B34+Cappamore!B34+Croom!B34+Hospital!B34+Kilfinnane!B34+Moroe!B34+Patrickswell!B34+'Rest of county'!B34 -> 3527.4533 | C34: =IF($B$38>0,B34/$B$38,0) -> 0.046234397 | D34: =C28 -> 9616.4848 | E34: =IF($D$38>0,D34/$D$38,0) -> 0.24123231 | F34: =B34+D34 -> 13143.938 | G34: =IF($F$38>0,F34/$F$38,0) -> 0.11315471
A35: 2-bed | B35: =Ballinacurra!B35+Caherdavin!B35+'Castletroy-Annacotty'!B35+'City Centre'!B35+'Corbally-Grove Island'!B35+Dooradoyle!B35+'Kings Island'!B35+'Singland-Garryowen'!B35+Southhill!B35+Abbeyfeale!B35+Caherconlish!B35+Castleconnell!B35+Kilmallock!B35+'Newcastle West'!B35+Rathkeale!B35+Adare!B35+Askeaton!B35+Bruff!B35+Cappamore!B35+Croom!B35+Hospital!B35+Kilfinnane!B35+Moroe!B35+Patrickswell!B35+'Rest of county'!B35 -> 13008.087 | C35: =IF($B$38>0,B35/$B$38,0) -> 0.17049723 | D35: =D28 -> 12368.87 | E35: =IF($D$38>0,D35/$D$38,0) -> 0.3102767 | F35: =B35+D35 -> 25376.957 | G35: =IF($F$38>0,F35/$F$38,0) -> 0.21846742
