Workbook

Sheet README
A1: Limerick residential delivery study – data companion
A3: Scheme | B3: A counted residential application from the Limerick pipeline workbook (after primacy rules), plus residential Part 8 schemes in the planning register that CIS does not hold (Source column).
A4: Owner / sector | B4: Public = Limerick City and County Council (incl. Part 8), approved housing bodies, Land Development Agency. From CIS grantee and promoter, building control local-authority and AHB flags, and Part 8 file numbers (yy/8nnn). Turnkey purchases not identified in these sources are classed as private.
A5: City neighbourhood | B5: Nine neighbourhoods defined by Limerick City and County Council from 42 Electoral Divisions (King’s Island, code 1a, shown separately). Schemes outside them are labelled Outside city neighbourhoods.
A6: Planning dates | B6: National Planning Applications dataset (Department of Housing, Local Government and Heritage), Limerick County Council records, queried 29/09/2026. An Coimisiún Pleanála case pages for SHD. CIS dates for Part 8 schemes.
A7: Start on site | B7: Earliest commencement date on a building control commencement notice (National Building Control Office open data, 2014–present) matched by planning reference, including extensions of duration and appeal references. CIS start date used only where no notice matched and CIS records the scheme on site or complete.
A8: Completion | B8: CIS. Date of the first dated CIS update recording the scheme as complete; CIS finish date where no such update exists. Completion certificates were tested but record 328 of the 1,226 units CIS reports complete on the same schemes, so they are not used for completions.
A9: Status | B9: Complete (CIS); Under construction (commencement notice or CIS on site / part complete); Not started – permission live; Not started – past expiry (register expiry, including extensions of duration, before 29/09/2026). Part 8 schemes have no register expiry.
A10: Size bands | B10: 1–9, 10–24, 25–49, 50–99, 100+ units (CIS units).
A11: LEA | B11: Point-in-polygon against Local Electoral Areas 2019 (Tailte Éireann, generalised 20m).
A12: Durations | B12: Approval = application received to final grant (appeal decision date where appealed). Grant to start = final grant to first commencement. Build period = start to completion. Negative intervals (data errors) are dropped.
A13: Formulas | B13: Status, expiry and LEA count/sum tables are live formulas on the Schemes sheet. Medians, quartiles and cumulative start shares were calculated in Python (delivery_analysis.py) and are values.
A14: Contacts | B14: No personal data. Scheme names are CIS project headings.

Sheet Schemes
A1: Planning ref | B1: Register ref | C1: Source | D1: Site ID | E1: Scheme | F1: Settlement | G1: LEA | H1: City neighbourhood | I1: Latitude | J1: Longitude | K1: Units | L1: Size band | M1: Type | N1: Route | O1: Owner | P1: Sector | Q1: CIS stage | R1: Status | S1: Application received | T1: Permission granted | U1: Further information | V1: Appealed | W1: Expiry | X1: Start on site | Y1: Start source | Z1: Commencement notices | AA1: Units on notices | AB1: Completion (CIS) | AC1: Completion certificates | AD1: Units on certificates | AE1: Approval (yrs) | AF1: Grant to start (yrs) | AG1: Build period (yrs) | AH1: Build rate (dpa) | AI1: Relationship | AJ1: Relationship confidence | AK1: CIS notes on barriers | AL1: Completion source | AM1: Social housing project no. | AN1: Social housing programme | AO1: Social housing stage | AP1: Social housing stage quarter | AQ1: Public delivery mode
A2: 22990 | B2: 22990 | C2: CIS | D2: SG-015 | E2: €22m - Residential Development, Adare | F2: Rathkeale | G2: Adare-Rathkeale | H2: Outside city neighbourhoods | I2: 52.558685 | J2: -8.7982115 | K2: 99 | L2: 50–99 | M2: Mixed | N2: Standard planning application | O2: Private | P2: Private | Q2: Permission Granted | R2: Not started – permission live | S2: 44817 | T2: 45713 | U2: Yes | V2: Yes | W2: 47538 | Z2: 0 | AA2: 0 | AC2: 0 | AD2: 0 | AE2: 2.4531143 | AI2: Additional application on site | AJ2: Low
A3: 21630 | B3: 21630 | C3: CIS | D3: U-1166991 | E3: €10.8m - Residential Development, Croom | F3: Other County Limerick | G3: Adare-Rathkeale | H3: Outside city neighbourhoods | I3: 52.525037 | J3: -8.7170903 | K3: 51 | L3: 50–99 | M3: Houses | N3: Standard planning application | O3: Private | P3: Private | Q3: Contract Awarded | R3: Not started – permission live | S3: 44328 | T3: 44693 | U3: Yes | V3: No | W3: 46518 | Z3: 1 | AA3: 12 | AC3: 0 | AD3: 0 | AE3: 0.99931554 | AI3: Primary | AJ3: High
A4: 22410 | B4: 22410 | C4: CIS | D4: P-1225380 | E4: €18.8m - Nursing Home Development, Croom | F4: Other County Limerick | G4: Adare-Rathkeale | H4: Outside city neighbourhoods | I4: 52.522213 | J4: -8.7125164 | K4: 32 | L4: 25–49 | M4: Unknown | N4: Standard planning application | O4: Private | P4: Private | Q4: Permission Granted | R4: Not started – permission live | S4: 44662 | T4: 44977 | U4: Yes | V4: No | W4: 46802 | Z4: 0 | AA4: 0 | AC4: 0 | AD4: 0 | AE4: 0.862423 | AI4: Primary | AJ4: High
A5: 198010 | B5: 198010 | C5: CIS | D5: SG-015 | E5: €5m - Housing Development | F5: Rathkeale | G5: Adare-Rathkeale | H5: Outside city neighbourhoods | I5: 52.557513 | J5: -8.7986152 | K5: 31 | L5: 25–49 | M5: Apartments | N5: Part 8 / council | O5: Public – local authority | P5: Public | Q5: Permission Granted | R5: Not started – permission live | S5: 43759 | T5: 43857 | U5: No | V5: No | Z5: 0 | AA5: 0 | AC5: 0 | AD5: 0 | AE5: 0.26830938 | AI5: Primary | AJ5: High
A6: 24352 | B6: 24352 | C6: CIS | D6: P-1366163 | E6: €7.3m - Residential Development | F6: Other County Limerick | G6: Adare-Rathkeale | H6: Outside city neighbourhoods | I6: 52.649054 | J6: -8.8667748 | K6: 30 | L6: 25–49 | M6: Houses | N6: Standard planning application | O6: Private | P6: Private | Q6: On Site | R6: Under construction | S6: 45547 | T6: 45917 | U6: Yes | V6: No | W6: 47742 | X6: 46013 | Y6: Commencement notice | Z6: 1 | AA6: 30 | AC6: 0 | AD6: 0 | AE6: 1.0130048 | AF6: 0.26283368 | AI6: Primary | AJ6: High
A7: 2660779 | B7: 2660779 | C7: CIS | D7: P-1444384 | E7: €8.6m - Staff Accommodation/8Apartments, Adare | F7: Adare | G7: Adare-Rathkeale | H7: Outside city neighbourhoods | I7: 52.561726 | J7: -8.7657741 | K7: 28 | L7: 25–49 | M7: Apartments | N7: Standard planning application | O7: Private | P7: Private | Q7: Permission Granted | R7: Not started – permission live | S7: 46212 | T7: 46267 | U7: No | V7: No | W7: 48093 | Z7: 0 | AA7: 0 | AC7: 0 | AD7: 0 | AE7: 0.15058179 | AI7: Primary | AJ7: High
A8: 2360793 | B8: 2360793 | C8: CIS | D8: SG-015 | E8: €6.1m - Residential Development, Adare | F8: Rathkeale | G8: Adare-Rathkeale | H8: Outside city neighbourhoods | I8: 52.558434 | J8: -8.7997018 | K8: 28 | L8: 25–49 | M8: Mixed | N8: Standard planning application | O8: Private | P8: Private | Q8: Permission Granted | R8: Not started – permission live | S8: 45231 | T8: 45737 | U8: No | V8: Yes | W8: 47562 | Z8: 0 | AA8: 0 | AC8: 0 | AD8: 0 | AE8: 1.3853525 | AI8: Additional phase | AJ8: Medium
A9: 2460304 | B9: 2460304 | C9: CIS | D9: SG-015 | E9: €6.2m - Residential Development, Adare | F9: Rathkeale | G9: Adare-Rathkeale | H9: Outside city neighbourhoods | I9: 52.560608 | J9: -8.7983532 | K9: 25 | L9: 25–49 | M9: Houses | N9: Standard planning application | O9: Private | P9: Private | Q9: Permission Granted | R9: Not started – permission live | S9: 45391 | T9: 45737 | U9: No | V9: Yes | W9: 47562 | Z9: 0 | AA9: 0 | AC9: 0 | AD9: 0 | AE9: 0.94729637 | AI9: Additional phase | AJ9: Medium
A10: 198005 | B10: 198005 | C10: CIS | D10: P-1058813 | E10: €1.7m - Residential Development | F10: Other County Limerick | G10: Adare-Rathkeale | H10: Outside city neighbourhoods | I10: 52.523142 | J10: -8.7171557 | K10: 16 | L10: 10–24 | M10: Mixed | N10: Part 8 / council | O10: Public – approved housing body | P10: Public | Q10: Complete | R10: Complete | S10: 43668 | T10: 44498 | U10: No | V10: No | X10: 45313 | Y10: Commencement notice | Z10: 1 | AA10: 16 | AB10: 46013 | AC10: 1 | AD10: 1 | AE10: 2.2724162 | AF10: 2.2313484 | AG10: 1.9164956 | AH10: 8.3485714 | AI10: Primary | AJ10: High | AL10: CIS | AM10: 1927 | AN10: CAS AHB Construction | AO10: Completed | AP10: Q4-2025 | AQ10: Construction
A11: 19552 | B11: 19552 | C11: CIS | D11: P-1051821 | E11: €2m - Apartment Development | F11: Other County Limerick | G11: Adare-Rathkeale | H11: Outside city neighbourhoods | I11: 52.524713 | J11: -8.7145002 | K11: 14 | L11: 10–24 | M11: Apartments | N11: Standard planning application | O11: Private | P11: Private | Q11: Permission Granted | R11: Not started – permission live | S11: 43623 | T11: 44148 | U11: Yes | V11: Yes | W11: 47070 | Z11: 0 | AA11: 0 | AC11: 0 | AD11: 0 | AE11: 1.4373717 | AI11: Primary | AJ11: High
A12: 20525 | B12: 20525 | C12: Register only (private, not in CIS) | E12: Register: the construction of 14 dwelling houses, including 2 no semi-detached 2 | F12: Croom | G12: Adare-Rathkeale | H12: Outside city neighbourhoods | I12: 52.523083 | J12: -8.7188044 | K12: 14 | L12: 10–24 | M12: Houses | N12: Standard planning application | O12: Private | P12: Private | Q12: Permission Granted | R12: Not started – permission live | S12: 44001 | T12: 44532 | U12: Yes | V12: Yes | W12: 46357 | Z12: 0 | AA12: 0 | AC12: 0 | AD12: 0 | AE12: 1.4537988 | AI12: Primary
A13: Part 8 - 1345677 | B13: Part 8 - 1345677 | C13: CIS | D13: P-1345677 | E13: €1.5m - New Traveller Welfare Units, Hillview Park | F13: Rathkeale | G13: Adare-Rathkeale | H13: Outside city neighbourhoods | I13: 52.52642 | J13: -8.9374848 | K13: 11 | L13: 10–24 | M13: Unknown | N13: Part 8 / council | O13: Public – local authority | P13: Public | Q13: On Site | R13: Under construction | S13: 45527 | U13: No | V13: No | X13: 45614 | Y13: CIS start date | Z13: 0 | AA13: 0 | AC13: 0 | AD13: 0 | AI13: Primary | AJ13: High
A14: 2560977 | B14: 2560977 | C14: CIS | D14: P-1424781 | E14: €2.7m - Self Catering Accommodation Lodges, Adare | F14: Rathkeale | G14: Adare-Rathkeale | H14: Outside city neighbourhoods | I14: 52.554604 | J14: -8.7893973 | K14: 10 | L14: 10–24 | M14: Houses | N14: Standard planning application | O14: Private | P14: Private | Q14: On Site | R14: Under construction | S14: 45926 | T14: 46104 | U14: Yes | V14: No | W14: 47929 | X14: 46174 | Y14: Commencement notice | Z14: 1 | AA14: 0 | AC14: 0 | AD14: 0 | AE14: 0.48733744 | AF14: 0.19164956 | AI14: Primary | AJ14: High
A15: 24151 | B15: 24151 | C15: Register only (private, not in CIS) | E15: Register: the construction of 10 dwelling units to include 2 no. detached 5 bedr | F15: Croom | G15: Adare-Rathkeale | H15: Outside city neighbourhoods | I15: 52.51598 | J15: -8.7204716 | K15: 10 | L15: 10–24 | M15: Houses | N15: Standard planning application | O15: Private | P15: Private | Q15: Permission Granted | R15: Not started – permission live | S15: 45394 | T15: 45672 | U15: Yes | V15: No | W15: 47497 | Z15: 0 | AA15: 0 | AC15: 0 | AD15: 0 | AE15: 0.76112252 | AI15: Primary
A16: 20314 | B16: 20314 | C16: CIS | D16: P-1098119 | E16: €1.1m - 6 Houses | F16: Adare | G16: Adare-Rathkeale | H16: Outside city neighbourhoods | I16: 52.58449 | J16: -8.7687836 | K16: 6 | L16: 1–9 | M16: Houses | N16: Standard planning application | O16: Private | P16: Private | Q16: On Site | R16: Under construction | S16: 43935 | T16: 44054 | U16: No | V16: No | W16: 45879 | X16: 44539 | Y16: Commencement notice | Z16: 1 | AA16: 6 | AC16: 0 | AD16: 0 | AE16: 0.32580424 | AF16: 1.3278576 | AI16: Primary | AJ16: High
A17: 201101 | B17: 201101 | C17: CIS | D17: P-1130829 | E17: €1m - 5 Houses | F17: Adare | G17: Adare-Rathkeale | H17: Outside city neighbourhoods | I17: 52.555542 | J17: -8.7931992 | K17: 5 | L17: 1–9 | M17: Houses | N17: Standard planning application | O17: Private | P17: Private | Q17: On Site | R17: Under construction | S17: 44133 | T17: 44333 | U17: No | V17: Yes | W17: 45428 | X17: 45554 | Y17: CIS start date | Z17: 0 | AA17: 0 | AC17: 0 | AD17: 0 | AE17: 0.54757016 | AF17: 3.3429158 | AI17: Primary | AJ17: High
A18: 197016 | B18: 197016 | C18: CIS | D18: P-1053166 | E18: €800k - Residential Development, Ballingarry | F18: Other County Limerick | G18: Adare-Rathkeale | H18: Outside city neighbourhoods | I18: 52.476141 | J18: -8.8677338 | K18: 4 | L18: 1–9 | M18: Houses | N18: Standard planning application | O18: Private | P18: Private | Q18: On Site | R18: Under construction | S18: 43629 | T18: 43711 | U18: Yes | V18: No | W18: 45501 | X18: 44427 | Y18: Commencement notice | Z18: 3 | AA18: 3 | AC18: 0 | AD18: 0 | AE18: 0.22450376 | AF18: 1.9603012 | AI18: Extension of duration (parent not in CIS) | AJ18: Low
A19: 2360207 | B19: 2360207 | C19: CIS | D19: P-1283723 | E19: €680k - 3 Houses | F19: Other County Limerick | G19: Adare-Rathkeale | H19: Outside city neighbourhoods | I19: 52.595345 | J19: -9.1866288 | K19: 3 | L19: 1–9 | M19: Houses | N19: Standard planning application | O19: Private | P19: Private | Q19: Permission Granted | R19: Not started – past expiry | S19: 45026 | T19: 45187 | U19: Yes | V19: No | W19: 46282 | Z19: 0 | AA19: 0 | AC19: 0 | AD19: 0 | AE19: 0.44079398 | AI19: Primary | AJ19: High
A20: 2460299 | B20: 2460299 | C20: CIS | D20: P-1339954 | E20: €884k - 3 Houses | F20: Other County Limerick | G20: Adare-Rathkeale | H20: Outside city neighbourhoods | I20: 52.459563 | J20: -8.7608001 | K20: 3 | L20: 1–9 | M20: Houses | N20: Standard planning application | O20: Private | P20: Private | Q20: Permission Granted | R20: Not started – permission live | S20: 45387 | T20: 45475 | U20: No | V20: No | W20: 47300 | Z20: 0 | AA20: 0 | AC20: 0 | AD20: 0 | AE20: 0.24093087 | AI20: Primary | AJ20: High
A21: 2360794 | B21: 2360794 | C21: CIS | D21: P-1316492 | E21: €15.3m - Residential Development, Bruff | F21: Bruff | G21: Cappamore-Kilmallock | H21: Outside city neighbourhoods | I21: 52.472417 | J21: -8.5493436 | K21: 74 | L21: 50–99 | M21: Houses | N21: Standard planning application | O21: Private | P21: Private | Q21: Permission Granted | R21: Not started – permission live | S21: 45231 | T21: 45419 | U21: Yes | V21: No | W21: 47244 | Z21: 0 | AA21: 0 | AC21: 0 | AD21: 0 | AE21: 0.51471595 | AI21: Primary | AJ21: High | AK21: Site for sale / sold
A22: 2460788 | B22: 2460788 | C22: CIS | D22: P-1360674 | E22: €7.4m - Residential Development, Kilmallock | F22: Kilmallock | G22: Cappamore-Kilmallock | H22: Outside city neighbourhoods | I22: 52.39729 | J22: -8.5779289 | K22: 42 | L22: 25–49 | M22: Mixed | N22: Standard planning application | O22: Private | P22: Private | Q22: On Site | R22: Under construction | S22: 45510 | T22: 45853 | U22: Yes | V22: No | W22: 47678 | X22: 46118 | Y22: Commencement notice | Z22: 1 | AA22: 28 | AC22: 0 | AD22: 0 | AE22: 0.93908282 | AF22: 0.72553046 | AI22: Primary | AJ22: High
A23: 191298 | B23: 191298 | C23: CIS | D23: P-1084266 | E23: €5.6m - Housing Development | F23: Other County Limerick | G23: Cappamore-Kilmallock | H23: Outside city neighbourhoods | I23: 52.650553 | J23: -8.3967629 | K23: 32 | L23: 25–49 | M23: Houses | N23: Standard planning application | O23: Private | P23: Private | Q23: Stalled or Suspended | R23: Not started – permission live | S23: 43822 | T23: 44161 | U23: Yes | V23: No | W23: 47082 | Z23: 0 | AA23: 0 | AC23: 0 | AD23: 0 | AE23: 0.92813142 | AI23: Primary | AJ23: High | AK23: On hold / no movement
A24: 2326 | B24: 2326 | C24: CIS | D24: P-1266613 | E24: €6.3m - Housing Development, Kilmallock | F24: Kilmallock | G24: Cappamore-Kilmallock | H24: Outside city neighbourhoods | I24: 52.402655 | J24: -8.5838068 | K24: 28 | L24: 25–49 | M24: Houses | N24: Standard planning application | O24: Private | P24: Private | Q24: On Site | R24: Under construction | S24: 44944 | T24: 45320 | U24: Yes | V24: No | W24: 47146 | X24: 46109 | Y24: Commencement notice | Z24: 1 | AA24: 28 | AC24: 0 | AD24: 0 | AE24: 1.0294319 | AF24: 2.1601643 | AI24: Primary | AJ24: High
A25: 2461182 | B25: 2461182 | C25: CIS | D25: P-1379266 | E25: €5.4m - Residential Development | F25: Other County Limerick | G25: Cappamore-Kilmallock | H25: Outside city neighbourhoods | I25: 52.605077 | J25: -8.2511879 | K25: 27 | L25: 25–49 | M25: Mixed | N25: Standard planning application | O25: Private | P25: Private | Q25: Permission Granted | R25: Not started – permission live | S25: 45625 | T25: 46111 | U25: Yes | V25: Yes | W25: 47936 | Z25: 0 | AA25: 0 | AC25: 0 | AD25: 0 | AE25: 1.3305955 | AI25: Primary | AJ25: High
A26: 23529 | B26: 23529 | C26: CIS | D26: P-1317302 | E26: €4.4m - Housing Development | F26: Cappamore | G26: Cappamore-Kilmallock | H26: Outside city neighbourhoods | I26: 52.612409 | J26: -8.3357647 | K26: 22 | L26: 10–24 | M26: Houses | N26: Standard planning application | O26: Private | P26: Private | Q26: On Site | R26: Under construction | S26: 45237 | T26: 45538 | U26: Yes | V26: No | W26: 47363 | X26: 45939 | Y26: Commencement notice | Z26: 1 | AA26: 22 | AC26: 0 | AD26: 0 | AE26: 0.82409309 | AF26: 1.0978782 | AI26: Primary | AJ26: High
A27: 19149 | B27: 19149 | C27: CIS | D27: U-1034286 | E27: €567k - Change of Use to Care Residential Units | F27: Other County Limerick | G27: Cappamore-Kilmallock | H27: Outside city neighbourhoods | I27: 52.603895 | J27: -8.244808 | K27: 21 | L27: 10–24 | M27: Apartments | N27: Standard planning application | O27: Public – approved housing body | P27: Public | Q27: Tender | R27: Not started – past expiry | S27: 43516 | T27: 43719 | U27: Yes | V27: No | W27: 45545 | Z27: 0 | AA27: 0 | AC27: 0 | AD27: 0 | AE27: 0.55578371 | AI27: Primary | AJ27: High | AM27: 1937 | AN27: CAS AHB Construction | AO27: Stage 3 Pre-Tender Design | AP27: Q2-2024 | AQ27: Construction
A28: 188002 | B28: 188002 | C28: CIS | D28: P-981494 | E28: €1.9m - Residential Development | F28: Other County Limerick | G28: Cappamore-Kilmallock | H28: Outside city neighbourhoods | I28: 52.472518 | J28: -8.4303433 | K28: 20 | L28: 10–24 | M28: Apartments | N28: Part 8 / council | O28: Public – local authority | P28: Public | Q28: Complete | R28: Complete | S28: 43174 | T28: 43234 | U28: No | V28: No | X28: 43908 | Y28: Commencement notice | Z28: 1 | AA28: 20 | AB28: 45274 | AC28: 1 | AD28: 1 | AE28: 0.16427105 | AF28: 1.8453114 | AG28: 3.7399042 | AH28: 5.3477306 | AI28: Primary | AJ28: High | AL28: CIS | AM28: 1819 | AN28: SHIP LA Construction | AO28: Completed | AP28: Q4-2023 | AQ28: Construction
A29: Part 8 - 1392454 | B29: Part 8 - 1392454 | C29: CIS | D29: P-1392454 | E29: €5.9m - Residential Development, Bruff | F29: Bruff | G29: Cappamore-Kilmallock | H29: Outside city neighbourhoods | I29: 52.475549 | J29: -8.5474034 | K29: 18 | L29: 10–24 | M29: Unknown | N29: Part 8 / council | O29: Public – local authority | P29: Public | Q29: On Site | R29: Under construction | S29: 45477 | T29: 45569 | U29: No | V29: No | X29: 46150 | Y29: CIS start date | Z29: 0 | AA29: 0 | AC29: 0 | AD29: 0 | AE29: 0.25188227 | AF29: 1.5906913 | AI29: Primary | AJ29: High | AM29: 1831 | AN29: SHIP LA Construction | AO29: Stage 4 Tender Report / Final Turnkey or CALF Approval | AP29: Q4-2025 | AQ29: Construction
A30: 221352 | B30: 221352 | C30: CIS | D30: SG-030 | E30: €5.5m - Housing Development, Cappamore | F30: Cappamore | G30: Cappamore-Kilmallock | H30: Outside city neighbourhoods | I30: 52.615676 | J30: -8.3431937 | K30: 17 | L30: 10–24 | M30: Houses | N30: Standard planning application | O30: Public – approved housing body | P30: Public | Q30: Complete | R30: Complete | S30: 44910 | T30: 45118 | U30: Yes | V30: No | W30: 46944 | X30: 45734 | Y30: Commencement notice | Z30: 1 | AA30: 17 | AB30: 46244 | AC30: 1 | AD30: 1 | AE30: 0.56947296 | AF30: 1.6865161 | AG30: 1.3963039 | AH30: 12.175 | AI30: Primary | AJ30: High | AL30: CIS | AM30: 1714 | AN30: CALF Construction | AO30: On Site | AP30: Q1-2025 | AQ30: Construction
A31: 211170 | B31: 211170 | C31: CIS | D31: P-1184979 | E31: €3m - Modifications to Housing Development, Kilfinane | F31: Other County Limerick | G31: Cappamore-Kilmallock | H31: Outside city neighbourhoods | I31: 52.358135 | J31: -8.4627718 | K31: 14 | L31: 10–24 | M31: Houses | N31: Standard planning application | O31: Public – local authority | P31: Public | Q31: On Site | R31: Under construction | S31: 44425 | T31: 44820 | U31: Yes | V31: No | W31: 46645 | X31: 45404 | Y31: Commencement notice | Z31: 1 | AA31: 1 | AC31: 0 | AD31: 0 | AE31: 1.0814511 | AF31: 1.5989049 | AI31: Primary | AJ31: High | AM31: 1812 | AN31: SHIP LA Turnkey | AO31: Stage 4 Tender Report / Final Turnkey or CALF Approval | AP31: Q1-2026 | AQ31: Turnkey
A32: 198007 | B32: 198007 | C32: CIS | D32: P-1065269 | E32: €1.4m - Housing Development | F32: Other County Limerick | G32: Cappamore-Kilmallock | H32: Outside city neighbourhoods | I32: 52.43691 | J32: -8.4080414 | K32: 12 | L32: 10–24 | M32: Unknown | N32: Part 8 / council | O32: Public – local authority | P32: Public | Q32: Complete | R32: Complete | S32: 43710 | T32: 43784 | U32: No | V32: No | X32: 44421 | Y32: Commencement notice | Z32: 1 | AA32: 12 | AB32: 45337 | AC32: 1 | AD32: 1 | AE32: 0.20260096 | AF32: 1.744011 | AG32: 2.5078713 | AH32: 4.7849345 | AI32: Primary | AJ32: High | AL32: CIS | AM32: 1821 | AN32: SHIP LA Construction | AO32: Completed | AP32: Q4-2022 | AQ32: Construction
A33: 19872 | B33: 19872 | C33: CIS | D33: P-1065293 | E33: €1.3m - Care Residential Units | F33: Cappamore | G33: Cappamore-Kilmallock | H33: Outside city neighbourhoods | I33: 52.612941 | J33: -8.3334135 | K33: 10 | L33: 10–24 | M33: Apartments | N33: Standard planning application | O33: Private | P33: Private | Q33: On Site | R33: Under construction | S33: 43710 | T33: 43886 | U33: Yes | V33: No | W33: 45712 | X33: 45420 | Y33: Commencement notice | Z33: 1 | AA33: 10 | AC33: 0 | AD33: 0 | AE33: 0.48186174 | AF33: 4.1998631 | AI33: Primary | AJ33: High
A34: 218013 | B34: 218013 | C34: CIS | D34: P-1205019 | E34: €3m - Housing Development | F34: Other County Limerick | G34: Cappamore-Kilmallock | H34: Outside city neighbourhoods | I34: 52.359072 | J34: -8.4736504 | K34: 10 | L34: 10–24 | M34: Unknown | N34: Part 8 / council | O34: Public – local authority | P34: Public | Q34: Complete | R34: Complete | S34: 44540 | T34: 44629 | U34: No | V34: No | X34: 45370 | Y34: Commencement notice | Z34: 1 | AA34: 10 | AB34: 46155 | AC34: 1 | AD34: 2 | AE34: 0.24366872 | AF34: 2.0287474 | AG34: 2.1492129 | AH34: 4.6528662 | AI34: Primary | AJ34: High | AL34: CIS | AM34: 1829 | AN34: SHIP LA Construction | AO34: Completed | AP34: Q4-2025 | AQ34: Construction
A35: 2148 | B35: 2148 | C35: CIS | D35: P-1144674 | E35: €1.9m - Change of Use to 9 Apartments, St. Paul's Convent | F35: Other County Limerick | G35: Cappamore-Kilmallock | H35: Outside city neighbourhoods | I35: 52.360612 | J35: -8.4700482 | K35: 9 | L35: 1–9 | M35: Apartments | N35: Standard planning application | O35: Public – approved housing body | P35: Public | Q35: Complete | R35: Complete | S35: 44215 | T35: 44475 | U35: Yes | V35: No | W35: 46300 | X35: 45250 | Y35: Commencement notice | Z35: 1 | AA35: 9 | AB35: 45950 | AC35: 1 | AD35: 1 | AE35: 0.7118412 | AF35: 2.1218344 | AG35: 1.9164956 | AH35: 4.6960714 | AI35: Primary | AJ35: High | AL35: CIS | AM35: 1931 | AN35: CAS AHB Construction | AO35: Completed | AP35: Q4-2024 | AQ35: Construction
A36: 21550 | B36: 21550 | C36: CIS | D36: P-1164066 | E36: €1.9m - 9 Houses | F36: Caherconlish | G36: Cappamore-Kilmallock | H36: Outside city neighbourhoods | I36: 52.595383 | J36: -8.4712455 | K36: 9 | L36: 1–9 | M36: Houses | N36: Standard planning application | O36: Private | P36: Private | Q36: Complete | R36: Complete | S36: 44314 | T36: 44615 | U36: Yes | V36: No | W36: 46440 | X36: 45393 | Y36: Commencement notice | Z36: 1 | AA36: 7 | AB36: 46195 | AC36: 1 | AD36: 3 | AE36: 0.82409309 | AF36: 2.1300479 | AG36: 2.1957563 | AH36: 4.0988155 | AI36: Primary | AJ36: High | AL36: CIS
A37: 228000 | B37: 228000 | C37: CIS | D37: P-1213266 | E37: €2.5m - 9 Houses | F37: Other County Limerick | G37: Cappamore-Kilmallock | H37: Outside city neighbourhoods | I37: 52.368832 | J37: -8.3446032 | K37: 9 | L37: 1–9 | M37: Houses | N37: Part 8 / council | O37: Public – local authority | P37: Public | Q37: On Site | R37: Under construction | S37: 44596 | T37: 44658 | U37: No | V37: No | X37: 45769 | Y37: Commencement notice | Z37: 1 | AA37: 9 | AC37: 0 | AD37: 0 | AE37: 0.16974675 | AF37: 3.0417522 | AI37: Additional application on site | AJ37: Low | AM37: 1828 | AN37: SHIP LA Construction | AO37: Stage 4 Tender Report / Final Turnkey or CALF Approval | AP37: Q1-2025 | AQ37: Construction
A38: 2560947 | B38: 2560947 | C38: CIS | D38: P-1414007 | E38: €1m - 8 Houses, Bruff | F38: Bruff | G38: Cappamore-Kilmallock | H38: Outside city neighbourhoods | I38: 52.476941 | J38: -8.5370467 | K38: 8 | L38: 1–9 | M38: Houses | N38: Standard planning application | O38: Private | P38: Private | Q38: Permission Granted | R38: Not started – permission live | S38: 45919 | T38: 46267 | U38: Yes | V38: No | W38: 48093 | Z38: 0 | AA38: 0 | AC38: 0 | AD38: 0 | AE38: 0.95277207 | AI38: Primary | AJ38: High
A39: 2360393 | B39: 2360393 | C39: CIS | D39: SG-016 | E39: €604k - 8 Residential Units | F39: Other County Limerick | G39: Cappamore-Kilmallock | H39: Outside city neighbourhoods | I39: 52.437319 | J39: -8.4085515 | K39: 8 | L39: 1–9 | M39: Houses | N39: Standard planning application | O39: Private | P39: Private | Q39: Complete | R39: Complete | S39: 45085 | T39: 45265 | U39: Yes | V39: No | W39: 47091 | X39: 45565 | Y39: Commencement notice | Z39: 1 | AA39: 4 | AB39: 46251 | AC39: 1 | AD39: 4 | AE39: 0.49281314 | AF39: 0.82135524 | AG39: 1.8781656 | AH39: 4.2594752 | AI39: Additional application on site | AJ39: Low | AL39: CIS
A40: 2461101 | B40: 2461101 | C40: CIS | D40: SG-030 | E40: €1.4m - 7 Houses | F40: Cappamore | G40: Cappamore-Kilmallock | H40: Outside city neighbourhoods | I40: 52.615241 | J40: -8.3441163 | K40: 7 | L40: 1–9 | M40: Houses | N40: Standard planning application | O40: Private | P40: Private | Q40: Permission Granted | R40: Not started – permission live | S40: 45603 | T40: 45868 | U40: Yes | V40: No | W40: 47042 | Z40: 0 | AA40: 0 | AC40: 0 | AD40: 0 | AE40: 0.72553046 | AI40: Replaces earlier | AJ40: Medium
...

Sheet Status (live)
A1: Units with permission by status and size band
A2: Size band | B2: Schemes | C2: Complete | D2: Under construction | E2: Not started – permission live | F2: Not started – past expiry | G2: Total units
A3: 1–9 | B3: =COUNTIFS(Schemes!$L$2:$L$266,$A3,Schemes!$R$2:$R$266,"<>In planning") -> 69 | C3: =SUMIFS(Schemes!$K$2:$K$266,Schemes!$L$2:$L$266,$A3,Schemes!$R$2:$R$266,"Complete") -> 110 | D3: =SUMIFS(Schemes!$K$2:$K$266,Schemes!$L$2:$L$266,$A3,Schemes!$R$2:$R$266,"Under construction") -> 154 | E3: =SUMIFS(Schemes!$K$2:$K$266,Schemes!$L$2:$L$266,$A3,Schemes!$R$2:$R$266,"Not started – permission live") -> 93 | F3: =SUMIFS(Schemes!$K$2:$K$266,Schemes!$L$2:$L$266,$A3,Schemes!$R$2:$R$266,"Not started – past expiry") -> 24 | G3: =SUM(C3:F3) -> 381
A4: 10–24 | B4: =COUNTIFS(Schemes!$L$2:$L$266,$A4,Schemes!$R$2:$R$266,"<>In planning") -> 69 | C4: =SUMIFS(Schemes!$K$2:$K$266,Schemes!$L$2:$L$266,$A4,Schemes!$R$2:$R$266,"Complete") -> 230 | D4: =SUMIFS(Schemes!$K$2:$K$266,Schemes!$L$2:$L$266,$A4,Schemes!$R$2:$R$266,"Under construction") -> 382 | E4: =SUMIFS(Schemes!$K$2:$K$266,Schemes!$L$2:$L$266,$A4,Schemes!$R$2:$R$266,"Not started – permission live") -> 396 | F4: =SUMIFS(Schemes!$K$2:$K$266,Schemes!$L$2:$L$266,$A4,Schemes!$R$2:$R$266,"Not started – past expiry") -> 101 | G4: =SUM(C4:F4) -> 1109
A5: 25–49 | B5: =COUNTIFS(Schemes!$L$2:$L$266,$A5,Schemes!$R$2:$R$266,"<>In planning") -> 47 | C5: =SUMIFS(Schemes!$K$2:$K$266,Schemes!$L$2:$L$266,$A5,Schemes!$R$2:$R$266,"Complete") -> 221 | D5: =SUMIFS(Schemes!$K$2:$K$266,Schemes!$L$2:$L$266,$A5,Schemes!$R$2:$R$266,"Under construction") -> 562 | E5: =SUMIFS(Schemes!$K$2:$K$266,Schemes!$L$2:$L$266,$A5,Schemes!$R$2:$R$266,"Not started – permission live") -> 745 | F5: =SUMIFS(Schemes!$K$2:$K$266,Schemes!$L$2:$L$266,$A5,Schemes!$R$2:$R$266,"Not started – past expiry") -> 49 | G5: =SUM(C5:F5) -> 1577
A6: 50–99 | B6: =COUNTIFS(Schemes!$L$2:$L$266,$A6,Schemes!$R$2:$R$266,"<>In planning") -> 36 | C6: =SUMIFS(Schemes!$K$2:$K$266,Schemes!$L$2:$L$266,$A6,Schemes!$R$2:$R$266,"Complete") -> 276 | D6: =SUMIFS(Schemes!$K$2:$K$266,Schemes!$L$2:$L$266,$A6,Schemes!$R$2:$R$266,"Under construction") -> 1456 | E6: =SUMIFS(Schemes!$K$2:$K$266,Schemes!$L$2:$L$266,$A6,Schemes!$R$2:$R$266,"Not started – permission live") -> 952 | F6: =SUMIFS(Schemes!$K$2:$K$266,Schemes!$L$2:$L$266,$A6,Schemes!$R$2:$R$266,"Not started – past expiry") -> 0 | G6: =SUM(C6:F6) -> 2684
A7: 100+ | B7: =COUNTIFS(Schemes!$L$2:$L$266,$A7,Schemes!$R$2:$R$266,"<>In planning") -> 23 | C7: =SUMIFS(Schemes!$K$2:$K$266,Schemes!$L$2:$L$266,$A7,Schemes!$R$2:$R$266,"Complete") -> 438 | D7: =SUMIFS(Schemes!$K$2:$K$266,Schemes!$L$2:$L$266,$A7,Schemes!$R$2:$R$266,"Under construction") -> 1510 | E7: =SUMIFS(Schemes!$K$2:$K$266,Schemes!$L$2:$L$266,$A7,Schemes!$R$2:$R$266,"Not started – permission live") -> 2957 | F7: =SUMIFS(Schemes!$K$2:$K$266,Schemes!$L$2:$L$266,$A7,Schemes!$R$2:$R$266,"Not started – past expiry") -> 137 | G7: =SUM(C7:F7) -> 5042
A8: All | B8: =SUM(B3:B7) -> 244 | C8: =SUM(C3:C7) -> 1275 | D8: =SUM(D3:D7) -> 4064 | E8: =SUM(E3:E7) -> 5143 | F8: =SUM(F3:F7) -> 311 | G8: =SUM(G3:G7) -> 10793
A11: Units with permission by status and LEA
A12: LEA | B12: Schemes | C12: Complete | D12: Under construction | E12: Not started – permission live | F12: Not started – past expiry | G12: Total units
A13: Limerick City East | B13: =COUNTIFS(Schemes!$G$2:$G$266,$A13,Schemes!$R$2:$R$266,"<>In planning") -> 56 | C13: =SUMIFS(Schemes!$K$2:$K$266,Schemes!$G$2:$G$266,$A13,Schemes!$R$2:$R$266,"Complete") -> 797 | D13: =SUMIFS(Schemes!$K$2:$K$266,Schemes!$G$2:$G$266,$A13,Schemes!$R$2:$R$266,"Under construction") -> 943 | E13: =SUMIFS(Schemes!$K$2:$K$266,Schemes!$G$2:$G$266,$A13,Schemes!$R$2:$R$266,"Not started – permission live") -> 2089 | F13: =SUMIFS(Schemes!$K$2:$K$266,Schemes!$G$2:$G$266,$A13,Schemes!$R$2:$R$266,"Not started – past expiry") -> 149 | G13: =SUM(C13:F13) -> 3978
A14: Limerick City North | B14: =COUNTIFS(Schemes!$G$2:$G$266,$A14,Schemes!$R$2:$R$266,"<>In planning") -> 48 | C14: =SUMIFS(Schemes!$K$2:$K$266,Schemes!$G$2:$G$266,$A14,Schemes!$R$2:$R$266,"Complete") -> 170 | D14: =SUMIFS(Schemes!$K$2:$K$266,Schemes!$G$2:$G$266,$A14,Schemes!$R$2:$R$266,"Under construction") -> 717 | E14: =SUMIFS(Schemes!$K$2:$K$266,Schemes!$G$2:$G$266,$A14,Schemes!$R$2:$R$266,"Not started – permission live") -> 793 | F14: =SUMIFS(Schemes!$K$2:$K$266,Schemes!$G$2:$G$266,$A14,Schemes!$R$2:$R$266,"Not started – past expiry") -> 16 | G14: =SUM(C14:F14) -> 1696
A15: Limerick City West | B15: =COUNTIFS(Schemes!$G$2:$G$266,$A15,Schemes!$R$2:$R$266,"<>In planning") -> 77 | C15: =SUMIFS(Schemes!$K$2:$K$266,Schemes!$G$2:$G$266,$A15,Schemes!$R$2:$R$266,"Complete") -> 182 | D15: =SUMIFS(Schemes!$K$2:$K$266,Schemes!$G$2:$G$266,$A15,Schemes!$R$2:$R$266,"Under construction") -> 1962 | E15: =SUMIFS(Schemes!$K$2:$K$266,Schemes!$G$2:$G$266,$A15,Schemes!$R$2:$R$266,"Not started – permission live") -> 1559 | F15: =SUMIFS(Schemes!$K$2:$K$266,Schemes!$G$2:$G$266,$A15,Schemes!$R$2:$R$266,"Not started – past expiry") -> 121 | G15: =SUM(C15:F15) -> 3824
A16: Adare-Rathkeale | B16: =COUNTIFS(Schemes!$G$2:$G$266,$A16,Schemes!$R$2:$R$266,"<>In planning") -> 19 | C16: =SUMIFS(Schemes!$K$2:$K$266,Schemes!$G$2:$G$266,$A16,Schemes!$R$2:$R$266,"Complete") -> 16 | D16: =SUMIFS(Schemes!$K$2:$K$266,Schemes!$G$2:$G$266,$A16,Schemes!$R$2:$R$266,"Under construction") -> 66 | E16: =SUMIFS(Schemes!$K$2:$K$266,Schemes!$G$2:$G$266,$A16,Schemes!$R$2:$R$266,"Not started – permission live") -> 335 | F16: =SUMIFS(Schemes!$K$2:$K$266,Schemes!$G$2:$G$266,$A16,Schemes!$R$2:$R$266,"Not started – past expiry") -> 3 | G16: =SUM(C16:F16) -> 420
A17: Cappamore-Kilmallock | B17: =COUNTIFS(Schemes!$G$2:$G$266,$A17,Schemes!$R$2:$R$266,"<>In planning") -> 30 | C17: =SUMIFS(Schemes!$K$2:$K$266,Schemes!$G$2:$G$266,$A17,Schemes!$R$2:$R$266,"Complete") -> 104 | D17: =SUMIFS(Schemes!$K$2:$K$266,Schemes!$G$2:$G$266,$A17,Schemes!$R$2:$R$266,"Under construction") -> 158 | E17: =SUMIFS(Schemes!$K$2:$K$266,Schemes!$G$2:$G$266,$A17,Schemes!$R$2:$R$266,"Not started – permission live") -> 151 | F17: =SUMIFS(Schemes!$K$2:$K$266,Schemes!$G$2:$G$266,$A17,Schemes!$R$2:$R$266,"Not started – past expiry") -> 22 | G17: =SUM(C17:F17) -> 435
A18: Newcastle West | B18: =COUNTIFS(Schemes!$G$2:$G$266,$A18,Schemes!$R$2:$R$266,"<>In planning") -> 19 | C18: =SUMIFS(Schemes!$K$2:$K$266,Schemes!$G$2:$G$266,$A18,Schemes!$R$2:$R$266,"Complete") -> 6 | D18: =SUMIFS(Schemes!$K$2:$K$266,Schemes!$G$2:$G$266,$A18,Schemes!$R$2:$R$266,"Under construction") -> 218 | E18: =SUMIFS(Schemes!$K$2:$K$266,Schemes!$G$2:$G$266,$A18,Schemes!$R$2:$R$266,"Not started – permission live") -> 216 | F18: =SUMIFS(Schemes!$K$2:$K$266,Schemes!$G$2:$G$266,$A18,Schemes!$R$2:$R$266,"Not started – past expiry") -> 0 | G18: =SUM(C18:F18) -> 440
A21: Units with permission by status and city neighbourhood
A22: Neighbourhood | B22: Schemes | C22: Complete | D22: Under construction | E22: Not started – permission live | F22: Not started – past expiry | G22: Total units
A23: City Centre | B23: =COUNTIFS(Schemes!$H$2:$H$266,$A23,Schemes!$R$2:$R$266,"<>In planning") -> 40 | C23: =SUMIFS(Schemes!$K$2:$K$266,Schemes!$H$2:$H$266,$A23,Schemes!$R$2:$R$266,"Complete") -> 83 | D23: =SUMIFS(Schemes!$K$2:$K$266,Schemes!$H$2:$H$266,$A23,Schemes!$R$2:$R$266,"Under construction") -> 127 | E23: =SUMIFS(Schemes!$K$2:$K$266,Schemes!$H$2:$H$266,$A23,Schemes!$R$2:$R$266,"Not started – permission live") -> 715 | F23: =SUMIFS(Schemes!$K$2:$K$266,Schemes!$H$2:$H$266,$A23,Schemes!$R$2:$R$266,"Not started – past expiry") -> 55 | G23: =SUM(C23:F23) -> 980
A24: Kings Island | B24: =COUNTIFS(Schemes!$H$2:$H$266,$A24,Schemes!$R$2:$R$266,"<>In planning") -> 2 | C24: =SUMIFS(Schemes!$K$2:$K$266,Schemes!$H$2:$H$266,$A24,Schemes!$R$2:$R$266,"Complete") -> 0 | D24: =SUMIFS(Schemes!$K$2:$K$266,Schemes!$H$2:$H$266,$A24,Schemes!$R$2:$R$266,"Under construction") -> 0 | E24: =SUMIFS(Schemes!$K$2:$K$266,Schemes!$H$2:$H$266,$A24,Schemes!$R$2:$R$266,"Not started – permission live") -> 50 | F24: =SUMIFS(Schemes!$K$2:$K$266,Schemes!$H$2:$H$266,$A24,Schemes!$R$2:$R$266,"Not started – past expiry") -> 0 | G24: =SUM(C24:F24) -> 50
A25: Corbally/Grove Island | B25: =COUNTIFS(Schemes!$H$2:$H$266,$A25,Schemes!$R$2:$R$266,"<>In planning") -> 4 | C25: =SUMIFS(Schemes!$K$2:$K$266,Schemes!$H$2:$H$266,$A25,Schemes!$R$2:$R$266,"Complete") -> 24 | D25: =SUMIFS(Schemes!$K$2:$K$266,Schemes!$H$2:$H$266,$A25,Schemes!$R$2:$R$266,"Under construction") -> 26 | E25: =SUMIFS(Schemes!$K$2:$K$266,Schemes!$H$2:$H$266,$A25,Schemes!$R$2:$R$266,"Not started – permission live") -> 40 | F25: =SUMIFS(Schemes!$K$2:$K$266,Schemes!$H$2:$H$266,$A25,Schemes!$R$2:$R$266,"Not started – past expiry") -> 0 | G25: =SUM(C25:F25) -> 90
A26: Singland/Garryowen | B26: =COUNTIFS(Schemes!$H$2:$H$266,$A26,Schemes!$R$2:$R$266,"<>In planning") -> 16 | C26: =SUMIFS(Schemes!$K$2:$K$266,Schemes!$H$2:$H$266,$A26,Schemes!$R$2:$R$266,"Complete") -> 22 | D26: =SUMIFS(Schemes!$K$2:$K$266,Schemes!$H$2:$H$266,$A26,Schemes!$R$2:$R$266,"Under construction") -> 146 | E26: =SUMIFS(Schemes!$K$2:$K$266,Schemes!$H$2:$H$266,$A26,Schemes!$R$2:$R$266,"Not started – permission live") -> 132 | F26: =SUMIFS(Schemes!$K$2:$K$266,Schemes!$H$2:$H$266,$A26,Schemes!$R$2:$R$266,"Not started – past expiry") -> 4 | G26: =SUM(C26:F26) -> 304
A27: Castletroy/Annacotty | B27: =COUNTIFS(Schemes!$H$2:$H$266,$A27,Schemes!$R$2:$R$266,"<>In planning") -> 32 | C27: =SUMIFS(Schemes!$K$2:$K$266,Schemes!$H$2:$H$266,$A27,Schemes!$R$2:$R$266,"Complete") -> 474 | D27: =SUMIFS(Schemes!$K$2:$K$266,Schemes!$H$2:$H$266,$A27,Schemes!$R$2:$R$266,"Under construction") -> 746 | E27: =SUMIFS(Schemes!$K$2:$K$266,Schemes!$H$2:$H$266,$A27,Schemes!$R$2:$R$266,"Not started – permission live") -> 1590 | F27: =SUMIFS(Schemes!$K$2:$K$266,Schemes!$H$2:$H$266,$A27,Schemes!$R$2:$R$266,"Not started – past expiry") -> 149 | G27: =SUM(C27:F27) -> 2959
A28: Southhill | B28: =COUNTIFS(Schemes!$H$2:$H$266,$A28,Schemes!$R$2:$R$266,"<>In planning") -> 12 | C28: =SUMIFS(Schemes!$K$2:$K$266,Schemes!$H$2:$H$266,$A28,Schemes!$R$2:$R$266,"Complete") -> 284 | D28: =SUMIFS(Schemes!$K$2:$K$266,Schemes!$H$2:$H$266,$A28,Schemes!$R$2:$R$266,"Under construction") -> 21 | E28: =SUMIFS(Schemes!$K$2:$K$266,Schemes!$H$2:$H$266,$A28,Schemes!$R$2:$R$266,"Not started – permission live") -> 418 | F28: =SUMIFS(Schemes!$K$2:$K$266,Schemes!$H$2:$H$266,$A28,Schemes!$R$2:$R$266,"Not started – past expiry") -> 0 | G28: =SUM(C28:F28) -> 723
A29: Dooradoyle | B29: =COUNTIFS(Schemes!$H$2:$H$266,$A29,Schemes!$R$2:$R$266,"<>In planning") -> 22 | C29: =SUMIFS(Schemes!$K$2:$K$266,Schemes!$H$2:$H$266,$A29,Schemes!$R$2:$R$266,"Complete") -> 98 | D29: =SUMIFS(Schemes!$K$2:$K$266,Schemes!$H$2:$H$266,$A29,Schemes!$R$2:$R$266,"Under construction") -> 1133 | E29: =SUMIFS(Schemes!$K$2:$K$266,Schemes!$H$2:$H$266,$A29,Schemes!$R$2:$R$266,"Not started – permission live") -> 689 | F29: =SUMIFS(Schemes!$K$2:$K$266,Schemes!$H$2:$H$266,$A29,Schemes!$R$2:$R$266,"Not started – past expiry") -> 0 | G29: =SUM(C29:F29) -> 1920
A30: Ballinacurra | B30: =COUNTIFS(Schemes!$H$2:$H$266,$A30,Schemes!$R$2:$R$266,"<>In planning") -> 4 | C30: =SUMIFS(Schemes!$K$2:$K$266,Schemes!$H$2:$H$266,$A30,Schemes!$R$2:$R$266,"Complete") -> 17 | D30: =SUMIFS(Schemes!$K$2:$K$266,Schemes!$H$2:$H$266,$A30,Schemes!$R$2:$R$266,"Under construction") -> 398 | E30: =SUMIFS(Schemes!$K$2:$K$266,Schemes!$H$2:$H$266,$A30,Schemes!$R$2:$R$266,"Not started – permission live") -> 0 | F30: =SUMIFS(Schemes!$K$2:$K$266,Schemes!$H$2:$H$266,$A30,Schemes!$R$2:$R$266,"Not started – past expiry") -> 0 | G30: =SUM(C30:F30) -> 415
A31: Caherdavin | B31: =COUNTIFS(Schemes!$H$2:$H$266,$A31,Schemes!$R$2:$R$266,"<>In planning") -> 24 | C31: =SUMIFS(Schemes!$K$2:$K$266,Schemes!$H$2:$H$266,$A31,Schemes!$R$2:$R$266,"Complete") -> 125 | D31: =SUMIFS(Schemes!$K$2:$K$266,Schemes!$H$2:$H$266,$A31,Schemes!$R$2:$R$266,"Under construction") -> 566 | E31: =SUMIFS(Schemes!$K$2:$K$266,Schemes!$H$2:$H$266,$A31,Schemes!$R$2:$R$266,"Not started – permission live") -> 607 | F31: =SUMIFS(Schemes!$K$2:$K$266,Schemes!$H$2:$H$266,$A31,Schemes!$R$2:$R$266,"Not started – past expiry") -> 12 | G31: =SUM(C31:F31) -> 1310
A32: Outside city neighbourhoods | B32: =COUNTIFS(Schemes!$H$2:$H$266,$A32,Schemes!$R$2:$R$266,"<>In planning") -> 93 | C32: =SUMIFS(Schemes!$K$2:$K$266,Schemes!$H$2:$H$266,$A32,Schemes!$R$2:$R$266,"Complete") -> 148 | D32: =SUMIFS(Schemes!$K$2:$K$266,Schemes!$H$2:$H$266,$A32,Schemes!$R$2:$R$266,"Under construction") -> 901 | E32: =SUMIFS(Schemes!$K$2:$K$266,Schemes!$H$2:$H$266,$A32,Schemes!$R$2:$R$266,"Not started – permission live") -> 902 | F32: =SUMIFS(Schemes!$K$2:$K$266,Schemes!$H$2:$H$266,$A32,Schemes!$R$2:$R$266,"Not started – past expiry") -> 91 | G32: =SUM(C32:F32) -> 2042
A35: Units with permission by status and sector
A36: Sector | B36: Schemes | C36: Complete | D36: Under construction | E36: Not started – permission live | F36: Not started – past expiry | G36: Total units
A37: Public | B37: =COUNTIFS(Schemes!$P$2:$P$266,$A37,Schemes!$R$2:$R$266,"<>In planning") -> 65 | C37: =SUMIFS(Schemes!$K$2:$K$266,Schemes!$P$2:$P$266,$A37,Schemes!$R$2:$R$266,"Complete") -> 301 | D37: =SUMIFS(Schemes!$K$2:$K$266,Schemes!$P$2:$P$266,$A37,Schemes!$R$2:$R$266,"Under construction") -> 717 | E37: =SUMIFS(Schemes!$K$2:$K$266,Schemes!$P$2:$P$266,$A37,Schemes!$R$2:$R$266,"Not started – permission live") -> 518 | F37: =SUMIFS(Schemes!$K$2:$K$266,Schemes!$P$2:$P$266,$A37,Schemes!$R$2:$R$266,"Not started – past expiry") -> 33 | G37: =SUM(C37:F37) -> 1569
A38: Private | B38: =COUNTIFS(Schemes!$P$2:$P$266,$A38,Schemes!$R$2:$R$266,"<>In planning") -> 186 | C38: =SUMIFS(Schemes!$K$2:$K$266,Schemes!$P$2:$P$266,$A38,Schemes!$R$2:$R$266,"Complete") -> 974 | D38: =SUMIFS(Schemes!$K$2:$K$266,Schemes!$P$2:$P$266,$A38,Schemes!$R$2:$R$266,"Under construction") -> 3347 | E38: =SUMIFS(Schemes!$K$2:$K$266,Schemes!$P$2:$P$266,$A38,Schemes!$R$2:$R$266,"Not started – permission live") -> 4625 | F38: =SUMIFS(Schemes!$K$2:$K$266,Schemes!$P$2:$P$266,$A38,Schemes!$R$2:$R$266,"Not started – past expiry") -> 278 | G38: =SUM(C38:F38) -> 9224

Sheet 1 Status by size
A1: Size band (units) | B1: Schemes | C1: Complete | D1: Under construction | E1: Not started – permission live | F1: Not started – past expiry | G1: Total units
A2: 1–9 | B2: 69 | C2: 110 | D2: 154 | E2: 93 | F2: 24 | G2: 381
A3: 10–24 | B3: 69 | C3: 230 | D3: 382 | E3: 396 | F3: 101 | G3: 1109
A4: 25–49 | B4: 47 | C4: 221 | D4: 562 | E4: 745 | F4: 49 | G4: 1577
A5: 50–99 | B5: 36 | C5: 276 | D5: 1456 | E5: 952 | F5: 0 | G5: 2684
A6: 100+ | B6: 23 | C6: 438 | D6: 1510 | E6: 2957 | F6: 137 | G6: 5042
A7: All | B7: 244 | C7: 1275 | D7: 4064 | E7: 5143 | F7: 311 | G7: 10793
A9: Values calculated in delivery_analysis.py from the Schemes sheet.

Sheet 2 Timeline by size
A1: Size band (units) | B1: Approval: n | C1: Approval: LQ | D1: Approval: median | E1: Approval: UQ | F1: Grant to start: n | G1: Grant to start: LQ | H1: Grant to start: median | I1: Grant to start: UQ | J1: Start to completion: n | K1: Start to completion: median | L1: Build rate (dpa): median
A2: 1–9 | B2: 65 | C2: 0.2 | D2: 0.5 | E2: 0.8 | F2: 45 | G2: 0.7 | H2: 1.3 | I2: 2.1 | J2: 18 | K2: 1.7 | L2: 4.1
A3: 10–24 | B3: 65 | C3: 0.3 | D3: 0.6 | E3: 0.9 | F3: 34 | G3: 0.6 | H3: 1.4 | I3: 2 | J3: 15 | K3: 1.8 | L3: 8.3
A4: 25–49 | B4: 47 | C4: 0.3 | D4: 0.6 | E4: 0.9 | F4: 23 | G4: 0.8 | H4: 1.6 | I4: 2.1 | J4: 6 | K4: 1.4 | L4: 21.5
A5: 50–99 | B5: 36 | C5: 0.6 | D5: 0.7 | E5: 1.2 | F5: 23 | G5: 0.7 | H5: 1.1 | I5: 2.1 | J5: 4 | K5: 2.3 | L5: 34
A6: 100+ | B6: 23 | C6: 0.3 | D6: 0.5 | E6: 0.7 | F6: 10 | G6: 1.1 | H6: 1.7 | I6: 1.9 | J6: 3 | K6: 2.1 | L6: 50.3
A7: All | B7: 240 | C7: 0.3 | D7: 0.6 | E7: 0.9 | F7: 136 | G7: 0.7 | H7: 1.3 | I7: 2.1 | J7: 47 | K7: 1.8 | L7: 8
A9: Values calculated in delivery_analysis.py from the Schemes sheet.

Sheet 3 Share started over time
A1: Scheme size | B1: Started within 1 yr (%) | C1: n (1 yr) | D1: Started within 2 yr (%) | E1: n (2 yr) | F1: Started within 3 yr (%) | G1: n (3 yr) | H1: Started within 4 yr (%) | I1: n (4 yr) | J1: Started within 5 yr (%) | K1: n (5 yr)
A2: 1–24 units | B2: 27 | C2: 119 | D2: 47 | E2: 106 | F2: 54 | G2: 82 | H2: 64 | I2: 70 | J2: 68 | K2: 50
A3: 25–99 units | B3: 22 | C3: 72 | D3: 47 | E3: 60 | F3: 65 | G3: 48 | H3: 71 | I3: 38 | J3: 84 | K3: 31
A4: 100+ units | B4: 14 | C4: 14 | D4: 67 | E4: 12 | F4: 67 | G4: 9 | H4: 62 | I4: 8 | K4: 4
A5: All | B5: 25 | C5: 208 | D5: 48 | E5: 181 | F5: 58 | G5: 142 | H5: 66 | I5: 119 | J5: 72 | K5: 88
A7: Values calculated in delivery_analysis.py from the Schemes sheet.

Sheet 4a Implementation by LEA
A1: lea | B1: Schemes | C1: Units permitted | D1: Units started | E1: Schemes started | F1: Units started (%) | G1: Schemes started (%) | H1: Median grant to start (yrs)
A2: Limerick City East | B2: 39 | C2: 1834 | D2: 1673 | E2: 36 | F2: 91 | G2: 92 | H2: 1.2
A3: Limerick City North | B3: 34 | C3: 1362 | D3: 838 | E3: 20 | F3: 62 | G3: 59 | H3: 1.4
A4: Limerick City West | B4: 58 | C4: 2487 | D4: 2084 | E4: 38 | F4: 84 | G4: 66 | H4: 1.4
A5: Adare-Rathkeale | B5: 11 | C5: 179 | D5: 31 | E5: 4 | F5: 17 | G5: 36 | H5: 2.1
A6: Cappamore-Kilmallock | B6: 23 | C6: 323 | D6: 192 | E6: 18 | F6: 59 | G6: 78 | H6: 1.8
A7: Newcastle West | B7: 16 | C7: 400 | D7: 206 | E7: 8 | F7: 52 | G7: 50 | H7: 1.3
A9: Values calculated in delivery_analysis.py from the Schemes sheet.

Sheet 4b Implementation by size
A1: band | B1: Schemes | C1: Units permitted | D1: Units started | E1: Schemes started | F1: Units started (%) | G1: Schemes started (%) | H1: Median grant to start (yrs)
A2: 1–9 | B2: 55 | C2: 297 | D2: 216 | E2: 40 | F2: 73 | G2: 73 | H2: 1.4
A3: 10–24 | B3: 51 | C3: 836 | D3: 530 | E3: 32 | F3: 63 | G3: 63 | H3: 1.5
A4: 25–49 | B4: 32 | C4: 1093 | D4: 652 | E4: 19 | F4: 60 | G4: 59 | H4: 1.8
A5: 50–99 | B5: 28 | C5: 2109 | D5: 1678 | E5: 22 | F5: 80 | G5: 79 | H5: 1.2
A6: 100+ | B6: 12 | C6: 2250 | D6: 1948 | E6: 10 | F6: 87 | G6: 83 | H6: 1.7
A8: Values calculated in delivery_analysis.py from the Schemes sheet.

Sheet 4c Implementation by type
A1: dwelling_type | B1: Schemes | C1: Units permitted | D1: Units started | E1: Schemes started | F1: Units started (%) | G1: Schemes started (%) | H1: Median grant to start (yrs)
A2: Houses | B2: 75 | C2: 1381 | D2: 954 | E2: 54 | F2: 69 | G2: 72 | H2: 1.3
A3: Mixed | B3: 28 | C3: 3260 | D3: 2773 | E3: 24 | F3: 85 | G3: 86 | H3: 1.7
A4: Apartments | B4: 52 | C4: 1452 | D4: 978 | E4: 30 | F4: 67 | G4: 58 | H4: 1.7
A5: Student | B5: 4 | C5: 82 | D5: 26 | E5: 1 | F5: 32 | G5: 25 | H5: 1.6
A6: Unknown | B6: 22 | C6: 410 | D6: 293 | E6: 15 | F6: 71 | G6: 68 | H6: 1.8
A8: Values calculated in delivery_analysis.py from the Schemes sheet.

Sheet 4d Implementation by route
A1: route | B1: Schemes | C1: Units permitted | D1: Units started | E1: Schemes started | F1: Units started (%) | G1: Schemes started (%) | H1: Median grant to start (yrs)
A2: Standard planning application | B2: 138 | C2: 4178 | D2: 3071 | E2: 93 | F2: 74 | G2: 67 | H2: 1.3
A3: LRD | B3: 3 | C3: 315 | D3: 315 | E3: 3 | F3: 100 | G3: 100 | H3: 1
A4: SHD (An Bord Pleanála) | B4: 5 | C4: 1257 | D4: 955 | E4: 3 | F4: 76 | G4: 60 | H4: 1.8
A5: Part 8 / council | B5: 35 | C5: 835 | D5: 683 | E5: 25 | F5: 82 | G5: 71 | H5: 1.8
A7: Values calculated in delivery_analysis.py from the Schemes sheet.

Sheet 4e Implementation by settlement
A1: settlement | B1: Schemes | C1: Units permitted | D1: Units started | E1: Schemes started | F1: Units started (%) | G1: Schemes started (%) | H1: Median grant to start (yrs)
A2: Other County Limerick | B2: 87 | C2: 2526 | D2: 1649 | E2: 51 | F2: 65 | G2: 59 | H2: 1.6
A3: Limerick City and Suburbs | B3: 40 | C3: 1958 | D3: 1838 | E3: 33 | F3: 94 | G3: 82 | H3: 1.4
A4: Mungret | B4: 13 | C4: 802 | D4: 781 | E4: 11 | F4: 97 | G4: 85 | H4: 0.8
A5: Patrickswell | B5: 13 | C5: 396 | D5: 282 | E5: 10 | F5: 71 | G5: 77 | H5: 3.6
A6: Newcastle West | B6: 7 | C6: 270 | D6: 172 | E6: 4 | F6: 64 | G6: 57 | H6: 0.5
A7: Annacotty | B7: 2 | C7: 149 | D7: 12 | E7: 1 | F7: 8 | G7: 50 | H7: 0.6
A8: Castleconnell | B8: 3 | C8: 129 | D8: 129 | E8: 3 | F8: 100 | G8: 100 | H8: 1.1
A9: Kilmallock | B9: 5 | C9: 92 | D9: 92 | E9: 5 | F9: 100 | G9: 100 | H9: 2.1
A10: Abbeyfeale | B10: 2 | C10: 75 | D10: 0 | E10: 0 | F10: 0 | G10: 0
A11: Bruff | B11: 1 | C11: 74 | D11: 0 | E11: 0 | F11: 0 | G11: 0
A12: Cappamore | B12: 3 | C12: 49 | D12: 49 | E12: 3 | F12: 100 | G12: 100 | H12: 1.7
A13: Rathkeale | B13: 1 | C13: 31 | D13: 0 | E13: 0 | F13: 0 | G13: 0
A14: Croom | B14: 1 | C14: 14 | D14: 0 | E14: 0 | F14: 0 | G14: 0
A15: Adare | B15: 2 | C15: 11 | D15: 11 | E15: 2 | F15: 100 | G15: 100 | H15: 2.3
A16: Caherconlish | B16: 1 | C16: 9 | D16: 9 | E16: 1 | F16: 100 | G16: 100 | H16: 2.1
A18: Values calculated in delivery_analysis.py from the Schemes sheet.

Sheet 4f Implementation by owner
A1: owner | B1: Schemes | C1: Units permitted | D1: Units started | E1: Schemes started | F1: Units started (%) | G1: Schemes started (%) | H1: Median grant to start (yrs)
A2: Public – local authority | B2: 36 | C2: 838 | D2: 686 | E2: 26 | F2: 82 | G2: 72 | H2: 1.7
A3: Public – approved housing body | B3: 14 | C3: 319 | D3: 265 | E3: 9 | F3: 83 | G3: 64 | H3: 2
A4: Private | B4: 131 | C4: 5428 | D4: 4073 | E4: 89 | F4: 75 | G4: 68 | H4: 1.2
A6: Values calculated in delivery_analysis.py from the Schemes sheet.

Sheet 4g Implementation by sector
A1: sector | B1: Schemes | C1: Units permitted | D1: Units started | E1: Schemes started | F1: Units started (%) | G1: Schemes started (%) | H1: Median grant to start (yrs)
A2: Public | B2: 50 | C2: 1157 | D2: 951 | E2: 35 | F2: 82 | G2: 70 | H2: 1.8
A3: Private | B3: 131 | C3: 5428 | D3: 4073 | E3: 89 | F3: 75 | G3: 68 | H3: 1.2
A5: Values calculated in delivery_analysis.py from the Schemes sheet.

Sheet 4h Implementation by nbhd
A1: nbhd | B1: Schemes | C1: Units permitted | D1: Units started | E1: Schemes started | F1: Units started (%) | G1: Schemes started (%) | H1: Median grant to start (yrs)
A2: City Centre | B2: 28 | C2: 409 | D2: 184 | E2: 14 | F2: 45 | G2: 50 | H2: 1.6
A3: Kings Island | B3: 1 | C3: 27 | D3: 0 | E3: 0 | F3: 0 | G3: 0
A4: Corbally/Grove Island | B4: 2 | C4: 50 | D4: 50 | E4: 2 | F4: 100 | G4: 100 | H4: 0.6
A5: Singland/Garryowen | B5: 9 | C5: 149 | D5: 123 | E5: 6 | F5: 83 | G5: 67 | H5: 1.7
A6: Castletroy/Annacotty | B6: 24 | C6: 1363 | D6: 1214 | E6: 22 | F6: 89 | G6: 92 | H6: 1.5
A7: Southhill | B7: 7 | C7: 288 | D7: 288 | E7: 7 | F7: 100 | G7: 100 | H7: 1.6
A8: Dooradoyle | B8: 16 | C8: 1282 | D8: 1231 | E8: 13 | F8: 96 | G8: 81 | H8: 0.8
A9: Ballinacurra | B9: 4 | C9: 415 | D9: 415 | E9: 4 | F9: 100 | G9: 100 | H9: 1.2
A10: Caherdavin | B10: 20 | C10: 1130 | D10: 663 | E10: 11 | F10: 59 | G10: 55 | H10: 1.1
A11: Outside city neighbourhoods | B11: 70 | C11: 1472 | D11: 856 | E11: 45 | F11: 58 | G11: 64 | H11: 1.8
A13: Values calculated in delivery_analysis.py from the Schemes sheet.

Sheet 12 Status by nbhd
A1: Neighbourhood | B1: Schemes | C1: Complete | D1: Under construction | E1: Not started – permission live | F1: Not started – past expiry | G1: Total units | H1: Public units | I1: Public share (%)
A2: City Centre | B2: 40 | C2: 83 | D2: 127 | E2: 715 | F2: 55 | G2: 980 | H2: 392 | I2: 40
A3: Kings Island | B3: 2 | C3: 0 | D3: 0 | E3: 50 | F3: 0 | G3: 50 | H3: 50 | I3: 100
A4: Corbally/Grove Island | B4: 4 | C4: 24 | D4: 26 | E4: 40 | F4: 0 | G4: 90 | H4: 0 | I4: 0
A5: Singland/Garryowen | B5: 16 | C5: 22 | D5: 146 | E5: 132 | F5: 4 | G5: 304 | H5: 59 | I5: 19
A6: Castletroy/Annacotty | B6: 32 | C6: 474 | D6: 746 | E6: 1590 | F6: 149 | G6: 2959 | H6: 6 | I6: 0
A7: Southhill | B7: 12 | C7: 284 | D7: 21 | E7: 418 | F7: 0 | G7: 723 | H7: 104 | I7: 14
A8: Dooradoyle | B8: 22 | C8: 98 | D8: 1133 | E8: 689 | F8: 0 | G8: 1920 | H8: 270 | I8: 14
A9: Ballinacurra | B9: 4 | C9: 17 | D9: 398 | E9: 0 | F9: 0 | G9: 415 | H9: 38 | I9: 9
A10: Caherdavin | B10: 24 | C10: 125 | D10: 566 | E10: 607 | F10: 12 | G10: 1310 | H10: 251 | I10: 19
A11: Outside city neighbourhoods | B11: 93 | C11: 148 | D11: 901 | E11: 902 | F11: 91 | G11: 2042 | H11: 399 | I11: 20
A13: Values calculated in delivery_analysis.py from the Schemes sheet.

Sheet 2b Timeline by sector
A1: Sector | B1: Schemes | C1: Units | D1: Approval: median | E1: Grant to start: median | F1: Grant to start: n | G1: Start to completion: median | H1: Start to completion: n | I1: Build rate (dpa): median
A2: Public | B2: 76 | C2: 1737 | D2: 0.3 | E2: 1.7 | F2: 36 | G2: 1.5 | H2: 18 | I2: 7.6
A3: Private | B3: 189 | C3: 9306 | D3: 0.7 | E3: 1 | F3: 100 | G3: 1.8 | H3: 29 | I3: 10.6
A5: Values calculated in delivery_analysis.py from the Schemes sheet.

Sheet 3b Started over time by sector
A1: Sector | B1: Started within 1 yr (%) | C1: n (1 yr) | D1: Started within 2 yr (%) | E1: n (2 yr) | F1: Started within 3 yr (%) | G1: n (3 yr) | H1: Started within 4 yr (%) | I1: n (4 yr) | J1: Started within 5 yr (%) | K1: n (5 yr)
A2: Public | B2: 8 | C2: 53 | D2: 44 | E2: 50 | F2: 58 | G2: 43 | H2: 69 | I2: 35 | J2: 60 | K2: 25
A3: Private | B3: 30 | C3: 155 | D3: 50 | E3: 131 | F3: 58 | G3: 99 | H3: 64 | I3: 84 | J3: 76 | K3: 63
A5: Values calculated in delivery_analysis.py from the Schemes sheet.

Sheet 5 Planning path
A1: Planning path | B1: Schemes | C1: Median approval (yrs) | D1: LQ | E1: UQ | F1: Units
A2: No further information, no appeal | B2: 31 | C2: 0.2 | D2: 0.2 | E2: 0.2 | F2: 1441
A3: Further information requested | B3: 126 | C3: 0.7 | D3: 0.5 | E3: 0.8 | F3: 4543
A4: Appealed | B4: 48 | C4: 1.3 | D4: 0.9 | E4: 1.7 | F4: 2703
A6: Values calculated in delivery_analysis.py from the Schemes sheet.

Sheet 6 Expiry of unstarted
A1: Expiry window | B1: Schemes | C1: Adare-Rathkeale | D1: Cappamore-Kilmallock | E1: Limerick City East | F1: Limerick City North | G1: Limerick City West | H1: Newcastle West | I1: Total units
A2: Already past expiry | B2: 14 | C2: 3 | D2: 22 | E2: 149 | F2: 16 | G2: 121 | H2: 0 | I2: 311
A3: Within 12 months | B3: 8 | C3: 65 | D3: 0 | E3: 0 | F3: 190 | G3: 51 | H3: 68 | I3: 374
A4: 12–24 months | B4: 6 | C4: 32 | D4: 0 | E4: 0 | F4: 90 | G4: 83 | H4: 0 | I4: 205
A5: 24–36 months | B5: 20 | C5: 17 | D5: 113 | E5: 0 | F5: 196 | G5: 116 | H5: 84 | I5: 526
A6: More than 36 months | B6: 43 | C6: 190 | D6: 35 | E6: 2072 | F6: 262 | G6: 1257 | H6: 10 | I6: 3826
A7: No expiry date (mainly Part 8) | B7: 17 | C7: 31 | D7: 3 | E7: 17 | F7: 55 | G7: 52 | H7: 54 | I7: 212
A9: Values calculated in delivery_analysis.py from the Schemes sheet.

Sheet 7 Expiry watchlist
A1: Planning ref | B1: Site ID | C1: Scheme | D1: Settlement | E1: LEA | F1: Neighbourhood | G1: Owner | H1: Units | I1: Size band | J1: Type | K1: Permission granted | L1: Expiry | M1: Expiry window | N1: CIS stage | O1: Last CIS update | P1: CIS notes
A2: 18168 | B2: P-978022 | C2: €3m - Mixed Use Development | D2: Other County Limerick | E2: Limerick City West | F2: City Centre | G2: Private | H2: 8 | I2: 1–9 | J2: Apartments | K2: 43300 | L2: 45125 | M2: Already past expiry | N2: Permission Granted | O2: 43271.635
A3: 18346 | B3: SG-004 | C3: €6.3m - Residential Development, Patrickswell | D3: Patrickswell | E3: Limerick City West | F3: Outside city neighbourhoods | G3: Private | H3: 49 | I3: 25–49 | J3: Houses | K3: 43396 | L3: 45221 | M3: Already past expiry | N3: Permission Granted | O3: 45187.611 | P3: Permission expiring
A4: 19302 | B4: U-1040199 | C4: €2.6m - Apartments | D4: Limerick City and Suburbs | E4: Limerick City North | F4: Caherdavin | G4: Public – approved housing body | H4: 12 | I4: 10–24 | J4: Apartments | K4: 43635 | L4: 45461 | M4: Already past expiry | N4: Tender | O4: 43738.409
A5: 19149 | B5: U-1034286 | C5: €567k - Change of Use to Care Residential Units | D5: Other County Limerick | E5: Cappamore-Kilmallock | F5: Outside city neighbourhoods | G5: Public – approved housing body | H5: 21 | I5: 10–24 | J5: Apartments | K5: 43719 | L5: 45545 | M5: Already past expiry | N5: Tender | O5: 45251.396
B6: P-1015929 | C6: €2m - Housing Development | D6: Other County Limerick | E6: Limerick City West | F6: Outside city neighbourhoods | G6: Private | H6: 17 | I6: 10–24 | J6: Unknown | K6: 43735 | L6: 45562 | M6: Already past expiry | N6: Permission Granted | O6: 43403.503
A7: 197025 | B7: SG-014 | C7: Housing Development | D7: Limerick City and Suburbs | E7: Limerick City East | F7: Castletroy/Annacotty | G7: Private | H7: 12 | I7: 10–24 | J7: Houses | K7: 43868 | L7: 45627 | M7: Already past expiry | N7: Permission Granted | O7: 43914.342
A8: 20341 | B8: P-1099323 | C8: €574k - Extension to Pub | D8: Other County Limerick | E8: Cappamore-Kilmallock | F8: Outside city neighbourhoods | G8: Private | H8: 1 | I8: 1–9 | J8: Unknown | K8: 44098 | L8: 45923 | M8: Already past expiry | N8: Permission Granted | O8: 44064.565
A9: 20622 | B9: P-1112715 | C9: €3.2m - Change of Use to Apartment Development | D9: Other County Limerick | E9: Limerick City West | F9: City Centre | G9: Private | H9: 15 | I9: 10–24 | J9: Apartments | K9: 44111 | L9: 45936 | M9: Already past expiry | N9: Permission Granted | O9: 44081.34
A10: 20222 | B10: SG-017 | C10: €8.9m - Mixed Use Development, 34-41 Catherine Street | D10: Other County Limerick | E10: Limerick City West | F10: City Centre | G10: Private | H10: 24 | I10: 10–24 | J10: Apartments | K10: 44202 | L10: 46027 | M10: Already past expiry | N10: Permission Granted | O10: 44166.485
A11: 20466 | B11: SG-018 | C11: €1.7m - 8 Apartments | D11: Other County Limerick | E11: Limerick City West | F11: City Centre | G11: Private | H11: 8 | I11: 1–9 | J11: Apartments | K11: 44306 | L11: 46131 | M11: Already past expiry | N11: Permission Granted | O11: 44315.597
A12: ABPREF309999 | B12: P-1163033 | C12: €30m - Residential Development, Annacotty | D12: Annacotty | E12: Limerick City East | F12: Castletroy/Annacotty | G12: Private | H12: 137 | I12: 100+ | J12: Mixed | K12: 44413 | L12: 46238 | M12: Already past expiry | N12: Permission Granted | O12: 45226.485 | P12: On hold / no movement
A13: 20827 | B13: P-1120093 | C13: €864k - 4 Houses | D13: Other County Limerick | E13: Limerick City North | F13: Singland/Garryowen | G13: Private | H13: 4 | I13: 1–9 | J13: Houses | K13: 44434 | L13: 46259 | M13: Already past expiry | N13: Permission Granted | O13: 44404.465
A14: 2360207 | B14: P-1283723 | C14: €680k - 3 Houses | D14: Other County Limerick | E14: Adare-Rathkeale | F14: Outside city neighbourhoods | G14: Private | H14: 3 | I14: 1–9 | J14: Houses | K14: 45187 | L14: 46282 | M14: Already past expiry | N14: Permission Granted | O14: 45155.461
A15: 201142 | B15: P-1132789 | C15: €919k - Student Accommodation Development, Saint Gerard Street | D15: Other County Limerick | E15: Limerick City West | F15: City Centre | G15: Private | I15: Unknown | J15: Student | K15: 44460 | L15: 46285 | M15: Already past expiry | N15: Permission Granted | O15: 44428.479
A16: 20525 | C16: Register: the construction of 14 dwelling houses, including 2 no semi-detached 2 | D16: Croom | E16: Adare-Rathkeale | F16: Outside city neighbourhoods | G16: Private | H16: 14 | I16: 10–24 | J16: Houses | K16: 44532 | L16: 46357 | M16: Within 12 months | N16: Permission Granted
A17: 21147 | B17: SG-021 | C17: €1.4m - Housing Development | D17: Limerick City and Suburbs | E17: Limerick City North | F17: Caherdavin | G17: Private | H17: 11 | I17: 10–24 | J17: Apartments | K17: 44599 | L17: 46424 | M17: Within 12 months | N17: Permission Granted | O17: 44565.307
A18: 21835 | B18: SG-025 | C18: €3.5m - Apartment Development, Limerick | D18: Other County Limerick | E18: Limerick City North | F18: Singland/Garryowen | G18: Private | H18: 14 | I18: 10–24 | J18: Apartments | K18: 44609 | L18: 46434 | M18: Within 12 months | N18: Permission Granted | O18: 44574.649
A19: 21630 | B19: U-1166991 | C19: €10.8m - Residential Development, Croom | D19: Other County Limerick | E19: Adare-Rathkeale | F19: Outside city neighbourhoods | G19: Private | H19: 51 | I19: 50–99 | J19: Houses | K19: 44693 | L19: 46518 | M19: Within 12 months | N19: Contract Awarded | O19: 45461.587
A20: 211598 | B20: SG-026 | C20: €5.8m - Apartment/Retail Development, Limerick | D20: Other County Limerick | E20: Limerick City West | F20: City Centre | G20: Private | H20: 37 | I20: 25–49 | J20: Apartments | K20: 44706 | L20: 46531 | M20: Within 12 months | N20: Permission Granted | O20: 44672.506
A21: ABPREF312683 | B21: P-1214059 | C21: €27.5m - Clonmacken Gardens Housing Development, Limerick | D21: Other County Limerick | E21: Limerick City North | F21: Caherdavin | G21: Private | H21: 165 | I21: 100+ | J21: Mixed | K21: 44707 | L21: 46532 | M21: Within 12 months | N21: Permission Granted | O21: 46078.359
A22: 21594 | B22: U-1165485 | C22: €11.3m - Residential Development | D22: Abbeyfeale | E22: Newcastle West | F22: Outside city neighbourhoods | G22: Private | H22: 68 | I22: 50–99 | J22: Apartments | K22: 44810 | L22: 46635 | M22: Within 12 months | N22: Contract Awarded | O22: 45217.478 | P22: On hold / no movement
A23: 211454 | B23: P-1195465 | C23: €2.1m - Apartment Development | D23: Other County Limerick | E23: Limerick City West | F23: City Centre | G23: Private | H23: 14 | I23: 10–24 | J23: Apartments | K23: 44825 | L23: 46650 | M23: Within 12 months | N23: Permission Granted | O23: 44797.607
