Workbook

Sheet Dashboard
A1: Limerick housing supply – audit land, consents and expected delivery
A2: Council city sites audit (134 sites; county audit not yet supplied) and counted residential permissions. Planning status at 08/10/2026.
A4: Headline | B4: Value
A5: Audit land (ha) | B5: =SUM(Sites!$I$2:$I$135) -> 316.212
A6: Audit sites | B6: =COUNTA(Sites!$A$2:$A$135) -> 134
A7: Estimated unit capacity on audit land | B7: =SUM(Sites!$J$2:$J$135) -> 14092
A8: Consented on audit land (within sites) | B8: =SUMIFS(Schemes!$M$2:$M$264,Schemes!$F$2:$F$264,"Audit land – within site",Schemes!$K$2:$K$264,"<>Not started – past expiry",Schemes!$K$2:$K$264,"<>In planning") -> 5252
A9: Share of capacity consented | B9: =B8/B7 -> 0.37269373
A10: Residual capacity (sum of sites) | B10: =SUM(Sites!$O$2:$O$135) -> 10143
A11: Consented partly on / at edge of audit sites (check) | B11: =SUMIFS(Schemes!$M$2:$M$264,Schemes!$F$2:$F$264,"Audit land – partly on / edge (check)",Schemes!$K$2:$K$264,"<>Not started – past expiry",Schemes!$K$2:$K$264,"<>In planning") -> 105
A12: Consented in city outside audit land | B12: =SUMIFS(Schemes!$M$2:$M$264,Schemes!$F$2:$F$264,"City – outside audit land",Schemes!$K$2:$K$264,"<>Not started – past expiry",Schemes!$K$2:$K$264,"<>In planning") -> 3174
A13: Consented in county (audit pending) | B13: =SUMIFS(Schemes!$M$2:$M$264,Schemes!$F$2:$F$264,"County – audit not yet supplied",Schemes!$K$2:$K$264,"<>Not started – past expiry",Schemes!$K$2:$K$264,"<>In planning") -> 1951
A14: All consented units | B14: =B8+B11+B12+B13 -> 10482
A15: Student bedspaces consented (PBSA)* | B15: =SUMIFS(Schemes!$N$2:$N$264,Schemes!$I$2:$I$264,"Student (PBSA)",Schemes!$K$2:$K$264,"<>Not started – past expiry",Schemes!$K$2:$K$264,"<>In planning") -> 2142
A16: Expected completions Q4 2026–2030, tracked schemes | B16: =SUM(Schemes!$W$2:$W$264)+SUM(Schemes!$X$2:$X$264)+SUM(Schemes!$Y$2:$Y$264)+SUM(Schemes!$Z$2:$Z$264)+SUM(Schemes!$AA$2:$AA$264) -> 7477.8
A17: + small schemes and one-off houses (CSO-based) | B17: ='CSO reconciliation'!H$27 -> 808.55
A18: * PBSA schemes are counted in the unit totals by their recorded units (cluster apartments), not bedspaces. See Breakdowns.
A20: 1. Audit land and capacity by landowner (city)
A21: Landowner | B21: Sites | C21: Area (ha) | D21: Capacity | E21: Complete | F21: Under constr. | G21: Permitted, not started | H21: Consented | I21: Residual
A22: Council | B22: =COUNTIFS(Sites!$E$2:$E$135,$A22) -> 39 | C22: =SUMIFS(Sites!$I$2:$I$135,Sites!$E$2:$E$135,$A22) -> 134.265 | D22: =SUMIFS(Sites!$J$2:$J$135,Sites!$E$2:$E$135,$A22) -> 6390 | E22: =SUMIFS(Sites!$K$2:$K$135,Sites!$E$2:$E$135,$A22) -> 11 | F22: =SUMIFS(Sites!$L$2:$L$135,Sites!$E$2:$E$135,$A22) -> 36 | G22: =SUMIFS(Sites!$M$2:$M$135,Sites!$E$2:$E$135,$A22) -> 663 | H22: =SUMIFS(Sites!$N$2:$N$135,Sites!$E$2:$E$135,$A22) -> 710 | I22: =SUMIFS(Sites!$O$2:$O$135,Sites!$E$2:$E$135,$A22) -> 5680
A23: Private | B23: =COUNTIFS(Sites!$E$2:$E$135,$A23) -> 77 | C23: =SUMIFS(Sites!$I$2:$I$135,Sites!$E$2:$E$135,$A23) -> 138.829 | D23: =SUMIFS(Sites!$J$2:$J$135,Sites!$E$2:$E$135,$A23) -> 6227 | E23: =SUMIFS(Sites!$K$2:$K$135,Sites!$E$2:$E$135,$A23) -> 65 | F23: =SUMIFS(Sites!$L$2:$L$135,Sites!$E$2:$E$135,$A23) -> 1359 | G23: =SUMIFS(Sites!$M$2:$M$135,Sites!$E$2:$E$135,$A23) -> 2458 | H23: =SUMIFS(Sites!$N$2:$N$135,Sites!$E$2:$E$135,$A23) -> 3882 | I23: =SUMIFS(Sites!$O$2:$O$135,Sites!$E$2:$E$135,$A23) -> 3602
A24: Unknown | B24: =COUNTIFS(Sites!$E$2:$E$135,$A24) -> 18 | C24: =SUMIFS(Sites!$I$2:$I$135,Sites!$E$2:$E$135,$A24) -> 43.118 | D24: =SUMIFS(Sites!$J$2:$J$135,Sites!$E$2:$E$135,$A24) -> 1475 | E24: =SUMIFS(Sites!$K$2:$K$135,Sites!$E$2:$E$135,$A24) -> 0 | F24: =SUMIFS(Sites!$L$2:$L$135,Sites!$E$2:$E$135,$A24) -> 240 | G24: =SUMIFS(Sites!$M$2:$M$135,Sites!$E$2:$E$135,$A24) -> 420 | H24: =SUMIFS(Sites!$N$2:$N$135,Sites!$E$2:$E$135,$A24) -> 660 | I24: =SUMIFS(Sites!$O$2:$O$135,Sites!$E$2:$E$135,$A24) -> 861
A25: Total | B25: =SUM(B22:B24) -> 134 | C25: =SUM(C22:C24) -> 316.212 | D25: =SUM(D22:D24) -> 14092 | E25: =SUM(E22:E24) -> 76 | F25: =SUM(F22:F24) -> 1635 | G25: =SUM(G22:G24) -> 3541 | H25: =SUM(H22:H24) -> 5252 | I25: =SUM(I22:I24) -> 10143
A27: 2. Residential permissions by location and status (units)
A28: Location | B28: Complete | C28: Under construction | D28: Not started – permission live | E28: Stalled (CIS) | F28: Consented total | G28: Expired, not started | H28: In planning
A29: Audit land – within site | B29: =SUMIFS(Schemes!$M$2:$M$264,Schemes!$F$2:$F$264,$A29,Schemes!$K$2:$K$264,"Complete") -> 76 | C29: =SUMIFS(Schemes!$M$2:$M$264,Schemes!$F$2:$F$264,$A29,Schemes!$K$2:$K$264,"Under construction") -> 1635 | D29: =SUMIFS(Schemes!$M$2:$M$264,Schemes!$F$2:$F$264,$A29,Schemes!$K$2:$K$264,"Not started – permission live") -> 3510 | E29: =SUMIFS(Schemes!$M$2:$M$264,Schemes!$F$2:$F$264,$A29,Schemes!$K$2:$K$264,"Stalled (CIS)") -> 31 | F29: =SUM(B29:E29) -> 5252 | G29: =SUMIFS(Schemes!$M$2:$M$264,Schemes!$F$2:$F$264,$A29,Schemes!$K$2:$K$264,"Not started – past expiry") -> 149 | H29: =SUMIFS(Schemes!$M$2:$M$264,Schemes!$F$2:$F$264,$A29,Schemes!$K$2:$K$264,"In planning") -> 97
A30: Audit land – partly on / edge (check) | B30: =SUMIFS(Schemes!$M$2:$M$264,Schemes!$F$2:$F$264,$A30,Schemes!$K$2:$K$264,"Complete") -> 0 | C30: =SUMIFS(Schemes!$M$2:$M$264,Schemes!$F$2:$F$264,$A30,Schemes!$K$2:$K$264,"Under construction") -> 50 | D30: =SUMIFS(Schemes!$M$2:$M$264,Schemes!$F$2:$F$264,$A30,Schemes!$K$2:$K$264,"Not started – permission live") -> 55 | E30: =SUMIFS(Schemes!$M$2:$M$264,Schemes!$F$2:$F$264,$A30,Schemes!$K$2:$K$264,"Stalled (CIS)") -> 0 | F30: =SUM(B30:E30) -> 105 | G30: =SUMIFS(Schemes!$M$2:$M$264,Schemes!$F$2:$F$264,$A30,Schemes!$K$2:$K$264,"Not started – past expiry") -> 0 | H30: =SUMIFS(Schemes!$M$2:$M$264,Schemes!$F$2:$F$264,$A30,Schemes!$K$2:$K$264,"In planning") -> 4
A31: City – outside audit land | B31: =SUMIFS(Schemes!$M$2:$M$264,Schemes!$F$2:$F$264,$A31,Schemes!$K$2:$K$264,"Complete") -> 1051 | C31: =SUMIFS(Schemes!$M$2:$M$264,Schemes!$F$2:$F$264,$A31,Schemes!$K$2:$K$264,"Under construction") -> 1478 | D31: =SUMIFS(Schemes!$M$2:$M$264,Schemes!$F$2:$F$264,$A31,Schemes!$K$2:$K$264,"Not started – permission live") -> 645 | E31: =SUMIFS(Schemes!$M$2:$M$264,Schemes!$F$2:$F$264,$A31,Schemes!$K$2:$K$264,"Stalled (CIS)") -> 0 | F31: =SUM(B31:E31) -> 3174 | G31: =SUMIFS(Schemes!$M$2:$M$264,Schemes!$F$2:$F$264,$A31,Schemes!$K$2:$K$264,"Not started – past expiry") -> 71 | H31: =SUMIFS(Schemes!$M$2:$M$264,Schemes!$F$2:$F$264,$A31,Schemes!$K$2:$K$264,"In planning") -> 59
A32: County – audit not yet supplied | B32: =SUMIFS(Schemes!$M$2:$M$264,Schemes!$F$2:$F$264,$A32,Schemes!$K$2:$K$264,"Complete") -> 148 | C32: =SUMIFS(Schemes!$M$2:$M$264,Schemes!$F$2:$F$264,$A32,Schemes!$K$2:$K$264,"Under construction") -> 901 | D32: =SUMIFS(Schemes!$M$2:$M$264,Schemes!$F$2:$F$264,$A32,Schemes!$K$2:$K$264,"Not started – permission live") -> 777 | E32: =SUMIFS(Schemes!$M$2:$M$264,Schemes!$F$2:$F$264,$A32,Schemes!$K$2:$K$264,"Stalled (CIS)") -> 125 | F32: =SUM(B32:E32) -> 1951 | G32: =SUMIFS(Schemes!$M$2:$M$264,Schemes!$F$2:$F$264,$A32,Schemes!$K$2:$K$264,"Not started – past expiry") -> 91 | H32: =SUMIFS(Schemes!$M$2:$M$264,Schemes!$F$2:$F$264,$A32,Schemes!$K$2:$K$264,"In planning") -> 90
A33: Total | B33: =SUM(B29:B32) -> 1275 | C33: =SUM(C29:C32) -> 4064 | D33: =SUM(D29:D32) -> 4987 | E33: =SUM(E29:E32) -> 156 | F33: =SUM(F29:F32) -> 10482 | G33: =SUM(G29:G32) -> 311 | H33: =SUM(H29:H32) -> 250
A35: 3. Consented units by sector and location
A36: Sector | B36: Audit land – within site | C36: Audit land – partly / edge | D36: City – outside audit land | E36: County | F36: Total | G36: Share
A37: Private | B37: =SUMIFS(Schemes!$M$2:$M$264,Schemes!$H$2:$H$264,$A37,Schemes!$F$2:$F$264,"Audit land – within site",Schemes!$K$2:$K$264,"<>Not started – past expiry",Schemes!$K$2:$K$264,"<>In planning") -> 4498 | C37: =SUMIFS(Schemes!$M$2:$M$264,Schemes!$H$2:$H$264,$A37,Schemes!$F$2:$F$264,"Audit land – partly on / edge (check)",Schemes!$K$2:$K$264,"<>Not started – past expiry",Schemes!$K$2:$K$264,"<>In planning") -> 27 | D37: =SUMIFS(Schemes!$M$2:$M$264,Schemes!$H$2:$H$264,$A37,Schemes!$F$2:$F$264,"City – outside audit land",Schemes!$K$2:$K$264,"<>Not started – past expiry",Schemes!$K$2:$K$264,"<>In planning") -> 2848 | E37: =SUMIFS(Schemes!$M$2:$M$264,Schemes!$H$2:$H$264,$A37,Schemes!$F$2:$F$264,"County – audit not yet supplied",Schemes!$K$2:$K$264,"<>Not started – past expiry",Schemes!$K$2:$K$264,"<>In planning") -> 1573 | F37: =SUM(B37:E37) -> 8946 | G37: =IF($F$41=0,0,F37/$F$41) -> 0.85346308
A38: Public – local authority | B38: =SUMIFS(Schemes!$M$2:$M$264,Schemes!$H$2:$H$264,$A38,Schemes!$F$2:$F$264,"Audit land – within site",Schemes!$K$2:$K$264,"<>Not started – past expiry",Schemes!$K$2:$K$264,"<>In planning") -> 324 | C38: =SUMIFS(Schemes!$M$2:$M$264,Schemes!$H$2:$H$264,$A38,Schemes!$F$2:$F$264,"Audit land – partly on / edge (check)",Schemes!$K$2:$K$264,"<>Not started – past expiry",Schemes!$K$2:$K$264,"<>In planning") -> 74 | D38: =SUMIFS(Schemes!$M$2:$M$264,Schemes!$H$2:$H$264,$A38,Schemes!$F$2:$F$264,"City – outside audit land",Schemes!$K$2:$K$264,"<>Not started – past expiry",Schemes!$K$2:$K$264,"<>In planning") -> 248 | E38: =SUMIFS(Schemes!$M$2:$M$264,Schemes!$H$2:$H$264,$A38,Schemes!$F$2:$F$264,"County – audit not yet supplied",Schemes!$K$2:$K$264,"<>Not started – past expiry",Schemes!$K$2:$K$264,"<>In planning") -> 307 | F38: =SUM(B38:E38) -> 953 | G38: =IF($F$41=0,0,F38/$F$41) -> 0.090917764
A39: Public – AHB | B39: =SUMIFS(Schemes!$M$2:$M$264,Schemes!$H$2:$H$264,$A39,Schemes!$F$2:$F$264,"Audit land – within site",Schemes!$K$2:$K$264,"<>Not started – past expiry",Schemes!$K$2:$K$264,"<>In planning") -> 145 | C39: =SUMIFS(Schemes!$M$2:$M$264,Schemes!$H$2:$H$264,$A39,Schemes!$F$2:$F$264,"Audit land – partly on / edge (check)",Schemes!$K$2:$K$264,"<>Not started – past expiry",Schemes!$K$2:$K$264,"<>In planning") -> 4 | D39: =SUMIFS(Schemes!$M$2:$M$264,Schemes!$H$2:$H$264,$A39,Schemes!$F$2:$F$264,"City – outside audit land",Schemes!$K$2:$K$264,"<>Not started – past expiry",Schemes!$K$2:$K$264,"<>In planning") -> 78 | E39: =SUMIFS(Schemes!$M$2:$M$264,Schemes!$H$2:$H$264,$A39,Schemes!$F$2:$F$264,"County – audit not yet supplied",Schemes!$K$2:$K$264,"<>Not started – past expiry",Schemes!$K$2:$K$264,"<>In planning") -> 71 | F39: =SUM(B39:E39) -> 298 | G39: =IF($F$41=0,0,F39/$F$41) -> 0.028429689
A40: Public – LDA | B40: =SUMIFS(Schemes!$M$2:$M$264,Schemes!$H$2:$H$264,$A40,Schemes!$F$2:$F$264,"Audit land – within site",Schemes!$K$2:$K$264,"<>Not started – past expiry",Schemes!$K$2:$K$264,"<>In planning") -> 285 | C40: =SUMIFS(Schemes!$M$2:$M$264,Schemes!$H$2:$H$264,$A40,Schemes!$F$2:$F$264,"Audit land – partly on / edge (check)",Schemes!$K$2:$K$264,"<>Not started – past expiry",Schemes!$K$2:$K$264,"<>In planning") -> 0 | D40: =SUMIFS(Schemes!$M$2:$M$264,Schemes!$H$2:$H$264,$A40,Schemes!$F$2:$F$264,"City – outside audit land",Schemes!$K$2:$K$264,"<>Not started – past expiry",Schemes!$K$2:$K$264,"<>In planning") -> 0 | E40: =SUMIFS(Schemes!$M$2:$M$264,Schemes!$H$2:$H$264,$A40,Schemes!$F$2:$F$264,"County – audit not yet supplied",Schemes!$K$2:$K$264,"<>Not started – past expiry",Schemes!$K$2:$K$264,"<>In planning") -> 0 | F40: =SUM(B40:E40) -> 285 | G40: =IF($F$41=0,0,F40/$F$41) -> 0.027189468
A41: Total | B41: =SUM(B37:B40) -> 5252 | C41: =SUM(C37:C40) -> 105 | D41: =SUM(D37:D40) -> 3174 | E41: =SUM(E37:E40) -> 1951 | F41: =SUM(F37:F40) -> 10482 | G41: =IF($F$41=0,0,F41/$F$41) -> 1
A42: Public subtotal (LA + AHB + LDA) | B42: =SUM(B38:B40) -> 754 | C42: =SUM(C38:C40) -> 78 | D42: =SUM(D38:D40) -> 326 | E42: =SUM(E38:E40) -> 378 | F42: =SUM(F38:F40) -> 1536 | G42: =IF($F$41=0,0,F42/$F$41) -> 0.14653692
A44: 4. Expected completions by year and sector (consented, not yet complete)
A45: Sector | B45: Q4 2026 | C45: 2027 | D45: 2028 | E45: 2029 | F45: 2030 | G45: 2031+ | H45: Total projected | I45: Not projected*
...

Sheet Breakdowns
A1: Breakdowns
A3: City neighbourhoods: audit land, capacity and consents
A4: Neighbourhood | B4: Audit sites | C4: Area (ha) | D4: Capacity | E4: Consented within sites | F4: Residual | G4: Consented, partly / edge | H4: Consented outside audit land | I4: All consented
A5: Ballinacurra | B5: =COUNTIFS(Sites!$C$2:$C$135,$A5) -> 5 | C5: =SUMIFS(Sites!$I$2:$I$135,Sites!$C$2:$C$135,$A5) -> 4.53 | D5: =SUMIFS(Sites!$J$2:$J$135,Sites!$C$2:$C$135,$A5) -> 203 | E5: =SUMIFS(Schemes!$M$2:$M$264,Schemes!$D$2:$D$264,$A5,Schemes!$F$2:$F$264,"Audit land – within site",Schemes!$K$2:$K$264,"<>Not started – past expiry",Schemes!$K$2:$K$264,"<>In planning") -> 371 | F5: =SUMIFS(Sites!$O$2:$O$135,Sites!$C$2:$C$135,$A5) -> 148 | G5: =SUMIFS(Schemes!$M$2:$M$264,Schemes!$D$2:$D$264,$A5,Schemes!$F$2:$F$264,"Audit land – partly on / edge (check)",Schemes!$K$2:$K$264,"<>Not started – past expiry",Schemes!$K$2:$K$264,"<>In planning") -> 0 | H5: =SUMIFS(Schemes!$M$2:$M$264,Schemes!$D$2:$D$264,$A5,Schemes!$F$2:$F$264,"City – outside audit land",Schemes!$K$2:$K$264,"<>Not started – past expiry",Schemes!$K$2:$K$264,"<>In planning") -> 44 | I5: =E5+G5+H5 -> 415
A6: Caherdavin | B6: =COUNTIFS(Sites!$C$2:$C$135,$A6) -> 19 | C6: =SUMIFS(Sites!$I$2:$I$135,Sites!$C$2:$C$135,$A6) -> 47.86 | D6: =SUMIFS(Sites!$J$2:$J$135,Sites!$C$2:$C$135,$A6) -> 1933 | E6: =SUMIFS(Schemes!$M$2:$M$264,Schemes!$D$2:$D$264,$A6,Schemes!$F$2:$F$264,"Audit land – within site",Schemes!$K$2:$K$264,"<>Not started – past expiry",Schemes!$K$2:$K$264,"<>In planning") -> 1037 | F6: =SUMIFS(Sites!$O$2:$O$135,Sites!$C$2:$C$135,$A6) -> 938 | G6: =SUMIFS(Schemes!$M$2:$M$264,Schemes!$D$2:$D$264,$A6,Schemes!$F$2:$F$264,"Audit land – partly on / edge (check)",Schemes!$K$2:$K$264,"<>Not started – past expiry",Schemes!$K$2:$K$264,"<>In planning") -> 38 | H6: =SUMIFS(Schemes!$M$2:$M$264,Schemes!$D$2:$D$264,$A6,Schemes!$F$2:$F$264,"City – outside audit land",Schemes!$K$2:$K$264,"<>Not started – past expiry",Schemes!$K$2:$K$264,"<>In planning") -> 223 | I6: =E6+G6+H6 -> 1298
A7: Castletroy/Annacotty | B7: =COUNTIFS(Sites!$C$2:$C$135,$A7) -> 16 | C7: =SUMIFS(Sites!$I$2:$I$135,Sites!$C$2:$C$135,$A7) -> 56.808 | D7: =SUMIFS(Sites!$J$2:$J$135,Sites!$C$2:$C$135,$A7) -> 2355 | E7: =SUMIFS(Schemes!$M$2:$M$264,Schemes!$D$2:$D$264,$A7,Schemes!$F$2:$F$264,"Audit land – within site",Schemes!$K$2:$K$264,"<>Not started – past expiry",Schemes!$K$2:$K$264,"<>In planning") -> 1666 | F7: =SUMIFS(Sites!$O$2:$O$135,Sites!$C$2:$C$135,$A7) -> 1188 | G7: =SUMIFS(Schemes!$M$2:$M$264,Schemes!$D$2:$D$264,$A7,Schemes!$F$2:$F$264,"Audit land – partly on / edge (check)",Schemes!$K$2:$K$264,"<>Not started – past expiry",Schemes!$K$2:$K$264,"<>In planning") -> 0 | H7: =SUMIFS(Schemes!$M$2:$M$264,Schemes!$D$2:$D$264,$A7,Schemes!$F$2:$F$264,"City – outside audit land",Schemes!$K$2:$K$264,"<>Not started – past expiry",Schemes!$K$2:$K$264,"<>In planning") -> 1144 | I7: =E7+G7+H7 -> 2810
A8: City Centre | B8: =COUNTIFS(Sites!$C$2:$C$135,$A8) -> 21 | C8: =SUMIFS(Sites!$I$2:$I$135,Sites!$C$2:$C$135,$A8) -> 77.639 | D8: =SUMIFS(Sites!$J$2:$J$135,Sites!$C$2:$C$135,$A8) -> 3633 | E8: =SUMIFS(Schemes!$M$2:$M$264,Schemes!$D$2:$D$264,$A8,Schemes!$F$2:$F$264,"Audit land – within site",Schemes!$K$2:$K$264,"<>Not started – past expiry",Schemes!$K$2:$K$264,"<>In planning") -> 332 | F8: =SUMIFS(Sites!$O$2:$O$135,Sites!$C$2:$C$135,$A8) -> 3301 | G8: =SUMIFS(Schemes!$M$2:$M$264,Schemes!$D$2:$D$264,$A8,Schemes!$F$2:$F$264,"Audit land – partly on / edge (check)",Schemes!$K$2:$K$264,"<>Not started – past expiry",Schemes!$K$2:$K$264,"<>In planning") -> 12 | H8: =SUMIFS(Schemes!$M$2:$M$264,Schemes!$D$2:$D$264,$A8,Schemes!$F$2:$F$264,"City – outside audit land",Schemes!$K$2:$K$264,"<>Not started – past expiry",Schemes!$K$2:$K$264,"<>In planning") -> 581 | I8: =E8+G8+H8 -> 925
A9: Corbally/Grove Island | B9: =COUNTIFS(Sites!$C$2:$C$135,$A9) -> 9 | C9: =SUMIFS(Sites!$I$2:$I$135,Sites!$C$2:$C$135,$A9) -> 16.707 | D9: =SUMIFS(Sites!$J$2:$J$135,Sites!$C$2:$C$135,$A9) -> 646 | E9: =SUMIFS(Schemes!$M$2:$M$264,Schemes!$D$2:$D$264,$A9,Schemes!$F$2:$F$264,"Audit land – within site",Schemes!$K$2:$K$264,"<>Not started – past expiry",Schemes!$K$2:$K$264,"<>In planning") -> 51 | F9: =SUMIFS(Sites!$O$2:$O$135,Sites!$C$2:$C$135,$A9) -> 599 | G9: =SUMIFS(Schemes!$M$2:$M$264,Schemes!$D$2:$D$264,$A9,Schemes!$F$2:$F$264,"Audit land – partly on / edge (check)",Schemes!$K$2:$K$264,"<>Not started – past expiry",Schemes!$K$2:$K$264,"<>In planning") -> 15 | H9: =SUMIFS(Schemes!$M$2:$M$264,Schemes!$D$2:$D$264,$A9,Schemes!$F$2:$F$264,"City – outside audit land",Schemes!$K$2:$K$264,"<>Not started – past expiry",Schemes!$K$2:$K$264,"<>In planning") -> 24 | I9: =E9+G9+H9 -> 90
A10: Dooradoyle | B10: =COUNTIFS(Sites!$C$2:$C$135,$A10) -> 21 | C10: =SUMIFS(Sites!$I$2:$I$135,Sites!$C$2:$C$135,$A10) -> 80.257 | D10: =SUMIFS(Sites!$J$2:$J$135,Sites!$C$2:$C$135,$A10) -> 3699 | E10: =SUMIFS(Schemes!$M$2:$M$264,Schemes!$D$2:$D$264,$A10,Schemes!$F$2:$F$264,"Audit land – within site",Schemes!$K$2:$K$264,"<>Not started – past expiry",Schemes!$K$2:$K$264,"<>In planning") -> 1124 | F10: =SUMIFS(Sites!$O$2:$O$135,Sites!$C$2:$C$135,$A10) -> 2792 | G10: =SUMIFS(Schemes!$M$2:$M$264,Schemes!$D$2:$D$264,$A10,Schemes!$F$2:$F$264,"Audit land – partly on / edge (check)",Schemes!$K$2:$K$264,"<>Not started – past expiry",Schemes!$K$2:$K$264,"<>In planning") -> 0 | H10: =SUMIFS(Schemes!$M$2:$M$264,Schemes!$D$2:$D$264,$A10,Schemes!$F$2:$F$264,"City – outside audit land",Schemes!$K$2:$K$264,"<>Not started – past expiry",Schemes!$K$2:$K$264,"<>In planning") -> 796 | I10: =E10+G10+H10 -> 1920
A11: Kings Island | B11: =COUNTIFS(Sites!$C$2:$C$135,$A11) -> 4 | C11: =SUMIFS(Sites!$I$2:$I$135,Sites!$C$2:$C$135,$A11) -> 0.734 | D11: =SUMIFS(Sites!$J$2:$J$135,Sites!$C$2:$C$135,$A11) -> 52 | E11: =SUMIFS(Schemes!$M$2:$M$264,Schemes!$D$2:$D$264,$A11,Schemes!$F$2:$F$264,"Audit land – within site",Schemes!$K$2:$K$264,"<>Not started – past expiry",Schemes!$K$2:$K$264,"<>In planning") -> 27 | F11: =SUMIFS(Sites!$O$2:$O$135,Sites!$C$2:$C$135,$A11) -> 25 | G11: =SUMIFS(Schemes!$M$2:$M$264,Schemes!$D$2:$D$264,$A11,Schemes!$F$2:$F$264,"Audit land – partly on / edge (check)",Schemes!$K$2:$K$264,"<>Not started – past expiry",Schemes!$K$2:$K$264,"<>In planning") -> 23 | H11: =SUMIFS(Schemes!$M$2:$M$264,Schemes!$D$2:$D$264,$A11,Schemes!$F$2:$F$264,"City – outside audit land",Schemes!$K$2:$K$264,"<>Not started – past expiry",Schemes!$K$2:$K$264,"<>In planning") -> 0 | I11: =E11+G11+H11 -> 50
A12: Singland/Garryowen | B12: =COUNTIFS(Sites!$C$2:$C$135,$A12) -> 19 | C12: =SUMIFS(Sites!$I$2:$I$135,Sites!$C$2:$C$135,$A12) -> 13.036 | D12: =SUMIFS(Sites!$J$2:$J$135,Sites!$C$2:$C$135,$A12) -> 615 | E12: =SUMIFS(Schemes!$M$2:$M$264,Schemes!$D$2:$D$264,$A12,Schemes!$F$2:$F$264,"Audit land – within site",Schemes!$K$2:$K$264,"<>Not started – past expiry",Schemes!$K$2:$K$264,"<>In planning") -> 231 | F12: =SUMIFS(Sites!$O$2:$O$135,Sites!$C$2:$C$135,$A12) -> 469 | G12: =SUMIFS(Schemes!$M$2:$M$264,Schemes!$D$2:$D$264,$A12,Schemes!$F$2:$F$264,"Audit land – partly on / edge (check)",Schemes!$K$2:$K$264,"<>Not started – past expiry",Schemes!$K$2:$K$264,"<>In planning") -> 0 | H12: =SUMIFS(Schemes!$M$2:$M$264,Schemes!$D$2:$D$264,$A12,Schemes!$F$2:$F$264,"City – outside audit land",Schemes!$K$2:$K$264,"<>Not started – past expiry",Schemes!$K$2:$K$264,"<>In planning") -> 69 | I12: =E12+G12+H12 -> 300
A13: Southhill | B13: =COUNTIFS(Sites!$C$2:$C$135,$A13) -> 20 | C13: =SUMIFS(Sites!$I$2:$I$135,Sites!$C$2:$C$135,$A13) -> 18.641 | D13: =SUMIFS(Sites!$J$2:$J$135,Sites!$C$2:$C$135,$A13) -> 956 | E13: =SUMIFS(Schemes!$M$2:$M$264,Schemes!$D$2:$D$264,$A13,Schemes!$F$2:$F$264,"Audit land – within site",Schemes!$K$2:$K$264,"<>Not started – past expiry",Schemes!$K$2:$K$264,"<>In planning") -> 413 | F13: =SUMIFS(Sites!$O$2:$O$135,Sites!$C$2:$C$135,$A13) -> 683 | G13: =SUMIFS(Schemes!$M$2:$M$264,Schemes!$D$2:$D$264,$A13,Schemes!$F$2:$F$264,"Audit land – partly on / edge (check)",Schemes!$K$2:$K$264,"<>Not started – past expiry",Schemes!$K$2:$K$264,"<>In planning") -> 17 | H13: =SUMIFS(Schemes!$M$2:$M$264,Schemes!$D$2:$D$264,$A13,Schemes!$F$2:$F$264,"City – outside audit land",Schemes!$K$2:$K$264,"<>Not started – past expiry",Schemes!$K$2:$K$264,"<>In planning") -> 293 | I13: =E13+G13+H13 -> 723
A14: Total | B14: =SUM(B5:B13) -> 134 | C14: =SUM(C5:C13) -> 316.212 | D14: =SUM(D5:D13) -> 14092 | E14: =SUM(E5:E13) -> 5252 | F14: =SUM(F5:F13) -> 10143 | G14: =SUM(G5:G13) -> 105 | H14: =SUM(H5:H13) -> 3174 | I14: =SUM(I5:I13) -> 8531
A15: Consents within sites are counted by the scheme’s own neighbourhood, so a few may sit in a different row from the site they fall on near a boundary.
A17: Consented units by tenure and location
A18: Tenure | B18: Audit land – within site | C18: Audit land – partly / edge | D18: City – outside audit land | E18: County | F18: Total
A19: Market (incl. Part V) | B19: =SUMIFS(Schemes!$M$2:$M$264,Schemes!$I$2:$I$264,$A19,Schemes!$F$2:$F$264,"Audit land – within site",Schemes!$K$2:$K$264,"<>Not started – past expiry",Schemes!$K$2:$K$264,"<>In planning") -> 3780 | C19: =SUMIFS(Schemes!$M$2:$M$264,Schemes!$I$2:$I$264,$A19,Schemes!$F$2:$F$264,"Audit land – partly on / edge (check)",Schemes!$K$2:$K$264,"<>Not started – past expiry",Schemes!$K$2:$K$264,"<>In planning") -> 27 | D19: =SUMIFS(Schemes!$M$2:$M$264,Schemes!$I$2:$I$264,$A19,Schemes!$F$2:$F$264,"City – outside audit land",Schemes!$K$2:$K$264,"<>Not started – past expiry",Schemes!$K$2:$K$264,"<>In planning") -> 2823 | E19: =SUMIFS(Schemes!$M$2:$M$264,Schemes!$I$2:$I$264,$A19,Schemes!$F$2:$F$264,"County – audit not yet supplied",Schemes!$K$2:$K$264,"<>Not started – past expiry",Schemes!$K$2:$K$264,"<>In planning") -> 1573 | F19: =SUM(B19:E19) -> 8203
A20: Social | B20: =SUMIFS(Schemes!$M$2:$M$264,Schemes!$I$2:$I$264,$A20,Schemes!$F$2:$F$264,"Audit land – within site",Schemes!$K$2:$K$264,"<>Not started – past expiry",Schemes!$K$2:$K$264,"<>In planning") -> 469 | C20: =SUMIFS(Schemes!$M$2:$M$264,Schemes!$I$2:$I$264,$A20,Schemes!$F$2:$F$264,"Audit land – partly on / edge (check)",Schemes!$K$2:$K$264,"<>Not started – past expiry",Schemes!$K$2:$K$264,"<>In planning") -> 78 | D20: =SUMIFS(Schemes!$M$2:$M$264,Schemes!$I$2:$I$264,$A20,Schemes!$F$2:$F$264,"City – outside audit land",Schemes!$K$2:$K$264,"<>Not started – past expiry",Schemes!$K$2:$K$264,"<>In planning") -> 326 | E20: =SUMIFS(Schemes!$M$2:$M$264,Schemes!$I$2:$I$264,$A20,Schemes!$F$2:$F$264,"County – audit not yet supplied",Schemes!$K$2:$K$264,"<>Not started – past expiry",Schemes!$K$2:$K$264,"<>In planning") -> 347 | F20: =SUM(B20:E20) -> 1220
A21: Affordable / cost rental | B21: =SUMIFS(Schemes!$M$2:$M$264,Schemes!$I$2:$I$264,$A21,Schemes!$F$2:$F$264,"Audit land – within site",Schemes!$K$2:$K$264,"<>Not started – past expiry",Schemes!$K$2:$K$264,"<>In planning") -> 285 | C21: =SUMIFS(Schemes!$M$2:$M$264,Schemes!$I$2:$I$264,$A21,Schemes!$F$2:$F$264,"Audit land – partly on / edge (check)",Schemes!$K$2:$K$264,"<>Not started – past expiry",Schemes!$K$2:$K$264,"<>In planning") -> 0 | D21: =SUMIFS(Schemes!$M$2:$M$264,Schemes!$I$2:$I$264,$A21,Schemes!$F$2:$F$264,"City – outside audit land",Schemes!$K$2:$K$264,"<>Not started – past expiry",Schemes!$K$2:$K$264,"<>In planning") -> 0 | E21: =SUMIFS(Schemes!$M$2:$M$264,Schemes!$I$2:$I$264,$A21,Schemes!$F$2:$F$264,"County – audit not yet supplied",Schemes!$K$2:$K$264,"<>Not started – past expiry",Schemes!$K$2:$K$264,"<>In planning") -> 31 | F21: =SUM(B21:E21) -> 316
A22: Student (PBSA) | B22: =SUMIFS(Schemes!$M$2:$M$264,Schemes!$I$2:$I$264,$A22,Schemes!$F$2:$F$264,"Audit land – within site",Schemes!$K$2:$K$264,"<>Not started – past expiry",Schemes!$K$2:$K$264,"<>In planning") -> 718 | C22: =SUMIFS(Schemes!$M$2:$M$264,Schemes!$I$2:$I$264,$A22,Schemes!$F$2:$F$264,"Audit land – partly on / edge (check)",Schemes!$K$2:$K$264,"<>Not started – past expiry",Schemes!$K$2:$K$264,"<>In planning") -> 0 | D22: =SUMIFS(Schemes!$M$2:$M$264,Schemes!$I$2:$I$264,$A22,Schemes!$F$2:$F$264,"City – outside audit land",Schemes!$K$2:$K$264,"<>Not started – past expiry",Schemes!$K$2:$K$264,"<>In planning") -> 25 | E22: =SUMIFS(Schemes!$M$2:$M$264,Schemes!$I$2:$I$264,$A22,Schemes!$F$2:$F$264,"County – audit not yet supplied",Schemes!$K$2:$K$264,"<>Not started – past expiry",Schemes!$K$2:$K$264,"<>In planning") -> 0 | F22: =SUM(B22:E22) -> 743
A23: Total | B23: =SUM(B19:B22) -> 5252 | C23: =SUM(C19:C22) -> 105 | D23: =SUM(D19:D22) -> 3174 | E23: =SUM(E19:E22) -> 1951 | F23: =SUM(F19:F22) -> 10482
A25: Consented units by sector and status
A26: Sector | B26: Complete | C26: Under construction | D26: Not started – permission live | E26: Stalled (CIS) | F26: Not started – past expiry | G26: In planning
A27: Private | B27: =SUMIFS(Schemes!$M$2:$M$264,Schemes!$H$2:$H$264,$A27,Schemes!$K$2:$K$264,"Complete") -> 974 | C27: =SUMIFS(Schemes!$M$2:$M$264,Schemes!$H$2:$H$264,$A27,Schemes!$K$2:$K$264,"Under construction") -> 3347 | D27: =SUMIFS(Schemes!$M$2:$M$264,Schemes!$H$2:$H$264,$A27,Schemes!$K$2:$K$264,"Not started – permission live") -> 4469 | E27: =SUMIFS(Schemes!$M$2:$M$264,Schemes!$H$2:$H$264,$A27,Schemes!$K$2:$K$264,"Stalled (CIS)") -> 156 | F27: =SUMIFS(Schemes!$M$2:$M$264,Schemes!$H$2:$H$264,$A27,Schemes!$K$2:$K$264,"Not started – past expiry") -> 278 | G27: =SUMIFS(Schemes!$M$2:$M$264,Schemes!$H$2:$H$264,$A27,Schemes!$K$2:$K$264,"In planning") -> 82
A28: Public – local authority | B28: =SUMIFS(Schemes!$M$2:$M$264,Schemes!$H$2:$H$264,$A28,Schemes!$K$2:$K$264,"Complete") -> 207 | C28: =SUMIFS(Schemes!$M$2:$M$264,Schemes!$H$2:$H$264,$A28,Schemes!$K$2:$K$264,"Under construction") -> 546 | D28: =SUMIFS(Schemes!$M$2:$M$264,Schemes!$H$2:$H$264,$A28,Schemes!$K$2:$K$264,"Not started – permission live") -> 200 | E28: =SUMIFS(Schemes!$M$2:$M$264,Schemes!$H$2:$H$264,$A28,Schemes!$K$2:$K$264,"Stalled (CIS)") -> 0 | F28: =SUMIFS(Schemes!$M$2:$M$264,Schemes!$H$2:$H$264,$A28,Schemes!$K$2:$K$264,"Not started – past expiry") -> 0 | G28: =SUMIFS(Schemes!$M$2:$M$264,Schemes!$H$2:$H$264,$A28,Schemes!$K$2:$K$264,"In planning") -> 160
A29: Public – AHB | B29: =SUMIFS(Schemes!$M$2:$M$264,Schemes!$H$2:$H$264,$A29,Schemes!$K$2:$K$264,"Complete") -> 94 | C29: =SUMIFS(Schemes!$M$2:$M$264,Schemes!$H$2:$H$264,$A29,Schemes!$K$2:$K$264,"Under construction") -> 171 | D29: =SUMIFS(Schemes!$M$2:$M$264,Schemes!$H$2:$H$264,$A29,Schemes!$K$2:$K$264,"Not started – permission live") -> 33 | E29: =SUMIFS(Schemes!$M$2:$M$264,Schemes!$H$2:$H$264,$A29,Schemes!$K$2:$K$264,"Stalled (CIS)") -> 0 | F29: =SUMIFS(Schemes!$M$2:$M$264,Schemes!$H$2:$H$264,$A29,Schemes!$K$2:$K$264,"Not started – past expiry") -> 33 | G29: =SUMIFS(Schemes!$M$2:$M$264,Schemes!$H$2:$H$264,$A29,Schemes!$K$2:$K$264,"In planning") -> 8
A30: Public – LDA | B30: =SUMIFS(Schemes!$M$2:$M$264,Schemes!$H$2:$H$264,$A30,Schemes!$K$2:$K$264,"Complete") -> 0 | C30: =SUMIFS(Schemes!$M$2:$M$264,Schemes!$H$2:$H$264,$A30,Schemes!$K$2:$K$264,"Under construction") -> 0 | D30: =SUMIFS(Schemes!$M$2:$M$264,Schemes!$H$2:$H$264,$A30,Schemes!$K$2:$K$264,"Not started – permission live") -> 285 | E30: =SUMIFS(Schemes!$M$2:$M$264,Schemes!$H$2:$H$264,$A30,Schemes!$K$2:$K$264,"Stalled (CIS)") -> 0 | F30: =SUMIFS(Schemes!$M$2:$M$264,Schemes!$H$2:$H$264,$A30,Schemes!$K$2:$K$264,"Not started – past expiry") -> 0 | G30: =SUMIFS(Schemes!$M$2:$M$264,Schemes!$H$2:$H$264,$A30,Schemes!$K$2:$K$264,"In planning") -> 0
A31: Total | B31: =SUM(B27:B30) -> 1275 | C31: =SUM(C27:C30) -> 4064 | D31: =SUM(D27:D30) -> 4987 | E31: =SUM(E27:E30) -> 156 | F31: =SUM(F27:F30) -> 311 | G31: =SUM(G27:G30) -> 250
A33: Purpose-built student accommodation: units and bedspaces
A34: Scheme | B34: Planning ref | C34: Location | D34: Status | E34: Units (in totals) | F34: Bedspaces | G34: Est. start | H34: Est. last completions | I34: Confidence
A35: €87m - Student Accommodation, Castletroy | B35: 2560113 | C35: Audit land – within site | D35: Not started – permission live | E35: 196 | F35: 1400 | G35: 2027 Q2 | H35: 2029 Q2 | I35: Medium
A36: €42m - Large Residential Development, Castletroy | B36: 2660089 | C36: Audit land – within site | D36: Not started – permission live | E36: 465 | F36: 309 | G36: 2028 Q2 | H36: 2037 Q3 | I36: Medium
A37: €14m - Old Dublin Road Student Village LRD, Limerick City | B37: 221216 | C37: Audit land – within site | D37: Under construction | E37: 26 | F37: 202 | G37: 2024 Q4 | H37: 2027 Q2 | I37: High
A38: €5.9m - Student Accommodation Development | B38: 221172 | C38: City – outside audit land | D38: Not started – permission live | E38: 25 | F38: 116 | G38: 2027 Q3 | H38: 2028 Q4 | I38: Low
A39: €9.4m - Student Accommodation Development, Limerick | B39: 2561232 | C39: City – outside audit land | D39: Not started – permission live | E39: 0 | F39: 115 | G39: 2027 Q4 | H39: 2029 Q3 | I39: Medium
A40: €8.5m - Student Accommodation Development, Former Hassett’s Bar | B40: 19710 | C40: Audit land – within site | D40: Stalled (CIS) | E40: 31 | I40: Not projected
A41: €919k - Student Accommodation Development, Saint Gerard Street | B41: 201142 | C41: City – outside audit land | D41: Not started – past expiry | E41: 0 | I41: Not projected
A42: Total (consented, excl. expired) | E42: =SUMIFS(Schemes!$M$2:$M$264,Schemes!$I$2:$I$264,"Student (PBSA)",Schemes!$K$2:$K$264,"<>Not started – past expiry",Schemes!$K$2:$K$264,"<>In planning") -> 743 | F42: =SUMIFS(Schemes!$N$2:$N$264,Schemes!$I$2:$I$264,"Student (PBSA)",Schemes!$K$2:$K$264,"<>Not started – past expiry",Schemes!$K$2:$K$264,"<>In planning") -> 2142
A43: Units are as recorded by CIS (usually cluster apartments). Bedspaces from the PBSA schedule or the planning register. Whitebox (25/60113): 196 units, 1,400 bedspaces. Existing PBSA stock is not pipeline and is not included.

Sheet Sites
A1: Site id | B1: Rsca | C1: Neighbourhood | D1: Local name | E1: Landowner | F1: Zoning | G1: Site type | H1: Register status | I1: Area ha | J1: Capacity units | K1: Complete units | L1: Under construction units | M1: Permitted not started units | N1: Consented units | O1: Residual capacity | P1: Expired not started units | Q1: In planning units | R1: Edge match units | S1: Permissions on site | T1: Flag | U1: Reconcile action
A2: CITY-129 | B2: 129 | C2: Ballinacurra | D2: City Centre | E2: Council | F2: New Resi | G2: Brownfield | H2: Undeveloped/Permission Sought | I2: 2.208 | J2: 99 | K2: 0 | L2: 0 | M2: 0 | N2: 0 | O2: 99 | P2: 0 | Q2: 0 | R2: 0 | S2: 0 | U2: Unchanged
A3: CITY-130 | B3: 130 | C3: Ballinacurra | D3: City Centre | E3: Council | F3: Exist Resi | G3: Infill | H3: Undeveloped/Permission Sought | I3: 0.144 | J3: 6 | K3: 0 | L3: 0 | M3: 0 | N3: 0 | O3: 6 | P3: 0 | Q3: 0 | R3: 0 | S3: 0 | U3: Unchanged
A4: CITY-131 | B4: 131 | C4: Ballinacurra | D4: City Centre | E4: Council | F4: New Resi | G4: Infill | H4: Undeveloped/Permission Sought | I4: 0.252 | J4: 11 | K4: 0 | L4: 0 | M4: 0 | N4: 0 | O4: 11 | P4: 0 | Q4: 0 | R4: 0 | S4: 0 | U4: Unchanged
A5: CITY-132 | B5: 132 | C5: Ballinacurra | D5: Dock Rd | E5: Private | F5: Exist Resi | G5: Brownfield | H5: Undeveloped/Permission Sought | I5: 0.706 | J5: 32 | K5: 0 | L5: 0 | M5: 0 | N5: 0 | O5: 32 | P5: 0 | Q5: 0 | R5: 0 | S5: 0 | U5: Unchanged
A6: CITY-133 | B6: 133 | C6: Ballinacurra | D6: Dock Rd | E6: Private | F6: New Resi | G6: Infill | H6: Complete/Commenced | I6: 1.22 | J6: 55 | K6: 0 | L6: 371 | M6: 0 | N6: 371 | O6: 0 | P6: 0 | Q6: 0 | R6: 0 | S6: 1 | T6: Consented above capacity | U6: Reduced Area
A7: CITY-1 | B7: 1 | C7: Caherdavin | D7: Northside | E7: Private | F7: New Resi | G7: Greenfield | H7: Permission Granted | I7: 2.408 | J7: 165 | K7: 0 | L7: 0 | M7: 165 | N7: 165 | O7: 0 | P7: 0 | Q7: 0 | R7: 0 | S7: 1 | U7: Unchanged
A8: CITY-2 | B8: 2 | C8: Caherdavin | D8: Northside | E8: Private | F8: New Resi | G8: Greenfield | H8: Undeveloped/Permission Sought | I8: 2.193 | J8: 77 | K8: 0 | L8: 0 | M8: 0 | N8: 0 | O8: 77 | P8: 0 | Q8: 0 | R8: 0 | S8: 0 | U8: Reinstated: removed in council review with no reason recorded; adjoining land built under 17/470, this remainder undeveloped
A9: CITY-3 | B9: 3 | C9: Caherdavin | D9: Northside | E9: Private | F9: New Resi | G9: Brownfield | H9: Permission Granted | I9: 2.013 | J9: 343 | K9: 65 | L9: 167 | M9: 0 | N9: 232 | O9: 111 | P9: 0 | Q9: 0 | R9: 0 | S9: 2 | U9: Unchanged
A10: CITY-5 | B10: 5 | C10: Caherdavin | D10: Northside | E10: Unknown | F10: New Resi | G10: Greenfield | H10: Permission Granted | I10: 2.729 | J10: 99 | K10: 0 | L10: 99 | M10: 0 | N10: 99 | O10: 0 | P10: 0 | Q10: 0 | R10: 0 | S10: 1 | U10: Unchanged
A11: CITY-6 | B11: 6 | C11: Caherdavin | D11: Northside | E11: Unknown | F11: Local Centre | G11: Greenfield | H11: Permission Granted | I11: 0.162 | J11: 12 | K11: 0 | L11: 0 | M11: 12 | N11: 12 | O11: 0 | P11: 0 | Q11: 0 | R11: 0 | S11: 1 | U11: Unchanged
A12: CITY-7 | B12: 7 | C12: Caherdavin | D12: Northside | E12: Unknown | F12: New Resi | G12: Greenfield | H12: Permission Granted | I12: 11.8 | J12: 413 | K12: 0 | L12: 0 | M12: 251 | N12: 251 | O12: 162 | P12: 0 | Q12: 0 | R12: 0 | S12: 3 | U12: Unchanged
A13: CITY-8 | B13: 8 | C13: Caherdavin | D13: Northside | E13: Unknown | F13: New Resi | G13: Greenfield | H13: Permission Granted | I13: 2.772 | J13: 97 | K13: 0 | L13: 0 | M13: 86 | N13: 86 | O13: 11 | P13: 0 | Q13: 0 | R13: 0 | S13: 1 | U13: Unchanged
A14: CITY-9 | B14: 9 | C14: Caherdavin | D14: Northside | E14: Council | F14: Exist Resi | G14: Infill | H14: Undeveloped/Permission Sought | I14: 1.07 | J14: 48 | K14: 0 | L14: 0 | M14: 0 | N14: 0 | O14: 48 | P14: 0 | Q14: 0 | R14: 0 | S14: 0 | U14: Unchanged
A15: CITY-10 | B15: 10 | C15: Caherdavin | D15: Northside | E15: Council | F15: Exist Resi | G15: Infill | H15: Undeveloped/Permission Sought | I15: 1.991 | J15: 90 | K15: 0 | L15: 0 | M15: 0 | N15: 0 | O15: 90 | P15: 0 | Q15: 0 | R15: 0 | S15: 0 | U15: Unchanged
A16: CITY-12 | B16: 12 | C16: Caherdavin | D16: Northside | E16: Unknown | F16: Mixed Use | G16: Greenfield | H16: Permission Granted | I16: 9.431 | J16: 73 | K16: 0 | L16: 115 | M16: 0 | N16: 115 | O16: 0 | P16: 0 | Q16: 0 | R16: 0 | S16: 1 | T16: Consented above capacity | U16: Unchanged (council file landowner "EOI", owner not stated: shown as Unknown)
A17: CITY-13 | B17: 13 | C17: Caherdavin | D17: Northside | E17: Council | F17: Exist Resi | G17: Infill | H17: Undeveloped/Permission Sought | I17: 0.899 | J17: 40 | K17: 0 | L17: 0 | M17: 0 | N17: 0 | O17: 40 | P17: 0 | Q17: 0 | R17: 38 | S17: 0 | T17: Edge match – check boundary | U17: Unchanged
A18: CITY-14 | B18: 14 | C18: Caherdavin | D18: Northside | E18: Council | F18: Exist Resi | G18: Infill | H18: Complete/Commenced | I18: 0.654 | J18: 30 | K18: 0 | L18: 0 | M18: 0 | N18: 0 | O18: 30 | P18: 0 | Q18: 0 | R18: 0 | S18: 0 | T18: Register says permitted/complete but no permission linked | U18: Reduced Area
A19: CITY-15 | B19: 15 | C19: Caherdavin | D19: Northside | E19: Council | F19: New Resi | G19: Infill | H19: Undeveloped/Permission Sought | I19: 3.003 | J19: 135 | K19: 0 | L19: 0 | M19: 0 | N19: 0 | O19: 135 | P19: 0 | Q19: 0 | R19: 0 | S19: 0 | U19: Unchanged
A20: CITY-16 | B20: 16 | C20: Caherdavin | D20: Northside | E20: Council | F20: Exist Resi | G20: Infill | H20: Undeveloped/Permission Sought | I20: 0.436 | J20: 20 | K20: 0 | L20: 0 | M20: 0 | N20: 0 | O20: 20 | P20: 0 | Q20: 0 | R20: 0 | S20: 0 | U20: Unchanged
A21: CITY-20 | B21: 20 | C21: Caherdavin | D21: Northside | E21: Private | F21: Mixed Use | G21: Infill | H21: Undeveloped/Permission Sought | I21: 0.641 | J21: 29 | K21: 0 | L21: 0 | M21: 0 | N21: 0 | O21: 29 | P21: 0 | Q21: 0 | R21: 0 | S21: 0 | U21: Unchanged
A22: CITY-21 | B22: 21 | C22: Caherdavin | D22: Northside | E22: Private | F22: New Resi | G22: Brownfield | H22: Permission Granted | I22: 0.172 | J22: 31 | K22: 0 | L22: 0 | M22: 31 | N22: 31 | O22: 0 | P22: 0 | Q22: 0 | R22: 0 | S22: 1 | U22: Unchanged
A23: CITY-24 | B23: 24 | C23: Caherdavin | D23: Northside | E23: Unknown | F23: New Resi | G23: Infill | H23: Permission Granted | I23: 0.249 | J23: 46 | K23: 0 | L23: 0 | M23: 46 | N23: 46 | O23: 0 | P23: 0 | Q23: 0 | R23: 0 | S23: 1 | U23: Unchanged
A24: CITY-25 | B24: 25 | C24: Caherdavin | D24: Northside | E24: Council | F24: Exist Resi | G24: Infill | H24: Undeveloped/Permission Sought | I24: 0.125 | J24: 6 | K24: 0 | L24: 0 | M24: 0 | N24: 0 | O24: 6 | P24: 0 | Q24: 6 | R24: 0 | S24: 1 | U24: Unchanged
A25: CITY-164 | B25: 164 | C25: Caherdavin | E25: Unknown | I25: 5.112 | J25: 179 | K25: 0 | L25: 0 | M25: 0 | N25: 0 | O25: 179 | P25: 0 | Q25: 0 | R25: 0 | S25: 0 | U25: Addition
A26: CITY-53 | B26: 53 | C26: Castletroy/Annacotty | D26: Castletroy | E26: Private | F26: New Resi | G26: Infill | H26: Permission Granted | I26: 2.401 | J26: 108 | K26: 0 | L26: 0 | M26: 196 | N26: 196 | O26: 0 | P26: 0 | Q26: 0 | R26: 0 | S26: 1 | T26: Consented above capacity | U26: Unchanged
A27: CITY-54 | B27: 54 | C27: Castletroy/Annacotty | D27: Castletroy | E27: Private | F27: New Resi | G27: Infill | H27: Undeveloped/Permission Sought | I27: 1.435 | J27: 65 | K27: 0 | L27: 0 | M27: 0 | N27: 0 | O27: 65 | P27: 0 | Q27: 0 | R27: 0 | S27: 0 | U27: Unchanged
A28: CITY-56 | B28: 56 | C28: Castletroy/Annacotty | D28: Castletroy | E28: Private | F28: New Resi | G28: Infill | H28: Complete/Commenced | I28: 3.528 | J28: 123 | K28: 0 | L28: 32 | M28: 114 | N28: 146 | O28: 0 | P28: 0 | Q28: 0 | R28: 0 | S28: 2 | T28: Consented above capacity | U28: Reduced Area
A29: CITY-57 | B29: 57 | C29: Castletroy/Annacotty | D29: Castletroy | E29: Private | F29: New Resi | G29: Infill | H29: Undeveloped/Permission Sought | I29: 12.36 | J29: 508 | K29: 0 | L29: 0 | M29: 523 | N29: 523 | O29: 0 | P29: 0 | Q29: 0 | R29: 0 | S29: 1 | U29: Unchanged
A30: CITY-60 | B30: 60 | C30: Castletroy/Annacotty | D30: Castletroy | E30: Private | F30: New Resi | G30: Infill | H30: Undeveloped/Permission Sought | I30: 1.133 | J30: 51 | K30: 0 | L30: 0 | M30: 0 | N30: 0 | O30: 51 | P30: 0 | Q30: 0 | R30: 0 | S30: 0 | U30: Unchanged
A31: CITY-61 | B31: 61 | C31: Castletroy/Annacotty | D31: Castletroy | E31: Private | F31: New Resi | G31: Infill | H31: Permission Granted | I31: 2.467 | J31: 137 | K31: 0 | L31: 0 | M31: 0 | N31: 0 | O31: 137 | P31: 137 | Q31: 0 | R31: 0 | S31: 1 | T31: Register says permitted/complete but no permission linked | U31: Unchanged
A32: CITY-62 | B32: 62 | C32: Castletroy/Annacotty | D32: Castletroy | E32: Private | F32: Exist Resi | G32: Infill | H32: Undeveloped/Permission Sought | I32: 1.582 | J32: 71 | K32: 0 | L32: 0 | M32: 76 | N32: 76 | O32: 0 | P32: 0 | Q32: 0 | R32: 0 | S32: 1 | U32: Unchanged
A33: CITY-63 | B33: 63 | C33: Castletroy/Annacotty | D33: Castletroy | E33: Council | F33: New Resi | G33: Brownfield | H33: Undeveloped/Permission Sought | I33: 0.467 | J33: 21 | K33: 0 | L33: 0 | M33: 0 | N33: 0 | O33: 21 | P33: 0 | Q33: 0 | R33: 0 | S33: 0 | U33: Unchanged
A34: CITY-65 | B34: 65 | C34: Castletroy/Annacotty | D34: Castletroy | E34: Private | F34: New Resi | G34: Infill | H34: Undeveloped/Permission Sought | I34: 1.181 | J34: 53 | K34: 0 | L34: 0 | M34: 0 | N34: 0 | O34: 53 | P34: 0 | Q34: 0 | R34: 0 | S34: 0 | U34: Unchanged
A35: CITY-66 | B35: 66 | C35: Castletroy/Annacotty | D35: Castletroy | E35: Private | F35: New Resi | G35: Infill | H35: Undeveloped/Permission Sought | I35: 0.191 | J35: 7 | K35: 0 | L35: 0 | M35: 0 | N35: 0 | O35: 7 | P35: 0 | Q35: 0 | R35: 0 | S35: 0 | U35: Unchanged
A36: CITY-67 | B36: 67 | C36: Castletroy/Annacotty | D36: Castletroy | E36: Private | F36: New Resi | G36: Infill | H36: Undeveloped/Permission Sought | I36: 2.056 | J36: 72 | K36: 0 | L36: 0 | M36: 0 | N36: 0 | O36: 72 | P36: 0 | Q36: 0 | R36: 0 | S36: 0 | U36: Unchanged
A37: CITY-69 | B37: 69 | C37: Castletroy/Annacotty | D37: Castletroy | E37: Private | F37: New Resi | G37: Greenfield | H37: Undeveloped/Permission Sought | I37: 8.746 | J37: 310 | K37: 0 | L37: 0 | M37: 0 | N37: 0 | O37: 310 | P37: 0 | Q37: 0 | R37: 0 | S37: 0 | U37: Unchanged
A38: CITY-70 | B38: 70 | C38: Castletroy/Annacotty | D38: Castletroy | E38: Private | F38: New Resi | G38: Greenfield | H38: Undeveloped/Permission Sought | I38: 8.56 | J38: 375 | K38: 0 | L38: 0 | M38: 0 | N38: 0 | O38: 375 | P38: 0 | Q38: 0 | R38: 0 | S38: 0 | U38: Unchanged
A39: CITY-71 | B39: 71 | C39: Castletroy/Annacotty | D39: Castletroy | E39: Private | F39: New Resi | G39: Infill | H39: Undeveloped/Permission Sought | I39: 3.167 | J39: 141 | K39: 0 | L39: 0 | M39: 465 | N39: 465 | O39: 0 | P39: 0 | Q39: 0 | R39: 0 | S39: 1 | T39: Consented above capacity | U39: Unchanged
A40: CITY-72 | B40: 72 | C40: Castletroy/Annacotty | D40: Castletroy | E40: Private | F40: Mixed Use | G40: Greenfield | H40: Permission Granted | I40: 4.8 | J40: 216 | K40: 0 | L40: 48 | M40: 212 | N40: 260 | O40: 0 | P40: 0 | Q40: 0 | R40: 0 | S40: 2 | T40: Consented above capacity | U40: Reduced Area
...

Sheet Schemes
A1: Perm id | B1: Planning ref | C1: Scheme | D1: Neighbourhood | E1: Settlement | F1: Location | G1: Site id | H1: Sector | I1: Tenure | J1: Route | K1: Status | L1: CIS stage | M1: Units | N1: Student bedspaces | O1: Final grant | P1: Start on site | Q1: Expiry | R1: Est. start | S1: Est. last completions | T1: Confidence | U1: Basis for estimate | V1: Complete | W1: Q4 2026 | X1: 2027 | Y1: 2028 | Z1: 2029 | AA1: 2030 | AB1: 2031+ | AC1: Not projected
A2: 1363929 | B2: 2460864 | C2: €4.2m - Residential Development | D2: Corbally/Grove Island | E2: Limerick City and Suburbs | F2: Audit land – partly on / edge (check) | G2: CITY-34 | H2: Private | I2: Market (incl. Part V) | J2: Standard planning application | K2: Not started – permission live | L2: Permission Granted | M2: 15 | O2: 2025-09-18 | Q2: 2030-09-17 | R2: 2027 Q1 | S2: 2029 Q1 | T2: Medium | U2: Permitted 2025-09; typical start 1.4 yrs after grant | V2: 0 | W2: 0 | X2: 0 | Y2: 15 | Z2: 0 | AA2: 0 | AB2: 0 | AC2: 0
A3: 1347165 | B3: 2460468 | C3: €3.6m - Housing/Creche Development, Crossagalla | D3: Southhill | E3: Kilmallock | F3: Audit land – partly on / edge (check) | G3: CITY-114 | H3: Private | I3: Market (incl. Part V) | J3: Standard planning application | K3: Under construction | L3: On Site | M3: 12 | O3: 2024-10-24 | P3: 2025-01-08 | Q3: 2029-10-23 | R3: 2025 Q1 | S3: 2027 Q4 | T3: High | U3: On site: started 2025-01 | V3: 0 | W3: 2.8 | X3: 9.2 | Y3: 0 | Z3: 0 | AA3: 0 | AB3: 0 | AC3: 0
A4: 1292276 | B4: 23283 | C4: €907k - Change of Use to 4 Apartments | D4: City Centre | E4: Other County Limerick | F4: Audit land – partly on / edge (check) | G4: CITY-104 | H4: Public – AHB | I4: Social | J4: Standard planning application | K4: Not started – permission live | L4: Permission Granted | M4: 4 | O4: 2023-08-16 | Q4: 2028-08-15 | R4: 2027 Q3 | S4: 2029 Q2 | T4: Low | U4: Permitted 2023-08, past typical start date with no commencement: start assumed in 9 months | V4: 0 | W4: 0 | X4: 0 | Y4: 2.5 | Z4: 1.5 | AA4: 0 | AB4: 0 | AC4: 0
A5: 1063948 | B5: Part 8 - 1063948 | C5: €9m - Rapid Housing Delivery | D5: Caherdavin | E5: Other County Limerick | F5: Audit land – partly on / edge (check) | G5: CITY-13 | H5: Public – local authority | I5: Social | J5: Part 8 / council | K5: Under construction | L5: On Site | M5: 38 | O5: 2019-12-06 | P5: 2021-04-22 | R5: 2021 Q2 | S5: 2027 Q4 | T5: High | U5: On site: started 2021-04 | V5: 0 | W5: 8.8 | X5: 29.2 | Y5: 0 | Z5: 0 | AA5: 0 | AB5: 0 | AC5: 0
A6: 1422145 | C6: €719k - Architect Led Integrated Design Team Services for 23 Residential Units, Limerick | D6: Kings Island | E6: Limerick City and Suburbs | F6: Audit land – partly on / edge (check) | G6: CITY-35 | H6: Public – local authority | I6: Social | J6: Standard planning application | K6: Not started – permission live | L6: Contract Awarded | M6: 23 | R6: 2027 Q2 | S6: 2030 Q1 | T6: Medium | U6: Contract Awarded (CIS): start assumed within 6 months | V6: 0 | W6: 0 | X6: 0 | Y6: 9.6 | Z6: 13.1 | AA6: 0.3 | AB6: 0 | AC6: 0
A7: 1264155 | B7: Part 8 - 1264155 | C7: €590k - Residential Development / Living Georgian Project, 58 O’Connell Street | D7: City Centre | E7: Other County Limerick | F7: Audit land – partly on / edge (check) | G7: CITY-93 | H7: Public – local authority | I7: Social | J7: Part 8 / council | K7: Not started – permission live | L7: Permission Granted | M7: 8 | O7: 2022-04-08 | R7: 2027 Q3 | S7: 2029 Q3 | T7: Low | U7: Permitted 2022-04, past typical start date with no commencement: start assumed in 9 months | V7: 0 | W7: 0 | X7: 0 | Y7: 4 | Z7: 4 | AA7: 0 | AB7: 0 | AC7: 0
A8: 1412368 | B8: PT8LL277 | C8: €1.5m - 5 Residential Units, Limerick | D8: Southhill | E8: Limerick City and Suburbs | F8: Audit land – partly on / edge (check) | G8: CITY-111 | H8: Public – local authority | I8: Social | J8: Part 8 / council | K8: Not started – permission live | L8: Tender | M8: 5 | O8: 2025-12-15 | R8: 2027 Q2 | S8: 2029 Q1 | T8: Medium | U8: At tender (CIS): start assumed in 6–12 months | V8: 0 | W8: 0 | X8: 0 | Y8: 4.4 | Z8: 0.6 | AA8: 0 | AB8: 0 | AC8: 0
A9: 1378081 | B9: Part 8 - 1378081 | C9: €879k - 4 Houses | D9: Southhill | E9: Limerick City and Suburbs | F9: Audit land – partly on / edge (check) | G9: CITY-127 | H9: Public – local authority | I9: Social | J9: Part 8 / council | K9: In planning | L9: Plans Submitted | M9: 4 | T9: Not projected | U9: Not yet decided – not projected | V9: 0 | W9: 0 | X9: 0 | Y9: 0 | Z9: 0 | AA9: 0 | AB9: 0 | AC9: 4
A10: 1417205 | C10: €1.4m - Architect Led Integrated Design Team for College Avenue Infill Housing Scheme, Moyross | D10: Caherdavin | E10: Limerick City and Suburbs | F10: Audit land – partly on / edge (check) | G10: CITY-14 | H10: Public – local authority | I10: Social | J10: Standard planning application | K10: Not started – permission live | L10: Contract Awarded | M10: 0 | T10: Not projected | U10: No units | V10: 0 | W10: 0 | X10: 0 | Y10: 0 | Z10: 0 | AA10: 0 | AB10: 0 | AC10: 0
A11: 1446288 | B11: 2660241 | C11: €125.6m - Large Residential Development, Castletroy | D11: Castletroy/Annacotty | E11: Limerick City and Suburbs | F11: Audit land – within site | G11: CITY-57 | H11: Private | I11: Market (incl. Part V) | J11: LRD | K11: Not started – permission live | L11: Permission Granted | M11: 523 | O11: 2026-04-28 | Q11: 2031-09-01 | R11: 2028 Q1 | S11: 2038 Q2 | T11: Medium | U11: Permitted 2026-04; typical start 1.7 yrs after grant | V11: 0 | W11: 0 | X11: 0 | Y11: 0 | Z11: 53.2 | AA11: 55.6 | AB11: 414.2 | AC11: 0
A12: 1423228 | B12: 2660089 | C12: €42m - Large Residential Development, Castletroy | D12: Castletroy/Annacotty | E12: Limerick City and Suburbs | F12: Audit land – within site | G12: CITY-71 | H12: Private | I12: Student (PBSA) | J12: LRD | K12: Not started – permission live | L12: Permission Granted | M12: 465 | N12: 309 | O12: 2026-07-22 | Q12: 2031-07-21 | R12: 2028 Q2 | S12: 2037 Q3 | T12: Medium | U12: Permitted 2026-07; typical start 1.7 yrs after grant | V12: 0 | W12: 0 | X12: 0 | Y12: 0 | Z12: 40.8 | AA12: 56.4 | AB12: 367.8 | AC12: 0
A13: 1437215 | B13: 2660603 | C13: €84m - Parkway Valley LRD, Singland | D13: Southhill | E13: Other County Limerick | F13: Audit land – within site | G13: CITY-76 | H13: Private | I13: Market (incl. Part V) | J13: LRD | K13: Not started – permission live | L13: Permission Granted | M13: 403 | O13: 2026-07-22 | Q13: 2031-07-22 | R13: 2028 Q2 | S13: 2036 Q2 | T13: Medium | U13: Permitted 2026-07; typical start 1.7 yrs after grant | V13: 0 | W13: 0 | X13: 0 | Y13: 0 | Z13: 41.6 | AA13: 57.4 | AB13: 304 | AC13: 0
A14: 1221693 | B14: ABPREF313124 | C14: €76m - Residential Development, Raheen | D14: Dooradoyle | E14: Limerick City and Suburbs | F14: Audit land – within site | G14: CITY-136 | H14: Private | I14: Market (incl. Part V) | J14: SHD (An Bord Pleanála) | K14: Under construction | L14: Commencement Expected | M14: 384 | O14: 2022-06-30 | P14: 2024-04-24 | Q14: 2032-06-29 | R14: 2024 Q2 | S14: 2031 Q4 | T14: High | U14: On site: started 2024-04 | V14: 0 | W14: 17.2 | X14: 74.1 | Y14: 74.1 | Z14: 74.1 | AA14: 74.1 | AB14: 70.4 | AC14: 0
A15: 1194302 | B15: ABPREF311588 | C15: €66m - Greenpark SHD Residential Development, Dock Road, Limerick | D15: Ballinacurra | E15: Other County Limerick | F15: Audit land – within site | G15: CITY-133 | H15: Private | I15: Market (incl. Part V) | J15: SHD (An Bord Pleanála) | K15: Under construction | L15: On Site | M15: 371 | O15: 2022-03-30 | P15: 2023-07-31 | Q15: 2027-03-29 | R15: 2023 Q3 | S15: 2030 Q4 | T15: High | U15: On site: started 2023-07 | V15: 0 | W15: 20.6 | X15: 88.5 | Y15: 88.5 | Z15: 88.5 | AA15: 84.9 | AB15: 0 | AC15: 0
A16: 1428325 | B16: 2660275 | C16: €42m - Large Residential Development,Limerick | D16: Castletroy/Annacotty | E16: Limerick City and Suburbs | F16: Audit land – within site | G16: CITY-72 | H16: Private | I16: Market (incl. Part V) | J16: LRD | K16: Not started – permission live | L16: Permission Granted | M16: 212 | O16: 2026-09-23 | Q16: 2031-09-22 | R16: 2028 Q2 | S16: 2032 Q3 | T16: Medium | U16: Permitted 2026-09; typical start 1.7 yrs after grant | V16: 0 | W16: 0 | X16: 0 | Y16: 0 | Z16: 36.4 | AA16: 65.9 | AB16: 109.7 | AC16: 0
A17: 1389800 | B17: 2560113 | C17: €87m - Student Accommodation, Castletroy | D17: Castletroy/Annacotty | E17: Limerick City and Suburbs | F17: Audit land – within site | G17: CITY-53 | H17: Private | I17: Student (PBSA) | J17: LRD | K17: Not started – permission live | L17: Commencement Expected | M17: 196 | N17: 1400 | O17: 2025-10-29 | Q17: 2030-10-28 | R17: 2027 Q2 | S17: 2029 Q2 | T17: Medium | U17: Commencement Expected (CIS): start assumed within 6 months; student block completes in one go | V17: 0 | W17: 0 | X17: 0 | Y17: 0 | Z17: 196 | AA17: 0 | AB17: 0 | AC17: 0
A18: 1432711 | B18: 2660396 | C18: €39m - Large Residential Development, Mungret | D18: Dooradoyle | E18: Mungret | F18: Audit land – within site | G18: CITY-144 | H18: Private | I18: Market (incl. Part V) | J18: LRD | K18: Not started – permission live | L18: Permission Granted | M18: 182 | O18: 2026-09-15 | Q18: 2031-09-15 | R18: 2028 Q2 | S18: 2032 Q1 | T18: Medium | U18: Permitted 2026-09; typical start 1.7 yrs after grant | V18: 0 | W18: 0 | X18: 0 | Y18: 0 | Z18: 39.8 | AA18: 69.4 | AB18: 72.8 | AC18: 0
A19: 1417769 | B19: 2561231 | C19: €32.5m - Large Residential Development, Mungret | D19: Dooradoyle | E19: Mungret | F19: Audit land – within site | G19: CITY-144 | H19: Private | I19: Market (incl. Part V) | J19: LRD | K19: Not started – permission live | L19: Permission Granted | M19: 169 | O19: 2026-07-30 | Q19: 2031-07-30 | R19: 2028 Q2 | S19: 2031 Q3 | T19: Medium | U19: Permitted 2026-07; typical start 1.7 yrs after grant | V19: 0 | W19: 0 | X19: 0 | Y19: 0 | Z19: 50.3 | AA19: 71.5 | AB19: 47.2 | AC19: 0
A20: 1319462 | B20: 23557 | C20: €33m - LRD Development, Limerick | D20: Caherdavin | E20: Other County Limerick | F20: Audit land – within site | G20: CITY-3 | H20: Private | I20: Market (incl. Part V) | J20: LRD | K20: Under construction | L20: On Site | M20: 167 | O20: 2024-08-23 | P20: 2025-09-04 | Q20: 2029-08-22 | R20: 2025 Q3 | S20: 2029 Q1 | T20: High | U20: On site: started 2025-09 | V20: 0 | W20: 17.4 | X20: 74.9 | Y20: 74.6 | Z20: 0 | AA20: 0 | AB20: 0.1 | AC20: 0
A21: 1214059 | B21: ABPREF312683 | C21: €27.5m - Clonmacken Gardens Housing Development, Limerick | D21: Caherdavin | E21: Other County Limerick | F21: Audit land – within site | G21: CITY-1 | H21: Private | I21: Market (incl. Part V) | J21: SHD (An Bord Pleanála) | K21: Not started – permission live | L21: Permission Granted | M21: 165 | O21: 2022-05-26 | Q21: 2027-05-25 | R21: 2027 Q3 | S21: 2030 Q4 | T21: Low | U21: Permitted 2022-05, past typical start date with no commencement: start assumed in 9 months; expiry falls before assumed start | V21: 0 | W21: 0 | X21: 0 | Y21: 34.9 | Z21: 72.3 | AA21: 57.8 | AB21: 0 | AC21: 0
A22: 1382991 | B22: 2461282 | C22: €32m - LRD, Mungret | D22: Dooradoyle | E22: Mungret | F22: Audit land – within site | G22: CITY-143 | H22: Private | I22: Market (incl. Part V) | J22: LRD | K22: Not started – permission live | L22: Permission Granted | M22: 139 | O22: 2025-09-24 | Q22: 2030-09-23 | R22: 2027 Q2 | S22: 2030 Q1 | T22: Medium | U22: Permitted 2025-09; typical start 1.7 yrs after grant | V22: 0 | W22: 0 | X22: 0 | Y22: 43.2 | Z22: 78.7 | AA22: 17 | AB22: 0.1 | AC22: 0
A23: 1163033 | B23: ABPREF309999 | C23: €30m - Residential Development, Annacotty | D23: Castletroy/Annacotty | E23: Annacotty | F23: Audit land – within site | G23: CITY-61 | H23: Private | I23: Market (incl. Part V) | J23: SHD (An Bord Pleanála) | K23: Not started – past expiry | L23: Permission Granted | M23: 137 | O23: 2021-08-05 | Q23: 2026-08-04 | T23: Not projected | U23: Permission expired – not projected | V23: 0 | W23: 0 | X23: 0 | Y23: 0 | Z23: 0 | AA23: 0 | AB23: 0 | AC23: 137
A24: 1397299 | B24: 2560271 | C24: €21m - Residential Development, Castletroy | D24: Castletroy/Annacotty | E24: Limerick City and Suburbs | F24: Audit land – within site | G24: CITY-56 | H24: Private | I24: Market (incl. Part V) | J24: LRD | K24: Not started – permission live | L24: Permission Granted | M24: 114 | O24: 2026-04-15 | Q24: 2031-04-14 | R24: 2028 Q1 | S24: 2030 Q2 | T24: Medium | U24: Permitted 2026-04; typical start 1.7 yrs after grant | V24: 0 | W24: 0 | X24: 0 | Y24: 0 | Z24: 89.3 | AA24: 24.7 | AB24: 0 | AC24: 0
A25: 1207014 | B25: 211800 | C25: €21m - Residential Development, Old Cratloe Road | D25: Caherdavin | E25: Other County Limerick | F25: Audit land – within site | G25: CITY-7 | H25: Private | I25: Market (incl. Part V) | J25: Standard planning application | K25: Not started – permission live | L25: Permission Granted | M25: 99 | O25: 2024-04-08 | Q25: 2029-04-07 | R25: 2027 Q3 | S25: 2030 Q2 | T25: Low | U25: Permitted 2024-04, past typical start date with no commencement: start assumed in 9 months | V25: 0 | W25: 0 | X25: 0 | Y25: 25.1 | Z25: 51.9 | AA25: 22 | AB25: 0 | AC25: 0
A26: 1327848 | B26: 2460032 | C26: €18.9m - Residential Development, Old Cratloe Road | D26: Caherdavin | E26: Other County Limerick | F26: Audit land – within site | G26: CITY-5 | H26: Private | I26: Market (incl. Part V) | J26: Standard planning application | K26: Under construction | L26: On Site | M26: 99 | O26: 2024-08-20 | P26: 2025-08-20 | Q26: 2029-08-19 | R26: 2025 Q3 | S26: 2028 Q3 | T26: High | U26: On site: started 2025-08 | V26: 0 | W26: 13 | X26: 55.8 | Y26: 30.2 | Z26: 0 | AA26: 0 | AB26: 0 | AC26: 0
A27: 1248019 | B27: 22959 | C27: €20m - Residential Development, Limerick. | D27: Caherdavin | E27: Other County Limerick | F27: Audit land – within site | G27: CITY-7 | H27: Private | I27: Market (incl. Part V) | J27: Standard planning application | K27: Not started – permission live | L27: Permission Granted | M27: 98 | O27: 2024-11-21 | Q27: 2029-11-20 | R27: 2027 Q3 | S27: 2030 Q2 | T27: Low | U27: Permitted 2024-11, past typical start date with no commencement: start assumed in 9 months | V27: 0 | W27: 0 | X27: 0 | Y27: 25.2 | Z27: 52.2 | AA27: 20.6 | AB27: 0 | AC27: 0
A28: 1242233 | B28: 22817 | C28: €11m - Residential Development, Limerick | D28: Caherdavin | E28: Other County Limerick | F28: Audit land – within site | G28: CITY-8 | H28: Private | I28: Market (incl. Part V) | J28: Standard planning application | K28: Not started – permission live | L28: Permission Granted | M28: 86 | O28: 2023-07-04 | Q28: 2028-07-03 | R28: 2027 Q3 | S28: 2030 Q1 | T28: Low | U28: Permitted 2023-07, past typical start date with no commencement: start assumed in 9 months | V28: 0 | W28: 0 | X28: 0 | Y28: 27.2 | Z28: 56.4 | AA28: 2.4 | AB28: 0 | AC28: 0
A29: 1402906 | B29: 2560399 | C29: €16.4m - Residential Development | D29: Castletroy/Annacotty | E29: Annacotty | F29: Audit land – within site | G29: CITY-62 | H29: Private | I29: Market (incl. Part V) | J29: Standard planning application | K29: Not started – permission live | L29: Permission Granted | M29: 76 | O29: 2026-07-13 | Q29: 2031-07-12 | R29: 2027 Q3 | S29: 2029 Q4 | T29: Medium | U29: Permitted 2026-07; typical start 1.1 yrs after grant | V29: 0 | W29: 0 | X29: 0 | Y29: 20.9 | Z29: 55.1 | AA29: 0 | AB29: 0 | AC29: 0
A30: 1172151 | B30: 217025 | C30: €3.7m - Ardhú Apartments Refurbishment, Ennis Road | D30: Caherdavin | E30: Other County Limerick | F30: Audit land – within site | G30: CITY-3 | H30: Private | I30: Market (incl. Part V) | J30: Standard planning application | K30: Complete | L30: Complete | M30: 65 | O30: 2021-07-14 | P30: 2022-08-29 | Q30: 2026-11-19 | T30: Delivered | U30: Complete (CIS) | V30: 65 | W30: 0 | X30: 0 | Y30: 0 | Z30: 0 | AA30: 0 | AB30: 0 | AC30: 0
A31: 1164424 | B31: 21580 | C31: €9.6m - Residential Development | D31: Singland/Garryowen | E31: Limerick City and Suburbs | F31: Audit land – within site | G31: CITY-79 | H31: Private | I31: Market (incl. Part V) | J31: Standard planning application | K31: Not started – permission live | L31: Contract Awarded | M31: 55 | O31: 2025-05-13 | Q31: 2030-05-12 | R31: 2027 Q1 | S31: 2029 Q2 | T31: Medium | U31: Contract Awarded (CIS): start assumed within 6 months | V31: 0 | W31: 0 | X31: 0 | Y31: 42.9 | Z31: 12.1 | AA31: 0 | AB31: 0 | AC31: 0
A32: 1254544 | B32: 221114 | C32: €12.2m - Residential Development, Limerick | D32: Caherdavin | E32: Other County Limerick | F32: Audit land – within site | G32: CITY-7 | H32: Private | I32: Market (incl. Part V) | J32: Standard planning application | K32: Not started – permission live | L32: Permission Granted | M32: 54 | O32: 2024-10-18 | Q32: 2029-10-17 | R32: 2027 Q3 | S32: 2029 Q4 | T32: Low | U32: Permitted 2024-10, past typical start date with no commencement: start assumed in 9 months | V32: 0 | W32: 0 | X32: 0 | Y32: 20.7 | Z32: 33.3 | AA32: 0 | AB32: 0 | AC32: 0
A33: 1247398 | B33: 22950 | C33: €13.9m - Lidl Mixed Use Development , Ballysimon | D33: Castletroy/Annacotty | E33: Limerick City and Suburbs | F33: Audit land – within site | G33: CITY-72 | H33: Private | I33: Market (incl. Part V) | J33: Standard planning application | K33: Under construction | L33: On Site | M33: 48 | O33: 2023-09-05 | P33: 2024-07-15 | Q33: 2028-09-04 | R33: 2024 Q3 | S33: 2027 Q4 | T33: High | U33: On site: started 2024-07 | V33: 0 | W33: 11.2 | X33: 36.8 | Y33: 0 | Z33: 0 | AA33: 0 | AB33: 0 | AC33: 0
A34: 1265188 | B34: 221400 | C34: €10.4m - Residential Development, Thomondgate | D34: Caherdavin | E34: Other County Limerick | F34: Audit land – within site | G34: CITY-24 | H34: Private | I34: Market (incl. Part V) | J34: Standard planning application | K34: Not started – permission live | L34: Permission Granted | M34: 46 | O34: 2024-07-26 | Q34: 2029-07-25 | R34: 2027 Q3 | S34: 2029 Q3 | T34: Low | U34: Permitted 2024-07, past typical start date with no commencement: start assumed in 9 months | V34: 0 | W34: 0 | X34: 0 | Y34: 19.4 | Z34: 26.6 | AA34: 0 | AB34: 0 | AC34: 0
A35: 973082 | B35: 1855 | C35: €4.8m - Residential Development, Castletroy | D35: Castletroy/Annacotty | E35: Limerick City and Suburbs | F35: Audit land – within site | G35: CITY-56 | H35: Private | I35: Market (incl. Part V) | J35: Standard planning application | K35: Under construction | L35: Commencement Expected | M35: 32 | O35: 2018-07-04 | P35: 2018-08-08 | Q35: 2023-07-03 | R35: 2018 Q3 | S35: 2027 Q4 | T35: High | U35: On site: started 2018-08 | V35: 0 | W35: 7.5 | X35: 24.5 | Y35: 0 | Z35: 0 | AA35: 0 | AB35: 0 | AC35: 0
A36: 1058796 | B36: 19710 | C36: €8.5m - Student Accommodation Development, Former Hassett’s Bar | D36: Caherdavin | E36: Other County Limerick | F36: Audit land – within site | G36: CITY-21 | H36: Private | I36: Student (PBSA) | J36: Standard planning application | K36: Stalled (CIS) | L36: Stalled or Suspended | M36: 31 | O36: 2021-03-15 | Q36: 2029-03-13 | T36: Not projected | U36: Stalled – not projected | V36: 0 | W36: 0 | X36: 0 | Y36: 0 | Z36: 0 | AA36: 0 | AB36: 0 | AC36: 31
